Workbook

Sheet 0-MetaPro_2026
A1: Código Dpto | B1: Departamento | C1: Municipio | D1: Divipola | E1: Meta Programatica2026 (20251228) RN | F1: Meta Mensual RN | G1: Población meta programatica 2026 (20251228) menores 1 año | H1: Meta Mensual Menores de 1 año | I1: Población meta programatica2026 (20251228) niños de 1 año | J1: Meta mensual 100% | K1: POB. Susceptibles FIEBRE AMARILLA 01/01/2025 9m_23m | L1: Población meta programatica2026 (20251228) niños de 5 años | M1: Meta Mensual de 5 años | N1: Población VPH NIÑAS DE 9 AÑOS Est_Deno_20260317 | O1: Poblacion VPH Niños de 9 años Est_Deno_20260317 | P1: Poblacion DANE De 60 años y mas 30% | Q1: Columna1 | R1: DEPARTAMENTO | S1: CODEP | T1: Meta Programatica2026 (20251228) RN | U1: Poblaciòn Menor de 1 año (Meta Programática 2026) | V1: Poblaciòn de 1 año (Meta Programática 2026) | W1: Pob. 5 años (Meta Programática 2026) | X1: Poblacion de 9 años DANE NIÑAS | Y1: Poblacion de 9 años DANE NIÑOS | Z1: Poblacion de 10 años | AA1: Poblacion de 11 años | AB1: Poblacion de 12 años | AC1: Poblacion de 13 años | AD1: Poblacion de 14 años | AE1: Poblacion de 15 años | AF1: Poblacion de 16 años | AG1: Poblacion de 17 años | AI1: Codepmure | AK1: Total_60 AÑOS | AL1: Total_61 | AM1: Total_62 | AN1: Total_63 | AO1: Total_64 | AP1: Total_65 | AQ1: Total_66 | AR1: Total_67 | AS1: Total_68 | AT1: Total_69 | AU1: Total_70 | AV1: Total_71 | AW1: Total_72 | AX1: Total_73 | AY1: Total_74 | AZ1: Total_75 | BA1: Total_76 | BB1: Total_77 | BC1: Total_78 | BD1: Total_79 | BE1: Total_80 | BF1: Total_81 | BG1: Total_82 | BH1: Total_83 | BI1: Total_84 | BJ1: Total_85 y más | BK1: TOTAL 60 AÑOS Y MAS | BL1: POBLACION 60 AÑOS Y MAS (30%) DANE | BM1: 0.3 | BP1: POBLACION DE FLU 2025 MENORES 1 AÑO PARA 9 MESES | BQ1: POBLACION DE FLU 2025 GESTANTES PARA 9 MESES | BR1: POBLACION DE FLU 2025 ADULTOS 60 AÑOS Y MAS PARA 9 MESES | BS1: POBLACION DE FLU 2025 NIÑOS DE 12 A 23 MESES PARA 9 MESES | BT1: DOSIS APLICADAS INFLUENZA DE 6 MESES A 11 MESES 2a 2024 | BU1: DENOMINADOR ESPERADO PARA NIÑOS 12 A 23 MESES DOSIS UNICA | BX1: Población VPH NIÑAS DE 9 AÑOS Est_Deno_20260317 | BY1: Poblacion VPH Niños de 9 años Est_Deno_20260317
A2: 05 | B2: ANTIOQUIA | C2: MEDELLIN | D2: 05001 | E2: 25883 | F2: =Tabla1[[#This Row],[Meta Programatica2026 (20251228) RN]]/12 | G2: 17132 | H2: =Tabla1[[#This Row],[Población meta programatica 2026 (20251228) menores 1 año]]/12 | I2: 17429 | J2: =Tabla1[[#This Row],[Población meta programatica2026 (20251228) niños de 1 año]]/12 | K2: 23411 | L2: 22448 | M2: =Tabla1[[#This Row],[Población meta programatica2026 (20251228) niños de 5 años]]/12 | N2: =BX2 | O2: =BY2 | P2: =BL2 | R2: ANTIOQUIA | S2: 05 | T2: =SUMIF($A$2:$A$1123,S2,$E$2:$E$1123) | U2: =SUMIF($A$2:$A$1123,S2,$G$2:$G$1123) | V2: =SUMIF($A$2:$A$1123,S2,$I$2:$I$1123) | W2: =SUMIF($A$2:$A$1123,$S2,$L$2:$L$1123) | X2: =SUMIF($A$2:$A$1123,$S2,$N$2:$N$1123) | Y2: =SUMIF($A$2:$A$1123,$S2,$O$2:$O$1123) | AI2: 05001 | AJ2: =AI2=Tabla1[[#This Row],[Divipola]] | AK2: 31197 | AL2: 30703 | AM2: 29961 | AN2: 29092 | AO2: 28095 | AP2: 27005 | AQ2: 25899 | AR2: 24727 | AS2: 23488 | AT2: 22195 | AU2: 20892 | AV2: 19603 | AW2: 18303 | AX2: 17043 | AY2: 15768 | AZ2: 14550 | BA2: 13392 | BB2: 12252 | BC2: 11175 | BD2: 10115 | BE2: 9082 | BF2: 8094 | BG2: 7136 | BH2: 6252 | BI2: 5420 | BJ2: 26845 | BK2: =SUM(AK2:BJ2) | BL2: =INT(BK2*$BM$1) | BP2: =(Tabla1[[#This Row],[Población meta programatica 2026 (20251228) menores 1 año]]/12)*9 | BQ2: =BP2 | BS2: =(Tabla1[[#This Row],[Población meta programatica2026 (20251228) niños de 1 año]]/12)*9 | BT2: 10684 | BU2: =BS2-BT2 | BX2: 14750 | BY2: 15450 | BZ2: 05001 | CA2: =BZ2=Tabla1[[#This Row],[Divipola]]
A3: 05 | B3: ANTIOQUIA | C3: ABEJORRAL | D3: 05002 | E3: 51 | F3: =Tabla1[[#This Row],[Meta Programatica2026 (20251228) RN]]/12 | G3: 115 | H3: =Tabla1[[#This Row],[Población meta programatica 2026 (20251228) menores 1 año]]/12 | I3: 137 | J3: =Tabla1[[#This Row],[Población meta programatica2026 (20251228) niños de 1 año]]/12 | K3: 183 | L3: 163 | M3: =Tabla1[[#This Row],[Población meta programatica2026 (20251228) niños de 5 años]]/12 | N3: =BX3 | O3: =BY3 | P3: =BL3 | R3: ATLANTICO | S3: 08 | T3: =SUMIF($A$2:$A$1123,S3,$E$2:$E$1123) | U3: =SUMIF($A$3:$A$1122,S3,$G$3:$G$1122) | V3: =SUMIF($A$3:$A$1122,S3,$I$3:$I$1122) | W3: =SUMIF($A$2:$A$1123,$S3,$L$2:$L$1123) | X3: =SUMIF($A$2:$A$1123,$S3,$N$2:$N$1123) | Y3: =SUMIF($A$2:$A$1123,$S3,$O$2:$O$1123) | AI3: 05002 | AJ3: =AI3=Tabla1[[#This Row],[Divipola]] | AK3: 298 | AL3: 307 | AM3: 301 | AN3: 295 | AO3: 287 | AP3: 277 | AQ3: 264 | AR3: 248 | AS3: 234 | AT3: 224 | AU3: 207 | AV3: 192 | AW3: 183 | AX3: 175 | AY3: 165 | AZ3: 151 | BA3: 138 | BB3: 133 | BC3: 122 | BD3: 108 | BE3: 98 | BF3: 91 | BG3: 80 | BH3: 68 | BI3: 59 | BJ3: 253 | BK3: =SUM(AK3:BJ3) | BL3: =INT(BK3*$BM$1) | BP3: =(Tabla1[[#This Row],[Población meta programatica 2026 (20251228) menores 1 año]]/12)*9 | BQ3: =BP3 | BS3: =(Tabla1[[#This Row],[Población meta programatica2026 (20251228) niños de 1 año]]/12)*9 | BT3: 80 | BU3: =BS3-BT3 | BX3: 112 | BY3: 108 | BZ3: 05002 | CA3: =BZ3=Tabla1[[#This Row],[Divipola]]
A4: 05 | B4: ANTIOQUIA | C4: ABRIAQUI | D4: 05004 | E4: 2 | F4: =Tabla1[[#This Row],[Meta Programatica2026 (20251228) RN]]/12 | G4: 12 | H4: =Tabla1[[#This Row],[Población meta programatica 2026 (20251228) menores 1 año]]/12 | I4: 13 | J4: =Tabla1[[#This Row],[Población meta programatica2026 (20251228) niños de 1 año]]/12 | K4: 21 | L4: 21 | M4: =Tabla1[[#This Row],[Población meta programatica2026 (20251228) niños de 5 años]]/12 | N4: =BX4 | O4: =BY4 | P4: =BL4 | R4: BARRANQUILLA | S4: 08001 | T4: =SUMIF($A$2:$A$1123,S4,$E$2:$E$1123) | U4: =SUMIF($D$3:$D$1122,S4,$G$3:$G$1122) | V4: =SUMIF($D$3:$D$1122,S4,$I$3:$I$1122) | W4: =SUMIF($D$3:$D$1122,$S4,$L$3:$L$1122) | X4: =SUMIF($A$2:$A$1123,$S4,$N$2:$N$1123) | Y4: =SUMIF($A$2:$A$1123,$S4,$O$2:$O$1123) | AI4: 05004 | AJ4: =AI4=Tabla1[[#This Row],[Divipola]] | AK4: 33 | AL4: 28 | AM4: 31 | AN4: 28 | AO4: 29 | AP4: 29 | AQ4: 29 | AR4: 25 | AS4: 23 | AT4: 27 | AU4: 23 | AV4: 25 | AW4: 24 | AX4: 20 | AY4: 22 | AZ4: 20 | BA4: 20 | BB4: 16 | BC4: 17 | BD4: 16 | BE4: 13 | BF4: 16 | BG4: 14 | BH4: 12 | BI4: 10 | BJ4: 34 | BK4: =SUM(AK4:BJ4) | BL4: =INT(BK4*$BM$1) | BP4: =(Tabla1[[#This Row],[Población meta programatica 2026 (20251228) menores 1 año]]/12)*9 | BQ4: =BP4 | BS4: =(Tabla1[[#This Row],[Población meta programatica2026 (20251228) niños de 1 año]]/12)*9 | BT4: 6 | BU4: =BS4-BT4 | BX4: 11 | BY4: 15 | BZ4: 05004 | CA4: =BZ4=Tabla1[[#This Row],[Divipola]]
A5: 05 | B5: ANTIOQUIA | C5: ALEJANDRIA | D5: 05021 | E5: 6 | F5: =Tabla1[[#This Row],[Meta Programatica2026 (20251228) RN]]/12 | G5: 30 | H5: =Tabla1[[#This Row],[Población meta programatica 2026 (20251228) menores 1 año]]/12 | I5: 28 | J5: =Tabla1[[#This Row],[Población meta programatica2026 (20251228) niños de 1 año]]/12 | K5: 37 | L5: 43 | M5: =Tabla1[[#This Row],[Población meta programatica2026 (20251228) niños de 5 años]]/12 | N5: =BX5 | O5: =BY5 | P5: =BL5 | R5: BOGOTA | S5: 11 | T5: =SUMIF($A$2:$A$1123,S5,$E$2:$E$1123) | U5: =SUMIF($A$3:$A$1122,S5,$G$3:$G$1122) | V5: =SUMIF($A$3:$A$1122,S5,$I$3:$I$1122) | W5: =SUMIF($A$2:$A$1123,$S5,$L$2:$L$1123) | X5: =SUMIF($A$2:$A$1123,$S5,$N$2:$N$1123) | Y5: =SUMIF($A$2:$A$1123,$S5,$O$2:$O$1123) | AI5: 05021 | AJ5: =AI5=Tabla1[[#This Row],[Divipola]] | AK5: 62 | AL5: 57 | AM5: 61 | AN5: 56 | AO5: 56 | AP5: 51 | AQ5: 48 | AR5: 48 | AS5: 47 | AT5: 43 | AU5: 42 | AV5: 41 | AW5: 41 | AX5: 40 | AY5: 36 | AZ5: 34 | BA5: 38 | BB5: 31 | BC5: 34 | BD5: 27 | BE5: 29 | BF5: 21 | BG5: 20 | BH5: 15 | BI5: 16 | BJ5: 73 | BK5: =SUM(AK5:BJ5) | BL5: =INT(BK5*$BM$1) | BP5: =(Tabla1[[#This Row],[Población meta programatica 2026 (20251228) menores 1 año]]/12)*9 | BQ5: =BP5 | BS5: =(Tabla1[[#This Row],[Población meta programatica2026 (20251228) niños de 1 año]]/12)*9 | BT5: 12 | BU5: =BS5-BT5 | BX5: 29 | BY5: 31 | BZ5: 05021 | CA5: =BZ5=Tabla1[[#This Row],[Divipola]]
A6: 05 | B6: ANTIOQUIA | C6: AMAGA | D6: 05030 | E6: 39 | F6: =Tabla1[[#This Row],[Meta Programatica2026 (20251228) RN]]/12 | G6: 189 | H6: =Tabla1[[#This Row],[Población meta programatica 2026 (20251228) menores 1 año]]/12 | I6: 205 | J6: =Tabla1[[#This Row],[Población meta programatica2026 (20251228) niños de 1 año]]/12 | K6: 273 | L6: 236 | M6: =Tabla1[[#This Row],[Población meta programatica2026 (20251228) niños de 5 años]]/12 | N6: =BX6 | O6: =BY6 | P6: =BL6 | R6: BOLIVAR | S6: 13 | T6: =SUMIF($A$2:$A$1123,S6,$E$2:$E$1123) | U6: =SUMIF($A$3:$A$1122,S6,$G$3:$G$1122) | V6: =SUMIF($A$3:$A$1122,S6,$I$3:$I$1122) | W6: =SUMIF($A$2:$A$1123,$S6,$L$2:$L$1123) | X6: =SUMIF($A$2:$A$1123,$S6,$N$2:$N$1123) | Y6: =SUMIF($A$2:$A$1123,$S6,$O$2:$O$1123) | AI6: 05030 | AJ6: =AI6=Tabla1[[#This Row],[Divipola]] | AK6: 406 | AL6: 400 | AM6: 385 | AN6: 370 | AO6: 351 | AP6: 337 | AQ6: 318 | AR6: 299 | AS6: 282 | AT6: 265 | AU6: 249 | AV6: 231 | AW6: 218 | AX6: 202 | AY6: 180 | AZ6: 171 | BA6: 151 | BB6: 141 | BC6: 125 | BD6: 116 | BE6: 103 | BF6: 96 | BG6: 80 | BH6: 75 | BI6: 61 | BJ6: 319 | BK6: =SUM(AK6:BJ6) | BL6: =INT(BK6*$BM$1) | BP6: =(Tabla1[[#This Row],[Población meta programatica 2026 (20251228) menores 1 año]]/12)*9 | BQ6: =BP6 | BS6: =(Tabla1[[#This Row],[Población meta programatica2026 (20251228) niños de 1 año]]/12)*9 | BT6: 127 | BU6: =BS6-BT6 | BX6: 136 | BY6: 150 | BZ6: 05030 | CA6: =BZ6=Tabla1[[#This Row],[Divipola]]
A7: 05 | B7: ANTIOQUIA | C7: AMALFI | D7: 05031 | E7: 55 | F7: =Tabla1[[#This Row],[Meta Programatica2026 (20251228) RN]]/12 | G7: 224 | H7: =Tabla1[[#This Row],[Población meta programatica 2026 (20251228) menores 1 año]]/12 | I7: 245 | J7: =Tabla1[[#This Row],[Población meta programatica2026 (20251228) niños de 1 año]]/12 | K7: 362 | L7: 274 | M7: =Tabla1[[#This Row],[Población meta programatica2026 (20251228) niños de 5 años]]/12 | N7: =BX7 | O7: =BY7 | P7: =BL7 | R7: CARTAGENA | S7: 13001 | T7: =SUMIF($A$2:$A$1123,S7,$E$2:$E$1123) | U7: =SUMIF($D$3:$D$1122,S7,$G$3:$G$1122) | V7: =SUMIF($D$3:$D$1122,S7,$I$3:$I$1122) | W7: =SUMIF($D$3:$D$1122,$S7,$L$3:$L$1122) | X7: =SUMIF($A$2:$A$1123,$S7,$N$2:$N$1123) | Y7: =SUMIF($A$2:$A$1123,$S7,$O$2:$O$1123) | AI7: 05031 | AJ7: =AI7=Tabla1[[#This Row],[Divipola]] | AK7: 267 | AL7: 260 | AM7: 256 | AN7: 249 | AO7: 238 | AP7: 231 | AQ7: 227 | AR7: 214 | AS7: 205 | AT7: 193 | AU7: 183 | AV7: 171 | AW7: 156 | AX7: 146 | AY7: 135 | AZ7: 123 | BA7: 114 | BB7: 104 | BC7: 96 | BD7: 85 | BE7: 80 | BF7: 71 | BG7: 64 | BH7: 59 | BI7: 51 | BJ7: 250 | BK7: =SUM(AK7:BJ7) | BL7: =INT(BK7*$BM$1) | BP7: =(Tabla1[[#This Row],[Población meta programatica 2026 (20251228) menores 1 año]]/12)*9 | BQ7: =BP7 | BS7: =(Tabla1[[#This Row],[Población meta programatica2026 (20251228) niños de 1 año]]/12)*9 | BT7: 172 | BU7: =BS7-BT7 | BX7: 150 | BY7: 186 | BZ7: 05031 | CA7: =BZ7=Tabla1[[#This Row],[Divipola]]
A8: 05 | B8: ANTIOQUIA | C8: ANDES | D8: 05034 | E8: 67 | F8: =Tabla1[[#This Row],[Meta Programatica2026 (20251228) RN]]/12 | G8: 284 | H8: =Tabla1[[#This Row],[Población meta programatica 2026 (20251228) menores 1 año]]/12 | I8: 324 | J8: =Tabla1[[#This Row],[Población meta programatica2026 (20251228) niños de 1 año]]/12 | K8: 406 | L8: 377 | M8: =Tabla1[[#This Row],[Población meta programatica2026 (20251228) niños de 5 años]]/12 | N8: =BX8 | O8: =BY8 | P8: =BL8 | R8: BOYACA | S8: 15 | T8: =SUMIF($A$2:$A$1123,S8,$E$2:$E$1123) | U8: =SUMIF($A$3:$A$1122,S8,$G$3:$G$1122) | V8: =SUMIF($A$3:$A$1122,S8,$I$3:$I$1122) | W8: =SUMIF($A$2:$A$1123,$S8,$L$2:$L$1123) | X8: =SUMIF($A$2:$A$1123,$S8,$N$2:$N$1123) | Y8: =SUMIF($A$2:$A$1123,$S8,$O$2:$O$1123) | AI8: 05034 | AJ8: =AI8=Tabla1[[#This Row],[Divipola]] | AK8: 558 | AL8: 560 | AM8: 561 | AN8: 542 | AO8: 526 | AP8: 507 | AQ8: 488 | AR8: 468 | AS8: 438 | AT8: 420 | AU8: 389 | AV8: 360 | AW8: 334 | AX8: 311 | AY8: 275 | AZ8: 252 | BA8: 227 | BB8: 211 | BC8: 186 | BD8: 165 | BE8: 146 | BF8: 131 | BG8: 114 | BH8: 101 | BI8: 85 | BJ8: 435 | BK8: =SUM(AK8:BJ8) | BL8: =INT(BK8*$BM$1) | BP8: =(Tabla1[[#This Row],[Población meta programatica 2026 (20251228) menores 1 año]]/12)*9 | BQ8: =BP8 | BS8: =(Tabla1[[#This Row],[Población meta programatica2026 (20251228) niños de 1 año]]/12)*9 | BT8: 240 | BU8: =BS8-BT8 | BX8: 245 | BY8: 258 | BZ8: 05034 | CA8: =BZ8=Tabla1[[#This Row],[Divipola]]
A9: 05 | B9: ANTIOQUIA | C9: ANGELOPOLIS | D9: 05036 | E9: 6 | F9: =Tabla1[[#This Row],[Meta Programatica2026 (20251228) RN]]/12 | G9: 28 | H9: =Tabla1[[#This Row],[Población meta programatica 2026 (20251228) menores 1 año]]/12 | I9: 32 | J9: =Tabla1[[#This Row],[Población meta programatica2026 (20251228) niños de 1 año]]/12 | K9: 53 | L9: 42 | M9: =Tabla1[[#This Row],[Población meta programatica2026 (20251228) niños de 5 años]]/12 | N9: =BX9 | O9: =BY9 | P9: =BL9 | R9: CALDAS | S9: 17 | T9: =SUMIF($A$2:$A$1123,S9,$E$2:$E$1123) | U9: =SUMIF($A$3:$A$1122,S9,$G$3:$G$1122) | V9: =SUMIF($A$3:$A$1122,S9,$I$3:$I$1122) | W9: =SUMIF($A$2:$A$1123,$S9,$L$2:$L$1123) | X9: =SUMIF($A$2:$A$1123,$S9,$N$2:$N$1123) | Y9: =SUMIF($A$2:$A$1123,$S9,$O$2:$O$1123) | AI9: 05036 | AJ9: =AI9=Tabla1[[#This Row],[Divipola]] | AK9: 81 | AL9: 79 | AM9: 80 | AN9: 74 | AO9: 74 | AP9: 69 | AQ9: 61 | AR9: 61 | AS9: 56 | AT9: 55 | AU9: 50 | AV9: 50 | AW9: 52 | AX9: 45 | AY9: 42 | AZ9: 41 | BA9: 39 | BB9: 33 | BC9: 31 | BD9: 26 | BE9: 25 | BF9: 23 | BG9: 20 | BH9: 18 | BI9: 12 | BJ9: 71 | BK9: =SUM(AK9:BJ9) | BL9: =INT(BK9*$BM$1) | BP9: =(Tabla1[[#This Row],[Población meta programatica 2026 (20251228) menores 1 año]]/12)*9 | BQ9: =BP9 | BS9: =(Tabla1[[#This Row],[Población meta programatica2026 (20251228) niños de 1 año]]/12)*9 | BT9: 23 | BU9: =BS9-BT9 | BX9: 28 | BY9: 34 | BZ9: 05036 | CA9: =BZ9=Tabla1[[#This Row],[Divipola]]
A10: 05 | B10: ANTIOQUIA | C10: ANGOSTURA | D10: 05038 | E10: 17 | F10: =Tabla1[[#This Row],[Meta Programatica2026 (20251228) RN]]/12 | G10: 63 | H10: =Tabla1[[#This Row],[Población meta programatica 2026 (20251228) menores 1 año]]/12 | I10: 75 | J10: =Tabla1[[#This Row],[Población meta programatica2026 (20251228) niños de 1 año]]/12 | K10: 113 | L10: 115 | M10: =Tabla1[[#This Row],[Población meta programatica2026 (20251228) niños de 5 años]]/12 | N10: =BX10 | O10: =BY10 | P10: =BL10 | R10: CAQUETA | S10: 18 | T10: =SUMIF($A$2:$A$1123,S10,$E$2:$E$1123) | U10: =SUMIF($A$3:$A$1122,S10,$G$3:$G$1122) | V10: =SUMIF($A$3:$A$1122,S10,$I$3:$I$1122) | W10: =SUMIF($A$2:$A$1123,$S10,$L$2:$L$1123) | X10: =SUMIF($A$2:$A$1123,$S10,$N$2:$N$1123) | Y10: =SUMIF($A$2:$A$1123,$S10,$O$2:$O$1123) | AI10: 05038 | AJ10: =AI10=Tabla1[[#This Row],[Divipola]] | AK10: 135 | AL10: 131 | AM10: 131 | AN10: 128 | AO10: 119 | AP10: 118 | AQ10: 112 | AR10: 107 | AS10: 101 | AT10: 98 | AU10: 88 | AV10: 86 | AW10: 76 | AX10: 69 | AY10: 67 | AZ10: 58 | BA10: 54 | BB10: 50 | BC10: 43 | BD10: 41 | BE10: 35 | BF10: 33 | BG10: 29 | BH10: 25 | BI10: 23 | BJ10: 112 | BK10: =SUM(AK10:BJ10) | BL10: =INT(BK10*$BM$1) | BP10: =(Tabla1[[#This Row],[Población meta programatica 2026 (20251228) menores 1 año]]/12)*9 | BQ10: =BP10 | BS10: =(Tabla1[[#This Row],[Población meta programatica2026 (20251228) niños de 1 año]]/12)*9 | BT10: 45 | BU10: =BS10-BT10 | BX10: 103 | BY10: 103 | BZ10: 05038 | CA10: =BZ10=Tabla1[[#This Row],[Divipola]]
A11: 05 | B11: ANTIOQUIA | C11: ANORI | D11: 05040 | E11: 47 | F11: =Tabla1[[#This Row],[Meta Programatica2026 (20251228) RN]]/12 | G11: 187 | H11: =Tabla1[[#This Row],[Población meta programatica 2026 (20251228) menores 1 año]]/12 | I11: 189 | J11: =Tabla1[[#This Row],[Población meta programatica2026 (20251228) niños de 1 año]]/12 | K11: 275 | L11: 213 | M11: =Tabla1[[#This Row],[Población meta programatica2026 (20251228) niños de 5 años]]/12 | N11: =BX11 | O11: =BY11 | P11: =BL11 | R11: CAUCA | S11: 19 | T11: =SUMIF($A$2:$A$1123,S11,$E$2:$E$1123) | U11: =SUMIF($A$3:$A$1122,S11,$G$3:$G$1122) | V11: =SUMIF($A$3:$A$1122,S11,$I$3:$I$1122) | W11: =SUMIF($A$2:$A$1123,$S11,$L$2:$L$1123) | X11: =SUMIF($A$2:$A$1123,$S11,$N$2:$N$1123) | Y11: =SUMIF($A$2:$A$1123,$S11,$O$2:$O$1123) | AI11: 05040 | AJ11: =AI11=Tabla1[[#This Row],[Divipola]] | AK11: 145 | AL11: 141 | AM11: 135 | AN11: 127 | AO11: 127 | AP11: 122 | AQ11: 116 | AR11: 109 | AS11: 105 | AT11: 104 | AU11: 97 | AV11: 91 | AW11: 90 | AX11: 79 | AY11: 74 | AZ11: 68 | BA11: 66 | BB11: 60 | BC11: 53 | BD11: 48 | BE11: 44 | BF11: 42 | BG11: 35 | BH11: 29 | BI11: 29 | BJ11: 128 | BK11: =SUM(AK11:BJ11) | BL11: =INT(BK11*$BM$1) | BP11: =(Tabla1[[#This Row],[Población meta programatica 2026 (20251228) menores 1 año]]/12)*9 | BQ11: =BP11 | BS11: =(Tabla1[[#This Row],[Población meta programatica2026 (20251228) niños de 1 año]]/12)*9 | BT11: 95 | BU11: =BS11-BT11 | BX11: 123 | BY11: 127 | BZ11: 05040 | CA11: =BZ11=Tabla1[[#This Row],[Divipola]]
A12: 05 | B12: ANTIOQUIA | C12: SANTAFE DE ANTIOQUIA | D12: 05042 | E12: 656 | F12: =Tabla1[[#This Row],[Meta Programatica2026 (20251228) RN]]/12 | G12: 238 | H12: =Tabla1[[#This Row],[Población meta programatica 2026 (20251228) menores 1 año]]/12 | I12: 247 | J12: =Tabla1[[#This Row],[Población meta programatica2026 (20251228) niños de 1 año]]/12 | K12: 369 | L12: 296 | M12: =Tabla1[[#This Row],[Población meta programatica2026 (20251228) niños de 5 años]]/12 | N12: =BX12 | O12: =BY12 | P12: =BL12 | R12: CESAR | S12: 20 | T12: =SUMIF($A$2:$A$1123,S12,$E$2:$E$1123) | U12: =SUMIF($A$3:$A$1122,S12,$G$3:$G$1122) | V12: =SUMIF($A$3:$A$1122,S12,$I$3:$I$1122) | W12: =SUMIF($A$2:$A$1123,$S12,$L$2:$L$1123) | X12: =SUMIF($A$2:$A$1123,$S12,$N$2:$N$1123) | Y12: =SUMIF($A$2:$A$1123,$S12,$O$2:$O$1123) | AI12: 05042 | AJ12: =AI12=Tabla1[[#This Row],[Divipola]] | AK12: 297 | AL12: 285 | AM12: 285 | AN12: 274 | AO12: 267 | AP12: 250 | AQ12: 242 | AR12: 232 | AS12: 220 | AT12: 213 | AU12: 201 | AV12: 192 | AW12: 185 | AX12: 173 | AY12: 160 | AZ12: 149 | BA12: 140 | BB12: 128 | BC12: 115 | BD12: 108 | BE12: 94 | BF12: 85 | BG12: 78 | BH12: 68 | BI12: 58 | BJ12: 349 | BK12: =SUM(AK12:BJ12) | BL12: =INT(BK12*$BM$1) | BP12: =(Tabla1[[#This Row],[Población meta programatica 2026 (20251228) menores 1 año]]/12)*9 | BQ12: =BP12 | BS12: =(Tabla1[[#This Row],[Población meta programatica2026 (20251228) niños de 1 año]]/12)*9 | BT12: 192 | BU12: =BS12-BT12 | BX12: 177 | BY12: 201 | BZ12: 05042 | CA12: =BZ12=Tabla1[[#This Row],[Divipola]]
A13: 05 | B13: ANTIOQUIA | C13: ANZA | D13: 05044 | E13: 20 | F13: =Tabla1[[#This Row],[Meta Programatica2026 (20251228) RN]]/12 | G13: 71 | H13: =Tabla1[[#This Row],[Población meta programatica 2026 (20251228) menores 1 año]]/12 | I13: 83 | J13: =Tabla1[[#This Row],[Población meta programatica2026 (20251228) niños de 1 año]]/12 | K13: 112 | L13: 108 | M13: =Tabla1[[#This Row],[Población meta programatica2026 (20251228) niños de 5 años]]/12 | N13: =BX13 | O13: =BY13 | P13: =BL13 | R13: CORDOBA | S13: 23 | T13: =SUMIF($A$2:$A$1123,S13,$E$2:$E$1123) | U13: =SUMIF($A$3:$A$1122,S13,$G$3:$G$1122) | V13: =SUMIF($A$3:$A$1122,S13,$I$3:$I$1122) | W13: =SUMIF($A$2:$A$1123,$S13,$L$2:$L$1123) | X13: =SUMIF($A$2:$A$1123,$S13,$N$2:$N$1123) | Y13: =SUMIF($A$2:$A$1123,$S13,$O$2:$O$1123) | AI13: 05044 | AJ13: =AI13=Tabla1[[#This Row],[Divipola]] | AK13: 71 | AL13: 66 | AM13: 65 | AN13: 64 | AO13: 68 | AP13: 61 | AQ13: 58 | AR13: 57 | AS13: 58 | AT13: 55 | AU13: 50 | AV13: 46 | AW13: 47 | AX13: 44 | AY13: 42 | AZ13: 40 | BA13: 37 | BB13: 34 | BC13: 30 | BD13: 26 | BE13: 26 | BF13: 22 | BG13: 22 | BH13: 19 | BI13: 17 | BJ13: 95 | BK13: =SUM(AK13:BJ13) | BL13: =INT(BK13*$BM$1) | BP13: =(Tabla1[[#This Row],[Población meta programatica 2026 (20251228) menores 1 año]]/12)*9 | BQ13: =BP13 | BS13: =(Tabla1[[#This Row],[Población meta programatica2026 (20251228) niños de 1 año]]/12)*9 | BT13: 63 | BU13: =BS13-BT13 | BX13: 49 | BY13: 50 | BZ13: 05044 | CA13: =BZ13=Tabla1[[#This Row],[Divipola]]
A14: 05 | B14: ANTIOQUIA | C14: APARTADO | D14: 05045 | E14: 2842 | F14: =Tabla1[[#This Row],[Meta Programatica2026 (20251228) RN]]/12 | G14: 1375 | H14: =Tabla1[[#This Row],[Población meta programatica 2026 (20251228) menores 1 año]]/12 | I14: 1375 | J14: =Tabla1[[#This Row],[Población meta programatica2026 (20251228) niños de 1 año]]/12 | K14: 2027 | L14: 2019 | M14: =Tabla1[[#This Row],[Población meta programatica2026 (20251228) niños de 5 años]]/12 | N14: =BX14 | O14: =BY14 | P14: =BL14 | R14: CUNDINAMARCA | S14: 25 | T14: =SUMIF($A$2:$A$1123,S14,$E$2:$E$1123) | U14: =SUMIF($A$3:$A$1122,S14,$G$3:$G$1122) | V14: =SUMIF($A$3:$A$1122,S14,$I$3:$I$1122) | W14: =SUMIF($A$2:$A$1123,$S14,$L$2:$L$1123) | X14: =SUMIF($A$2:$A$1123,$S14,$N$2:$N$1123) | Y14: =SUMIF($A$2:$A$1123,$S14,$O$2:$O$1123) | AI14: 05045 | AJ14: =AI14=Tabla1[[#This Row],[Divipola]] | AK14: 1016 | AL14: 969 | AM14: 915 | AN14: 859 | AO14: 799 | AP14: 741 | AQ14: 678 | AR14: 627 | AS14: 573 | AT14: 525 | AU14: 483 | AV14: 444 | AW14: 408 | AX14: 381 | AY14: 350 | AZ14: 326 | BA14: 305 | BB14: 283 | BC14: 262 | BD14: 237 | BE14: 214 | BF14: 190 | BG14: 170 | BH14: 147 | BI14: 124 | BJ14: 515 | BK14: =SUM(AK14:BJ14) | BL14: =INT(BK14*$BM$1) | BP14: =(Tabla1[[#This Row],[Población meta programatica 2026 (20251228) menores 1 año]]/12)*9 | BQ14: =BP14 | BS14: =(Tabla1[[#This Row],[Población meta programatica2026 (20251228) niños de 1 año]]/12)*9 | BT14: 933 | BU14: =BS14-BT14 | BX14: 1085 | BY14: 1153 | BZ14: 05045 | CA14: =BZ14=Tabla1[[#This Row],[Divipola]]
A15: 05 | B15: ANTIOQUIA | C15: ARBOLETES | D15: 05051 | E15: 67 | F15: =Tabla1[[#This Row],[Meta Programatica2026 (20251228) RN]]/12 | G15: 302 | H15: =Tabla1[[#This Row],[Población meta programatica 2026 (20251228) menores 1 año]]/12 | I15: 335 | J15: =Tabla1[[#This Row],[Población meta programatica2026 (20251228) niños de 1 año]]/12 | K15: 503 | L15: 461 | M15: =Tabla1[[#This Row],[Población meta programatica2026 (20251228) niños de 5 años]]/12 | N15: =BX15 | O15: =BY15 | P15: =BL15 | R15: CHOCO | S15: 27 | T15: =SUMIF($A$2:$A$1123,S15,$E$2:$E$1123) | U15: =SUMIF($A$3:$A$1122,S15,$G$3:$G$1122) | V15: =SUMIF($A$3:$A$1122,S15,$I$3:$I$1122) | W15: =SUMIF($A$2:$A$1123,$S15,$L$2:$L$1123) | X15: =SUMIF($A$2:$A$1123,$S15,$N$2:$N$1123) | Y15: =SUMIF($A$2:$A$1123,$S15,$O$2:$O$1123) | AI15: 05051 | AJ15: =AI15=Tabla1[[#This Row],[Divipola]] | AK15: 295 | AL15: 291 | AM15: 285 | AN15: 278 | AO15: 273 | AP15: 257 | AQ15: 245 | AR15: 227 | AS15: 220 | AT15: 203 | AU15: 194 | AV15: 186 | AW15: 175 | AX15: 161 | AY15: 153 | AZ15: 141 | BA15: 136 | BB15: 129 | BC15: 117 | BD15: 110 | BE15: 98 | BF15: 88 | BG15: 80 | BH15: 69 | BI15: 57 | BJ15: 270 | BK15: =SUM(AK15:BJ15) | BL15: =INT(BK15*$BM$1) | BP15: =(Tabla1[[#This Row],[Población meta programatica 2026 (20251228) menores 1 año]]/12)*9 | BQ15: =BP15 | BS15: =(Tabla1[[#This Row],[Población meta programatica2026 (20251228) niños de 1 año]]/12)*9 | BT15: 212 | BU15: =BS15-BT15 | BX15: 284 | BY15: 290 | BZ15: 05051 | CA15: =BZ15=Tabla1[[#This Row],[Divipola]]
A16: 05 | B16: ANTIOQUIA | C16: ARGELIA | D16: 05055 | E16: 16 | F16: =Tabla1[[#This Row],[Meta Programatica2026 (20251228) RN]]/12 | G16: 57 | H16: =Tabla1[[#This Row],[Población meta programatica 2026 (20251228) menores 1 año]]/12 | I16: 59 | J16: =Tabla1[[#This Row],[Población meta programatica2026 (20251228) niños de 1 año]]/12 | K16: 86 | L16: 93 | M16: =Tabla1[[#This Row],[Población meta programatica2026 (20251228) niños de 5 años]]/12 | N16: =BX16 | O16: =BY16 | P16: =BL16 | R16: HUILA | S16: 41 | T16: =SUMIF($A$2:$A$1123,S16,$E$2:$E$1123) | U16: =SUMIF($A$3:$A$1122,S16,$G$3:$G$1122) | V16: =SUMIF($A$3:$A$1122,S16,$I$3:$I$1122) | W16: =SUMIF($A$2:$A$1123,$S16,$L$2:$L$1123) | X16: =SUMIF($A$2:$A$1123,$S16,$N$2:$N$1123) | Y16: =SUMIF($A$2:$A$1123,$S16,$O$2:$O$1123) | AI16: 05055 | AJ16: =AI16=Tabla1[[#This Row],[Divipola]] | AK16: 86 | AL16: 86 | AM16: 88 | AN16: 88 | AO16: 88 | AP16: 82 | AQ16: 81 | AR16: 82 | AS16: 77 | AT16: 73 | AU16: 71 | AV16: 65 | AW16: 61 | AX16: 56 | AY16: 54 | AZ16: 46 | BA16: 45 | BB16: 40 | BC16: 36 | BD16: 33 | BE16: 29 | BF16: 26 | BG16: 23 | BH16: 21 | BI16: 17 | BJ16: 73 | BK16: =SUM(AK16:BJ16) | BL16: =INT(BK16*$BM$1) | BP16: =(Tabla1[[#This Row],[Población meta programatica 2026 (20251228) menores 1 año]]/12)*9 | BQ16: =BP16 | BS16: =(Tabla1[[#This Row],[Población meta programatica2026 (20251228) niños de 1 año]]/12)*9 | BT16: 48 | BU16: =BS16-BT16 | BX16: 60 | BY16: 69 | BZ16: 05055 | CA16: =BZ16=Tabla1[[#This Row],[Divipola]]
A17: 05 | B17: ANTIOQUIA | C17: ARMENIA | D17: 05059 | E17: 3 | F17: =Tabla1[[#This Row],[Meta Programatica2026 (20251228) RN]]/12 | G17: 14 | H17: =Tabla1[[#This Row],[Población meta programatica 2026 (20251228) menores 1 año]]/12 | I17: 17 | J17: =Tabla1[[#This Row],[Población meta programatica2026 (20251228) niños de 1 año]]/12 | K17: 19 | L17: 19 | M17: =Tabla1[[#This Row],[Población meta programatica2026 (20251228) niños de 5 años]]/12 | N17: =BX17 | O17: =BY17 | P17: =BL17 | R17: LA GUAJIRA | S17: 44 | T17: =SUMIF($A$2:$A$1123,S17,$E$2:$E$1123) | U17: =SUMIF($A$3:$A$1122,S17,$G$3:$G$1122) | V17: =SUMIF($A$3:$A$1122,S17,$I$3:$I$1122) | W17: =SUMIF($A$2:$A$1123,$S17,$L$2:$L$1123) | X17: =SUMIF($A$2:$A$1123,$S17,$N$2:$N$1123) | Y17: =SUMIF($A$2:$A$1123,$S17,$O$2:$O$1123) | AI17: 05059 | AJ17: =AI17=Tabla1[[#This Row],[Divipola]] | AK17: 87 | AL17: 90 | AM17: 88 | AN17: 83 | AO17: 84 | AP17: 82 | AQ17: 77 | AR17: 73 | AS17: 68 | AT17: 71 | AU17: 58 | AV17: 63 | AW17: 55 | AX17: 53 | AY17: 51 | AZ17: 49 | BA17: 47 | BB17: 44 | BC17: 43 | BD17: 41 | BE17: 34 | BF17: 33 | BG17: 32 | BH17: 25 | BI17: 22 | BJ17: 85 | BK17: =SUM(AK17:BJ17) | BL17: =INT(BK17*$BM$1) | BP17: =(Tabla1[[#This Row],[Población meta programatica 2026 (20251228) menores 1 año]]/12)*9 | BQ17: =BP17 | BS17: =(Tabla1[[#This Row],[Población meta programatica2026 (20251228) niños de 1 año]]/12)*9 | BT17: 14 | BU17: =BS17-BT17 | BX17: 20 | BY17: 27 | BZ17: 05059 | CA17: =BZ17=Tabla1[[#This Row],[Divipola]]
A18: 05 | B18: ANTIOQUIA | C18: BARBOSA | D18: 05079 | E18: 61 | F18: =Tabla1[[#This Row],[Meta Programatica2026 (20251228) RN]]/12 | G18: 281 | H18: =Tabla1[[#This Row],[Población meta programatica 2026 (20251228) menores 1 año]]/12 | I18: 304 | J18: =Tabla1[[#This Row],[Población meta programatica2026 (20251228) niños de 1 año]]/12 | K18: 416 | L18: 485 | M18: =Tabla1[[#This Row],[Población meta programatica2026 (20251228) niños de 5 años]]/12 | N18: =BX18 | O18: =BY18 | P18: =BL18 | R18: MAGDALENA | S18: 47 | T18: =SUMIF($A$2:$A$1123,S18,$E$2:$E$1123) | U18: =SUMIF($A$3:$A$1122,S18,$G$3:$G$1122) | V18: =SUMIF($A$3:$A$1122,S18,$I$3:$I$1122) | W18: =SUMIF($A$2:$A$1123,$S18,$L$2:$L$1123) | X18: =SUMIF($A$2:$A$1123,$S18,$N$2:$N$1123) | Y18: =SUMIF($A$2:$A$1123,$S18,$O$2:$O$1123) | AI18: 05079 | AJ18: =AI18=Tabla1[[#This Row],[Divipola]] | AK18: 661 | AL18: 646 | AM18: 634 | AN18: 616 | AO18: 591 | AP18: 571 | AQ18: 553 | AR18: 529 | AS18: 501 | AT18: 483 | AU18: 462 | AV18: 440 | AW18: 419 | AX18: 390 | AY18: 361 | AZ18: 336 | BA18: 312 | BB18: 286 | BC18: 264 | BD18: 238 | BE18: 211 | BF18: 183 | BG18: 161 | BH18: 137 | BI18: 116 | BJ18: 555 | BK18: =SUM(AK18:BJ18) | BL18: =INT(BK18*$BM$1) | BP18: =(Tabla1[[#This Row],[Población meta programatica 2026 (20251228) menores 1 año]]/12)*9 | BQ18: =BP18 | BS18: =(Tabla1[[#This Row],[Población meta programatica2026 (20251228) niños de 1 año]]/12)*9 | BT18: 212 | BU18: =BS18-BT18 | BX18: 287 | BY18: 234 | BZ18: 05079 | CA18: =BZ18=Tabla1[[#This Row],[Divipola]]
A19: 05 | B19: ANTIOQUIA | C19: BELMIRA | D19: 05086 | E19: 12 | F19: =Tabla1[[#This Row],[Meta Programatica2026 (20251228) RN]]/12 | G19: 32 | H19: =Tabla1[[#This Row],[Población meta programatica 2026 (20251228) menores 1 año]]/12 | I19: 38 | J19: =Tabla1[[#This Row],[Población meta programatica2026 (20251228) niños de 1 año]]/12 | K19: 50 | L19: 50 | M19: =Tabla1[[#This Row],[Población meta programatica2026 (20251228) niños de 5 años]]/12 | N19: =BX19 | O19: =BY19 | P19: =BL19 | R19: SANTA MARTA | S19: 47001 | T19: =SUMIF($A$2:$A$1123,S19,$E$2:$E$1123) | U19: =SUMIF($D$3:$D$1122,S19,$G$3:$G$1122) | V19: =SUMIF($D$3:$D$1122,S19,$I$3:$I$1122) | W19: =SUMIF($D$3:$D$1122,$S19,$L$3:$L$1122) | X19: =SUMIF($A$2:$A$1123,$S19,$N$2:$N$1123) | Y19: =SUMIF($A$2:$A$1123,$S19,$O$2:$O$1123) | AI19: 05086 | AJ19: =AI19=Tabla1[[#This Row],[Divipola]] | AK19: 60 | AL19: 57 | AM19: 54 | AN19: 54 | AO19: 50 | AP19: 48 | AQ19: 46 | AR19: 42 | AS19: 41 | AT19: 40 | AU19: 36 | AV19: 37 | AW19: 35 | AX19: 30 | AY19: 31 | AZ19: 32 | BA19: 27 | BB19: 26 | BC19: 24 | BD19: 20 | BE19: 20 | BF19: 17 | BG19: 18 | BH19: 15 | BI19: 12 | BJ19: 59 | BK19: =SUM(AK19:BJ19) | BL19: =INT(BK19*$BM$1) | BP19: =(Tabla1[[#This Row],[Población meta programatica 2026 (20251228) menores 1 año]]/12)*9 | BQ19: =BP19 | BS19: =(Tabla1[[#This Row],[Población meta programatica2026 (20251228) niños de 1 año]]/12)*9 | BT19: 24 | BU19: =BS19-BT19 | BX19: 46 | BY19: 57 | BZ19: 05086 | CA19: =BZ19=Tabla1[[#This Row],[Divipola]]
A20: 05 | B20: ANTIOQUIA | C20: BELLO | D20: 05088 | E20: 1238 | F20: =Tabla1[[#This Row],[Meta Programatica2026 (20251228) RN]]/12 | G20: 3409 | H20: =Tabla1[[#This Row],[Población meta programatica 2026 (20251228) menores 1 año]]/12 | I20: 3545 | J20: =Tabla1[[#This Row],[Población meta programatica2026 (20251228) niños de 1 año]]/12 | K20: 4733 | L20: 4477 | M20: =Tabla1[[#This Row],[Población meta programatica2026 (20251228) niños de 5 años]]/12 | N20: =BX20 | O20: =BY20 | P20: =BL20 | R20: META | S20: 50 | T20: =SUMIF($A$2:$A$1123,S20,$E$2:$E$1123) | U20: =SUMIF($A$3:$A$1122,S20,$G$3:$G$1122) | V20: =SUMIF($A$3:$A$1122,S20,$I$3:$I$1122) | W20: =SUMIF($A$2:$A$1123,$S20,$L$2:$L$1123) | X20: =SUMIF($A$2:$A$1123,$S20,$N$2:$N$1123) | Y20: =SUMIF($A$2:$A$1123,$S20,$O$2:$O$1123) | AI20: 05088 | AJ20: =AI20=Tabla1[[#This Row],[Divipola]] | AK20: 6177 | AL20: 6030 | AM20: 5826 | AN20: 5595 | AO20: 5341 | AP20: 5071 | AQ20: 4801 | AR20: 4526 | AS20: 4238 | AT20: 3944 | AU20: 3655 | AV20: 3374 | AW20: 3110 | AX20: 2848 | AY20: 2600 | AZ20: 2368 | BA20: 2153 | BB20: 1954 | BC20: 1757 | BD20: 1579 | BE20: 1406 | BF20: 1243 | BG20: 1090 | BH20: 949 | BI20: 821 | BJ20: 3980 | BK20: =SUM(AK20:BJ20) | BL20: =INT(BK20*$BM$1) | BP20: =(Tabla1[[#This Row],[Población meta programatica 2026 (20251228) menores 1 año]]/12)*9 | BQ20: =BP20 | BS20: =(Tabla1[[#This Row],[Población meta programatica2026 (20251228) niños de 1 año]]/12)*9 | BT20: 2330 | BU20: =BS20-BT20 | BX20: 3082 | BY20: 3165 | BZ20: 05088 | CA20: =BZ20=Tabla1[[#This Row],[Divipola]]
A21: 05 | B21: ANTIOQUIA | C21: BETANIA | D21: 05091 | E21: 14 | F21: =Tabla1[[#This Row],[Meta Programatica2026 (20251228) RN]]/12 | G21: 54 | H21: =Tabla1[[#This Row],[Población meta programatica 2026 (20251228) menores 1 año]]/12 | I21: 55 | J21: =Tabla1[[#This Row],[Población meta programatica2026 (20251228) niños de 1 año]]/12 | K21: 85 | L21: 97 | M21: =Tabla1[[#This Row],[Población meta programatica2026 (20251228) niños de 5 años]]/12 | N21: =BX21 | O21: =BY21 | P21: =BL21 | R21: NARIÑO | S21: 52 | T21: =SUMIF($A$2:$A$1123,S21,$E$2:$E$1123) | U21: =SUMIF($A$3:$A$1122,S21,$G$3:$G$1122) | V21: =SUMIF($A$3:$A$1122,S21,$I$3:$I$1122) | W21: =SUMIF($A$2:$A$1123,$S21,$L$2:$L$1123) | X21: =SUMIF($A$2:$A$1123,$S21,$N$2:$N$1123) | Y21: =SUMIF($A$2:$A$1123,$S21,$O$2:$O$1123) | AI21: 05091 | AJ21: =AI21=Tabla1[[#This Row],[Divipola]] | AK21: 129 | AL21: 131 | AM21: 127 | AN21: 124 | AO21: 119 | AP21: 112 | AQ21: 108 | AR21: 101 | AS21: 98 | AT21: 86 | AU21: 84 | AV21: 79 | AW21: 77 | AX21: 70 | AY21: 70 | AZ21: 62 | BA21: 51 | BB21: 47 | BC21: 47 | BD21: 43 | BE21: 36 | BF21: 34 | BG21: 28 | BH21: 23 | BI21: 21 | BJ21: 103 | BK21: =SUM(AK21:BJ21) | BL21: =INT(BK21*$BM$1) | BP21: =(Tabla1[[#This Row],[Población meta programatica 2026 (20251228) menores 1 año]]/12)*9 | BQ21: =BP21 | BS21: =(Tabla1[[#This Row],[Población meta programatica2026 (20251228) niños de 1 año]]/12)*9 | BT21: 37 | BU21: =BS21-BT21 | BX21: 47 | BY21: 63 | BZ21: 05091 | CA21: =BZ21=Tabla1[[#This Row],[Divipola]]
A22: 05 | B22: ANTIOQUIA | C22: BETULIA | D22: 05093 | E22: 39 | F22: =Tabla1[[#This Row],[Meta Programatica2026 (20251228) RN]]/12 | G22: 158 | H22: =Tabla1[[#This Row],[Población meta programatica 2026 (20251228) menores 1 año]]/12 | I22: 163 | J22: =Tabla1[[#This Row],[Población meta programatica2026 (20251228) niños de 1 año]]/12 | K22: 238 | L22: 200 | M22: =Tabla1[[#This Row],[Población meta programatica2026 (20251228) niños de 5 años]]/12 | N22: =BX22 | O22: =BY22 | P22: =BL22 | R22: NORTE DE SANTANDER | S22: 54 | T22: =SUMIF($A$2:$A$1123,S22,$E$2:$E$1123) | U22: =SUMIF($A$3:$A$1122,S22,$G$3:$G$1122) | V22: =SUMIF($A$3:$A$1122,S22,$I$3:$I$1122) | W22: =SUMIF($A$2:$A$1123,$S22,$L$2:$L$1123) | X22: =SUMIF($A$2:$A$1123,$S22,$N$2:$N$1123) | Y22: =SUMIF($A$2:$A$1123,$S22,$O$2:$O$1123) | AI22: 05093 | AJ22: =AI22=Tabla1[[#This Row],[Divipola]] | AK22: 164 | AL22: 162 | AM22: 160 | AN22: 156 | AO22: 147 | AP22: 137 | AQ22: 136 | AR22: 125 | AS22: 124 | AT22: 117 | AU22: 108 | AV22: 99 | AW22: 94 | AX22: 90 | AY22: 84 | AZ22: 77 | BA22: 71 | BB22: 65 | BC22: 60 | BD22: 51 | BE22: 49 | BF22: 43 | BG22: 36 | BH22: 32 | BI22: 29 | BJ22: 131 | BK22: =SUM(AK22:BJ22) | BL22: =INT(BK22*$BM$1) | BP22: =(Tabla1[[#This Row],[Población meta programatica 2026 (20251228) menores 1 año]]/12)*9 | BQ22: =BP22 | BS22: =(Tabla1[[#This Row],[Población meta programatica2026 (20251228) niños de 1 año]]/12)*9 | BT22: 87 | BU22: =BS22-BT22 | BX22: 127 | BY22: 149 | BZ22: 05093 | CA22: =BZ22=Tabla1[[#This Row],[Divipola]]
A23: 05 | B23: ANTIOQUIA | C23: CIUDAD BOLIVAR | D23: 05101 | E23: 399 | F23: =Tabla1[[#This Row],[Meta Programatica2026 (20251228) RN]]/12 | G23: 187 | H23: =Tabla1[[#This Row],[Población meta programatica 2026 (20251228) menores 1 año]]/12 | I23: 191 | J23: =Tabla1[[#This Row],[Población meta programatica2026 (20251228) niños de 1 año]]/12 | K23: 299 | L23: 261 | M23: =Tabla1[[#This Row],[Población meta programatica2026 (20251228) niños de 5 años]]/12 | N23: =BX23 | O23: =BY23 | P23: =BL23 | R23: QUINDIO | S23: 63 | T23: =SUMIF($A$2:$A$1123,S23,$E$2:$E$1123) | U23: =SUMIF($A$3:$A$1122,S23,$G$3:$G$1122) | V23: =SUMIF($A$3:$A$1122,S23,$I$3:$I$1122) | W23: =SUMIF($A$2:$A$1123,$S23,$L$2:$L$1123) | X23: =SUMIF($A$2:$A$1123,$S23,$N$2:$N$1123) | Y23: =SUMIF($A$2:$A$1123,$S23,$O$2:$O$1123) | AI23: 05101 | AJ23: =AI23=Tabla1[[#This Row],[Divipola]] | AK23: 343 | AL23: 343 | AM23: 333 | AN23: 327 | AO23: 317 | AP23: 306 | AQ23: 292 | AR23: 275 | AS23: 260 | AT23: 243 | AU23: 230 | AV23: 219 | AW23: 203 | AX23: 193 | AY23: 176 | AZ23: 161 | BA23: 150 | BB23: 144 | BC23: 125 | BD23: 116 | BE23: 103 | BF23: 92 | BG23: 82 | BH23: 73 | BI23: 62 | BJ23: 420 | BK23: =SUM(AK23:BJ23) | BL23: =INT(BK23*$BM$1) | BP23: =(Tabla1[[#This Row],[Población meta programatica 2026 (20251228) menores 1 año]]/12)*9 | BQ23: =BP23 | BS23: =(Tabla1[[#This Row],[Población meta programatica2026 (20251228) niños de 1 año]]/12)*9 | BT23: 137 | BU23: =BS23-BT23 | BX23: 207 | BY23: 184 | BZ23: 05101 | CA23: =BZ23=Tabla1[[#This Row],[Divipola]]
A24: 05 | B24: ANTIOQUIA | C24: BRICEÑO | D24: 05107 | E24: 12 | F24: =Tabla1[[#This Row],[Meta Programatica2026 (20251228) RN]]/12 | G24: 46 | H24: =Tabla1[[#This Row],[Población meta programatica 2026 (20251228) menores 1 año]]/12 | I24: 52 | J24: =Tabla1[[#This Row],[Población meta programatica2026 (20251228) niños de 1 año]]/12 | K24: 83 | L24: 81 | M24: =Tabla1[[#This Row],[Población meta programatica2026 (20251228) niños de 5 años]]/12 | N24: =BX24 | O24: =BY24 | P24: =BL24 | R24: RISARALDA | S24: 66 | T24: =SUMIF($A$2:$A$1123,S24,$E$2:$E$1123) | U24: =SUMIF($A$3:$A$1122,S24,$G$3:$G$1122) | V24: =SUMIF($A$3:$A$1122,S24,$I$3:$I$1122) | W24: =SUMIF($A$2:$A$1123,$S24,$L$2:$L$1123) | X24: =SUMIF($A$2:$A$1123,$S24,$N$2:$N$1123) | Y24: =SUMIF($A$2:$A$1123,$S24,$O$2:$O$1123) | AI24: 05107 | AJ24: =AI24=Tabla1[[#This Row],[Divipola]] | AK24: 73 | AL24: 70 | AM24: 70 | AN24: 67 | AO24: 62 | AP24: 60 | AQ24: 54 | AR24: 55 | AS24: 50 | AT24: 47 | AU24: 45 | AV24: 43 | AW24: 39 | AX24: 36 | AY24: 35 | AZ24: 32 | BA24: 29 | BB24: 29 | BC24: 21 | BD24: 26 | BE24: 21 | BF24: 16 | BG24: 15 | BH24: 11 | BI24: 13 | BJ24: 51 | BK24: =SUM(AK24:BJ24) | BL24: =INT(BK24*$BM$1) | BP24: =(Tabla1[[#This Row],[Población meta programatica 2026 (20251228) menores 1 año]]/12)*9 | BQ24: =BP24 | BS24: =(Tabla1[[#This Row],[Población meta programatica2026 (20251228) niños de 1 año]]/12)*9 | BT24: 44 | BU24: =BS24-BT24 | BX24: 60 | BY24: 57 | BZ24: 05107 | CA24: =BZ24=Tabla1[[#This Row],[Divipola]]
A25: 05 | B25: ANTIOQUIA | C25: BURITICA | D25: 05113 | E25: 24 | F25: =Tabla1[[#This Row],[Meta Programatica2026 (20251228) RN]]/12 | G25: 100 | H25: =Tabla1[[#This Row],[Población meta programatica 2026 (20251228) menores 1 año]]/12 | I25: 100 | J25: =Tabla1[[#This Row],[Población meta programatica2026 (20251228) niños de 1 año]]/12 | K25: 138 | L25: 106 | M25: =Tabla1[[#This Row],[Población meta programatica2026 (20251228) niños de 5 años]]/12 | N25: =BX25 | O25: =BY25 | P25: =BL25 | R25: SANTANDER | S25: 68 | T25: =SUMIF($A$2:$A$1123,S25,$E$2:$E$1123) | U25: =SUMIF($A$3:$A$1122,S25,$G$3:$G$1122) | V25: =SUMIF($A$3:$A$1122,S25,$I$3:$I$1122) | W25: =SUMIF($A$2:$A$1123,$S25,$L$2:$L$1123) | X25: =SUMIF($A$2:$A$1123,$S25,$N$2:$N$1123) | Y25: =SUMIF($A$2:$A$1123,$S25,$O$2:$O$1123) | AI25: 05113 | AJ25: =AI25=Tabla1[[#This Row],[Divipola]] | AK25: 86 | AL25: 85 | AM25: 82 | AN25: 79 | AO25: 80 | AP25: 75 | AQ25: 72 | AR25: 70 | AS25: 66 | AT25: 60 | AU25: 63 | AV25: 58 | AW25: 56 | AX25: 54 | AY25: 52 | AZ25: 53 | BA25: 50 | BB25: 47 | BC25: 48 | BD25: 46 | BE25: 39 | BF25: 39 | BG25: 33 | BH25: 31 | BI25: 26 | BJ25: 127 | BK25: =SUM(AK25:BJ25) | BL25: =INT(BK25*$BM$1) | BP25: =(Tabla1[[#This Row],[Población meta programatica 2026 (20251228) menores 1 año]]/12)*9 | BQ25: =BP25 | BS25: =(Tabla1[[#This Row],[Población meta programatica2026 (20251228) niños de 1 año]]/12)*9 | BT25: 36 | BU25: =BS25-BT25 | BX25: 69 | BY25: 59 | BZ25: 05113 | CA25: =BZ25=Tabla1[[#This Row],[Divipola]]
A26: 05 | B26: ANTIOQUIA | C26: CACERES | D26: 05120 | E26: 66 | F26: =Tabla1[[#This Row],[Meta Programatica2026 (20251228) RN]]/12 | G26: 283 | H26: =Tabla1[[#This Row],[Población meta programatica 2026 (20251228) menores 1 año]]/12 | I26: 329 | J26: =Tabla1[[#This Row],[Población meta programatica2026 (20251228) niños de 1 año]]/12 | K26: 494 | L26: 357 | M26: =Tabla1[[#This Row],[Población meta programatica2026 (20251228) niños de 5 años]]/12 | N26: =BX26 | O26: =BY26 | P26: =BL26 | R26: SUCRE | S26: 70 | T26: =SUMIF($A$2:$A$1123,S26,$E$2:$E$1123) | U26: =SUMIF($A$3:$A$1122,S26,$G$3:$G$1122) | V26: =SUMIF($A$3:$A$1122,S26,$I$3:$I$1122) | W26: =SUMIF($A$2:$A$1123,$S26,$L$2:$L$1123) | X26: =SUMIF($A$2:$A$1123,$S26,$N$2:$N$1123) | Y26: =SUMIF($A$2:$A$1123,$S26,$O$2:$O$1123) | AI26: 05120 | AJ26: =AI26=Tabla1[[#This Row],[Divipola]] | AK26: 233 | AL26: 232 | AM26: 218 | AN26: 212 | AO26: 200 | AP26: 187 | AQ26: 184 | AR26: 173 | AS26: 165 | AT26: 154 | AU26: 144 | AV26: 140 | AW26: 131 | AX26: 126 | AY26: 121 | AZ26: 112 | BA26: 107 | BB26: 101 | BC26: 95 | BD26: 88 | BE26: 79 | BF26: 72 | BG26: 64 | BH26: 56 | BI26: 51 | BJ26: 220 | BK26: =SUM(AK26:BJ26) | BL26: =INT(BK26*$BM$1) | BP26: =(Tabla1[[#This Row],[Población meta programatica 2026 (20251228) menores 1 año]]/12)*9 | BQ26: =BP26 | BS26: =(Tabla1[[#This Row],[Población meta programatica2026 (20251228) niños de 1 año]]/12)*9 | BT26: 158 | BU26: =BS26-BT26 | BX26: 285 | BY26: 304 | BZ26: 05120 | CA26: =BZ26=Tabla1[[#This Row],[Divipola]]
A27: 05 | B27: ANTIOQUIA | C27: CAICEDO | D27: 05125 | E27: 19 | F27: =Tabla1[[#This Row],[Meta Programatica2026 (20251228) RN]]/12 | G27: 69 | H27: =Tabla1[[#This Row],[Población meta programatica 2026 (20251228) menores 1 año]]/12 | I27: 71 | J27: =Tabla1[[#This Row],[Población meta programatica2026 (20251228) niños de 1 año]]/12 | K27: 113 | L27: 91 | M27: =Tabla1[[#This Row],[Población meta programatica2026 (20251228) niños de 5 años]]/12 | N27: =BX27 | O27: =BY27 | P27: =BL27 | R27: TOLIMA | S27: 73 | T27: =SUMIF($A$2:$A$1123,S27,$E$2:$E$1123) | U27: =SUMIF($A$3:$A$1122,S27,$G$3:$G$1122) | V27: =SUMIF($A$3:$A$1122,S27,$I$3:$I$1122) | W27: =SUMIF($A$2:$A$1123,$S27,$L$2:$L$1123) | X27: =SUMIF($A$2:$A$1123,$S27,$N$2:$N$1123) | Y27: =SUMIF($A$2:$A$1123,$S27,$O$2:$O$1123) | AI27: 05125 | AJ27: =AI27=Tabla1[[#This Row],[Divipola]] | AK27: 76 | AL27: 77 | AM27: 69 | AN27: 71 | AO27: 69 | AP27: 68 | AQ27: 63 | AR27: 65 | AS27: 63 | AT27: 62 | AU27: 62 | AV27: 58 | AW27: 56 | AX27: 51 | AY27: 46 | AZ27: 45 | BA27: 43 | BB27: 35 | BC27: 33 | BD27: 27 | BE27: 29 | BF27: 22 | BG27: 21 | BH27: 15 | BI27: 15 | BJ27: 62 | BK27: =SUM(AK27:BJ27) | BL27: =INT(BK27*$BM$1) | BP27: =(Tabla1[[#This Row],[Población meta programatica 2026 (20251228) menores 1 año]]/12)*9 | BQ27: =BP27 | BS27: =(Tabla1[[#This Row],[Población meta programatica2026 (20251228) niños de 1 año]]/12)*9 | BT27: 67 | BU27: =BS27-BT27 | BX27: 57 | BY27: 63 | BZ27: 05125 | CA27: =BZ27=Tabla1[[#This Row],[Divipola]]
A28: 05 | B28: ANTIOQUIA | C28: CALDAS | D28: 05129 | E28: 399 | F28: =Tabla1[[#This Row],[Meta Programatica2026 (20251228) RN]]/12 | G28: 623 | H28: =Tabla1[[#This Row],[Población meta programatica 2026 (20251228) menores 1 año]]/12 | I28: 634 | J28: =Tabla1[[#This Row],[Población meta programatica2026 (20251228) niños de 1 año]]/12 | K28: 871 | L28: 785 | M28: =Tabla1[[#This Row],[Población meta programatica2026 (20251228) niños de 5 años]]/12 | N28: =BX28 | O28: =BY28 | P28: =BL28 | R28: VALLE DEL CAUCA | S28: 76 | T28: =SUMIF($A$2:$A$1123,S28,$E$2:$E$1123) | U28: =SUMIF($A$3:$A$1122,S28,$G$3:$G$1122) | V28: =SUMIF($A$3:$A$1122,S28,$I$3:$I$1122) | W28: =SUMIF($A$2:$A$1123,$S28,$L$2:$L$1123) | X28: =SUMIF($A$2:$A$1123,$S28,$N$2:$N$1123) | Y28: =SUMIF($A$2:$A$1123,$S28,$O$2:$O$1123) | AI28: 05129 | AJ28: =AI28=Tabla1[[#This Row],[Divipola]] | AK28: 1142 | AL28: 1123 | AM28: 1092 | AN28: 1054 | AO28: 1008 | AP28: 965 | AQ28: 918 | AR28: 874 | AS28: 825 | AT28: 774 | AU28: 718 | AV28: 668 | AW28: 620 | AX28: 571 | AY28: 524 | AZ28: 476 | BA28: 429 | BB28: 388 | BC28: 346 | BD28: 307 | BE28: 274 | BF28: 247 | BG28: 211 | BH28: 185 | BI28: 160 | BJ28: 796 | BK28: =SUM(AK28:BJ28) | BL28: =INT(BK28*$BM$1) | BP28: =(Tabla1[[#This Row],[Población meta programatica 2026 (20251228) menores 1 año]]/12)*9 | BQ28: =BP28 | BS28: =(Tabla1[[#This Row],[Población meta programatica2026 (20251228) niños de 1 año]]/12)*9 | BT28: 389 | BU28: =BS28-BT28 | BX28: 471 | BY28: 483 | BZ28: 05129 | CA28: =BZ28=Tabla1[[#This Row],[Divipola]]
A29: 05 | B29: ANTIOQUIA | C29: CAMPAMENTO | D29: 05134 | E29: 14 | F29: =Tabla1[[#This Row],[Meta Programatica2026 (20251228) RN]]/12 | G29: 54 | H29: =Tabla1[[#This Row],[Población meta programatica 2026 (20251228) menores 1 año]]/12 | I29: 60 | J29: =Tabla1[[#This Row],[Población meta programatica2026 (20251228) niños de 1 año]]/12 | K29: 77 | L29: 80 | M29: =Tabla1[[#This Row],[Población meta programatica2026 (20251228) niños de 5 años]]/12 | N29: =BX29 | O29: =BY29 | P29: =BL29 | R29: CALI | S29: 76001 | T29: =SUMIF($A$2:$A$1123,S29,$E$2:$E$1123) | U29: =SUMIF($A$3:$A$1122,S29,$G$3:$G$1122) | V29: =SUMIF($A$3:$A$1122,S29,$I$3:$I$1122) | W29: =SUMIF($D$3:$D$1122,$S29,$L$3:$L$1122) | X29: =SUMIF($A$2:$A$1123,$S29,$N$2:$N$1123) | Y29: =SUMIF($A$2:$A$1123,$S29,$O$2:$O$1123) | AI29: 05134 | AJ29: =AI29=Tabla1[[#This Row],[Divipola]] | AK29: 96 | AL29: 93 | AM29: 95 | AN29: 85 | AO29: 85 | AP29: 81 | AQ29: 75 | AR29: 75 | AS29: 70 | AT29: 66 | AU29: 67 | AV29: 61 | AW29: 59 | AX29: 56 | AY29: 51 | AZ29: 44 | BA29: 49 | BB29: 44 | BC29: 41 | BD29: 34 | BE29: 36 | BF29: 29 | BG29: 26 | BH29: 23 | BI29: 20 | BJ29: 91 | BK29: =SUM(AK29:BJ29) | BL29: =INT(BK29*$BM$1) | BP29: =(Tabla1[[#This Row],[Población meta programatica 2026 (20251228) menores 1 año]]/12)*9 | BQ29: =BP29 | BS29: =(Tabla1[[#This Row],[Población meta programatica2026 (20251228) niños de 1 año]]/12)*9 | BT29: 51 | BU29: =BS29-BT29 | BX29: 57 | BY29: 57 | BZ29: 05134 | CA29: =BZ29=Tabla1[[#This Row],[Divipola]]
A30: 05 | B30: ANTIOQUIA | C30: CAÑASGORDAS | D30: 05138 | E30: 29 | F30: =Tabla1[[#This Row],[Meta Programatica2026 (20251228) RN]]/12 | G30: 119 | H30: =Tabla1[[#This Row],[Población meta programatica 2026 (20251228) menores 1 año]]/12 | I30: 123 | J30: =Tabla1[[#This Row],[Población meta programatica2026 (20251228) niños de 1 año]]/12 | K30: 198 | L30: 185 | M30: =Tabla1[[#This Row],[Población meta programatica2026 (20251228) niños de 5 años]]/12 | N30: =BX30 | O30: =BY30 | P30: =BL30 | R30: BUENAVENTURA | S30: 76109 | T30: =SUMIF($A$2:$A$1123,S30,$E$2:$E$1123) | U30: =SUMIF($D$3:$D$1122,S30,$G$3:$G$1122) | V30: =SUMIF($D$3:$D$1122,S30,$I$3:$I$1122) | W30: =SUMIF($D$3:$D$1122,$S30,$L$3:$L$1122) | X30: =SUMIF($A$2:$A$1123,$S30,$N$2:$N$1123) | Y30: =SUMIF($A$2:$A$1123,$S30,$O$2:$O$1123) | AI30: 05138 | AJ30: =AI30=Tabla1[[#This Row],[Divipola]] | AK30: 190 | AL30: 190 | AM30: 189 | AN30: 185 | AO30: 175 | AP30: 172 | AQ30: 163 | AR30: 156 | AS30: 149 | AT30: 145 | AU30: 135 | AV30: 131 | AW30: 126 | AX30: 120 | AY30: 120 | AZ30: 110 | BA30: 101 | BB30: 98 | BC30: 88 | BD30: 79 | BE30: 72 | BF30: 67 | BG30: 60 | BH30: 51 | BI30: 45 | BJ30: 239 | BK30: =SUM(AK30:BJ30) | BL30: =INT(BK30*$BM$1) | BP30: =(Tabla1[[#This Row],[Población meta programatica 2026 (20251228) menores 1 año]]/12)*9 | BQ30: =BP30 | BS30: =(Tabla1[[#This Row],[Población meta programatica2026 (20251228) niños de 1 año]]/12)*9 | BT30: 107 | BU30: =BS30-BT30 | BX30: 98 | BY30: 99 | BZ30: 05138 | CA30: =BZ30=Tabla1[[#This Row],[Divipola]]
A31: 05 | B31: ANTIOQUIA | C31: CARACOLI | D31: 05142 | E31: 11 | F31: =Tabla1[[#This Row],[Meta Programatica2026 (20251228) RN]]/12 | G31: 42 | H31: =Tabla1[[#This Row],[Población meta programatica 2026 (20251228) menores 1 año]]/12 | I31: 42 | J31: =Tabla1[[#This Row],[Población meta programatica2026 (20251228) niños de 1 año]]/12 | K31: 52 | L31: 56 | M31: =Tabla1[[#This Row],[Población meta programatica2026 (20251228) niños de 5 años]]/12 | N31: =BX31 | O31: =BY31 | P31: =BL31 | R31: ARAUCA | S31: 81 | T31: =SUMIF($A$2:$A$1123,S31,$E$2:$E$1123) | U31: =SUMIF($A$3:$A$1122,S31,$G$3:$G$1122) | V31: =SUMIF($A$3:$A$1122,S31,$I$3:$I$1122) | W31: =SUMIF($A$2:$A$1123,$S31,$L$2:$L$1123) | X31: =SUMIF($A$2:$A$1123,$S31,$N$2:$N$1123) | Y31: =SUMIF($A$2:$A$1123,$S31,$O$2:$O$1123) | AI31: 05142 | AJ31: =AI31=Tabla1[[#This Row],[Divipola]] | AK31: 66 | AL31: 65 | AM31: 64 | AN31: 61 | AO31: 61 | AP31: 59 | AQ31: 55 | AR31: 57 | AS31: 54 | AT31: 51 | AU31: 54 | AV31: 48 | AW31: 49 | AX31: 50 | AY31: 45 | AZ31: 45 | BA31: 37 | BB31: 39 | BC31: 31 | BD31: 27 | BE31: 27 | BF31: 24 | BG31: 17 | BH31: 16 | BI31: 13 | BJ31: 76 | BK31: =SUM(AK31:BJ31) | BL31: =INT(BK31*$BM$1) | BP31: =(Tabla1[[#This Row],[Población meta programatica 2026 (20251228) menores 1 año]]/12)*9 | BQ31: =BP31 | BS31: =(Tabla1[[#This Row],[Población meta programatica2026 (20251228) niños de 1 año]]/12)*9 | BT31: 34 | BU31: =BS31-BT31 | BX31: 29 | BY31: 26 | BZ31: 05142 | CA31: =BZ31=Tabla1[[#This Row],[Divipola]]
A32: 05 | B32: ANTIOQUIA | C32: CARAMANTA | D32: 05145 | E32: 12 | F32: =Tabla1[[#This Row],[Meta Programatica2026 (20251228) RN]]/12 | G32: 44 | H32: =Tabla1[[#This Row],[Población meta programatica 2026 (20251228) menores 1 año]]/12 | I32: 44 | J32: =Tabla1[[#This Row],[Población meta programatica2026 (20251228) niños de 1 año]]/12 | K32: 53 | L32: 46 | M32: =Tabla1[[#This Row],[Población meta programatica2026 (20251228) niños de 5 años]]/12 | N32: =BX32 | O32: =BY32 | P32: =BL32 | R32: CASANARE | S32: 85 | T32: =SUMIF($A$2:$A$1123,S32,$E$2:$E$1123) | U32: =SUMIF($A$3:$A$1122,S32,$G$3:$G$1122) | V32: =SUMIF($A$3:$A$1122,S32,$I$3:$I$1122) | W32: =SUMIF($A$2:$A$1123,$S32,$L$2:$L$1123) | X32: =SUMIF($A$2:$A$1123,$S32,$N$2:$N$1123) | Y32: =SUMIF($A$2:$A$1123,$S32,$O$2:$O$1123) | AI32: 05145 | AJ32: =AI32=Tabla1[[#This Row],[Divipola]] | AK32: 73 | AL32: 74 | AM32: 75 | AN32: 79 | AO32: 76 | AP32: 72 | AQ32: 68 | AR32: 67 | AS32: 65 | AT32: 57 | AU32: 57 | AV32: 50 | AW32: 47 | AX32: 41 | AY32: 41 | AZ32: 36 | BA32: 30 | BB32: 29 | BC32: 24 | BD32: 21 | BE32: 18 | BF32: 20 | BG32: 15 | BH32: 13 | BI32: 14 | BJ32: 55 | BK32: =SUM(AK32:BJ32) | BL32: =INT(BK32*$BM$1) | BP32: =(Tabla1[[#This Row],[Población meta programatica 2026 (20251228) menores 1 año]]/12)*9 | BQ32: =BP32 | BS32: =(Tabla1[[#This Row],[Población meta programatica2026 (20251228) niños de 1 año]]/12)*9 | BT32: 22 | BU32: =BS32-BT32 | BX32: 34 | BY32: 29 | BZ32: 05145 | CA32: =BZ32=Tabla1[[#This Row],[Divipola]]
A33: 05 | B33: ANTIOQUIA | C33: CAREPA | D33: 05147 | E33: 119 | F33: =Tabla1[[#This Row],[Meta Programatica2026 (20251228) RN]]/12 | G33: 680 | H33: =Tabla1[[#This Row],[Población meta programatica 2026 (20251228) menores 1 año]]/12 | I33: 689 | J33: =Tabla1[[#This Row],[Población meta programatica2026 (20251228) niños de 1 año]]/12 | K33: 1067 | L33: 911 | M33: =Tabla1[[#This Row],[Población meta programatica2026 (20251228) niños de 5 años]]/12 | N33: =BX33 | O33: =BY33 | P33: =BL33 | R33: PUTUMAYO | S33: 86 | T33: =SUMIF($A$2:$A$1123,S33,$E$2:$E$1123) | U33: =SUMIF($A$3:$A$1122,S33,$G$3:$G$1122) | V33: =SUMIF($A$3:$A$1122,S33,$I$3:$I$1122) | W33: =SUMIF($A$2:$A$1123,$S33,$L$2:$L$1123) | X33: =SUMIF($A$2:$A$1123,$S33,$N$2:$N$1123) | Y33: =SUMIF($A$2:$A$1123,$S33,$O$2:$O$1123) | AI33: 05147 | AJ33: =AI33=Tabla1[[#This Row],[Divipola]] | AK33: 365 | AL33: 349 | AM33: 334 | AN33: 310 | AO33: 287 | AP33: 265 | AQ33: 245 | AR33: 227 | AS33: 211 | AT33: 194 | AU33: 178 | AV33: 164 | AW33: 152 | AX33: 142 | AY33: 128 | AZ33: 120 | BA33: 116 | BB33: 103 | BC33: 94 | BD33: 88 | BE33: 77 | BF33: 69 | BG33: 62 | BH33: 52 | BI33: 44 | BJ33: 194 | BK33: =SUM(AK33:BJ33) | BL33: =INT(BK33*$BM$1) | BP33: =(Tabla1[[#This Row],[Población meta programatica 2026 (20251228) menores 1 año]]/12)*9 | BQ33: =BP33 | BS33: =(Tabla1[[#This Row],[Población meta programatica2026 (20251228) niños de 1 año]]/12)*9 | BT33: 402 | BU33: =BS33-BT33 | BX33: 897 | BY33: 1035 | BZ33: 05147 | CA33: =BZ33=Tabla1[[#This Row],[Divipola]]
A34: 05 | B34: ANTIOQUIA | C34: EL CARMEN DE VIBORAL | D34: 05148 | E34: 41 | F34: =Tabla1[[#This Row],[Meta Programatica2026 (20251228) RN]]/12 | G34: 418 | H34: =Tabla1[[#This Row],[Población meta programatica 2026 (20251228) menores 1 año]]/12 | I34: 441 | J34: =Tabla1[[#This Row],[Población meta programatica2026 (20251228) niños de 1 año]]/12 | K34: 623 | L34: 651 | M34: =Tabla1[[#This Row],[Población meta programatica2026 (20251228) niños de 5 años]]/12 | N34: =BX34 | O34: =BY34 | P34: =BL34 | R34: SAN ANDRES ISLAS | S34: 88 | T34: =SUMIF($A$2:$A$1123,S34,$E$2:$E$1123) | U34: =SUMIF($A$3:$A$1122,S34,$G$3:$G$1122) | V34: =SUMIF($A$3:$A$1122,S34,$I$3:$I$1122) | W34: =SUMIF($A$2:$A$1123,$S34,$L$2:$L$1123) | X34: =SUMIF($A$2:$A$1123,$S34,$N$2:$N$1123) | Y34: =SUMIF($A$2:$A$1123,$S34,$O$2:$O$1123) | AI34: 05148 | AJ34: =AI34=Tabla1[[#This Row],[Divipola]] | AK34: 648 | AL34: 641 | AM34: 632 | AN34: 614 | AO34: 591 | AP34: 567 | AQ34: 543 | AR34: 514 | AS34: 484 | AT34: 458 | AU34: 430 | AV34: 399 | AW34: 364 | AX34: 333 | AY34: 302 | AZ34: 273 | BA34: 255 | BB34: 223 | BC34: 199 | BD34: 178 | BE34: 158 | BF34: 136 | BG34: 118 | BH34: 107 | BI34: 89 | BJ34: 404 | BK34: =SUM(AK34:BJ34) | BL34: =INT(BK34*$BM$1) | BP34: =(Tabla1[[#This Row],[Población meta programatica 2026 (20251228) menores 1 año]]/12)*9 | BQ34: =BP34 | BS34: =(Tabla1[[#This Row],[Población meta programatica2026 (20251228) niños de 1 año]]/12)*9 | BT34: 316 | BU34: =BS34-BT34 | BX34: 316 | BY34: 354 | BZ34: 05148 | CA34: =BZ34=Tabla1[[#This Row],[Divipola]]
A35: 05 | B35: ANTIOQUIA | C35: CAROLINA | D35: 05150 | E35: 3 | F35: =Tabla1[[#This Row],[Meta Programatica2026 (20251228) RN]]/12 | G35: 15 | H35: =Tabla1[[#This Row],[Población meta programatica 2026 (20251228) menores 1 año]]/12 | I35: 17 | J35: =Tabla1[[#This Row],[Población meta programatica2026 (20251228) niños de 1 año]]/12 | K35: 23 | L35: 30 | M35: =Tabla1[[#This Row],[Población meta programatica2026 (20251228) niños de 5 años]]/12 | N35: =BX35 | O35: =BY35 | P35: =BL35 | R35: AMAZONAS | S35: 91 | T35: =SUMIF($A$2:$A$1123,S35,$E$2:$E$1123) | U35: =SUMIF($A$3:$A$1122,S35,$G$3:$G$1122) | V35: =SUMIF($A$3:$A$1122,S35,$I$3:$I$1122) | W35: =SUMIF($A$2:$A$1123,$S35,$L$2:$L$1123) | X35: =SUMIF($A$2:$A$1123,$S35,$N$2:$N$1123) | Y35: =SUMIF($A$2:$A$1123,$S35,$O$2:$O$1123) | AI35: 05150 | AJ35: =AI35=Tabla1[[#This Row],[Divipola]] | AK35: 67 | AL35: 61 | AM35: 60 | AN35: 58 | AO35: 57 | AP35: 57 | AQ35: 49 | AR35: 49 | AS35: 51 | AT35: 48 | AU35: 45 | AV35: 42 | AW35: 39 | AX35: 41 | AY35: 37 | AZ35: 36 | BA35: 29 | BB35: 34 | BC35: 27 | BD35: 23 | BE35: 22 | BF35: 17 | BG35: 15 | BH35: 16 | BI35: 12 | BJ35: 68 | BK35: =SUM(AK35:BJ35) | BL35: =INT(BK35*$BM$1) | BP35: =(Tabla1[[#This Row],[Población meta programatica 2026 (20251228) menores 1 año]]/12)*9 | BQ35: =BP35 | BS35: =(Tabla1[[#This Row],[Población meta programatica2026 (20251228) niños de 1 año]]/12)*9 | BT35: 6 | BU35: =BS35-BT35 | BX35: 11 | BY35: 18 | BZ35: 05150 | CA35: =BZ35=Tabla1[[#This Row],[Divipola]]
A36: 05 | B36: ANTIOQUIA | C36: CAUCASIA | D36: 05154 | E36: 2996 | F36: =Tabla1[[#This Row],[Meta Programatica2026 (20251228) RN]]/12 | G36: 1096 | H36: =Tabla1[[#This Row],[Población meta programatica 2026 (20251228) menores 1 año]]/12 | I36: 1139 | J36: =Tabla1[[#This Row],[Población meta programatica2026 (20251228) niños de 1 año]]/12 | K36: 1626 | L36: 1378 | M36: =Tabla1[[#This Row],[Población meta programatica2026 (20251228) niños de 5 años]]/12 | N36: =BX36 | O36: =BY36 | P36: =BL36 | R36: GUAINIA | S36: 94 | T36: =SUMIF($A$2:$A$1123,S36,$E$2:$E$1123) | U36: =SUMIF($A$3:$A$1122,S36,$G$3:$G$1122) | V36: =SUMIF($A$3:$A$1122,S36,$I$3:$I$1122) | W36: =SUMIF($A$2:$A$1123,$S36,$L$2:$L$1123) | X36: =SUMIF($A$2:$A$1123,$S36,$N$2:$N$1123) | Y36: =SUMIF($A$2:$A$1123,$S36,$O$2:$O$1123) | AI36: 05154 | AJ36: =AI36=Tabla1[[#This Row],[Divipola]] | AK36: 844 | AL36: 819 | AM36: 791 | AN36: 754 | AO36: 721 | AP36: 683 | AQ36: 644 | AR36: 601 | AS36: 558 | AT36: 511 | AU36: 475 | AV36: 437 | AW36: 404 | AX36: 375 | AY36: 349 | AZ36: 323 | BA36: 302 | BB36: 278 | BC36: 256 | BD36: 241 | BE36: 216 | BF36: 192 | BG36: 173 | BH36: 150 | BI36: 125 | BJ36: 588 | BK36: =SUM(AK36:BJ36) | BL36: =INT(BK36*$BM$1) | BP36: =(Tabla1[[#This Row],[Población meta programatica 2026 (20251228) menores 1 año]]/12)*9 | BQ36: =BP36 | BS36: =(Tabla1[[#This Row],[Población meta programatica2026 (20251228) niños de 1 año]]/12)*9 | BT36: 696 | BU36: =BS36-BT36 | BX36: 857 | BY36: 861 | BZ36: 05154 | CA36: =BZ36=Tabla1[[#This Row],[Divipola]]
A37: 05 | B37: ANTIOQUIA | C37: CHIGORODO | D37: 05172 | E37: 1433 | F37: =Tabla1[[#This Row],[Meta Programatica2026 (20251228) RN]]/12 | G37: 884 | H37: =Tabla1[[#This Row],[Población meta programatica 2026 (20251228) menores 1 año]]/12 | I37: 921 | J37: =Tabla1[[#This Row],[Población meta programatica2026 (20251228) niños de 1 año]]/12 | K37: 1343 | L37: 1144 | M37: =Tabla1[[#This Row],[Población meta programatica2026 (20251228) niños de 5 años]]/12 | N37: =BX37 | O37: =BY37 | P37: =BL37 | R37: GUAVIARE | S37: 95 | T37: =SUMIF($A$2:$A$1123,S37,$E$2:$E$1123) | U37: =SUMIF($A$3:$A$1122,S37,$G$3:$G$1122) | V37: =SUMIF($A$3:$A$1122,S37,$I$3:$I$1122) | W37: =SUMIF($A$2:$A$1123,$S37,$L$2:$L$1123) | X37: =SUMIF($A$2:$A$1123,$S37,$N$2:$N$1123) | Y37: =SUMIF($A$2:$A$1123,$S37,$O$2:$O$1123) | AI37: 05172 | AJ37: =AI37=Tabla1[[#This Row],[Divipola]] | AK37: 463 | AL37: 447 | AM37: 427 | AN37: 412 | AO37: 388 | AP37: 362 | AQ37: 341 | AR37: 317 | AS37: 299 | AT37: 281 | AU37: 264 | AV37: 248 | AW37: 227 | AX37: 214 | AY37: 199 | AZ37: 183 | BA37: 177 | BB37: 158 | BC37: 149 | BD37: 134 | BE37: 120 | BF37: 106 | BG37: 88 | BH37: 81 | BI37: 69 | BJ37: 306 | BK37: =SUM(AK37:BJ37) | BL37: =INT(BK37*$BM$1) | BP37: =(Tabla1[[#This Row],[Población meta programatica 2026 (20251228) menores 1 año]]/12)*9 | BQ37: =BP37 | BS37: =(Tabla1[[#This Row],[Población meta programatica2026 (20251228) niños de 1 año]]/12)*9 | BT37: 734 | BU37: =BS37-BT37 | BX37: 586 | BY37: 575 | BZ37: 05172 | CA37: =BZ37=Tabla1[[#This Row],[Divipola]]
A38: 05 | B38: ANTIOQUIA | C38: CISNEROS | D38: 05190 | E38: 21 | F38: =Tabla1[[#This Row],[Meta Programatica2026 (20251228) RN]]/12 | G38: 78 | H38: =Tabla1[[#This Row],[Población meta programatica 2026 (20251228) menores 1 año]]/12 | I38: 94 | J38: =Tabla1[[#This Row],[Población meta programatica2026 (20251228) niños de 1 año]]/12 | K38: 119 | L38: 139 | M38: =Tabla1[[#This Row],[Población meta programatica2026 (20251228) niños de 5 años]]/12 | N38: =BX38 | O38: =BY38 | P38: =BL38 | R38: VAUPES | S38: 97 | T38: =SUMIF($A$2:$A$1123,S38,$E$2:$E$1123) | U38: =SUMIF($A$3:$A$1122,S38,$G$3:$G$1122) | V38: =SUMIF($A$3:$A$1122,S38,$I$3:$I$1122) | W38: =SUMIF($A$2:$A$1123,$S38,$L$2:$L$1123) | X38: =SUMIF($A$2:$A$1123,$S38,$N$2:$N$1123) | Y38: =SUMIF($A$2:$A$1123,$S38,$O$2:$O$1123) | AI38: 05190 | AJ38: =AI38=Tabla1[[#This Row],[Divipola]] | AK38: 139 | AL38: 136 | AM38: 134 | AN38: 129 | AO38: 129 | AP38: 122 | AQ38: 119 | AR38: 117 | AS38: 107 | AT38: 105 | AU38: 99 | AV38: 95 | AW38: 91 | AX38: 86 | AY38: 82 | AZ38: 79 | BA38: 73 | BB38: 67 | BC38: 65 | BD38: 63 | BE38: 51 | BF38: 45 | BG38: 43 | BH38: 37 | BI38: 32 | BJ38: 132 | BK38: =SUM(AK38:BJ38) | BL38: =INT(BK38*$BM$1) | BP38: =(Tabla1[[#This Row],[Población meta programatica 2026 (20251228) menores 1 año]]/12)*9 | BQ38: =BP38 | BS38: =(Tabla1[[#This Row],[Población meta programatica2026 (20251228) niños de 1 año]]/12)*9 | BT38: 75 | BU38: =BS38-BT38 | BX38: 103 | BY38: 80 | BZ38: 05190 | CA38: =BZ38=Tabla1[[#This Row],[Divipola]]
A39: 05 | B39: ANTIOQUIA | C39: COCORNA | D39: 05197 | E39: 35 | F39: =Tabla1[[#This Row],[Meta Programatica2026 (20251228) RN]]/12 | G39: 121 | H39: =Tabla1[[#This Row],[Población meta programatica 2026 (20251228) menores 1 año]]/12 | I39: 135 | J39: =Tabla1[[#This Row],[Población meta programatica2026 (20251228) niños de 1 año]]/12 | K39: 192 | L39: 194 | M39: =Tabla1[[#This Row],[Población meta programatica2026 (20251228) niños de 5 años]]/12 | N39: =BX39 | O39: =BY39 | P39: =BL39 | R39: VICHADA | S39: 99 | T39: =SUMIF($A$2:$A$1123,S39,$E$2:$E$1123) | U39: =SUMIF($A$3:$A$1122,S39,$G$3:$G$1122) | V39: =SUMIF($A$3:$A$1122,S39,$I$3:$I$1122) | W39: =SUMIF($A$2:$A$1123,$S39,$L$2:$L$1123) | X39: =SUMIF($A$2:$A$1123,$S39,$N$2:$N$1123) | Y39: =SUMIF($A$2:$A$1123,$S39,$O$2:$O$1123) | AI39: 05197 | AJ39: =AI39=Tabla1[[#This Row],[Divipola]] | AK39: 196 | AL39: 200 | AM39: 193 | AN39: 191 | AO39: 185 | AP39: 183 | AQ39: 176 | AR39: 167 | AS39: 164 | AT39: 155 | AU39: 151 | AV39: 143 | AW39: 133 | AX39: 126 | AY39: 123 | AZ39: 111 | BA39: 111 | BB39: 101 | BC39: 92 | BD39: 85 | BE39: 79 | BF39: 77 | BG39: 64 | BH39: 57 | BI39: 48 | BJ39: 228 | BK39: =SUM(AK39:BJ39) | BL39: =INT(BK39*$BM$1) | BP39: =(Tabla1[[#This Row],[Población meta programatica 2026 (20251228) menores 1 año]]/12)*9 | BQ39: =BP39 | BS39: =(Tabla1[[#This Row],[Población meta programatica2026 (20251228) niños de 1 año]]/12)*9 | BT39: 94 | BU39: =BS39-BT39 | BX39: 94 | BY39: 106 | BZ39: 05197 | CA39: =BZ39=Tabla1[[#This Row],[Divipola]]
