Workbook

Sheet 1_BRASIL
E1: =D1+1 -> 1 | F1: =E1+1 -> 2 | G1: =F1+1 -> 3 | H1: =G1+1 -> 4 | I1: =H1+1 -> 5 | J1: =I1+1 -> 6 | K1: =J1+1 -> 7 | L1: =K1+1 -> 8 | ... ON1: =OM1+1 -> 400
A2: NOMBRE DEPARTAMENTO: | D2: ='6_VENEZOLANOS'!D2 -> RISARALDA | E2: CODIGO DEPARTAMENTO: | G2: ='6_VENEZOLANOS'!G2 -> 66 | H2: =G2 -> 66
A3: AÑO: | D3: ='6_VENEZOLANOS'!D3 -> 2026 | HE3: DE 1 AÑO 2022 | HF3: DE 2 AÑOS 2021 | HG3: DE 3 AÑOS 2020 | HH3: DE 4 AÑOS 2019 | HI3: DE 5 AÑOS 2018 | HJ3: DE 6 AÑOS 2017 | HK3: DE 7 AÑOS 2016 | HL3: DE 8 AÑOS 2015 | HM3: DE 9 AÑOS 2014 | HN3: DE 10 AÑOS 2013 | HO3: DE 11 AÑOS 2012 | HP3: DE 12 AÑOS 2011 | HQ3: DE 13 AÑOS 2010 | HR3: DE 14 AÑOS 2009 | HS3: DE 15 AÑOS 2008 | HT3: DE 16 AÑOS 2007 | HU3: DE 17 AÑOS 2006 | OG3: .
A4: MES DE REPORTE | D4: ='6_VENEZOLANOS'!D4 -> agosto | F4: VACUNAS PAI | S4: VACUNAS PAI | BV4: VACUNAS PAI | CW4: VACUNAS PAI | EI4: VACUNAS PAI | FE4: VACUNAS PAI | JZ4: VACUNAS PAI | NH4: VACUNAS PAI | OF4: VACUNAS PAI
A5: MUNICIPIO | D5: REGIMEN / GRUPO ETNICO | E5: BCG | H5: HEPATITIS B | AE5: HEPATITIS B (RESOLUCION. 0459/2012 y Circular 031/2014) | BK5: POBLACION PRIORIZADA PARA HEPATITIS B | BO5: ANTIPOLIO INACTIVADA (VIP) | CU5: HEXAVALENTE (DPTa-HB-Hib-VIP) | CX5: PENTAVALENTE DPT - HB - Hib | DI5: DPT | DV5: TDaP Acelular Pediatrica | FA5: ROTAVIRUS | FC5: NEUMOCOCO CONJUGADA DECAVALENTE | FI5: NEUMOCOCO CONJUGADA TRECEVALENTE | FO5: SRP (TRIPLE VIRAL) | GI5: SR (DOBLE VIRAL) | HD5: FIEBRE AMARILLA DOSIS UNICA | IC5: HEPATITIS A (Cohorte de nacidos a partir de 1 de enero de 2012) | IP5: VARICELA (Cohorte de nacidos a partir de 1 de julio de 2014) | JH5: TOXOIDE TETANICO-DIFTERICO DE ADULTOS (Td) | LM5: Tdap ACELULAR (Se debe garantizar una dosis por cada embarazo y se aplica a partir de las semana 26 y zona rural a partir de la semana 20 y otros grupos de dificil acceso o captación) | LZ5: INFLUENZA | MR5: MENINGOCOCO USO EN BROTES (Serogrupo A, C, Y y W-135) | MX5: V P H | NH5: ANTIRRABICA HUMANA PRE/POST-EXPOSICION | NW5: INMUNOGLOBULINA ANTI HEPATITIS B | OB5: INMUNOGLOBULINAS /ANTITOXINAS TETÁNICAS | OD5: ANTI TOXINA DIFTERICA (Suero heterólogo) | OF5: COVID 19
E6: RECIEN NACIDO (DE 0 HASTA 29 DÍAS) | F6: MENOR DE UN AÑO (A PARTIR DE 30 DIAS HASTA 11 MESES 29 DIAS) | G6: POBLACION INDIGENA Y RURAL DISPERSA (DE 1 AÑO A 5 AÑOS, 11 MESES, 29 DIAS) | H6: RECIEN NACIDO (HASTA 29 DÍAS) | J6: DE 2 A 11 MESES 29 DÍAS | M6: DE 1 AÑO | P6: DE 2 AÑOS | S6: DE 3 AÑOS | V6: DE 4 AÑOS | Y6: DE 5 AÑOS | AB6: DE 6 a 17 AÑOS 11 MESES Y 29 DIAS (ICBF) | AE6: DE 1 AÑO | AI6: DE 2 AÑOS | AM6: DE 3 AÑOS | AQ6: DE 4 AÑOS | AU6: DE 5 AÑOS | AY6: 6 A 14 AÑOS | BC6: DE 15 AÑOS A 17 AÑOS | BG6: DE 18 AÑOS Y MAS | BO6: < DE 1 AÑO | BR6: DE 1 AÑO | BU6: DE 2 AÑOS | BX6: DE 3 AÑOS | CA6: DE 4 AÑOS | CD6: DE 5 AÑOS | CG6: AL AÑO DE LA 3ra DOSIS (De 18 a 23 meses) | CH6: DE 2 AÑOS | CI6: DE 3 AÑOS | CJ6: DE 4 AÑOS | CK6: DE 5 AÑOS | CL6: DE 5 AÑOS | CM6: DE 6 AÑOS | CP6: DE 7 A 17 AÑOS (AUTORIZADAS POR EL MINISTERIO) | CS6: DE 18 A 60 AÑOS (AUTORIZADAS POR EL MINISTERIO) | CU6: < DE 1 AÑO (Prematuros Extremos (MENOR DE 1500 GRAMOS según lineamientos) | CX6: < DE 1 AÑO | DA6: De 18 a 23 meses | DB6: DE 1 AÑO (12 a 23 meses) Sin antecedente de Penta | DE6: DE 2 AÑOS (24 a 35 meses) Sin antecedente de Penta | DF6: DE 3 AÑOS (36 a 47 meses) Sin antecedente de Penta | DG6: DE 4 AÑOS (48 a 70 meses) Sin antecedente de Penta | DH6: 5 AÑOS HASTA UN DIA ANTES DE CUMPLIR LOS 6 AÑOS | DI6: DE 2 AÑOS | DL6: DE 3 AÑOS | DO6: DE 4 AÑOS | DR6: DE 5 AÑOS | DV6: < DE 1 AÑO | DY6: DE 1 AÑO | EB6: DE 2 AÑOS | EE6: DE 3 AÑOS | EH6: DE 4 AÑOS | EK6: DE 5 AÑOS | EN6: De 18 a 23 meses | EO6: DE 2 AÑOS | EP6: DE 3 AÑOS | EQ6: DE 4 AÑOS | ER6: DE 5 AÑOS | ES6: 3 AÑOS | ET6: 4 AÑOS | EU6: 5 AÑOS | EV6: DE 6 AÑOS | FA6: DE 2 MESES A 3 MESES y 21 DIAS | FB6: DE 4 MESES A LOS 11 MESES y 29 DIAS | FC6: DE 2 A 11 MESES 29 DIAS | FE6: DE 12 MESES A 23 MESES | FH6: DE 24 MESES A 71 MESES 29 DIAS | FI6: DE 2 A 11 MESES 29 DIAS | FK6: DE 12 A 23 MESES | FL6: DE 12 A 23 MESES | FN6: DE 24 MESES A 71 MESES 29 DIAS | FO6: PRIMERA DOSIS (Se deben registrar las dosis aplicadas en población nacida del 1 de enero al 31 de diciembre de cada año) | FY6: SEGUNDA DOSIS | GI6: DOSIS CERO | GJ6: DOSIS UNICA | HD6: DE 1 AÑO 2024 | HE6: DE 2 AÑOS 2023 | HF6: DE 3 AÑOS 2022 | HG6: DE 4 AÑOS 2021 | HH6: DE 5 AÑOS 2020 | HI6: DE 6 AÑOS 2019 | HJ6: DE 7 AÑOS 2018 | HK6: DE 8 AÑOS 2017 | HL6: DE 9 AÑOS 2016 | HM6: DE 10 AÑOS 2015 | HN6: DE 11 AÑOS 2014 | HO6: DE 12 AÑOS 2013 | HP6: DE 13 AÑOS 2012 | HQ6: DE 14 AÑOS 2011 | HR6: DE 15 AÑOS 2010 | HS6: DE 16 AÑOS 2009 | HT6: DE 17 AÑOS 2008 | HU6: DE 18 AÑOS 2007 | HV6: DE 19 AÑOS 2006 | HW6: 20 A 30 AÑOS (2007-1994) | HX6: 31 A 40 AÑOS | HY6: 41 A 50 AÑOS | HZ6: 51 A 59 AÑOS | IA6: 60 A 69 AÑOS (previa autorizacion del Ministerio). | IB6: EN SITUACIÓN DE BROTE Y PAISES QUE EXIGEN ANTECEDENTE VACUNAL | IC6: DOSIS ÚNICA | IP6: PRIMERA DOSIS | JA6: REFUERZO (aplicadas a partir del 1 de julio de 2019) | JH6: NIÑOS Y NIÑAS DE 7 A 9 AÑOS | JM6: GESTANTES DE 9 AÑOS A 17 AÑOS | JR6: GESTANTES DE 18 AÑOS Y MAS | JW6: REFUERZOS GESTANTES 15 A 49 AÑOS | KA6: MUJERES EN EDAD FERTIL (MEF) DE 10 AÑOS A 17 AÑOS | KF6: MUJERES EN EDAD FERTIL (MEF) DE 18 A 49 AÑOS | KK6: REFUERZOS MEF DE 15 A 49 AÑOS | KO6: HOMBRES DE 10 A 17 AÑOS | KT6: HOMBRES DE 18 A 49 AÑOS | KY6: REFUERZOS HOMBRES DE 15 A 49 AÑOS | LC6: OTROS DE 50 A 59 AÑOS | LH6: OTROS DE 60 AÑOS Y MAS | LM6: GESTANTES DE 9 A 17 AÑOS de acuerdo al lineamiento | LS6: GESTANTES DE 18 AÑOS Y MAS, de acuerdo al lineamiento | LY6: UNICA DOSIS OTROS GRUPOS (Con Autorizacion del MSPS ) | LZ6: DE 6 MESES A 11 MESES | MB6: DE 12 MESES A 23 MESES | ME6: 24 A 35 MESES SEGÚN AUTORIZACION DEL MINISTERIO | MH6: DE 50 a 59 AÑOS (SEGÚN AUTORIZACION DEL MINISTERIO) | MI6: DE 60 Y MAS AÑOS | MJ6: GESTANTES A PARTIR DE LA SEMANA 14 | MK6: DE 3 A 8 AÑOS (Poblaciones autorizadas de acuerdo a los lineamientos emitidos por el MSPS ) | MN6: DE 9 A 17 AÑOS (Poblaciones con diagnóstico de riesgo, recibir de acuerdo a los lineamientos emitidos por el MSPS ) | MO6: DE 18 A 59 AÑOS (Poblaciones con diagnóstico de riesgo de acuerdo a los lineamientos emitidos por el MSPS) | MP6: PERSONAL DE LA SALUD | MQ6: Familiares y convivientes de menores de 18 años con Cancér (Ley 1388/2010) | MR6: DE 6 A 11 MESES | MU6: 12 A 23 MESES | MW6: MAYORES DE 2 AÑOS | MX6: 9 AÑOS | MY6: 10 AÑOS | MZ6: 11 AÑOS | NA6: 12 AÑOS | NB6: 13 AÑOS | NC6: 14 AÑOS | ND6: 15 AÑOS | NE6: 16 AÑOS | NF6: 17 AÑOS | NG6: 2as Dosis Inmunosuprimidos, según linemientos del 30 de septiembre/2023 | NH6: ESQUEMA PRE EXPOSICIÓN OPCION 1 (I.D.) (Se aplica previa autorización del Ministerio) | NJ6: ESQUEMA PRE EXPOSICIÓN OPCION 2 (I.M.) (Se aplica previa autorización del Ministerio) | NL6: ESQUEMA POST EXPOSICION Número de dosis aplicadas | NQ6: ESQUEMA RE-EXPOSICIÓN | NT6: TOTAL DE ESQUEMAS POST EXPOSICION (USUARIOS CON ESQUEMA DE VACUNACION COMPLETO) | NU6: INMUNOGLOBULINA ANTIRRÁBICA (Número de frascos utilizados) | NV6: No. De personas que recibieron inmunoglobulina antirrabica. | NW6: RECIEN NACIDO (Hijo de Madre Antigenos + para HB) | NZ6: RESOLUCION 0459/2012- Circular 031/2014) | OB6: INMUNOGLOBULINA ANTI TETANICA (Suero homólogo) | OF6: DE 6 MESES A 4 AÑOS | OI6: DE 5 AÑOS A 11 AÑOS | OJ6: DE 12 A 59 AÑOS | OK6: GESTANTES | OL6: MAYORES DE 60 AÑOS | OM6: TALENTO HUMANO EN SALUD | ON6: DE 12 AÑOS A 59 AÑOS PERSONAS CON COMORBILIDADES
A7: Nº | B7: COD DANE MPIO | C7: NOMBRE MUNICIPIO/ IPS | H7: RECIEN NACIDO (Primeras 12 Horas) | I7: RECIEN NACIDO Entre 12 horas y 29 dias | J7: 1a | K7: 2a | L7: 3a | M7: 1a | N7: 2a | O7: 3a | P7: 1a | Q7: 2a | R7: 3a | S7: 1a | T7: 2a | U7: 3a | V7: 1a | W7: 2a | X7: 3a | Y7: 1a | Z7: 2a | AA7: 3a | AB7: 1a | AC7: 2a | AD7: 3a | AE7: 1a | AF7: 2a | AG7: 3a | AH7: Ref. | AI7: 1a | AJ7: 2a | AK7: 3a | AL7: Ref. | AM7: 1a | AN7: 2a | AO7: 3a | AP7: Ref. | AQ7: 1a | AR7: 2a | AS7: 3a | AT7: Ref. | AU7: 1a | AV7: 2a | AW7: 3a | AX7: Ref. | AY7: 1a | AZ7: 2a | BA7: 3a | BB7: Ref. | BC7: 1a | BD7: 2a | BE7: 3a | BF7: Ref. | BG7: 1a | BH7: 2a | BI7: 3a | BJ7: Ref. | BK7: 1a | BL7: 2a | BM7: 3a | BN7: Ref- | BO7: 1a | BP7: 2a | BQ7: 3a | BR7: 1a | BS7: 2a | BT7: 3a | BU7: 1a | BV7: 2a | BW7: 3a | BX7: 1a | BY7: 2a | BZ7: 3a | CA7: 1a | CB7: 2a | CC7: 3a | CD7: 1a | CE7: 2a | CF7: 3a | CG7: Primer Refuerzo | CL7: Segundo Refuerzo | CM7: 1a | CN7: 2a | CO7: 3a | CP7: 1a | CQ7: 2a | CR7: 3a | CS7: 1a | CT7: 2a | CU7: 1a | CV7: 2a | CW7: 3a | CX7: 1a | CY7: 2a | CZ7: 3a | DA7: 1er REF de acuerdo a lineamiento | DB7: 1a | DC7: 2a | DD7: 3a | DE7: Unica | DF7: Unica | DG7: Unica | DH7: Unica | DI7: 2a | DJ7: 3a | DK7: REF. | DL7: 2a | DM7: 3a | DN7: REF. | DO7: 2a | DP7: 3a | DQ7: REF. | DR7: 2a | DS7: 3a | DT7: 1° REF. | DU7: 2° REF. | DV7: 1a | DW7: 2a | DX7: 3a | DY7: 1a | DZ7: 2a | EA7: 3a | EB7: 1a | EC7: 2a | ED7: 3a | EE7: 1a | EF7: 2a | EG7: 3a | EH7: 1a | EI7: 2a | EJ7: 3a | EK7: 1a | EL7: 2a | EM7: 3a | EN7: 1er REF. | ES7: 2° REF. | EV7: 1a | EW7: 2a | EX7: 3a | EY7: 1er REF. | EZ7: 2° REF. | FA7: 1a | FB7: 2a | FC7: 1a | FD7: 2a | FE7: REF. | FF7: 1a | FG7: 2a | FH7: ÚNICA | FI7: 1a | FJ7: 2a | FK7: REF. | FL7: 1a | FM7: 2a | FN7: ÚNICA | FO7: Nacidos 2024 1 año | FP7: Nacidos 2023 2 años | FQ7: Nacidos 2022 3 años | FR7: Nacidos 2021 4 años | FS7: Nacidos 2020 5 años | FT7: Nacidos 2019 6 años | FU7: Nacidos 2018 7 años | FV7: Nacidos 2017 8 años | FW7: Nacidos 2016 9 años | FX7: Nacidos 2015 10 años | FY7: De 18 a 23 meses | FZ7: Nacidos 2023 (Seguimiento) 2 años | GA7: Nacidos 2022 (Seguimiento) 3 años | GB7: Nacidos 2021 (Seguimiento) 4 años | GC7: Nacidos 2020 5 años | GD7: Nacidos 2019 6 años | GE7: Nacidos 2018 7 años | GF7: Nacidos 2017 8 años | GG7: Nacidos 2016 9 años | GH7: Nacidos 2015 10 años | GI7: SR * 6 a 11 MESES 29 DIAS | GJ7: DE 1 AÑO 2024 | GK7: DE 2 AÑOS 2023 | GL7: DE 3 AÑOS 2022 | GM7: DE 4 AÑOS 2021 | GN7: DE 5 AÑOS 2020 | GO7: DE 6 AÑOS 2019 | GP7: DE 7 AÑOS 2018 | GQ7: DE 8 AÑOS 2017 | GR7: DE 9 AÑOS 2016 | GS7: DE 10 AÑOS 2015 | GT7: DE 11 AÑOS 2014 | GU7: DE 12 AÑOS 2013 | GV7: DE 13 AÑOS 2012 | GW7: DE 14 AÑOS 2011 | GX7: DE 15 AÑOS 2010 | GY7: DE 16 AÑOS 2009 | GZ7: DE 17 AÑOS 2008 | HA7: 18 A 30 AÑOS | HB7: 31 A 40 AÑOS | HC7: 41 Y MAS AÑOS | IB7: 9 meses a 11 meses (Con Autorizacion del MSPS de acuerdo a Lineamientos) | IC7: DE 1 AÑO 2024 | ID7: DE 2 AÑOS 2023 | IE7: DE 3 AÑOS 2022 | IF7: DE 4 AÑOS 2021 | IG7: DE 5 AÑOS 2020 | IH7: DE 6 AÑOS 2019 | II7: DE 7 AÑOS 2018 | IJ7: DE 8 AÑOS 2017 | IK7: DE 9 AÑOS 2016 | IL7: DE 10 AÑOS 2015 | IM7: DE 11 AÑOS 2014 | IN7: DE 12 AÑOS 2013 | IO7: DE 13 AÑOS 2012 | IP7: DE 1 AÑO 2024 | IQ7: DE 2 AÑOS 2023 | IR7: DE 3 AÑOS 2022 | IS7: DE 4 AÑOS 2021 | IT7: DE 5 AÑOS 2020 | IU7: DE 6 AÑOS 2019 | IV7: DE 7 AÑOS 2018 | IW7: DE 8 AÑOS 2017 | IX7: DE 9 AÑOS 2016 | IY7: DE 10 AÑOS 2015 | IZ7: DE 11 AÑOS 2014 | JA7: DE 5 AÑOS 2024 | JB7: DE 6 AÑOS 2023 | JC7: DE 7 AÑOS 2022 | JD7: DE 8 AÑOS 2021 | JE7: DE 9 AÑOS 2020 | JF7: DE 10 AÑOS 2019 | JG7: DE 11 AÑOS 2018 | JH7: Td1 | JI7: Td2 | JJ7: Td3 | JK7: Ref 1 | JL7: Ref 2 | JM7: Td1 | JN7: Td2 | JO7: Td3 | JP7: Td4 | JQ7: Td5 | JR7: Td1 | JS7: Td2 | JT7: Td3 | JU7: Td4 | JV7: Td5 | JW7: REF. 1 | JX7: REF. 2 | JY7: REF. 3 | JZ7: REF. 4 | KA7: Td1 | KB7: Td2 | KC7: Td3 | KD7: Td4 | KE7: Td5 | KF7: Td1 | KG7: Td2 | KH7: Td3 | KI7: Td4 | KJ7: Td5 | KK7: REF. 1 | KL7: REF. 2 | KM7: REF. 3 | KN7: REF. 4 | KO7: Td1 | KP7: Td2 | KQ7: Td3 | KR7: Td4 | KS7: Td5 | KT7: Td1 | KU7: Td2 | KV7: Td3 | KW7: Td4 | KX7: Td5 | KY7: REF. 1 | KZ7: REF. 2 | LA7: REF. 3 | LB7: REF. 4 | LC7: Td1 | LD7: Td2 | LE7: Td3 | LF7: Td4 | LG7: Td5 | LH7: Td1 | LI7: Td2 | LJ7: Td3 | LK7: Td4 | LL7: Td5 | LM7: UNICA DOSIS EN CADA EMBARAZO | LN7: Td1 | LO7: Td2 | LP7: Td3 | LQ7: Td4 | LR7: Td5 | LS7: UNICA DOSIS EN CADA EMBARAZO | LT7: Td1 | LU7: Td2 | LV7: Td3 | LW7: Td4 | LX7: Td5 | LZ7: 1a | MA7: 2a | MB7: 1a | MC7: 2a | MD7: ÚNICA | ME7: 1a | MF7: 2a | MG7: ÚNICA | MH7: ÚNICA | MI7: ÚNICA | MJ7: ÚNICA | MK7: 1a | ML7: 2a | MM7: ÚNICA | MN7: ÚNICA | MO7: ÚNICA | MP7: ÚNICA | MQ7: ÚNICA | MR7: 1a | MS7: 2a | MT7: 3a | MU7: 1a | MV7: 2a | MW7: ÚNICA | MX7: Dosis Ùnica | NH7: 1a. y 2a día 0 | NI7: 3a y 4a. día 7 | NJ7: 1a . día 0 | NK7: 2a. día 7 | NL7: 1a. día 0 | NM7: 2a. dia 3 | NN7: 3a. día 7 | NO7: 4a . día 14 | NP7: 5a . día 21 a 28 | NQ7: 1a . día 0 | NR7: 2a. día 3 | NS7: 3a. día 7 a 14 | NT7: Número de usuarios | NW7: Número de frascos utilizados | NX7: N° recién nacidos que recibieron dosis de Ig en las primeras 12 horas | NY7: N° recién nacidos que recibieron dosis de Ig despues de las primeras 12 horas | NZ7: Número de frascos utilizados | OA7: N° Personas que recibieron dosis de Ig | OB7: Número de frascos utilizados | OC7: N° Personas que recibieron dosis de Ig | OD7: Número de frascos utilizados | OE7: N° Personas que recibieron dosis de antitoxina | OF7: Primera dosis | OG7: Segunda dosis | OH7: Adicional | OI7: Adicional | OJ7: Adicional | OK7: Adicional | OL7: Adicional | OM7: Adicional | ON7: Adicional | OO7: TOTAL DOSIS
A8: 1 | B8: ='[1]6_VENEZOLANOS'!B8:B16 -> 001 | C8: ENERO | D8: FEMENINO | OO8: =SUM(E8:ON8)-SUM(NT8:NW8)-SUM(NZ8:OE8) -> 0
D9: MASCULINO | OO9: =SUM(E9:ON9)-SUM(NT9:NW9)-SUM(NZ9:OE9) -> 0
D10: OTRO | OO10: =SUM(E10:ON10)-SUM(NT10:NW10)-SUM(NZ10:OE10) -> 0
D11: TOTAL GENERO | E11: =SUM(E8:E10) -> 0 | F11: =SUM(F8:F10) -> 0 | G11: =SUM(G8:G10) -> 0 | H11: =SUM(H8:H10) -> 0 | I11: =SUM(I8:I10) -> 0 | J11: =SUM(J8:J10) -> 0 | K11: =SUM(K8:K10) -> 0 | L11: =SUM(L8:L10) -> 0 | ... OO11: =SUM(OO8:OO10) -> 0
D12: CONTRIBUTIVO | OO12: =SUM(E12:ON12)-SUM(NT12:NW12)-SUM(NZ12:OE12) -> 0
D13: SUBSIDIADO | OO13: =SUM(E13:ON13)-SUM(NT13:NW13)-SUM(NZ13:OE13) -> 0
D14: POBRE NO ASEGURADO | OO14: =SUM(E14:ON14)-SUM(NT14:NW14)-SUM(NZ14:OE14) -> 0
D15: REGIMEN ESPECIAL | OO15: =SUM(E15:ON15)-SUM(NT15:NW15)-SUM(NZ15:OE15) -> 0
D16: TOTAL REGIMEN | E16: =SUM(E12:E15) -> 0 | F16: =SUM(F12:F15) -> 0 | G16: =SUM(G12:G15) -> 0 | H16: =SUM(H12:H15) -> 0 | I16: =SUM(I12:I15) -> 0 | J16: =SUM(J12:J15) -> 0 | K16: =SUM(K12:K15) -> 0 | L16: =SUM(L12:L15) -> 0 | ... OO16: =SUM(OO12:OO15) -> 0
A17: 2 | B17: ='[1]6_VENEZOLANOS'!B17:B25 -> 045 | C17: FEBRERO | D17: FEMENINO | OO17: =SUM(E17:ON17)-SUM(NT17:NW17)-SUM(NZ17:OE17) -> 0
D18: MASCULINO | OO18: =SUM(E18:ON18)-SUM(NT18:NW18)-SUM(NZ18:OE18) -> 0
D19: OTRO | OO19: =SUM(E19:ON19)-SUM(NT19:NW19)-SUM(NZ19:OE19) -> 0
D20: TOTAL GENERO | E20: =SUM(E17:E19) -> 0 | F20: =SUM(F17:F19) -> 0 | G20: =SUM(G17:G19) -> 0 | H20: =SUM(H17:H19) -> 0 | I20: =SUM(I17:I19) -> 0 | J20: =SUM(J17:J19) -> 0 | K20: =SUM(K17:K19) -> 0 | L20: =SUM(L17:L19) -> 0 | ... OO20: =SUM(OO17:OO19) -> 0
D21: CONTRIBUTIVO | OO21: =SUM(E21:ON21)-SUM(NT21:NW21)-SUM(NZ21:OE21) -> 0
D22: SUBSIDIADO | OO22: =SUM(E22:ON22)-SUM(NT22:NW22)-SUM(NZ22:OE22) -> 0
D23: POBRE NO ASEGURADO | OO23: =SUM(E23:ON23)-SUM(NT23:NW23)-SUM(NZ23:OE23) -> 0
D24: REGIMEN ESPECIAL | OO24: =SUM(E24:ON24)-SUM(NT24:NW24)-SUM(NZ24:OE24) -> 0
D25: TOTAL REGIMEN | E25: =SUM(E21:E24) -> 0 | F25: =SUM(F21:F24) -> 0 | G25: =SUM(G21:G24) -> 0 | H25: =SUM(H21:H24) -> 0 | I25: =SUM(I21:I24) -> 0 | J25: =SUM(J21:J24) -> 0 | K25: =SUM(K21:K24) -> 0 | L25: =SUM(L21:L24) -> 0 | ... OO25: =SUM(OO21:OO24) -> 0
A26: 3 | B26: ='[1]6_VENEZOLANOS'!B26:B34 -> 075 | C26: MARZO | D26: FEMENINO | OO26: =SUM(E26:ON26)-SUM(NT26:NW26)-SUM(NZ26:OE26) -> 0
D27: MASCULINO | OO27: =SUM(E27:ON27)-SUM(NT27:NW27)-SUM(NZ27:OE27) -> 0
D28: OTRO | OO28: =SUM(E28:ON28)-SUM(NT28:NW28)-SUM(NZ28:OE28) -> 0
D29: TOTAL GENERO | E29: =SUM(E26:E28) -> 0 | F29: =SUM(F26:F28) -> 0 | G29: =SUM(G26:G28) -> 0 | H29: =SUM(H26:H28) -> 0 | I29: =SUM(I26:I28) -> 0 | J29: =SUM(J26:J28) -> 0 | K29: =SUM(K26:K28) -> 0 | L29: =SUM(L26:L28) -> 0 | ... OO29: =SUM(OO26:OO28) -> 0
D30: CONTRIBUTIVO | OO30: =SUM(E30:ON30)-SUM(NT30:NW30)-SUM(NZ30:OE30) -> 0
D31: SUBSIDIADO | OO31: =SUM(E31:ON31)-SUM(NT31:NW31)-SUM(NZ31:OE31) -> 0
D32: POBRE NO ASEGURADO | OO32: =SUM(E32:ON32)-SUM(NT32:NW32)-SUM(NZ32:OE32) -> 0
D33: REGIMEN ESPECIAL | OO33: =SUM(E33:ON33)-SUM(NT33:NW33)-SUM(NZ33:OE33) -> 0
D34: TOTAL REGIMEN | E34: =SUM(E30:E33) -> 0 | F34: =SUM(F30:F33) -> 0 | G34: =SUM(G30:G33) -> 0 | H34: =SUM(H30:H33) -> 0 | I34: =SUM(I30:I33) -> 0 | J34: =SUM(J30:J33) -> 0 | K34: =SUM(K30:K33) -> 0 | L34: =SUM(L30:L33) -> 0 | ... OO34: =SUM(OO30:OO33) -> 0
A35: 4 | B35: ='[1]6_VENEZOLANOS'!B35:B43 -> 088 | C35: ABRIL | D35: FEMENINO | OO35: =SUM(E35:ON35)-SUM(NT35:NW35)-SUM(NZ35:OE35) -> 0
D36: MASCULINO | OO36: =SUM(E36:ON36)-SUM(NT36:NW36)-SUM(NZ36:OE36) -> 0
D37: OTRO | OO37: =SUM(E37:ON37)-SUM(NT37:NW37)-SUM(NZ37:OE37) -> 0
D38: TOTAL GENERO | E38: =SUM(E35:E37) -> 0 | F38: =SUM(F35:F37) -> 0 | G38: =SUM(G35:G37) -> 0 | H38: =SUM(H35:H37) -> 0 | I38: =SUM(I35:I37) -> 0 | J38: =SUM(J35:J37) -> 0 | K38: =SUM(K35:K37) -> 0 | L38: =SUM(L35:L37) -> 0 | ... OO38: =SUM(OO35:OO37) -> 0
D39: CONTRIBUTIVO | OO39: =SUM(E39:ON39)-SUM(NT39:NW39)-SUM(NZ39:OE39) -> 0
D40: SUBSIDIADO | OO40: =SUM(E40:ON40)-SUM(NT40:NW40)-SUM(NZ40:OE40) -> 0
...

Sheet 2_ECUADOR
E1: =D1+1 -> 1 | F1: =E1+1 -> 2 | G1: =F1+1 -> 3 | H1: =G1+1 -> 4 | I1: =H1+1 -> 5 | J1: =I1+1 -> 6 | K1: =J1+1 -> 7 | L1: =K1+1 -> 8 | ... ON1: =OM1+1 -> 400
A2: NOMBRE DEPARTAMENTO: | D2: ='6_VENEZOLANOS'!D2 -> RISARALDA | E2: CODIGO DEPARTAMENTO: | G2: ='6_VENEZOLANOS'!G2 -> 66 | H2: =G2 -> 66
A3: AÑO: | D3: ='6_VENEZOLANOS'!D3 -> 2026 | HE3: DE 1 AÑO 2022 | HF3: DE 2 AÑOS 2021 | HG3: DE 3 AÑOS 2020 | HH3: DE 4 AÑOS 2019 | HI3: DE 5 AÑOS 2018 | HJ3: DE 6 AÑOS 2017 | HK3: DE 7 AÑOS 2016 | HL3: DE 8 AÑOS 2015 | HM3: DE 9 AÑOS 2014 | HN3: DE 10 AÑOS 2013 | HO3: DE 11 AÑOS 2012 | HP3: DE 12 AÑOS 2011 | HQ3: DE 13 AÑOS 2010 | HR3: DE 14 AÑOS 2009 | HS3: DE 15 AÑOS 2008 | HT3: DE 16 AÑOS 2007 | HU3: DE 17 AÑOS 2006 | OG3: .
A4: MES DE REPORTE | D4: ='6_VENEZOLANOS'!D4 -> agosto | F4: VACUNAS PAI | S4: VACUNAS PAI | BV4: VACUNAS PAI | CW4: VACUNAS PAI | EI4: VACUNAS PAI | FE4: VACUNAS PAI | JZ4: VACUNAS PAI | NH4: VACUNAS PAI | OF4: VACUNAS PAI
A5: MUNICIPIO | D5: REGIMEN / GRUPO ETNICO | E5: BCG | H5: HEPATITIS B | AE5: HEPATITIS B (RESOLUCION. 0459/2012 y Circular 031/2014) | BK5: POBLACION PRIORIZADA PARA HEPATITIS B | BO5: ANTIPOLIO INACTIVADA (VIP) | CU5: HEXAVALENTE (DPTa-HB-Hib-VIP) | CX5: PENTAVALENTE DPT - HB - Hib | DI5: DPT | DV5: TDaP Acelular Pediatrica | FA5: ROTAVIRUS | FC5: NEUMOCOCO CONJUGADA DECAVALENTE | FI5: NEUMOCOCO CONJUGADA TRECEVALENTE | FO5: SRP (TRIPLE VIRAL) | GI5: SR (DOBLE VIRAL) | HD5: FIEBRE AMARILLA DOSIS UNICA | IC5: HEPATITIS A (Cohorte de nacidos a partir de 1 de enero de 2012) | IP5: VARICELA (Cohorte de nacidos a partir de 1 de julio de 2014) | JH5: TOXOIDE TETANICO-DIFTERICO DE ADULTOS (Td) | LM5: Tdap ACELULAR (Se debe garantizar una dosis por cada embarazo y se aplica a partir de las semana 26 y zona rural a partir de la semana 20 y otros grupos de dificil acceso o captación) | LZ5: INFLUENZA | MR5: MENINGOCOCO USO EN BROTES (Serogrupo A, C, Y y W-135) | MX5: V P H | NH5: ANTIRRABICA HUMANA PRE/POST-EXPOSICION | NW5: INMUNOGLOBULINA ANTI HEPATITIS B | OB5: INMUNOGLOBULINAS /ANTITOXINAS TETÁNICAS | OD5: ANTI TOXINA DIFTERICA (Suero heterólogo) | OF5: COVID 19
E6: RECIEN NACIDO (DE 0 HASTA 29 DÍAS) | F6: MENOR DE UN AÑO (A PARTIR DE 30 DIAS HASTA 11 MESES 29 DIAS) | G6: POBLACION INDIGENA Y RURAL DISPERSA (DE 1 AÑO A 5 AÑOS, 11 MESES, 29 DIAS) | H6: RECIEN NACIDO (HASTA 29 DÍAS) | J6: DE 2 A 11 MESES 29 DÍAS | M6: DE 1 AÑO | P6: DE 2 AÑOS | S6: DE 3 AÑOS | V6: DE 4 AÑOS | Y6: DE 5 AÑOS | AB6: DE 6 a 17 AÑOS 11 MESES Y 29 DIAS (ICBF) | AE6: DE 1 AÑO | AI6: DE 2 AÑOS | AM6: DE 3 AÑOS | AQ6: DE 4 AÑOS | AU6: DE 5 AÑOS | AY6: 6 A 14 AÑOS | BC6: DE 15 AÑOS A 17 AÑOS | BG6: DE 18 AÑOS Y MAS | BO6: < DE 1 AÑO | BR6: DE 1 AÑO | BU6: DE 2 AÑOS | BX6: DE 3 AÑOS | CA6: DE 4 AÑOS | CD6: DE 5 AÑOS | CG6: AL AÑO DE LA 3ra DOSIS (De 18 a 23 meses) | CH6: DE 2 AÑOS | CI6: DE 3 AÑOS | CJ6: DE 4 AÑOS | CK6: DE 5 AÑOS | CL6: DE 5 AÑOS | CM6: DE 6 AÑOS | CP6: DE 7 A 17 AÑOS (AUTORIZADAS POR EL MINISTERIO) | CS6: DE 18 A 60 AÑOS (AUTORIZADAS POR EL MINISTERIO) | CU6: < DE 1 AÑO (Prematuros Extremos (MENOR DE 1500 GRAMOS según lineamientos) | CX6: < DE 1 AÑO | DA6: De 18 a 23 meses | DB6: DE 1 AÑO (12 a 23 meses) Sin antecedente de Penta | DE6: DE 2 AÑOS (24 a 35 meses) Sin antecedente de Penta | DF6: DE 3 AÑOS (36 a 47 meses) Sin antecedente de Penta | DG6: DE 4 AÑOS (48 a 70 meses) Sin antecedente de Penta | DH6: 5 AÑOS HASTA UN DIA ANTES DE CUMPLIR LOS 6 AÑOS | DI6: DE 2 AÑOS | DL6: DE 3 AÑOS | DO6: DE 4 AÑOS | DR6: DE 5 AÑOS | DV6: < DE 1 AÑO | DY6: DE 1 AÑO | EB6: DE 2 AÑOS | EE6: DE 3 AÑOS | EH6: DE 4 AÑOS | EK6: DE 5 AÑOS | EN6: De 18 a 23 meses | EO6: DE 2 AÑOS | EP6: DE 3 AÑOS | EQ6: DE 4 AÑOS | ER6: DE 5 AÑOS | ES6: 3 AÑOS | ET6: 4 AÑOS | EU6: 5 AÑOS | EV6: DE 6 AÑOS | FA6: DE 2 MESES A 3 MESES y 21 DIAS | FB6: DE 4 MESES A LOS 11 MESES y 29 DIAS | FC6: DE 2 A 11 MESES 29 DIAS | FE6: DE 12 MESES A 23 MESES | FH6: DE 24 MESES A 71 MESES 29 DIAS | FI6: DE 2 A 11 MESES 29 DIAS | FK6: DE 12 A 23 MESES | FL6: DE 12 A 23 MESES | FN6: DE 24 MESES A 71 MESES 29 DIAS | FO6: PRIMERA DOSIS (Se deben registrar las dosis aplicadas en población nacida del 1 de enero al 31 de diciembre de cada año) | FY6: SEGUNDA DOSIS | GI6: DOSIS CERO | GJ6: DOSIS UNICA | HD6: DE 1 AÑO 2024 | HE6: DE 2 AÑOS 2023 | HF6: DE 3 AÑOS 2022 | HG6: DE 4 AÑOS 2021 | HH6: DE 5 AÑOS 2020 | HI6: DE 6 AÑOS 2019 | HJ6: DE 7 AÑOS 2018 | HK6: DE 8 AÑOS 2017 | HL6: DE 9 AÑOS 2016 | HM6: DE 10 AÑOS 2015 | HN6: DE 11 AÑOS 2014 | HO6: DE 12 AÑOS 2013 | HP6: DE 13 AÑOS 2012 | HQ6: DE 14 AÑOS 2011 | HR6: DE 15 AÑOS 2010 | HS6: DE 16 AÑOS 2009 | HT6: DE 17 AÑOS 2008 | HU6: DE 18 AÑOS 2007 | HV6: DE 19 AÑOS 2006 | HW6: 20 A 30 AÑOS (2007-1994) | HX6: 31 A 40 AÑOS | HY6: 41 A 50 AÑOS | HZ6: 51 A 59 AÑOS | IA6: 60 A 69 AÑOS (previa autorizacion del Ministerio). | IB6: EN SITUACIÓN DE BROTE Y PAISES QUE EXIGEN ANTECEDENTE VACUNAL | IC6: DOSIS ÚNICA | IP6: PRIMERA DOSIS | JA6: REFUERZO (aplicadas a partir del 1 de julio de 2019) | JH6: NIÑOS Y NIÑAS DE 7 A 9 AÑOS | JM6: GESTANTES DE 9 AÑOS A 17 AÑOS | JR6: GESTANTES DE 18 AÑOS Y MAS | JW6: REFUERZOS GESTANTES 15 A 49 AÑOS | KA6: MUJERES EN EDAD FERTIL (MEF) DE 10 AÑOS A 17 AÑOS | KF6: MUJERES EN EDAD FERTIL (MEF) DE 18 A 49 AÑOS | KK6: REFUERZOS MEF DE 15 A 49 AÑOS | KO6: HOMBRES DE 10 A 17 AÑOS | KT6: HOMBRES DE 18 A 49 AÑOS | KY6: REFUERZOS HOMBRES DE 15 A 49 AÑOS | LC6: OTROS DE 50 A 59 AÑOS | LH6: OTROS DE 60 AÑOS Y MAS | LM6: GESTANTES DE 9 A 17 AÑOS de acuerdo al lineamiento | LS6: GESTANTES DE 18 AÑOS Y MAS, de acuerdo al lineamiento | LY6: UNICA DOSIS OTROS GRUPOS (Con Autorizacion del MSPS ) | LZ6: DE 6 MESES A 11 MESES | MB6: DE 12 MESES A 23 MESES | ME6: 24 A 35 MESES SEGÚN AUTORIZACION DEL MINISTERIO | MH6: DE 50 a 59 AÑOS (SEGÚN AUTORIZACION DEL MINISTERIO) | MI6: DE 60 Y MAS AÑOS | MJ6: GESTANTES A PARTIR DE LA SEMANA 14 | MK6: DE 3 A 8 AÑOS (Poblaciones autorizadas de acuerdo a los lineamientos emitidos por el MSPS ) | MN6: DE 9 A 17 AÑOS (Poblaciones con diagnóstico de riesgo, recibir de acuerdo a los lineamientos emitidos por el MSPS ) | MO6: DE 18 A 59 AÑOS (Poblaciones con diagnóstico de riesgo de acuerdo a los lineamientos emitidos por el MSPS) | MP6: PERSONAL DE LA SALUD | MQ6: Familiares y convivientes de menores de 18 años con Cancér (Ley 1388/2010) | MR6: DE 6 A 11 MESES | MU6: 12 A 23 MESES | MW6: MAYORES DE 2 AÑOS | MX6: 9 AÑOS | MY6: 10 AÑOS | MZ6: 11 AÑOS | NA6: 12 AÑOS | NB6: 13 AÑOS | NC6: 14 AÑOS | ND6: 15 AÑOS | NE6: 16 AÑOS | NF6: 17 AÑOS | NG6: 2as Dosis Inmunosuprimidos, según linemientos del 30 de septiembre/2023 | NH6: ESQUEMA PRE EXPOSICIÓN OPCION 1 (I.D.) (Se aplica previa autorización del Ministerio) | NJ6: ESQUEMA PRE EXPOSICIÓN OPCION 2 (I.M.) (Se aplica previa autorización del Ministerio) | NL6: ESQUEMA POST EXPOSICION Número de dosis aplicadas | NQ6: ESQUEMA RE-EXPOSICIÓN | NT6: TOTAL DE ESQUEMAS POST EXPOSICION (USUARIOS CON ESQUEMA DE VACUNACION COMPLETO) | NU6: INMUNOGLOBULINA ANTIRRÁBICA (Número de frascos utilizados) | NV6: No. De personas que recibieron inmunoglobulina antirrabica. | NW6: RECIEN NACIDO (Hijo de Madre Antigenos + para HB) | NZ6: RESOLUCION 0459/2012- Circular 031/2014) | OB6: INMUNOGLOBULINA ANTI TETANICA (Suero homólogo) | OF6: DE 6 MESES A 4 AÑOS | OI6: DE 5 AÑOS A 11 AÑOS | OJ6: DE 12 A 59 AÑOS | OK6: GESTANTES | OL6: MAYORES DE 60 AÑOS | OM6: TALENTO HUMANO EN SALUD | ON6: DE 12 AÑOS A 59 AÑOS PERSONAS CON COMORBILIDADES
A7: Nº | B7: COD DANE MPIO | C7: NOMBRE MUNICIPIO/ IPS | H7: RECIEN NACIDO (Primeras 12 Horas) | I7: RECIEN NACIDO Entre 12 horas y 29 dias | J7: 1a | K7: 2a | L7: 3a | M7: 1a | N7: 2a | O7: 3a | P7: 1a | Q7: 2a | R7: 3a | S7: 1a | T7: 2a | U7: 3a | V7: 1a | W7: 2a | X7: 3a | Y7: 1a | Z7: 2a | AA7: 3a | AB7: 1a | AC7: 2a | AD7: 3a | AE7: 1a | AF7: 2a | AG7: 3a | AH7: Ref. | AI7: 1a | AJ7: 2a | AK7: 3a | AL7: Ref. | AM7: 1a | AN7: 2a | AO7: 3a | AP7: Ref. | AQ7: 1a | AR7: 2a | AS7: 3a | AT7: Ref. | AU7: 1a | AV7: 2a | AW7: 3a | AX7: Ref. | AY7: 1a | AZ7: 2a | BA7: 3a | BB7: Ref. | BC7: 1a | BD7: 2a | BE7: 3a | BF7: Ref. | BG7: 1a | BH7: 2a | BI7: 3a | BJ7: Ref. | BK7: 1a | BL7: 2a | BM7: 3a | BN7: Ref- | BO7: 1a | BP7: 2a | BQ7: 3a | BR7: 1a | BS7: 2a | BT7: 3a | BU7: 1a | BV7: 2a | BW7: 3a | BX7: 1a | BY7: 2a | BZ7: 3a | CA7: 1a | CB7: 2a | CC7: 3a | CD7: 1a | CE7: 2a | CF7: 3a | CG7: Primer Refuerzo | CL7: Segundo Refuerzo | CM7: 1a | CN7: 2a | CO7: 3a | CP7: 1a | CQ7: 2a | CR7: 3a | CS7: 1a | CT7: 2a | CU7: 1a | CV7: 2a | CW7: 3a | CX7: 1a | CY7: 2a | CZ7: 3a | DA7: 1er REF de acuerdo a lineamiento | DB7: 1a | DC7: 2a | DD7: 3a | DE7: Unica | DF7: Unica | DG7: Unica | DH7: Unica | DI7: 2a | DJ7: 3a | DK7: REF. | DL7: 2a | DM7: 3a | DN7: REF. | DO7: 2a | DP7: 3a | DQ7: REF. | DR7: 2a | DS7: 3a | DT7: 1° REF. | DU7: 2° REF. | DV7: 1a | DW7: 2a | DX7: 3a | DY7: 1a | DZ7: 2a | EA7: 3a | EB7: 1a | EC7: 2a | ED7: 3a | EE7: 1a | EF7: 2a | EG7: 3a | EH7: 1a | EI7: 2a | EJ7: 3a | EK7: 1a | EL7: 2a | EM7: 3a | EN7: 1er REF. | ES7: 2° REF. | EV7: 1a | EW7: 2a | EX7: 3a | EY7: 1er REF. | EZ7: 2° REF. | FA7: 1a | FB7: 2a | FC7: 1a | FD7: 2a | FE7: REF. | FF7: 1a | FG7: 2a | FH7: ÚNICA | FI7: 1a | FJ7: 2a | FK7: REF. | FL7: 1a | FM7: 2a | FN7: ÚNICA | FO7: Nacidos 2024 1 año | FP7: Nacidos 2023 2 años | FQ7: Nacidos 2022 3 años | FR7: Nacidos 2021 4 años | FS7: Nacidos 2020 5 años | FT7: Nacidos 2019 6 años | FU7: Nacidos 2018 7 años | FV7: Nacidos 2017 8 años | FW7: Nacidos 2016 9 años | FX7: Nacidos 2015 10 años | FY7: De 18 a 23 meses | FZ7: Nacidos 2023 (Seguimiento) 2 años | GA7: Nacidos 2022 (Seguimiento) 3 años | GB7: Nacidos 2021 (Seguimiento) 4 años | GC7: Nacidos 2020 5 años | GD7: Nacidos 2019 6 años | GE7: Nacidos 2018 7 años | GF7: Nacidos 2017 8 años | GG7: Nacidos 2016 9 años | GH7: Nacidos 2015 10 años | GI7: SR * 6 a 11 MESES 29 DIAS | GJ7: DE 1 AÑO 2024 | GK7: DE 2 AÑOS 2023 | GL7: DE 3 AÑOS 2022 | GM7: DE 4 AÑOS 2021 | GN7: DE 5 AÑOS 2020 | GO7: DE 6 AÑOS 2019 | GP7: DE 7 AÑOS 2018 | GQ7: DE 8 AÑOS 2017 | GR7: DE 9 AÑOS 2016 | GS7: DE 10 AÑOS 2015 | GT7: DE 11 AÑOS 2014 | GU7: DE 12 AÑOS 2013 | GV7: DE 13 AÑOS 2012 | GW7: DE 14 AÑOS 2011 | GX7: DE 15 AÑOS 2010 | GY7: DE 16 AÑOS 2009 | GZ7: DE 17 AÑOS 2008 | HA7: 18 A 30 AÑOS | HB7: 31 A 40 AÑOS | HC7: 41 Y MAS AÑOS | IB7: 9 meses a 11 meses (Con Autorizacion del MSPS de acuerdo a Lineamientos) | IC7: DE 1 AÑO 2024 | ID7: DE 2 AÑOS 2023 | IE7: DE 3 AÑOS 2022 | IF7: DE 4 AÑOS 2021 | IG7: DE 5 AÑOS 2020 | IH7: DE 6 AÑOS 2019 | II7: DE 7 AÑOS 2018 | IJ7: DE 8 AÑOS 2017 | IK7: DE 9 AÑOS 2016 | IL7: DE 10 AÑOS 2015 | IM7: DE 11 AÑOS 2014 | IN7: DE 12 AÑOS 2013 | IO7: DE 13 AÑOS 2012 | IP7: DE 1 AÑO 2024 | IQ7: DE 2 AÑOS 2023 | IR7: DE 3 AÑOS 2022 | IS7: DE 4 AÑOS 2021 | IT7: DE 5 AÑOS 2020 | IU7: DE 6 AÑOS 2019 | IV7: DE 7 AÑOS 2018 | IW7: DE 8 AÑOS 2017 | IX7: DE 9 AÑOS 2016 | IY7: DE 10 AÑOS 2015 | IZ7: DE 11 AÑOS 2014 | JA7: DE 5 AÑOS 2024 | JB7: DE 6 AÑOS 2023 | JC7: DE 7 AÑOS 2022 | JD7: DE 8 AÑOS 2021 | JE7: DE 9 AÑOS 2020 | JF7: DE 10 AÑOS 2019 | JG7: DE 11 AÑOS 2018 | JH7: Td1 | JI7: Td2 | JJ7: Td3 | JK7: Ref 1 | JL7: Ref 2 | JM7: Td1 | JN7: Td2 | JO7: Td3 | JP7: Td4 | JQ7: Td5 | JR7: Td1 | JS7: Td2 | JT7: Td3 | JU7: Td4 | JV7: Td5 | JW7: REF. 1 | JX7: REF. 2 | JY7: REF. 3 | JZ7: REF. 4 | KA7: Td1 | KB7: Td2 | KC7: Td3 | KD7: Td4 | KE7: Td5 | KF7: Td1 | KG7: Td2 | KH7: Td3 | KI7: Td4 | KJ7: Td5 | KK7: REF. 1 | KL7: REF. 2 | KM7: REF. 3 | KN7: REF. 4 | KO7: Td1 | KP7: Td2 | KQ7: Td3 | KR7: Td4 | KS7: Td5 | KT7: Td1 | KU7: Td2 | KV7: Td3 | KW7: Td4 | KX7: Td5 | KY7: REF. 1 | KZ7: REF. 2 | LA7: REF. 3 | LB7: REF. 4 | LC7: Td1 | LD7: Td2 | LE7: Td3 | LF7: Td4 | LG7: Td5 | LH7: Td1 | LI7: Td2 | LJ7: Td3 | LK7: Td4 | LL7: Td5 | LM7: UNICA DOSIS EN CADA EMBARAZO | LN7: Td1 | LO7: Td2 | LP7: Td3 | LQ7: Td4 | LR7: Td5 | LS7: UNICA DOSIS EN CADA EMBARAZO | LT7: Td1 | LU7: Td2 | LV7: Td3 | LW7: Td4 | LX7: Td5 | LZ7: 1a | MA7: 2a | MB7: 1a | MC7: 2a | MD7: ÚNICA | ME7: 1a | MF7: 2a | MG7: ÚNICA | MH7: ÚNICA | MI7: ÚNICA | MJ7: ÚNICA | MK7: 1a | ML7: 2a | MM7: ÚNICA | MN7: ÚNICA | MO7: ÚNICA | MP7: ÚNICA | MQ7: ÚNICA | MR7: 1a | MS7: 2a | MT7: 3a | MU7: 1a | MV7: 2a | MW7: ÚNICA | MX7: Dosis Ùnica | NH7: 1a. y 2a día 0 | NI7: 3a y 4a. día 7 | NJ7: 1a . día 0 | NK7: 2a. día 7 | NL7: 1a. día 0 | NM7: 2a. dia 3 | NN7: 3a. día 7 | NO7: 4a . día 14 | NP7: 5a . día 21 a 28 | NQ7: 1a . día 0 | NR7: 2a. día 3 | NS7: 3a. día 7 a 14 | NT7: Número de usuarios | NW7: Número de frascos utilizados | NX7: N° recién nacidos que recibieron dosis de Ig en las primeras 12 horas | NY7: N° recién nacidos que recibieron dosis de Ig despues de las primeras 12 horas | NZ7: Número de frascos utilizados | OA7: N° Personas que recibieron dosis de Ig | OB7: Número de frascos utilizados | OC7: N° Personas que recibieron dosis de Ig | OD7: Número de frascos utilizados | OE7: N° Personas que recibieron dosis de antitoxina | OF7: Primera dosis | OG7: Segunda dosis | OH7: Adicional | OI7: Adicional | OJ7: Adicional | OK7: Adicional | OL7: Adicional | OM7: Adicional | ON7: Adicional | OO7: TOTAL DOSIS
A8: 1 | B8: ='[1]6_VENEZOLANOS'!B8:B16 -> 001 | C8: ENERO | D8: FEMENINO | OO8: =SUM(E8:ON8)-SUM(NT8:NW8)-SUM(NZ8:OE8) -> 0
D9: MASCULINO | OO9: =SUM(E9:ON9)-SUM(NT9:NW9)-SUM(NZ9:OE9) -> 0
D10: OTRO | OO10: =SUM(E10:ON10)-SUM(NT10:NW10)-SUM(NZ10:OE10) -> 0
D11: TOTAL GENERO | E11: =SUM(E8:E10) -> 0 | F11: =SUM(F8:F10) -> 0 | G11: =SUM(G8:G10) -> 0 | H11: =SUM(H8:H10) -> 0 | I11: =SUM(I8:I10) -> 0 | J11: =SUM(J8:J10) -> 0 | K11: =SUM(K8:K10) -> 0 | L11: =SUM(L8:L10) -> 0 | ... OO11: =SUM(OO8:OO10) -> 0
D12: CONTRIBUTIVO | OO12: =SUM(E12:ON12)-SUM(NT12:NW12)-SUM(NZ12:OE12) -> 0
D13: SUBSIDIADO | OO13: =SUM(E13:ON13)-SUM(NT13:NW13)-SUM(NZ13:OE13) -> 0
D14: POBRE NO ASEGURADO | OO14: =SUM(E14:ON14)-SUM(NT14:NW14)-SUM(NZ14:OE14) -> 0
D15: REGIMEN ESPECIAL | OO15: =SUM(E15:ON15)-SUM(NT15:NW15)-SUM(NZ15:OE15) -> 0
D16: TOTAL REGIMEN | E16: =SUM(E12:E15) -> 0 | F16: =SUM(F12:F15) -> 0 | G16: =SUM(G12:G15) -> 0 | H16: =SUM(H12:H15) -> 0 | I16: =SUM(I12:I15) -> 0 | J16: =SUM(J12:J15) -> 0 | K16: =SUM(K12:K15) -> 0 | L16: =SUM(L12:L15) -> 0 | ... OO16: =SUM(OO12:OO15) -> 0
A17: 2 | B17: ='[1]6_VENEZOLANOS'!B17:B25 -> 045 | C17: FEBRERO | D17: FEMENINO | OO17: =SUM(E17:ON17)-SUM(NT17:NW17)-SUM(NZ17:OE17) -> 0
D18: MASCULINO | OO18: =SUM(E18:ON18)-SUM(NT18:NW18)-SUM(NZ18:OE18) -> 0
D19: OTRO | OO19: =SUM(E19:ON19)-SUM(NT19:NW19)-SUM(NZ19:OE19) -> 0
D20: TOTAL GENERO | E20: =SUM(E17:E19) -> 0 | F20: =SUM(F17:F19) -> 0 | G20: =SUM(G17:G19) -> 0 | H20: =SUM(H17:H19) -> 0 | I20: =SUM(I17:I19) -> 0 | J20: =SUM(J17:J19) -> 0 | K20: =SUM(K17:K19) -> 0 | L20: =SUM(L17:L19) -> 0 | ... OO20: =SUM(OO17:OO19) -> 0
D21: CONTRIBUTIVO | OO21: =SUM(E21:ON21)-SUM(NT21:NW21)-SUM(NZ21:OE21) -> 0
D22: SUBSIDIADO | OO22: =SUM(E22:ON22)-SUM(NT22:NW22)-SUM(NZ22:OE22) -> 0
D23: POBRE NO ASEGURADO | OO23: =SUM(E23:ON23)-SUM(NT23:NW23)-SUM(NZ23:OE23) -> 0
D24: REGIMEN ESPECIAL | OO24: =SUM(E24:ON24)-SUM(NT24:NW24)-SUM(NZ24:OE24) -> 0
D25: TOTAL REGIMEN | E25: =SUM(E21:E24) -> 0 | F25: =SUM(F21:F24) -> 0 | G25: =SUM(G21:G24) -> 0 | H25: =SUM(H21:H24) -> 0 | I25: =SUM(I21:I24) -> 0 | J25: =SUM(J21:J24) -> 0 | K25: =SUM(K21:K24) -> 0 | L25: =SUM(L21:L24) -> 0 | ... OO25: =SUM(OO21:OO24) -> 0
A26: 3 | B26: ='[1]6_VENEZOLANOS'!B26:B34 -> 075 | C26: MARZO | D26: FEMENINO | OO26: =SUM(E26:ON26)-SUM(NT26:NW26)-SUM(NZ26:OE26) -> 0
D27: MASCULINO | OO27: =SUM(E27:ON27)-SUM(NT27:NW27)-SUM(NZ27:OE27) -> 0
D28: OTRO | OO28: =SUM(E28:ON28)-SUM(NT28:NW28)-SUM(NZ28:OE28) -> 0
D29: TOTAL GENERO | E29: =SUM(E26:E28) -> 0 | F29: =SUM(F26:F28) -> 0 | G29: =SUM(G26:G28) -> 0 | H29: =SUM(H26:H28) -> 0 | I29: =SUM(I26:I28) -> 0 | J29: =SUM(J26:J28) -> 0 | K29: =SUM(K26:K28) -> 0 | L29: =SUM(L26:L28) -> 0 | ... OO29: =SUM(OO26:OO28) -> 0
D30: CONTRIBUTIVO | OO30: =SUM(E30:ON30)-SUM(NT30:NW30)-SUM(NZ30:OE30) -> 0
D31: SUBSIDIADO | OO31: =SUM(E31:ON31)-SUM(NT31:NW31)-SUM(NZ31:OE31) -> 0
D32: POBRE NO ASEGURADO | OO32: =SUM(E32:ON32)-SUM(NT32:NW32)-SUM(NZ32:OE32) -> 0
D33: REGIMEN ESPECIAL | OO33: =SUM(E33:ON33)-SUM(NT33:NW33)-SUM(NZ33:OE33) -> 0
D34: TOTAL REGIMEN | E34: =SUM(E30:E33) -> 0 | F34: =SUM(F30:F33) -> 0 | G34: =SUM(G30:G33) -> 0 | H34: =SUM(H30:H33) -> 0 | I34: =SUM(I30:I33) -> 0 | J34: =SUM(J30:J33) -> 0 | K34: =SUM(K30:K33) -> 0 | L34: =SUM(L30:L33) -> 0 | ... OO34: =SUM(OO30:OO33) -> 0
A35: 4 | B35: ='[1]6_VENEZOLANOS'!B35:B43 -> 088 | C35: ABRIL | D35: FEMENINO | OO35: =SUM(E35:ON35)-SUM(NT35:NW35)-SUM(NZ35:OE35) -> 0
D36: MASCULINO | OO36: =SUM(E36:ON36)-SUM(NT36:NW36)-SUM(NZ36:OE36) -> 0
D37: OTRO | OO37: =SUM(E37:ON37)-SUM(NT37:NW37)-SUM(NZ37:OE37) -> 0
D38: TOTAL GENERO | E38: =SUM(E35:E37) -> 0 | F38: =SUM(F35:F37) -> 0 | G38: =SUM(G35:G37) -> 0 | H38: =SUM(H35:H37) -> 0 | I38: =SUM(I35:I37) -> 0 | J38: =SUM(J35:J37) -> 0 | K38: =SUM(K35:K37) -> 0 | L38: =SUM(L35:L37) -> 0 | ... OO38: =SUM(OO35:OO37) -> 0
D39: CONTRIBUTIVO | OO39: =SUM(E39:ON39)-SUM(NT39:NW39)-SUM(NZ39:OE39) -> 0
D40: SUBSIDIADO | OO40: =SUM(E40:ON40)-SUM(NT40:NW40)-SUM(NZ40:OE40) -> 0
...

Sheet 3_PANAMA
E1: =D1+1 -> 1 | F1: =E1+1 -> 2 | G1: =F1+1 -> 3 | H1: =G1+1 -> 4 | I1: =H1+1 -> 5 | J1: =I1+1 -> 6 | K1: =J1+1 -> 7 | L1: =K1+1 -> 8 | ... ON1: =OM1+1 -> 400
A2: NOMBRE DEPARTAMENTO: | D2: ='6_VENEZOLANOS'!D2 -> RISARALDA | E2: CODIGO DEPARTAMENTO: | G2: ='6_VENEZOLANOS'!G2 -> 66 | H2: =G2 -> 66
A3: AÑO: | D3: ='6_VENEZOLANOS'!D3 -> 2026 | HE3: DE 1 AÑO 2022 | HF3: DE 2 AÑOS 2021 | HG3: DE 3 AÑOS 2020 | HH3: DE 4 AÑOS 2019 | HI3: DE 5 AÑOS 2018 | HJ3: DE 6 AÑOS 2017 | HK3: DE 7 AÑOS 2016 | HL3: DE 8 AÑOS 2015 | HM3: DE 9 AÑOS 2014 | HN3: DE 10 AÑOS 2013 | HO3: DE 11 AÑOS 2012 | HP3: DE 12 AÑOS 2011 | HQ3: DE 13 AÑOS 2010 | HR3: DE 14 AÑOS 2009 | HS3: DE 15 AÑOS 2008 | HT3: DE 16 AÑOS 2007 | HU3: DE 17 AÑOS 2006 | OG3: .
A4: MES DE REPORTE | D4: ='6_VENEZOLANOS'!D4 -> agosto | F4: VACUNAS PAI | S4: VACUNAS PAI | BV4: VACUNAS PAI | CW4: VACUNAS PAI | EI4: VACUNAS PAI | FE4: VACUNAS PAI | JZ4: VACUNAS PAI | NH4: VACUNAS PAI | OF4: VACUNAS PAI
A5: MUNICIPIO | D5: REGIMEN / GRUPO ETNICO | E5: BCG | H5: HEPATITIS B | AE5: HEPATITIS B (RESOLUCION. 0459/2012 y Circular 031/2014) | BK5: POBLACION PRIORIZADA PARA HEPATITIS B | BO5: ANTIPOLIO INACTIVADA (VIP) | CU5: HEXAVALENTE (DPTa-HB-Hib-VIP) | CX5: PENTAVALENTE DPT - HB - Hib | DI5: DPT | DV5: TDaP Acelular Pediatrica | FA5: ROTAVIRUS | FC5: NEUMOCOCO CONJUGADA DECAVALENTE | FI5: NEUMOCOCO CONJUGADA TRECEVALENTE | FO5: SRP (TRIPLE VIRAL) | GI5: SR (DOBLE VIRAL) | HD5: FIEBRE AMARILLA DOSIS UNICA | IC5: HEPATITIS A (Cohorte de nacidos a partir de 1 de enero de 2012) | IP5: VARICELA (Cohorte de nacidos a partir de 1 de julio de 2014) | JH5: TOXOIDE TETANICO-DIFTERICO DE ADULTOS (Td) | LM5: Tdap ACELULAR (Se debe garantizar una dosis por cada embarazo y se aplica a partir de las semana 26 y zona rural a partir de la semana 20 y otros grupos de dificil acceso o captación) | LZ5: INFLUENZA | MR5: MENINGOCOCO USO EN BROTES (Serogrupo A, C, Y y W-135) | MX5: V P H | NH5: ANTIRRABICA HUMANA PRE/POST-EXPOSICION | NW5: INMUNOGLOBULINA ANTI HEPATITIS B | OB5: INMUNOGLOBULINAS /ANTITOXINAS TETÁNICAS | OD5: ANTI TOXINA DIFTERICA (Suero heterólogo) | OF5: COVID 19
E6: RECIEN NACIDO (DE 0 HASTA 29 DÍAS) | F6: MENOR DE UN AÑO (A PARTIR DE 30 DIAS HASTA 11 MESES 29 DIAS) | G6: POBLACION INDIGENA Y RURAL DISPERSA (DE 1 AÑO A 5 AÑOS, 11 MESES, 29 DIAS) | H6: RECIEN NACIDO (HASTA 29 DÍAS) | J6: DE 2 A 11 MESES 29 DÍAS | M6: DE 1 AÑO | P6: DE 2 AÑOS | S6: DE 3 AÑOS | V6: DE 4 AÑOS | Y6: DE 5 AÑOS | AB6: DE 6 a 17 AÑOS 11 MESES Y 29 DIAS (ICBF) | AE6: DE 1 AÑO | AI6: DE 2 AÑOS | AM6: DE 3 AÑOS | AQ6: DE 4 AÑOS | AU6: DE 5 AÑOS | AY6: 6 A 14 AÑOS | BC6: DE 15 AÑOS A 17 AÑOS | BG6: DE 18 AÑOS Y MAS | BO6: < DE 1 AÑO | BR6: DE 1 AÑO | BU6: DE 2 AÑOS | BX6: DE 3 AÑOS | CA6: DE 4 AÑOS | CD6: DE 5 AÑOS | CG6: AL AÑO DE LA 3ra DOSIS (De 18 a 23 meses) | CH6: DE 2 AÑOS | CI6: DE 3 AÑOS | CJ6: DE 4 AÑOS | CK6: DE 5 AÑOS | CL6: DE 5 AÑOS | CM6: DE 6 AÑOS | CP6: DE 7 A 17 AÑOS (AUTORIZADAS POR EL MINISTERIO) | CS6: DE 18 A 60 AÑOS (AUTORIZADAS POR EL MINISTERIO) | CU6: < DE 1 AÑO (Prematuros Extremos (MENOR DE 1500 GRAMOS según lineamientos) | CX6: < DE 1 AÑO | DA6: De 18 a 23 meses | DB6: DE 1 AÑO (12 a 23 meses) Sin antecedente de Penta | DE6: DE 2 AÑOS (24 a 35 meses) Sin antecedente de Penta | DF6: DE 3 AÑOS (36 a 47 meses) Sin antecedente de Penta | DG6: DE 4 AÑOS (48 a 70 meses) Sin antecedente de Penta | DH6: 5 AÑOS HASTA UN DIA ANTES DE CUMPLIR LOS 6 AÑOS | DI6: DE 2 AÑOS | DL6: DE 3 AÑOS | DO6: DE 4 AÑOS | DR6: DE 5 AÑOS | DV6: < DE 1 AÑO | DY6: DE 1 AÑO | EB6: DE 2 AÑOS | EE6: DE 3 AÑOS | EH6: DE 4 AÑOS | EK6: DE 5 AÑOS | EN6: De 18 a 23 meses | EO6: DE 2 AÑOS | EP6: DE 3 AÑOS | EQ6: DE 4 AÑOS | ER6: DE 5 AÑOS | ES6: 3 AÑOS | ET6: 4 AÑOS | EU6: 5 AÑOS | EV6: DE 6 AÑOS | FA6: DE 2 MESES A 3 MESES y 21 DIAS | FB6: DE 4 MESES A LOS 11 MESES y 29 DIAS | FC6: DE 2 A 11 MESES 29 DIAS | FE6: DE 12 MESES A 23 MESES | FH6: DE 24 MESES A 71 MESES 29 DIAS | FI6: DE 2 A 11 MESES 29 DIAS | FK6: DE 12 A 23 MESES | FL6: DE 12 A 23 MESES | FN6: DE 24 MESES A 71 MESES 29 DIAS | FO6: PRIMERA DOSIS (Se deben registrar las dosis aplicadas en población nacida del 1 de enero al 31 de diciembre de cada año) | FY6: SEGUNDA DOSIS | GI6: DOSIS CERO | GJ6: DOSIS UNICA | HD6: DE 1 AÑO 2024 | HE6: DE 2 AÑOS 2023 | HF6: DE 3 AÑOS 2022 | HG6: DE 4 AÑOS 2021 | HH6: DE 5 AÑOS 2020 | HI6: DE 6 AÑOS 2019 | HJ6: DE 7 AÑOS 2018 | HK6: DE 8 AÑOS 2017 | HL6: DE 9 AÑOS 2016 | HM6: DE 10 AÑOS 2015 | HN6: DE 11 AÑOS 2014 | HO6: DE 12 AÑOS 2013 | HP6: DE 13 AÑOS 2012 | HQ6: DE 14 AÑOS 2011 | HR6: DE 15 AÑOS 2010 | HS6: DE 16 AÑOS 2009 | HT6: DE 17 AÑOS 2008 | HU6: DE 18 AÑOS 2007 | HV6: DE 19 AÑOS 2006 | HW6: 20 A 30 AÑOS (2007-1994) | HX6: 31 A 40 AÑOS | HY6: 41 A 50 AÑOS | HZ6: 51 A 59 AÑOS | IA6: 60 A 69 AÑOS (previa autorizacion del Ministerio). | IB6: EN SITUACIÓN DE BROTE Y PAISES QUE EXIGEN ANTECEDENTE VACUNAL | IC6: DOSIS ÚNICA | IP6: PRIMERA DOSIS | JA6: REFUERZO (aplicadas a partir del 1 de julio de 2019) | JH6: NIÑOS Y NIÑAS DE 7 A 9 AÑOS | JM6: GESTANTES DE 9 AÑOS A 17 AÑOS | JR6: GESTANTES DE 18 AÑOS Y MAS | JW6: REFUERZOS GESTANTES 15 A 49 AÑOS | KA6: MUJERES EN EDAD FERTIL (MEF) DE 10 AÑOS A 17 AÑOS | KF6: MUJERES EN EDAD FERTIL (MEF) DE 18 A 49 AÑOS | KK6: REFUERZOS MEF DE 15 A 49 AÑOS | KO6: HOMBRES DE 10 A 17 AÑOS | KT6: HOMBRES DE 18 A 49 AÑOS | KY6: REFUERZOS HOMBRES DE 15 A 49 AÑOS | LC6: OTROS DE 50 A 59 AÑOS | LH6: OTROS DE 60 AÑOS Y MAS | LM6: GESTANTES DE 9 A 17 AÑOS de acuerdo al lineamiento | LS6: GESTANTES DE 18 AÑOS Y MAS, de acuerdo al lineamiento | LY6: UNICA DOSIS OTROS GRUPOS (Con Autorizacion del MSPS ) | LZ6: DE 6 MESES A 11 MESES | MB6: DE 12 MESES A 23 MESES | ME6: 24 A 35 MESES SEGÚN AUTORIZACION DEL MINISTERIO | MH6: DE 50 a 59 AÑOS (SEGÚN AUTORIZACION DEL MINISTERIO) | MI6: DE 60 Y MAS AÑOS | MJ6: GESTANTES A PARTIR DE LA SEMANA 14 | MK6: DE 3 A 8 AÑOS (Poblaciones autorizadas de acuerdo a los lineamientos emitidos por el MSPS ) | MN6: DE 9 A 17 AÑOS (Poblaciones con diagnóstico de riesgo, recibir de acuerdo a los lineamientos emitidos por el MSPS ) | MO6: DE 18 A 59 AÑOS (Poblaciones con diagnóstico de riesgo de acuerdo a los lineamientos emitidos por el MSPS) | MP6: PERSONAL DE LA SALUD | MQ6: Familiares y convivientes de menores de 18 años con Cancér (Ley 1388/2010) | MR6: DE 6 A 11 MESES | MU6: 12 A 23 MESES | MW6: MAYORES DE 2 AÑOS | MX6: 9 AÑOS | MY6: 10 AÑOS | MZ6: 11 AÑOS | NA6: 12 AÑOS | NB6: 13 AÑOS | NC6: 14 AÑOS | ND6: 15 AÑOS | NE6: 16 AÑOS | NF6: 17 AÑOS | NG6: 2as Dosis Inmunosuprimidos, según linemientos del 30 de septiembre/2023 | NH6: ESQUEMA PRE EXPOSICIÓN OPCION 1 (I.D.) (Se aplica previa autorización del Ministerio) | NJ6: ESQUEMA PRE EXPOSICIÓN OPCION 2 (I.M.) (Se aplica previa autorización del Ministerio) | NL6: ESQUEMA POST EXPOSICION Número de dosis aplicadas | NQ6: ESQUEMA RE-EXPOSICIÓN | NT6: TOTAL DE ESQUEMAS POST EXPOSICION (USUARIOS CON ESQUEMA DE VACUNACION COMPLETO) | NU6: INMUNOGLOBULINA ANTIRRÁBICA (Número de frascos utilizados) | NV6: No. De personas que recibieron inmunoglobulina antirrabica. | NW6: RECIEN NACIDO (Hijo de Madre Antigenos + para HB) | NZ6: RESOLUCION 0459/2012- Circular 031/2014) | OB6: INMUNOGLOBULINA ANTI TETANICA (Suero homólogo) | OF6: DE 6 MESES A 4 AÑOS | OI6: DE 5 AÑOS A 11 AÑOS | OJ6: DE 12 A 59 AÑOS | OK6: GESTANTES | OL6: MAYORES DE 60 AÑOS | OM6: TALENTO HUMANO EN SALUD | ON6: DE 12 AÑOS A 59 AÑOS PERSONAS CON COMORBILIDADES
A7: Nº | B7: COD DANE MPIO | C7: NOMBRE MUNICIPIO/ IPS | H7: RECIEN NACIDO (Primeras 12 Horas) | I7: RECIEN NACIDO Entre 12 horas y 29 dias | J7: 1a | K7: 2a | L7: 3a | M7: 1a | N7: 2a | O7: 3a | P7: 1a | Q7: 2a | R7: 3a | S7: 1a | T7: 2a | U7: 3a | V7: 1a | W7: 2a | X7: 3a | Y7: 1a | Z7: 2a | AA7: 3a | AB7: 1a | AC7: 2a | AD7: 3a | AE7: 1a | AF7: 2a | AG7: 3a | AH7: Ref. | AI7: 1a | AJ7: 2a | AK7: 3a | AL7: Ref. | AM7: 1a | AN7: 2a | AO7: 3a | AP7: Ref. | AQ7: 1a | AR7: 2a | AS7: 3a | AT7: Ref. | AU7: 1a | AV7: 2a | AW7: 3a | AX7: Ref. | AY7: 1a | AZ7: 2a | BA7: 3a | BB7: Ref. | BC7: 1a | BD7: 2a | BE7: 3a | BF7: Ref. | BG7: 1a | BH7: 2a | BI7: 3a | BJ7: Ref. | BK7: 1a | BL7: 2a | BM7: 3a | BN7: Ref- | BO7: 1a | BP7: 2a | BQ7: 3a | BR7: 1a | BS7: 2a | BT7: 3a | BU7: 1a | BV7: 2a | BW7: 3a | BX7: 1a | BY7: 2a | BZ7: 3a | CA7: 1a | CB7: 2a | CC7: 3a | CD7: 1a | CE7: 2a | CF7: 3a | CG7: Primer Refuerzo | CL7: Segundo Refuerzo | CM7: 1a | CN7: 2a | CO7: 3a | CP7: 1a | CQ7: 2a | CR7: 3a | CS7: 1a | CT7: 2a | CU7: 1a | CV7: 2a | CW7: 3a | CX7: 1a | CY7: 2a | CZ7: 3a | DA7: 1er REF de acuerdo a lineamiento | DB7: 1a | DC7: 2a | DD7: 3a | DE7: Unica | DF7: Unica | DG7: Unica | DH7: Unica | DI7: 2a | DJ7: 3a | DK7: REF. | DL7: 2a | DM7: 3a | DN7: REF. | DO7: 2a | DP7: 3a | DQ7: REF. | DR7: 2a | DS7: 3a | DT7: 1° REF. | DU7: 2° REF. | DV7: 1a | DW7: 2a | DX7: 3a | DY7: 1a | DZ7: 2a | EA7: 3a | EB7: 1a | EC7: 2a | ED7: 3a | EE7: 1a | EF7: 2a | EG7: 3a | EH7: 1a | EI7: 2a | EJ7: 3a | EK7: 1a | EL7: 2a | EM7: 3a | EN7: 1er REF. | ES7: 2° REF. | EV7: 1a | EW7: 2a | EX7: 3a | EY7: 1er REF. | EZ7: 2° REF. | FA7: 1a | FB7: 2a | FC7: 1a | FD7: 2a | FE7: REF. | FF7: 1a | FG7: 2a | FH7: ÚNICA | FI7: 1a | FJ7: 2a | FK7: REF. | FL7: 1a | FM7: 2a | FN7: ÚNICA | FO7: Nacidos 2024 1 año | FP7: Nacidos 2023 2 años | FQ7: Nacidos 2022 3 años | FR7: Nacidos 2021 4 años | FS7: Nacidos 2020 5 años | FT7: Nacidos 2019 6 años | FU7: Nacidos 2018 7 años | FV7: Nacidos 2017 8 años | FW7: Nacidos 2016 9 años | FX7: Nacidos 2015 10 años | FY7: De 18 a 23 meses | FZ7: Nacidos 2023 (Seguimiento) 2 años | GA7: Nacidos 2022 (Seguimiento) 3 años | GB7: Nacidos 2021 (Seguimiento) 4 años | GC7: Nacidos 2020 5 años | GD7: Nacidos 2019 6 años | GE7: Nacidos 2018 7 años | GF7: Nacidos 2017 8 años | GG7: Nacidos 2016 9 años | GH7: Nacidos 2015 10 años | GI7: SR * 6 a 11 MESES 29 DIAS | GJ7: DE 1 AÑO 2024 | GK7: DE 2 AÑOS 2023 | GL7: DE 3 AÑOS 2022 | GM7: DE 4 AÑOS 2021 | GN7: DE 5 AÑOS 2020 | GO7: DE 6 AÑOS 2019 | GP7: DE 7 AÑOS 2018 | GQ7: DE 8 AÑOS 2017 | GR7: DE 9 AÑOS 2016 | GS7: DE 10 AÑOS 2015 | GT7: DE 11 AÑOS 2014 | GU7: DE 12 AÑOS 2013 | GV7: DE 13 AÑOS 2012 | GW7: DE 14 AÑOS 2011 | GX7: DE 15 AÑOS 2010 | GY7: DE 16 AÑOS 2009 | GZ7: DE 17 AÑOS 2008 | HA7: 18 A 30 AÑOS | HB7: 31 A 40 AÑOS | HC7: 41 Y MAS AÑOS | IB7: 9 meses a 11 meses (Con Autorizacion del MSPS de acuerdo a Lineamientos) | IC7: DE 1 AÑO 2024 | ID7: DE 2 AÑOS 2023 | IE7: DE 3 AÑOS 2022 | IF7: DE 4 AÑOS 2021 | IG7: DE 5 AÑOS 2020 | IH7: DE 6 AÑOS 2019 | II7: DE 7 AÑOS 2018 | IJ7: DE 8 AÑOS 2017 | IK7: DE 9 AÑOS 2016 | IL7: DE 10 AÑOS 2015 | IM7: DE 11 AÑOS 2014 | IN7: DE 12 AÑOS 2013 | IO7: DE 13 AÑOS 2012 | IP7: DE 1 AÑO 2024 | IQ7: DE 2 AÑOS 2023 | IR7: DE 3 AÑOS 2022 | IS7: DE 4 AÑOS 2021 | IT7: DE 5 AÑOS 2020 | IU7: DE 6 AÑOS 2019 | IV7: DE 7 AÑOS 2018 | IW7: DE 8 AÑOS 2017 | IX7: DE 9 AÑOS 2016 | IY7: DE 10 AÑOS 2015 | IZ7: DE 11 AÑOS 2014 | JA7: DE 5 AÑOS 2024 | JB7: DE 6 AÑOS 2023 | JC7: DE 7 AÑOS 2022 | JD7: DE 8 AÑOS 2021 | JE7: DE 9 AÑOS 2020 | JF7: DE 10 AÑOS 2019 | JG7: DE 11 AÑOS 2018 | JH7: Td1 | JI7: Td2 | JJ7: Td3 | JK7: Ref 1 | JL7: Ref 2 | JM7: Td1 | JN7: Td2 | JO7: Td3 | JP7: Td4 | JQ7: Td5 | JR7: Td1 | JS7: Td2 | JT7: Td3 | JU7: Td4 | JV7: Td5 | JW7: REF. 1 | JX7: REF. 2 | JY7: REF. 3 | JZ7: REF. 4 | KA7: Td1 | KB7: Td2 | KC7: Td3 | KD7: Td4 | KE7: Td5 | KF7: Td1 | KG7: Td2 | KH7: Td3 | KI7: Td4 | KJ7: Td5 | KK7: REF. 1 | KL7: REF. 2 | KM7: REF. 3 | KN7: REF. 4 | KO7: Td1 | KP7: Td2 | KQ7: Td3 | KR7: Td4 | KS7: Td5 | KT7: Td1 | KU7: Td2 | KV7: Td3 | KW7: Td4 | KX7: Td5 | KY7: REF. 1 | KZ7: REF. 2 | LA7: REF. 3 | LB7: REF. 4 | LC7: Td1 | LD7: Td2 | LE7: Td3 | LF7: Td4 | LG7: Td5 | LH7: Td1 | LI7: Td2 | LJ7: Td3 | LK7: Td4 | LL7: Td5 | LM7: UNICA DOSIS EN CADA EMBARAZO | LN7: Td1 | LO7: Td2 | LP7: Td3 | LQ7: Td4 | LR7: Td5 | LS7: UNICA DOSIS EN CADA EMBARAZO | LT7: Td1 | LU7: Td2 | LV7: Td3 | LW7: Td4 | LX7: Td5 | LZ7: 1a | MA7: 2a | MB7: 1a | MC7: 2a | MD7: ÚNICA | ME7: 1a | MF7: 2a | MG7: ÚNICA | MH7: ÚNICA | MI7: ÚNICA | MJ7: ÚNICA | MK7: 1a | ML7: 2a | MM7: ÚNICA | MN7: ÚNICA | MO7: ÚNICA | MP7: ÚNICA | MQ7: ÚNICA | MR7: 1a | MS7: 2a | MT7: 3a | MU7: 1a | MV7: 2a | MW7: ÚNICA | MX7: Dosis Ùnica | NH7: 1a. y 2a día 0 | NI7: 3a y 4a. día 7 | NJ7: 1a . día 0 | NK7: 2a. día 7 | NL7: 1a. día 0 | NM7: 2a. dia 3 | NN7: 3a. día 7 | NO7: 4a . día 14 | NP7: 5a . día 21 a 28 | NQ7: 1a . día 0 | NR7: 2a. día 3 | NS7: 3a. día 7 a 14 | NT7: Número de usuarios | NW7: Número de frascos utilizados | NX7: N° recién nacidos que recibieron dosis de Ig en las primeras 12 horas | NY7: N° recién nacidos que recibieron dosis de Ig despues de las primeras 12 horas | NZ7: Número de frascos utilizados | OA7: N° Personas que recibieron dosis de Ig | OB7: Número de frascos utilizados | OC7: N° Personas que recibieron dosis de Ig | OD7: Número de frascos utilizados | OE7: N° Personas que recibieron dosis de antitoxina | OF7: Primera dosis | OG7: Segunda dosis | OH7: Adicional | OI7: Adicional | OJ7: Adicional | OK7: Adicional | OL7: Adicional | OM7: Adicional | ON7: Adicional | OO7: TOTAL DOSIS
A8: 1 | B8: ='[1]6_VENEZOLANOS'!B8:B16 -> 001 | C8: ENERO | D8: FEMENINO | OO8: =SUM(E8:ON8)-SUM(NT8:NW8)-SUM(NZ8:OE8) -> 0
D9: MASCULINO | OO9: =SUM(E9:ON9)-SUM(NT9:NW9)-SUM(NZ9:OE9) -> 0
D10: OTRO | OO10: =SUM(E10:ON10)-SUM(NT10:NW10)-SUM(NZ10:OE10) -> 0
D11: TOTAL GENERO | E11: =SUM(E8:E10) -> 0 | F11: =SUM(F8:F10) -> 0 | G11: =SUM(G8:G10) -> 0 | H11: =SUM(H8:H10) -> 0 | I11: =SUM(I8:I10) -> 0 | J11: =SUM(J8:J10) -> 0 | K11: =SUM(K8:K10) -> 0 | L11: =SUM(L8:L10) -> 0 | ... OO11: =SUM(OO8:OO10) -> 0
D12: CONTRIBUTIVO | OO12: =SUM(E12:ON12)-SUM(NT12:NW12)-SUM(NZ12:OE12) -> 0
D13: SUBSIDIADO | OO13: =SUM(E13:ON13)-SUM(NT13:NW13)-SUM(NZ13:OE13) -> 0
D14: POBRE NO ASEGURADO | OO14: =SUM(E14:ON14)-SUM(NT14:NW14)-SUM(NZ14:OE14) -> 0
D15: REGIMEN ESPECIAL | OO15: =SUM(E15:ON15)-SUM(NT15:NW15)-SUM(NZ15:OE15) -> 0
D16: TOTAL REGIMEN | E16: =SUM(E12:E15) -> 0 | F16: =SUM(F12:F15) -> 0 | G16: =SUM(G12:G15) -> 0 | H16: =SUM(H12:H15) -> 0 | I16: =SUM(I12:I15) -> 0 | J16: =SUM(J12:J15) -> 0 | K16: =SUM(K12:K15) -> 0 | L16: =SUM(L12:L15) -> 0 | ... OO16: =SUM(OO12:OO15) -> 0
A17: 2 | B17: ='[1]6_VENEZOLANOS'!B17:B25 -> 045 | C17: FEBRERO | D17: FEMENINO | OO17: =SUM(E17:ON17)-SUM(NT17:NW17)-SUM(NZ17:OE17) -> 0
D18: MASCULINO | OO18: =SUM(E18:ON18)-SUM(NT18:NW18)-SUM(NZ18:OE18) -> 0
D19: OTRO | OO19: =SUM(E19:ON19)-SUM(NT19:NW19)-SUM(NZ19:OE19) -> 0
D20: TOTAL GENERO | E20: =SUM(E17:E19) -> 0 | F20: =SUM(F17:F19) -> 0 | G20: =SUM(G17:G19) -> 0 | H20: =SUM(H17:H19) -> 0 | I20: =SUM(I17:I19) -> 0 | J20: =SUM(J17:J19) -> 0 | K20: =SUM(K17:K19) -> 0 | L20: =SUM(L17:L19) -> 0 | ... OO20: =SUM(OO17:OO19) -> 0
D21: CONTRIBUTIVO | OO21: =SUM(E21:ON21)-SUM(NT21:NW21)-SUM(NZ21:OE21) -> 0
D22: SUBSIDIADO | OO22: =SUM(E22:ON22)-SUM(NT22:NW22)-SUM(NZ22:OE22) -> 0
D23: POBRE NO ASEGURADO | OO23: =SUM(E23:ON23)-SUM(NT23:NW23)-SUM(NZ23:OE23) -> 0
D24: REGIMEN ESPECIAL | OO24: =SUM(E24:ON24)-SUM(NT24:NW24)-SUM(NZ24:OE24) -> 0
D25: TOTAL REGIMEN | E25: =SUM(E21:E24) -> 0 | F25: =SUM(F21:F24) -> 0 | G25: =SUM(G21:G24) -> 0 | H25: =SUM(H21:H24) -> 0 | I25: =SUM(I21:I24) -> 0 | J25: =SUM(J21:J24) -> 0 | K25: =SUM(K21:K24) -> 0 | L25: =SUM(L21:L24) -> 0 | ... OO25: =SUM(OO21:OO24) -> 0
A26: 3 | B26: ='[1]6_VENEZOLANOS'!B26:B34 -> 075 | C26: MARZO | D26: FEMENINO | OO26: =SUM(E26:ON26)-SUM(NT26:NW26)-SUM(NZ26:OE26) -> 0
D27: MASCULINO | OO27: =SUM(E27:ON27)-SUM(NT27:NW27)-SUM(NZ27:OE27) -> 0
D28: OTRO | OO28: =SUM(E28:ON28)-SUM(NT28:NW28)-SUM(NZ28:OE28) -> 0
D29: TOTAL GENERO | E29: =SUM(E26:E28) -> 0 | F29: =SUM(F26:F28) -> 0 | G29: =SUM(G26:G28) -> 0 | H29: =SUM(H26:H28) -> 0 | I29: =SUM(I26:I28) -> 0 | J29: =SUM(J26:J28) -> 0 | K29: =SUM(K26:K28) -> 0 | L29: =SUM(L26:L28) -> 0 | ... OO29: =SUM(OO26:OO28) -> 0
D30: CONTRIBUTIVO | OO30: =SUM(E30:ON30)-SUM(NT30:NW30)-SUM(NZ30:OE30) -> 0
D31: SUBSIDIADO | OO31: =SUM(E31:ON31)-SUM(NT31:NW31)-SUM(NZ31:OE31) -> 0
D32: POBRE NO ASEGURADO | OO32: =SUM(E32:ON32)-SUM(NT32:NW32)-SUM(NZ32:OE32) -> 0
D33: REGIMEN ESPECIAL | OO33: =SUM(E33:ON33)-SUM(NT33:NW33)-SUM(NZ33:OE33) -> 0
D34: TOTAL REGIMEN | E34: =SUM(E30:E33) -> 0 | F34: =SUM(F30:F33) -> 0 | G34: =SUM(G30:G33) -> 0 | H34: =SUM(H30:H33) -> 0 | I34: =SUM(I30:I33) -> 0 | J34: =SUM(J30:J33) -> 0 | K34: =SUM(K30:K33) -> 0 | L34: =SUM(L30:L33) -> 0 | ... OO34: =SUM(OO30:OO33) -> 0
A35: 4 | B35: ='[1]6_VENEZOLANOS'!B35:B43 -> 088 | C35: ABRIL | D35: FEMENINO | OO35: =SUM(E35:ON35)-SUM(NT35:NW35)-SUM(NZ35:OE35) -> 0
D36: MASCULINO | OO36: =SUM(E36:ON36)-SUM(NT36:NW36)-SUM(NZ36:OE36) -> 0
D37: OTRO | OO37: =SUM(E37:ON37)-SUM(NT37:NW37)-SUM(NZ37:OE37) -> 0
D38: TOTAL GENERO | E38: =SUM(E35:E37) -> 0 | F38: =SUM(F35:F37) -> 0 | G38: =SUM(G35:G37) -> 0 | H38: =SUM(H35:H37) -> 0 | I38: =SUM(I35:I37) -> 0 | J38: =SUM(J35:J37) -> 0 | K38: =SUM(K35:K37) -> 0 | L38: =SUM(L35:L37) -> 0 | ... OO38: =SUM(OO35:OO37) -> 0
D39: CONTRIBUTIVO | OO39: =SUM(E39:ON39)-SUM(NT39:NW39)-SUM(NZ39:OE39) -> 0
D40: SUBSIDIADO | OO40: =SUM(E40:ON40)-SUM(NT40:NW40)-SUM(NZ40:OE40) -> 0
...

Sheet 4_PERU
E1: =D1+1 -> 1 | F1: =E1+1 -> 2 | G1: =F1+1 -> 3 | H1: =G1+1 -> 4 | I1: =H1+1 -> 5 | J1: =I1+1 -> 6 | K1: =J1+1 -> 7 | L1: =K1+1 -> 8 | ... ON1: =OM1+1 -> 400
A2: NOMBRE DEPARTAMENTO: | D2: ='6_VENEZOLANOS'!D2 -> RISARALDA | E2: CODIGO DEPARTAMENTO: | G2: ='6_VENEZOLANOS'!G2 -> 66 | H2: =G2 -> 66
A3: AÑO: | D3: ='6_VENEZOLANOS'!D3 -> 2026 | HE3: DE 1 AÑO 2022 | HF3: DE 2 AÑOS 2021 | HG3: DE 3 AÑOS 2020 | HH3: DE 4 AÑOS 2019 | HI3: DE 5 AÑOS 2018 | HJ3: DE 6 AÑOS 2017 | HK3: DE 7 AÑOS 2016 | HL3: DE 8 AÑOS 2015 | HM3: DE 9 AÑOS 2014 | HN3: DE 10 AÑOS 2013 | HO3: DE 11 AÑOS 2012 | HP3: DE 12 AÑOS 2011 | HQ3: DE 13 AÑOS 2010 | HR3: DE 14 AÑOS 2009 | HS3: DE 15 AÑOS 2008 | HT3: DE 16 AÑOS 2007 | HU3: DE 17 AÑOS 2006 | OG3: .
A4: MES DE REPORTE | D4: ='6_VENEZOLANOS'!D4 -> agosto | F4: VACUNAS PAI | S4: VACUNAS PAI | BV4: VACUNAS PAI | CW4: VACUNAS PAI | EI4: VACUNAS PAI | FE4: VACUNAS PAI | JZ4: VACUNAS PAI | NH4: VACUNAS PAI | OF4: VACUNAS PAI
A5: MUNICIPIO | D5: REGIMEN / GRUPO ETNICO | E5: BCG | H5: HEPATITIS B | AE5: HEPATITIS B (RESOLUCION. 0459/2012 y Circular 031/2014) | BK5: POBLACION PRIORIZADA PARA HEPATITIS B | BO5: ANTIPOLIO INACTIVADA (VIP) | CU5: HEXAVALENTE (DPTa-HB-Hib-VIP) | CX5: PENTAVALENTE DPT - HB - Hib | DI5: DPT | DV5: TDaP Acelular Pediatrica | FA5: ROTAVIRUS | FC5: NEUMOCOCO CONJUGADA DECAVALENTE | FI5: NEUMOCOCO CONJUGADA TRECEVALENTE | FO5: SRP (TRIPLE VIRAL) | GI5: SR (DOBLE VIRAL) | HD5: FIEBRE AMARILLA DOSIS UNICA | IC5: HEPATITIS A (Cohorte de nacidos a partir de 1 de enero de 2012) | IP5: VARICELA (Cohorte de nacidos a partir de 1 de julio de 2014) | JH5: TOXOIDE TETANICO-DIFTERICO DE ADULTOS (Td) | LM5: Tdap ACELULAR (Se debe garantizar una dosis por cada embarazo y se aplica a partir de las semana 26 y zona rural a partir de la semana 20 y otros grupos de dificil acceso o captación) | LZ5: INFLUENZA | MR5: MENINGOCOCO USO EN BROTES (Serogrupo A, C, Y y W-135) | MX5: V P H | NH5: ANTIRRABICA HUMANA PRE/POST-EXPOSICION | NW5: INMUNOGLOBULINA ANTI HEPATITIS B | OB5: INMUNOGLOBULINAS /ANTITOXINAS TETÁNICAS | OD5: ANTI TOXINA DIFTERICA (Suero heterólogo) | OF5: COVID 19
E6: RECIEN NACIDO (DE 0 HASTA 29 DÍAS) | F6: MENOR DE UN AÑO (A PARTIR DE 30 DIAS HASTA 11 MESES 29 DIAS) | G6: POBLACION INDIGENA Y RURAL DISPERSA (DE 1 AÑO A 5 AÑOS, 11 MESES, 29 DIAS) | H6: RECIEN NACIDO (HASTA 29 DÍAS) | J6: DE 2 A 11 MESES 29 DÍAS | M6: DE 1 AÑO | P6: DE 2 AÑOS | S6: DE 3 AÑOS | V6: DE 4 AÑOS | Y6: DE 5 AÑOS | AB6: DE 6 a 17 AÑOS 11 MESES Y 29 DIAS (ICBF) | AE6: DE 1 AÑO | AI6: DE 2 AÑOS | AM6: DE 3 AÑOS | AQ6: DE 4 AÑOS | AU6: DE 5 AÑOS | AY6: 6 A 14 AÑOS | BC6: DE 15 AÑOS A 17 AÑOS | BG6: DE 18 AÑOS Y MAS | BO6: < DE 1 AÑO | BR6: DE 1 AÑO | BU6: DE 2 AÑOS | BX6: DE 3 AÑOS | CA6: DE 4 AÑOS | CD6: DE 5 AÑOS | CG6: AL AÑO DE LA 3ra DOSIS (De 18 a 23 meses) | CH6: DE 2 AÑOS | CI6: DE 3 AÑOS | CJ6: DE 4 AÑOS | CK6: DE 5 AÑOS | CL6: DE 5 AÑOS | CM6: DE 6 AÑOS | CP6: DE 7 A 17 AÑOS (AUTORIZADAS POR EL MINISTERIO) | CS6: DE 18 A 60 AÑOS (AUTORIZADAS POR EL MINISTERIO) | CU6: < DE 1 AÑO (Prematuros Extremos (MENOR DE 1500 GRAMOS según lineamientos) | CX6: < DE 1 AÑO | DA6: De 18 a 23 meses | DB6: DE 1 AÑO (12 a 23 meses) Sin antecedente de Penta | DE6: DE 2 AÑOS (24 a 35 meses) Sin antecedente de Penta | DF6: DE 3 AÑOS (36 a 47 meses) Sin antecedente de Penta | DG6: DE 4 AÑOS (48 a 70 meses) Sin antecedente de Penta | DH6: 5 AÑOS HASTA UN DIA ANTES DE CUMPLIR LOS 6 AÑOS | DI6: DE 2 AÑOS | DL6: DE 3 AÑOS | DO6: DE 4 AÑOS | DR6: DE 5 AÑOS | DV6: < DE 1 AÑO | DY6: DE 1 AÑO | EB6: DE 2 AÑOS | EE6: DE 3 AÑOS | EH6: DE 4 AÑOS | EK6: DE 5 AÑOS | EN6: De 18 a 23 meses | EO6: DE 2 AÑOS | EP6: DE 3 AÑOS | EQ6: DE 4 AÑOS | ER6: DE 5 AÑOS | ES6: 3 AÑOS | ET6: 4 AÑOS | EU6: 5 AÑOS | EV6: DE 6 AÑOS | FA6: DE 2 MESES A 3 MESES y 21 DIAS | FB6: DE 4 MESES A LOS 11 MESES y 29 DIAS | FC6: DE 2 A 11 MESES 29 DIAS | FE6: DE 12 MESES A 23 MESES | FH6: DE 24 MESES A 71 MESES 29 DIAS | FI6: DE 2 A 11 MESES 29 DIAS | FK6: DE 12 A 23 MESES | FL6: DE 12 A 23 MESES | FN6: DE 24 MESES A 71 MESES 29 DIAS | FO6: PRIMERA DOSIS (Se deben registrar las dosis aplicadas en población nacida del 1 de enero al 31 de diciembre de cada año) | FY6: SEGUNDA DOSIS | GI6: DOSIS CERO | GJ6: DOSIS UNICA | HD6: DE 1 AÑO 2024 | HE6: DE 2 AÑOS 2023 | HF6: DE 3 AÑOS 2022 | HG6: DE 4 AÑOS 2021 | HH6: DE 5 AÑOS 2020 | HI6: DE 6 AÑOS 2019 | HJ6: DE 7 AÑOS 2018 | HK6: DE 8 AÑOS 2017 | HL6: DE 9 AÑOS 2016 | HM6: DE 10 AÑOS 2015 | HN6: DE 11 AÑOS 2014 | HO6: DE 12 AÑOS 2013 | HP6: DE 13 AÑOS 2012 | HQ6: DE 14 AÑOS 2011 | HR6: DE 15 AÑOS 2010 | HS6: DE 16 AÑOS 2009 | HT6: DE 17 AÑOS 2008 | HU6: DE 18 AÑOS 2007 | HV6: DE 19 AÑOS 2006 | HW6: 20 A 30 AÑOS (2007-1994) | HX6: 31 A 40 AÑOS | HY6: 41 A 50 AÑOS | HZ6: 51 A 59 AÑOS | IA6: 60 A 69 AÑOS (previa autorizacion del Ministerio). | IB6: EN SITUACIÓN DE BROTE Y PAISES QUE EXIGEN ANTECEDENTE VACUNAL | IC6: DOSIS ÚNICA | IP6: PRIMERA DOSIS | JA6: REFUERZO (aplicadas a partir del 1 de julio de 2019) | JH6: NIÑOS Y NIÑAS DE 7 A 9 AÑOS | JM6: GESTANTES DE 9 AÑOS A 17 AÑOS | JR6: GESTANTES DE 18 AÑOS Y MAS | JW6: REFUERZOS GESTANTES 15 A 49 AÑOS | KA6: MUJERES EN EDAD FERTIL (MEF) DE 10 AÑOS A 17 AÑOS | KF6: MUJERES EN EDAD FERTIL (MEF) DE 18 A 49 AÑOS | KK6: REFUERZOS MEF DE 15 A 49 AÑOS | KO6: HOMBRES DE 10 A 17 AÑOS | KT6: HOMBRES DE 18 A 49 AÑOS | KY6: REFUERZOS HOMBRES DE 15 A 49 AÑOS | LC6: OTROS DE 50 A 59 AÑOS | LH6: OTROS DE 60 AÑOS Y MAS | LM6: GESTANTES DE 9 A 17 AÑOS de acuerdo al lineamiento | LS6: GESTANTES DE 18 AÑOS Y MAS, de acuerdo al lineamiento | LY6: UNICA DOSIS OTROS GRUPOS (Con Autorizacion del MSPS ) | LZ6: DE 6 MESES A 11 MESES | MB6: DE 12 MESES A 23 MESES | ME6: 24 A 35 MESES SEGÚN AUTORIZACION DEL MINISTERIO | MH6: DE 50 a 59 AÑOS (SEGÚN AUTORIZACION DEL MINISTERIO) | MI6: DE 60 Y MAS AÑOS | MJ6: GESTANTES A PARTIR DE LA SEMANA 14 | MK6: DE 3 A 8 AÑOS (Poblaciones autorizadas de acuerdo a los lineamientos emitidos por el MSPS ) | MN6: DE 9 A 17 AÑOS (Poblaciones con diagnóstico de riesgo, recibir de acuerdo a los lineamientos emitidos por el MSPS ) | MO6: DE 18 A 59 AÑOS (Poblaciones con diagnóstico de riesgo de acuerdo a los lineamientos emitidos por el MSPS) | MP6: PERSONAL DE LA SALUD | MQ6: Familiares y convivientes de menores de 18 años con Cancér (Ley 1388/2010) | MR6: DE 6 A 11 MESES | MU6: 12 A 23 MESES | MW6: MAYORES DE 2 AÑOS | MX6: 9 AÑOS | MY6: 10 AÑOS | MZ6: 11 AÑOS | NA6: 12 AÑOS | NB6: 13 AÑOS | NC6: 14 AÑOS | ND6: 15 AÑOS | NE6: 16 AÑOS | NF6: 17 AÑOS | NG6: 2as Dosis Inmunosuprimidos, según linemientos del 30 de septiembre/2023 | NH6: ESQUEMA PRE EXPOSICIÓN OPCION 1 (I.D.) (Se aplica previa autorización del Ministerio) | NJ6: ESQUEMA PRE EXPOSICIÓN OPCION 2 (I.M.) (Se aplica previa autorización del Ministerio) | NL6: ESQUEMA POST EXPOSICION Número de dosis aplicadas | NQ6: ESQUEMA RE-EXPOSICIÓN | NT6: TOTAL DE ESQUEMAS POST EXPOSICION (USUARIOS CON ESQUEMA DE VACUNACION COMPLETO) | NU6: INMUNOGLOBULINA ANTIRRÁBICA (Número de frascos utilizados) | NV6: No. De personas que recibieron inmunoglobulina antirrabica. | NW6: RECIEN NACIDO (Hijo de Madre Antigenos + para HB) | NZ6: RESOLUCION 0459/2012- Circular 031/2014) | OB6: INMUNOGLOBULINA ANTI TETANICA (Suero homólogo) | OF6: DE 6 MESES A 4 AÑOS | OI6: DE 5 AÑOS A 11 AÑOS | OJ6: DE 12 A 59 AÑOS | OK6: GESTANTES | OL6: MAYORES DE 60 AÑOS | OM6: TALENTO HUMANO EN SALUD | ON6: DE 12 AÑOS A 59 AÑOS PERSONAS CON COMORBILIDADES
