Workbook

Sheet CLASF. PERDIDAS
A2: CLASIFICACIÓN DE MOTIVOS DE PERDIDAS
A3: MOVIMIENTO DE BIOLÓGICOS (MB) VS PAIWEB
B5: MOTIVO DE PERDIDA MOVIMIENTO DE BIOLÓGICO | C5: MOTIVO DE PERDIDA PAIWEB
A6: 1 | B6: POR FRASCO ABIERTO INSTITUCIONAL | C6: PAI - Política de frascos abiertos intramural (Verificar lo contenido en la Circular 26 del 01 de agosto de 2017).
B7: POR FRASCO ABIERTO EXTRAMURAL | C7: PAI - Política de frasco abierto extramural (Verificar lo contenido en la Circular 26 del 01 de agosto de 2017).
A8: 2 | B8: INTERRUPCIÓN DE CADENA DE FRÍO | C8: PAI - Pérdida de cadena de frío.
C9: PAI - Por excursión temperatura.
C10: PEDIDOS - Interrupción de cadena de frío en el transporte o en el lugar de la recepción.
A11: 3 | B11: CONTAMINACION DEL BIOLÓGICO/DISPOSITIVO MÉDICO | C11: PAI - Contaminación del biológico o dispositivo en la cadena de distribución que no incluya la manipulación (ejemplo: accidente en el transporte que representa que la vacuna se salga de su contenedor sin ruptura, pero si exposición con agentes contaminantes).
A12: 4 | B12: VIAL ROTO | C12: PAI - Frasco vial roto (aplica para viales, jeringas prellenadas y diluyentes)
C13: PEDIDOS - Frasco de biológico roto en recepción (aplica para viales, jeringas prellenadas y diluyentes)
A14: 5 | B14: ERRORES EN LA MANIPULACIÓN | C14: PAI - Derrame de biológico o diluyente en la prepara
C15: PAI - Derrame del biológico o diluyente en la aplición
C16: PAI - Contaminación dispositivo médico x manipulación
C17: PAI - Anulación por error al diligenciamiento
C18: PAI - Error en la dosificación sobre o subdosificación
C19: PAI - Reconstitución de vacuna
C20: PAI - Error en la reconstitución - jeringa
A21: 6 | B21: VENCIMIENTO DEL BIOLÓGICO O JERINGA | C21: PAI - Vencimiento de biológico
C22: PAI - Vencimiento de diluyente
C23: PAI - Vencimiento de jeringa
C24: PAI - Excede días de almacenamiento permitidos por reconstitución del biológico según el laboratorio fabricante.
A25: 7 | B25: FARMACOVIGILANCIA/ TECNOVIGILANCIA | C25: PAI - Defectos de fabricación dispositivos médicos (ejemplo: desprendimiento de agujas, mal sellamiento del embolo, etc.)
C26: PAI - Defectos de fabricación en biológicos
C27: PAI - Por reacción alérgica a biológicos
C28: PAI - Rendimiento menor a la presentación
A29: 8 | B29: VOMITO FRANCO | C29: PAI - Vómito franco por a administración de vacunas por vía oral
A30: 9 | B30: APLICACIÓN FUERA DE LA EDAD | C30: PAI - Aplicación fuera de edad
C31: PAI - Revacunación
A32: 10 | B32: POR DECISIÓN FINAL DEL PACIENTE DE NO VACUNACIÓN | C32: PAI - Reconstitución o alistamiento de la vacuna posterior al diligenciamiento del consentimiento informado con decisión final de no vacunación por parte del paciente o adulto responsable.
C33: PAI - Jeringa o insumo utilizado en la reconstitución o alistamiento de la vacuna en el contexto de este punto.
A34: 11 | B34: SINIESTRO O ROBO | C34: PAI - Robo de biológico
C35: PAI - Robo de jeringa
C36: PAI - Siniestro
A39: MOTIVOS DE PÉRDIDAS DE VACUNAS CONTRA LA COVID-19 RESOLUCIÓN 0986 DEL 21 DE JUNIO DE 2023 DISPONIBLE EN EL SIGUIENTE LINK: chrome-extension://efaidnbmnnnibpcajpcglclefindmkaj/https://www.minsalud.gov.co/Normatividad_Nuevo/Resoluci%C3%B3n%20No.%20986%20de%202023.pdf
A40: MOVIMIENTO DE BIOLÓGICOS (MB) VS PAIWEB
A42: ÍTEM | B42: MOTIVO DE PERDIDA MOVIMIENTO DE BIOLÓGICO | C42: MOTIVO DE PERDIDA PAIWEB
A43: =+[1]Hoja1!$C$3 -> 1 | B43: POLÍTICA DE FRASCOS ABIERTO | C43: Dosis pérdidas de acuerdo con las indicaciones del laboratorio productor en la estrategia intramural o extramural.
A44: =+[1]Hoja1!$C4 -> 2 | B44: INTERRUPCIÓN DE LA CADENA DE FRÍO | C44: Vacuna COVID-19 con concepto técnico de NO USO por parte del INVIMA.
A45: =+[1]Hoja1!$C5 -> 3 | B45: CONTAMINACIÓN DEL BIOLÓGICO | C45: Corresponde a la cantidad de dosis pérdidas debido a que el vial se contaminó durante el proceso de almacenamiento, alistamiento, envasado, aplicación de la vacuna COVID-19, entre otras, inmersión del vial, agujas permanentes insertadas sobre el tapón del frasco, mala manipulación.
...

Sheet Enero
A1: MUNICIPIOS / IPS VACUNADORAS
A2: ÍTEM | B2: INSUMOS | D2: SALDO MES ANTERIOR | E2: BIOLÓGICO RECIBIDO DEL CENTRO DE ACOPIO DEPARTAMENTAL / DISTRITAL | F2: DOSIS APLICADAS | H2: Entradas | I2: Salidas | J2: TOTAL DOSIS APLICADAS | K2: DOSIS PERDIDAS | L2: TOTAL DOSIS ÚTILIZADAS EN EL MES | M2: SALDO QUE INICIA EL MES SIGUIENTE (SOLO MUNICIPIOS) | N2: DOSIS POR LOTES | O2: No. LOTE | P2: LABORATORIO | Q2: FECHA DE VENCIMIENTO | R2: SEMAFORIZACION VIDA ÚTIL DEL BIOLÓGICO | S2: CONDICIÓN FINAL DEL BIOLÓGICO, DILUYENTE Y CARNET | T2: DOSIS EN CUARENTENA | U2: LABORATORIO | V2: No. LOTE | W2: FECHA DE VENCIMEINTO | X2: FECHA DE INICIO CUARENTENA | Y2: PORCENTAJE DE PERDIDA DEL MES | Z2: OBSERVACIONES | AB2: CAUSAS PERDIDA DE BIOLÓGICOS (Remítase a la primera hoja donde se especifica la clasificación de las perdidas) | AO2: TOTAL DOSIS PERDIDAS
F3: DOSIS APLICADAS COLOMBIANOS | G3: DOSIS APLICADAS EXTRANJEROS | H3: DOSIS INGRESADAS POR TRASLADOS DE MUNICIPIOS O IPS | I3: DOSIS TRASLADADAS A OTROS MUNICIPIOS O IPS | AB3: 1 | AE3: 2 | AF3: 3 | AG3: 4 | AH3: 5 | AI3: 6 | AJ3: 7 | AK3: 8 | AL3: 9 | AM3: 10 | AN3: 11
AB4: POLÍTICA DE FRASCOS ABIERTO | AE4: INTERRUPCIÓN DE CADENA DE FRÍO | AF4: CONTAMINACION DEL BIOLÓGICO/DISPOSITIVO MÉDICO | AG4: VIAL ROTO | AH4: ERRORES EN LA MANIPULACIÓN | AI4: VENCIMIENTO DEL BIOLÓGICO O JERINGA | AJ4: FARMACOVIGILANCIA / TECNOVIGILANCIA | AK4: VOMITO FRANCO | AL4: APLICACIÓN FUERA DE LA EDAD | AM4: POR DECISIÓN FINAL DEL PACIENTE DE NO VACUNACIÓN | AN4: SINIESTRO O ROBO
AB5: INSTITUCIONAL | AC5: EXTRAMURAL | AD5: TOTAL
A6: 1 | B6: Vacuna de BCG (Bacilo de Calmette y Guérin) Liofilizada | D6: 390 | F6: 49 | J6: =+F6+G6 -> 49 | K6: =+AO6 -> 251 | L6: =+J6+K6 -> 300 | M6: =+(D6+E6)-(L6)+H6-I6 -> 90 | N6: 90 | O6: 0374MA071 | Q6: 12/026 | R6: =IF(Q6=0," ",IFERROR(IF(DATEDIF(TODAY(),Q6,"M")<=5,"ROJO",IF(DATEDIF(TODAY(),Q6,"M")>=12,"VERDE",IF(AND(DATEDIF(TODAY(),Q6,"M")>=6,DATEDIF(TODAY(),Q6,"M")<=11),"AMARILLO"))),S6)) -> NO VENCIDO | S6: =IF(Q6=0," ",IF(Q6<=$N$5,"VENCIDO","NO VENCIDO")) -> NO VENCIDO | Y6: =+AT6 -> 0 | AB6: 115 | AC6: 136 | AD6: =+AB6+AC6 -> 251 | AO6: =SUM(AD6:AN10) -> 251
R7: =IF(Q7=0," ",IFERROR(IF(DATEDIF(TODAY(),Q7,"M")<=5,"ROJO",IF(DATEDIF(TODAY(),Q7,"M")>=12,"VERDE",IF(AND(DATEDIF(TODAY(),Q7,"M")>=6,DATEDIF(TODAY(),Q7,"M")<=11),"AMARILLO"))),S7)) | S7: =IF(Q7=0," ",IF(Q7<=$N$5,"VENCIDO","NO VENCIDO"))
R8: =IF(Q8=0," ",IFERROR(IF(DATEDIF(TODAY(),Q8,"M")<=5,"ROJO",IF(DATEDIF(TODAY(),Q8,"M")>=12,"VERDE",IF(AND(DATEDIF(TODAY(),Q8,"M")>=6,DATEDIF(TODAY(),Q8,"M")<=11),"AMARILLO"))),S8)) | S8: =IF(Q8=0," ",IF(Q8<=$N$5,"VENCIDO","NO VENCIDO"))
R9: =IF(Q9=0," ",IFERROR(IF(DATEDIF(TODAY(),Q9,"M")<=5,"ROJO",IF(DATEDIF(TODAY(),Q9,"M")>=12,"VERDE",IF(AND(DATEDIF(TODAY(),Q9,"M")>=6,DATEDIF(TODAY(),Q9,"M")<=11),"AMARILLO"))),S9)) | S9: =IF(Q9=0," ",IF(Q9<=$N$5,"VENCIDO","NO VENCIDO"))
R10: =IF(Q10=0," ",IFERROR(IF(DATEDIF(TODAY(),Q10,"M")<=5,"ROJO",IF(DATEDIF(TODAY(),Q10,"M")>=12,"VERDE",IF(AND(DATEDIF(TODAY(),Q10,"M")>=6,DATEDIF(TODAY(),Q10,"M")<=11),"AMARILLO"))),S10)) | S10: =IF(Q10=0," ",IF(Q10<=$N$5,"VENCIDO","NO VENCIDO"))
M11: =M6=N11 -> TRUE | N11: =SUM(N6:N10) -> 90 | O11: “Verdadero” indica que la cantidad por lote, coincide con el saldo que inicia al mes siguiente. "Falso" no coinicide. | T11: =SUM(T6:T10) -> 0
A12: =A6+1 -> 2 | B12: Vacuna de Hepatitis B Recombinante Pediátrica - Liquida | D12: 160 | F12: 42 | J12: =+F12+G12 -> 42 | K12: =+AO12 -> 0 | L12: =+J12+K12 -> 42 | M12: =+(D12+E12)-(L12)+H12-I12 -> 118 | N12: 118 | O12: 0324L013B | Q12: 46692 | R12: =IF(Q12=0," ",IFERROR(IF(DATEDIF(TODAY(),Q12,"M")<=5,"ROJO",IF(DATEDIF(TODAY(),Q12,"M")>=12,"VERDE",IF(AND(DATEDIF(TODAY(),Q12,"M")>=6,DATEDIF(TODAY(),Q12,"M")<=11),"AMARILLO"))),S12)) -> VERDE | S12: =IF(Q12=0," ",IF(Q12<=$N$5,"VENCIDO","NO VENCIDO")) -> NO VENCIDO | Y12: =+AT12 -> 0 | AD12: =+AB12+AC12 -> 0 | AO12: =SUM(AD12:AN16) -> 0
R13: =IF(Q13=0," ",IFERROR(IF(DATEDIF(TODAY(),Q13,"M")<=5,"ROJO",IF(DATEDIF(TODAY(),Q13,"M")>=12,"VERDE",IF(AND(DATEDIF(TODAY(),Q13,"M")>=6,DATEDIF(TODAY(),Q13,"M")<=11),"AMARILLO"))),S13)) | S13: =IF(Q13=0," ",IF(Q13<=$N$5,"VENCIDO","NO VENCIDO"))
R14: =IF(Q14=0," ",IFERROR(IF(DATEDIF(TODAY(),Q14,"M")<=5,"ROJO",IF(DATEDIF(TODAY(),Q14,"M")>=12,"VERDE",IF(AND(DATEDIF(TODAY(),Q14,"M")>=6,DATEDIF(TODAY(),Q14,"M")<=11),"AMARILLO"))),S14)) | S14: =IF(Q14=0," ",IF(Q14<=$N$5,"VENCIDO","NO VENCIDO"))
R15: =IF(Q15=0," ",IFERROR(IF(DATEDIF(TODAY(),Q15,"M")<=5,"ROJO",IF(DATEDIF(TODAY(),Q15,"M")>=12,"VERDE",IF(AND(DATEDIF(TODAY(),Q15,"M")>=6,DATEDIF(TODAY(),Q15,"M")<=11),"AMARILLO"))),S15)) | S15: =IF(Q15=0," ",IF(Q15<=$N$5,"VENCIDO","NO VENCIDO"))
R16: =IF(Q16=0," ",IFERROR(IF(DATEDIF(TODAY(),Q16,"M")<=5,"ROJO",IF(DATEDIF(TODAY(),Q16,"M")>=12,"VERDE",IF(AND(DATEDIF(TODAY(),Q16,"M")>=6,DATEDIF(TODAY(),Q16,"M")<=11),"AMARILLO"))),S16)) | S16: =IF(Q16=0," ",IF(Q16<=$N$5,"VENCIDO","NO VENCIDO"))
M17: =M12=N17 -> TRUE | N17: =SUM(N12:N16) -> 118 | O17: “Verdadero” indica que la cantidad por lote, coincide con el saldo que inicia al mes siguiente. "Falso" no coinicide. | T17: =SUM(T12:T16) -> 0
A18: =A12+1 -> 3 | B18: Vacuna de Hepatitis B Recombinante Adultos - Liquida | D18: 21 | F18: 5 | J18: =+F18+G18 -> 5 | K18: =+AO18 -> 0 | L18: =+J18+K18 -> 5 | M18: =+(D18+E18)-(L18)+H18-I18 -> 16 | N18: 16 | O18: 0344X002C | Q18: 46539 | R18: =IF(Q18=0," ",IFERROR(IF(DATEDIF(TODAY(),Q18,"M")<=5,"ROJO",IF(DATEDIF(TODAY(),Q18,"M")>=12,"VERDE",IF(AND(DATEDIF(TODAY(),Q18,"M")>=6,DATEDIF(TODAY(),Q18,"M")<=11),"AMARILLO"))),S18)) -> AMARILLO | S18: =IF(Q18=0," ",IF(Q18<=$N$5,"VENCIDO","NO VENCIDO")) -> NO VENCIDO | Y18: =+AT18 -> 0 | AD18: =+AB18+AC18 -> 0 | AO18: =SUM(AD18:AN22) -> 0
R19: =IF(Q19=0," ",IFERROR(IF(DATEDIF(TODAY(),Q19,"M")<=5,"ROJO",IF(DATEDIF(TODAY(),Q19,"M")>=12,"VERDE",IF(AND(DATEDIF(TODAY(),Q19,"M")>=6,DATEDIF(TODAY(),Q19,"M")<=11),"AMARILLO"))),S19)) | S19: =IF(Q19=0," ",IF(Q19<=$N$5,"VENCIDO","NO VENCIDO"))
R20: =IF(Q20=0," ",IFERROR(IF(DATEDIF(TODAY(),Q20,"M")<=5,"ROJO",IF(DATEDIF(TODAY(),Q20,"M")>=12,"VERDE",IF(AND(DATEDIF(TODAY(),Q20,"M")>=6,DATEDIF(TODAY(),Q20,"M")<=11),"AMARILLO"))),S20)) | S20: =IF(Q20=0," ",IF(Q20<=$N$5,"VENCIDO","NO VENCIDO"))
R21: =IF(Q21=0," ",IFERROR(IF(DATEDIF(TODAY(),Q21,"M")<=5,"ROJO",IF(DATEDIF(TODAY(),Q21,"M")>=12,"VERDE",IF(AND(DATEDIF(TODAY(),Q21,"M")>=6,DATEDIF(TODAY(),Q21,"M")<=11),"AMARILLO"))),S21)) | S21: =IF(Q21=0," ",IF(Q21<=$N$5,"VENCIDO","NO VENCIDO"))
R22: =IF(Q22=0," ",IFERROR(IF(DATEDIF(TODAY(),Q22,"M")<=5,"ROJO",IF(DATEDIF(TODAY(),Q22,"M")>=12,"VERDE",IF(AND(DATEDIF(TODAY(),Q22,"M")>=6,DATEDIF(TODAY(),Q22,"M")<=11),"AMARILLO"))),S22)) | S22: =IF(Q22=0," ",IF(Q22<=$N$5,"VENCIDO","NO VENCIDO"))
M23: =M18=N23 -> TRUE | N23: =SUM(N18:N22) -> 16 | O23: “Verdadero” indica que la cantidad por lote, coincide con el saldo que inicia al mes siguiente. "Falso" no coinicide. | T23: =SUM(T18:T22) -> 0
A24: =A18+1 -> 4 | B24: Vacuna de Poliovirus Inactiva IPV - Liquida | D24: 730 | F24: 297 | J24: =+F24+G24 -> 297 | K24: =+AO24 -> 0 | L24: =+J24+K24 -> 297 | M24: =+(D24+E24)-(L24)+H24-I24 -> 433 | N24: 433 | O24: 2435007 | Q24: 46521 | R24: =IF(Q24=0," ",IFERROR(IF(DATEDIF(TODAY(),Q24,"M")<=5,"ROJO",IF(DATEDIF(TODAY(),Q24,"M")>=12,"VERDE",IF(AND(DATEDIF(TODAY(),Q24,"M")>=6,DATEDIF(TODAY(),Q24,"M")<=11),"AMARILLO"))),S24)) -> AMARILLO | S24: =IF(Q24=0," ",IF(Q24<=$N$5,"VENCIDO","NO VENCIDO")) -> NO VENCIDO | Y24: =+AT24 -> 0 | AD24: =+AB24+AC24 -> 0 | AO24: =SUM(AD24:AN28) -> 0
R25: =IF(Q25=0," ",IFERROR(IF(DATEDIF(TODAY(),Q25,"M")<=5,"ROJO",IF(DATEDIF(TODAY(),Q25,"M")>=12,"VERDE",IF(AND(DATEDIF(TODAY(),Q25,"M")>=6,DATEDIF(TODAY(),Q25,"M")<=11),"AMARILLO"))),S25)) | S25: =IF(Q25=0," ",IF(Q25<=$N$5,"VENCIDO","NO VENCIDO"))
R26: =IF(Q26=0," ",IFERROR(IF(DATEDIF(TODAY(),Q26,"M")<=5,"ROJO",IF(DATEDIF(TODAY(),Q26,"M")>=12,"VERDE",IF(AND(DATEDIF(TODAY(),Q26,"M")>=6,DATEDIF(TODAY(),Q26,"M")<=11),"AMARILLO"))),S26)) | S26: =IF(Q26=0," ",IF(Q26<=$N$5,"VENCIDO","NO VENCIDO"))
R27: =IF(Q27=0," ",IFERROR(IF(DATEDIF(TODAY(),Q27,"M")<=5,"ROJO",IF(DATEDIF(TODAY(),Q27,"M")>=12,"VERDE",IF(AND(DATEDIF(TODAY(),Q27,"M")>=6,DATEDIF(TODAY(),Q27,"M")<=11),"AMARILLO"))),S27)) | S27: =IF(Q27=0," ",IF(Q27<=$N$5,"VENCIDO","NO VENCIDO"))
R28: =IF(Q28=0," ",IFERROR(IF(DATEDIF(TODAY(),Q28,"M")<=5,"ROJO",IF(DATEDIF(TODAY(),Q28,"M")>=12,"VERDE",IF(AND(DATEDIF(TODAY(),Q28,"M")>=6,DATEDIF(TODAY(),Q28,"M")<=11),"AMARILLO"))),S28)) | S28: =IF(Q28=0," ",IF(Q28<=$N$5,"VENCIDO","NO VENCIDO"))
M29: =M24=N29 -> TRUE | N29: =SUM(N24:N28) -> 433 | O29: “Verdadero” indica que la cantidad por lote, coincide con el saldo que inicia al mes siguiente. "Falso" no coinicide. | T29: =SUM(T24:T28) -> 0
A30: =A24+1 -> 5 | B30: Vacuna de Difteria - Tos ferina (Celula completa) - Tétanos - Hepatitis B - Haemophilus influenzae tipo B (DTwP-HepB-Hib) PENTAVALENTE PEDIÁTRICA - Liquida | D30: 670 | F30: 249 | J30: =+F30+G30 -> 249 | K30: =+AO30 -> 0 | L30: =+J30+K30 -> 249 | M30: =+(D30+E30)-(L30)+H30-I30 -> 421 | N30: 421 | O30: 2854X041B | Q30: 46478 | R30: =IF(Q30=0," ",IFERROR(IF(DATEDIF(TODAY(),Q30,"M")<=5,"ROJO",IF(DATEDIF(TODAY(),Q30,"M")>=12,"VERDE",IF(AND(DATEDIF(TODAY(),Q30,"M")>=6,DATEDIF(TODAY(),Q30,"M")<=11),"AMARILLO"))),S30)) -> ROJO | S30: =IF(Q30=0," ",IF(Q30<=$N$5,"VENCIDO","NO VENCIDO")) -> NO VENCIDO | Y30: =+AT30 -> 0 | AD30: =+AB30+AC30 -> 0 | AO30: =SUM(AD30:AN34) -> 0
R31: =IF(Q31=0," ",IFERROR(IF(DATEDIF(TODAY(),Q31,"M")<=5,"ROJO",IF(DATEDIF(TODAY(),Q31,"M")>=12,"VERDE",IF(AND(DATEDIF(TODAY(),Q31,"M")>=6,DATEDIF(TODAY(),Q31,"M")<=11),"AMARILLO"))),S31)) | S31: =IF(Q31=0," ",IF(Q31<=$N$5,"VENCIDO","NO VENCIDO"))
R32: =IF(Q32=0," ",IFERROR(IF(DATEDIF(TODAY(),Q32,"M")<=5,"ROJO",IF(DATEDIF(TODAY(),Q32,"M")>=12,"VERDE",IF(AND(DATEDIF(TODAY(),Q32,"M")>=6,DATEDIF(TODAY(),Q32,"M")<=11),"AMARILLO"))),S32)) | S32: =IF(Q32=0," ",IF(Q32<=$N$5,"VENCIDO","NO VENCIDO"))
R33: =IF(Q33=0," ",IFERROR(IF(DATEDIF(TODAY(),Q33,"M")<=5,"ROJO",IF(DATEDIF(TODAY(),Q33,"M")>=12,"VERDE",IF(AND(DATEDIF(TODAY(),Q33,"M")>=6,DATEDIF(TODAY(),Q33,"M")<=11),"AMARILLO"))),S33)) | S33: =IF(Q33=0," ",IF(Q33<=$N$5,"VENCIDO","NO VENCIDO"))
R34: =IF(Q34=0," ",IFERROR(IF(DATEDIF(TODAY(),Q34,"M")<=5,"ROJO",IF(DATEDIF(TODAY(),Q34,"M")>=12,"VERDE",IF(AND(DATEDIF(TODAY(),Q34,"M")>=6,DATEDIF(TODAY(),Q34,"M")<=11),"AMARILLO"))),S34)) | S34: =IF(Q34=0," ",IF(Q34<=$N$5,"VENCIDO","NO VENCIDO"))
M35: =M30=N35 -> TRUE | N35: =SUM(N30:N34) -> 421 | O35: “Verdadero” indica que la cantidad por lote, coincide con el saldo que inicia al mes siguiente. "Falso" no coinicide. | T35: =SUM(T30:T34) -> 0
A36: =A30+1 -> 6 | B36: Vacuna de Difteria - Tétanos - Tos ferina acelular - Poliovirus inactivado - Hepatitis B - Haemophilus influenzae tipo B (DTaP-IPV-HepB-Hib (HEXAVALENTE ACELULAR) - Liquida | D36: 3 | J36: =+F36+G36 -> 0 | K36: =+AO36 -> 0 | L36: =+J36+K36 -> 0 | M36: =+(D36+E36)-(L36)+H36-I36 -> 3 | N36: 3 | O36: Y3C49 | Q36: 46784 | R36: =IF(Q36=0," ",IFERROR(IF(DATEDIF(TODAY(),Q36,"M")<=5,"ROJO",IF(DATEDIF(TODAY(),Q36,"M")>=12,"VERDE",IF(AND(DATEDIF(TODAY(),Q36,"M")>=6,DATEDIF(TODAY(),Q36,"M")<=11),"AMARILLO"))),S36)) -> VERDE | S36: =IF(Q36=0," ",IF(Q36<=$N$5,"VENCIDO","NO VENCIDO")) -> NO VENCIDO | Y36: =+AT36 -> 0 | AD36: =+AB36+AC36 -> 0 | AO36: =SUM(AD36:AN40) -> 0
R37: =IF(Q37=0," ",IFERROR(IF(DATEDIF(TODAY(),Q37,"M")<=5,"ROJO",IF(DATEDIF(TODAY(),Q37,"M")>=12,"VERDE",IF(AND(DATEDIF(TODAY(),Q37,"M")>=6,DATEDIF(TODAY(),Q37,"M")<=11),"AMARILLO"))),S37)) | S37: =IF(Q37=0," ",IF(Q37<=$N$5,"VENCIDO","NO VENCIDO"))
R38: =IF(Q38=0," ",IFERROR(IF(DATEDIF(TODAY(),Q38,"M")<=5,"ROJO",IF(DATEDIF(TODAY(),Q38,"M")>=12,"VERDE",IF(AND(DATEDIF(TODAY(),Q38,"M")>=6,DATEDIF(TODAY(),Q38,"M")<=11),"AMARILLO"))),S38)) | S38: =IF(Q38=0," ",IF(Q38<=$N$5,"VENCIDO","NO VENCIDO"))
R39: =IF(Q39=0," ",IFERROR(IF(DATEDIF(TODAY(),Q39,"M")<=5,"ROJO",IF(DATEDIF(TODAY(),Q39,"M")>=12,"VERDE",IF(AND(DATEDIF(TODAY(),Q39,"M")>=6,DATEDIF(TODAY(),Q39,"M")<=11),"AMARILLO"))),S39)) | S39: =IF(Q39=0," ",IF(Q39<=$N$5,"VENCIDO","NO VENCIDO"))
R40: =IF(Q40=0," ",IFERROR(IF(DATEDIF(TODAY(),Q40,"M")<=5,"ROJO",IF(DATEDIF(TODAY(),Q40,"M")>=12,"VERDE",IF(AND(DATEDIF(TODAY(),Q40,"M")>=6,DATEDIF(TODAY(),Q40,"M")<=11),"AMARILLO"))),S40)) | S40: =IF(Q40=0," ",IF(Q40<=$N$5,"VENCIDO","NO VENCIDO"))
...

Sheet Febrero
A1: MUNICIPIOS / IPS VACUNADORAS
A2: ÍTEM | B2: INSUMOS | D2: SALDO MES ANTERIOR | E2: BIOLÓGICO RECIBIDO DEL CENTRO DE ACOPIO DEPARTAMENTAL / DISTRITAL | F2: DOSIS APLICADAS | H2: Entradas | I2: Salidas | J2: TOTAL DOSIS APLICADAS | K2: DOSIS PERDIDAS | L2: TOTAL DOSIS ÚTILIZADAS EN EL MES | M2: SALDO QUE INICIA EL MES SIGUIENTE (SOLO MUNICIPIOS) | N2: DOSIS POR LOTES | O2: No. LOTE | P2: LABORATORIO | Q2: FECHA DE VENCIMIENTO | R2: SEMAFORIZACION VIDA ÚTIL DEL BIOLÓGICO | S2: CONDICIÓN FINAL DEL BIOLÓGICO, DILUYENTE Y CARNET | T2: DOSIS EN CUARENTENA | U2: LABORATORIO | V2: No. LOTE | W2: FECHA DE VENCIMEINTO | X2: FECHA DE INICIO CUARENTENA | Y2: PORCENTAJE DE PERDIDA DEL MES | Z2: OBSERVACIONES | AB2: CAUSAS PERDIDA DE BIOLÓGICOS (Remítase a la primera hoja donde se especifica la clasificación de las perdidas) | AO2: TOTAL DOSIS PERDIDAS
F3: DOSIS APLICADAS COLOMBIANOS | G3: DOSIS APLICADAS EXTRANJEROS | H3: DOSIS INGRESADAS POR TRASLADOS DE MUNICIPIOS O IPS | I3: DOSIS TRASLADADAS A OTROS MUNICIPIOS O IPS | AB3: 1 | AE3: 2 | AF3: 3 | AG3: 4 | AH3: 5 | AI3: 6 | AJ3: 7 | AK3: 8 | AL3: 9 | AM3: 10 | AN3: 11
AB4: POLÍTICA DE FRASCOS ABIERTO | AE4: INTERRUPCIÓN DE CADENA DE FRÍO | AF4: CONTAMINACION DEL BIOLÓGICO/DISPOSITIVO MÉDICO | AG4: VIAL ROTO | AH4: ERRORES EN LA MANIPULACIÓN | AI4: VENCIMIENTO DEL BIOLÓGICO O JERINGA | AJ4: FARMACOVIGILANCIA / TECNOVIGILANCIA | AK4: VOMITO FRANCO | AL4: APLICACIÓN FUERA DE LA EDAD | AM4: POR DECISIÓN FINAL DEL PACIENTE DE NO VACUNACIÓN | AN4: SINIESTRO O ROBO
AB5: INSTITUCIONAL | AC5: EXTRAMURAL | AD5: TOTAL
A6: 1 | B6: Vacuna de BCG (Bacilo de Calmette y Guérin) Liofilizada | D6: =+Enero!M6 -> 90 | E6: 400 | F6: 54 | J6: =+F6+G6 -> 54 | K6: =+AO6 -> 236 | L6: =+J6+K6 -> 290 | M6: =+(D6+E6)-(L6)+H6-I6 -> 200 | N6: 200 | O6: 037MA071 | Q6: 46357 | R6: =IF(Q6=0," ",IFERROR(IF(DATEDIF(TODAY(),Q6,"M")<=5,"ROJO",IF(DATEDIF(TODAY(),Q6,"M")>=12,"VERDE",IF(AND(DATEDIF(TODAY(),Q6,"M")>=6,DATEDIF(TODAY(),Q6,"M")<=11),"AMARILLO"))),S6)) -> ROJO | S6: =IF(Q6=0," ",IF(Q6<=$N$5,"VENCIDO","NO VENCIDO")) -> NO VENCIDO | Y6: =+AT6 -> 0 | AB6: 141 | AC6: 95 | AD6: =+AB6+AC6 -> 236 | AO6: =SUM(AD6:AN10) -> 236
R7: =IF(Q7=0," ",IFERROR(IF(DATEDIF(TODAY(),Q7,"M")<=5,"ROJO",IF(DATEDIF(TODAY(),Q7,"M")>=12,"VERDE",IF(AND(DATEDIF(TODAY(),Q7,"M")>=6,DATEDIF(TODAY(),Q7,"M")<=11),"AMARILLO"))),S7)) | S7: =IF(Q7=0," ",IF(Q7<=$N$5,"VENCIDO","NO VENCIDO"))
R8: =IF(Q8=0," ",IFERROR(IF(DATEDIF(TODAY(),Q8,"M")<=5,"ROJO",IF(DATEDIF(TODAY(),Q8,"M")>=12,"VERDE",IF(AND(DATEDIF(TODAY(),Q8,"M")>=6,DATEDIF(TODAY(),Q8,"M")<=11),"AMARILLO"))),S8)) | S8: =IF(Q8=0," ",IF(Q8<=$N$5,"VENCIDO","NO VENCIDO"))
R9: =IF(Q9=0," ",IFERROR(IF(DATEDIF(TODAY(),Q9,"M")<=5,"ROJO",IF(DATEDIF(TODAY(),Q9,"M")>=12,"VERDE",IF(AND(DATEDIF(TODAY(),Q9,"M")>=6,DATEDIF(TODAY(),Q9,"M")<=11),"AMARILLO"))),S9)) | S9: =IF(Q9=0," ",IF(Q9<=$N$5,"VENCIDO","NO VENCIDO"))
R10: =IF(Q10=0," ",IFERROR(IF(DATEDIF(TODAY(),Q10,"M")<=5,"ROJO",IF(DATEDIF(TODAY(),Q10,"M")>=12,"VERDE",IF(AND(DATEDIF(TODAY(),Q10,"M")>=6,DATEDIF(TODAY(),Q10,"M")<=11),"AMARILLO"))),S10)) | S10: =IF(Q10=0," ",IF(Q10<=$N$5,"VENCIDO","NO VENCIDO"))
M11: =M6=N11 -> TRUE | N11: =SUM(N6:N10) -> 200 | O11: “Verdadero” indica que la cantidad por lote, coincide con el saldo que inicia al mes siguiente. "Falso" no coinicide. | T11: =SUM(T6:T10) -> 0
A12: =A6+1 -> 2 | B12: Vacuna de Hepatitis B Recombinante Pediátrica - Liquida | D12: =+Enero!M12 -> 118 | F12: 39 | J12: =+F12+G12 -> 39 | K12: =+AO12 -> 0 | L12: =+J12+K12 -> 39 | M12: =+(D12+E12)-(L12)+H12-I12 -> 79 | N12: 79 | O12: 03241013B | Q12: 46692 | R12: =IF(Q12=0," ",IFERROR(IF(DATEDIF(TODAY(),Q12,"M")<=5,"ROJO",IF(DATEDIF(TODAY(),Q12,"M")>=12,"VERDE",IF(AND(DATEDIF(TODAY(),Q12,"M")>=6,DATEDIF(TODAY(),Q12,"M")<=11),"AMARILLO"))),S12)) -> VERDE | S12: =IF(Q12=0," ",IF(Q12<=$N$5,"VENCIDO","NO VENCIDO")) -> NO VENCIDO | Y12: =+AT12 -> 0 | AD12: =+AB12+AC12 -> 0 | AO12: =SUM(AD12:AN16) -> 0
R13: =IF(Q13=0," ",IFERROR(IF(DATEDIF(TODAY(),Q13,"M")<=5,"ROJO",IF(DATEDIF(TODAY(),Q13,"M")>=12,"VERDE",IF(AND(DATEDIF(TODAY(),Q13,"M")>=6,DATEDIF(TODAY(),Q13,"M")<=11),"AMARILLO"))),S13)) | S13: =IF(Q13=0," ",IF(Q13<=$N$5,"VENCIDO","NO VENCIDO"))
R14: =IF(Q14=0," ",IFERROR(IF(DATEDIF(TODAY(),Q14,"M")<=5,"ROJO",IF(DATEDIF(TODAY(),Q14,"M")>=12,"VERDE",IF(AND(DATEDIF(TODAY(),Q14,"M")>=6,DATEDIF(TODAY(),Q14,"M")<=11),"AMARILLO"))),S14)) | S14: =IF(Q14=0," ",IF(Q14<=$N$5,"VENCIDO","NO VENCIDO"))
R15: =IF(Q15=0," ",IFERROR(IF(DATEDIF(TODAY(),Q15,"M")<=5,"ROJO",IF(DATEDIF(TODAY(),Q15,"M")>=12,"VERDE",IF(AND(DATEDIF(TODAY(),Q15,"M")>=6,DATEDIF(TODAY(),Q15,"M")<=11),"AMARILLO"))),S15)) | S15: =IF(Q15=0," ",IF(Q15<=$N$5,"VENCIDO","NO VENCIDO"))
R16: =IF(Q16=0," ",IFERROR(IF(DATEDIF(TODAY(),Q16,"M")<=5,"ROJO",IF(DATEDIF(TODAY(),Q16,"M")>=12,"VERDE",IF(AND(DATEDIF(TODAY(),Q16,"M")>=6,DATEDIF(TODAY(),Q16,"M")<=11),"AMARILLO"))),S16)) | S16: =IF(Q16=0," ",IF(Q16<=$N$5,"VENCIDO","NO VENCIDO"))
M17: =M12=N17 -> TRUE | N17: =SUM(N12:N16) -> 79 | O17: “Verdadero” indica que la cantidad por lote, coincide con el saldo que inicia al mes siguiente. "Falso" no coinicide. | T17: =SUM(T12:T16) -> 0
A18: =A12+1 -> 3 | B18: Vacuna de Hepatitis B Recombinante Adultos - Liquida | D18: =+Enero!M18 -> 16 | F18: 4 | J18: =+F18+G18 -> 4 | K18: =+AO18 -> 0 | L18: =+J18+K18 -> 4 | M18: =+(D18+E18)-(L18)+H18-I18 -> 12 | N18: 12 | O18: 03344X002C | Q18: 46539 | R18: =IF(Q18=0," ",IFERROR(IF(DATEDIF(TODAY(),Q18,"M")<=5,"ROJO",IF(DATEDIF(TODAY(),Q18,"M")>=12,"VERDE",IF(AND(DATEDIF(TODAY(),Q18,"M")>=6,DATEDIF(TODAY(),Q18,"M")<=11),"AMARILLO"))),S18)) -> AMARILLO | S18: =IF(Q18=0," ",IF(Q18<=$N$5,"VENCIDO","NO VENCIDO")) -> NO VENCIDO | Y18: =+AT18 -> 0 | AD18: =+AB18+AC18 -> 0 | AO18: =SUM(AD18:AN22) -> 0
R19: =IF(Q19=0," ",IFERROR(IF(DATEDIF(TODAY(),Q19,"M")<=5,"ROJO",IF(DATEDIF(TODAY(),Q19,"M")>=12,"VERDE",IF(AND(DATEDIF(TODAY(),Q19,"M")>=6,DATEDIF(TODAY(),Q19,"M")<=11),"AMARILLO"))),S19)) | S19: =IF(Q19=0," ",IF(Q19<=$N$5,"VENCIDO","NO VENCIDO"))
R20: =IF(Q20=0," ",IFERROR(IF(DATEDIF(TODAY(),Q20,"M")<=5,"ROJO",IF(DATEDIF(TODAY(),Q20,"M")>=12,"VERDE",IF(AND(DATEDIF(TODAY(),Q20,"M")>=6,DATEDIF(TODAY(),Q20,"M")<=11),"AMARILLO"))),S20)) | S20: =IF(Q20=0," ",IF(Q20<=$N$5,"VENCIDO","NO VENCIDO"))
R21: =IF(Q21=0," ",IFERROR(IF(DATEDIF(TODAY(),Q21,"M")<=5,"ROJO",IF(DATEDIF(TODAY(),Q21,"M")>=12,"VERDE",IF(AND(DATEDIF(TODAY(),Q21,"M")>=6,DATEDIF(TODAY(),Q21,"M")<=11),"AMARILLO"))),S21)) | S21: =IF(Q21=0," ",IF(Q21<=$N$5,"VENCIDO","NO VENCIDO"))
R22: =IF(Q22=0," ",IFERROR(IF(DATEDIF(TODAY(),Q22,"M")<=5,"ROJO",IF(DATEDIF(TODAY(),Q22,"M")>=12,"VERDE",IF(AND(DATEDIF(TODAY(),Q22,"M")>=6,DATEDIF(TODAY(),Q22,"M")<=11),"AMARILLO"))),S22)) | S22: =IF(Q22=0," ",IF(Q22<=$N$5,"VENCIDO","NO VENCIDO"))
M23: =M18=N23 -> TRUE | N23: =SUM(N18:N22) -> 12 | O23: “Verdadero” indica que la cantidad por lote, coincide con el saldo que inicia al mes siguiente. "Falso" no coinicide. | T23: =SUM(T18:T22) -> 0
A24: =A18+1 -> 4 | B24: Vacuna de Poliovirus Inactiva IPV - Liquida | D24: =+Enero!M24 -> 433 | F24: 256 | J24: =+F24+G24 -> 256 | K24: =+AO24 -> 0 | L24: =+J24+K24 -> 256 | M24: =+(D24+E24)-(L24)+H24-I24 -> 177 | N24: 177 | O24: 2435007 | Q24: 14/05/2027 | R24: =IF(Q24=0," ",IFERROR(IF(DATEDIF(TODAY(),Q24,"M")<=5,"ROJO",IF(DATEDIF(TODAY(),Q24,"M")>=12,"VERDE",IF(AND(DATEDIF(TODAY(),Q24,"M")>=6,DATEDIF(TODAY(),Q24,"M")<=11),"AMARILLO"))),S24)) -> AMARILLO | S24: =IF(Q24=0," ",IF(Q24<=$N$5,"VENCIDO","NO VENCIDO")) -> NO VENCIDO | Y24: =+AT24 -> 0 | AD24: =+AB24+AC24 -> 0 | AO24: =SUM(AD24:AN28) -> 0
R25: =IF(Q25=0," ",IFERROR(IF(DATEDIF(TODAY(),Q25,"M")<=5,"ROJO",IF(DATEDIF(TODAY(),Q25,"M")>=12,"VERDE",IF(AND(DATEDIF(TODAY(),Q25,"M")>=6,DATEDIF(TODAY(),Q25,"M")<=11),"AMARILLO"))),S25)) | S25: =IF(Q25=0," ",IF(Q25<=$N$5,"VENCIDO","NO VENCIDO"))
R26: =IF(Q26=0," ",IFERROR(IF(DATEDIF(TODAY(),Q26,"M")<=5,"ROJO",IF(DATEDIF(TODAY(),Q26,"M")>=12,"VERDE",IF(AND(DATEDIF(TODAY(),Q26,"M")>=6,DATEDIF(TODAY(),Q26,"M")<=11),"AMARILLO"))),S26)) | S26: =IF(Q26=0," ",IF(Q26<=$N$5,"VENCIDO","NO VENCIDO"))
R27: =IF(Q27=0," ",IFERROR(IF(DATEDIF(TODAY(),Q27,"M")<=5,"ROJO",IF(DATEDIF(TODAY(),Q27,"M")>=12,"VERDE",IF(AND(DATEDIF(TODAY(),Q27,"M")>=6,DATEDIF(TODAY(),Q27,"M")<=11),"AMARILLO"))),S27)) | S27: =IF(Q27=0," ",IF(Q27<=$N$5,"VENCIDO","NO VENCIDO"))
R28: =IF(Q28=0," ",IFERROR(IF(DATEDIF(TODAY(),Q28,"M")<=5,"ROJO",IF(DATEDIF(TODAY(),Q28,"M")>=12,"VERDE",IF(AND(DATEDIF(TODAY(),Q28,"M")>=6,DATEDIF(TODAY(),Q28,"M")<=11),"AMARILLO"))),S28)) | S28: =IF(Q28=0," ",IF(Q28<=$N$5,"VENCIDO","NO VENCIDO"))
M29: =M24=N29 -> TRUE | N29: =SUM(N24:N28) -> 177 | O29: “Verdadero” indica que la cantidad por lote, coincide con el saldo que inicia al mes siguiente. "Falso" no coinicide. | T29: =SUM(T24:T28) -> 0
A30: =A24+1 -> 5 | B30: Vacuna de Difteria - Tos ferina (Celula completa) - Tétanos - Hepatitis B - Haemophilus influenzae tipo B (DTwP-HepB-Hib) PENTAVALENTE PEDIÁTRICA - Liquida | D30: =+Enero!M30 -> 421 | F30: 197 | J30: =+F30+G30 -> 197 | K30: =+AO30 -> 0 | L30: =+J30+K30 -> 197 | M30: =+(D30+E30)-(L30)+H30-I30 -> 224 | N30: 224 | O30: 2854X0414B | Q30: 46478 | R30: =IF(Q30=0," ",IFERROR(IF(DATEDIF(TODAY(),Q30,"M")<=5,"ROJO",IF(DATEDIF(TODAY(),Q30,"M")>=12,"VERDE",IF(AND(DATEDIF(TODAY(),Q30,"M")>=6,DATEDIF(TODAY(),Q30,"M")<=11),"AMARILLO"))),S30)) -> ROJO | S30: =IF(Q30=0," ",IF(Q30<=$N$5,"VENCIDO","NO VENCIDO")) -> NO VENCIDO | Y30: =+AT30 -> 0 | AD30: =+AB30+AC30 -> 0 | AO30: =SUM(AD30:AN34) -> 0
R31: =IF(Q31=0," ",IFERROR(IF(DATEDIF(TODAY(),Q31,"M")<=5,"ROJO",IF(DATEDIF(TODAY(),Q31,"M")>=12,"VERDE",IF(AND(DATEDIF(TODAY(),Q31,"M")>=6,DATEDIF(TODAY(),Q31,"M")<=11),"AMARILLO"))),S31)) | S31: =IF(Q31=0," ",IF(Q31<=$N$5,"VENCIDO","NO VENCIDO"))
R32: =IF(Q32=0," ",IFERROR(IF(DATEDIF(TODAY(),Q32,"M")<=5,"ROJO",IF(DATEDIF(TODAY(),Q32,"M")>=12,"VERDE",IF(AND(DATEDIF(TODAY(),Q32,"M")>=6,DATEDIF(TODAY(),Q32,"M")<=11),"AMARILLO"))),S32)) | S32: =IF(Q32=0," ",IF(Q32<=$N$5,"VENCIDO","NO VENCIDO"))
R33: =IF(Q33=0," ",IFERROR(IF(DATEDIF(TODAY(),Q33,"M")<=5,"ROJO",IF(DATEDIF(TODAY(),Q33,"M")>=12,"VERDE",IF(AND(DATEDIF(TODAY(),Q33,"M")>=6,DATEDIF(TODAY(),Q33,"M")<=11),"AMARILLO"))),S33)) | S33: =IF(Q33=0," ",IF(Q33<=$N$5,"VENCIDO","NO VENCIDO"))
R34: =IF(Q34=0," ",IFERROR(IF(DATEDIF(TODAY(),Q34,"M")<=5,"ROJO",IF(DATEDIF(TODAY(),Q34,"M")>=12,"VERDE",IF(AND(DATEDIF(TODAY(),Q34,"M")>=6,DATEDIF(TODAY(),Q34,"M")<=11),"AMARILLO"))),S34)) | S34: =IF(Q34=0," ",IF(Q34<=$N$5,"VENCIDO","NO VENCIDO"))
M35: =M30=N35 -> TRUE | N35: =SUM(N30:N34) -> 224 | O35: “Verdadero” indica que la cantidad por lote, coincide con el saldo que inicia al mes siguiente. "Falso" no coinicide. | T35: =SUM(T30:T34) -> 0
A36: =A30+1 -> 6 | B36: Vacuna de Difteria - Tétanos - Tos ferina acelular - Poliovirus inactivado - Hepatitis B - Haemophilus influenzae tipo B (DTaP-IPV-HepB-Hib (HEXAVALENTE ACELULAR) - Liquida | D36: =+Enero!M36 -> 3 | J36: =+F36+G36 -> 0 | K36: =+AO36 -> 0 | L36: =+J36+K36 -> 0 | M36: =+(D36+E36)-(L36)+H36-I36 -> 3 | N36: 3 | O36: Y3CY9 | Q36: 46784 | R36: =IF(Q36=0," ",IFERROR(IF(DATEDIF(TODAY(),Q36,"M")<=5,"ROJO",IF(DATEDIF(TODAY(),Q36,"M")>=12,"VERDE",IF(AND(DATEDIF(TODAY(),Q36,"M")>=6,DATEDIF(TODAY(),Q36,"M")<=11),"AMARILLO"))),S36)) -> VERDE | S36: =IF(Q36=0," ",IF(Q36<=$N$5,"VENCIDO","NO VENCIDO")) -> NO VENCIDO | Y36: =+AT36 -> 0 | AD36: =+AB36+AC36 -> 0 | AO36: =SUM(AD36:AN40) -> 0
R37: =IF(Q37=0," ",IFERROR(IF(DATEDIF(TODAY(),Q37,"M")<=5,"ROJO",IF(DATEDIF(TODAY(),Q37,"M")>=12,"VERDE",IF(AND(DATEDIF(TODAY(),Q37,"M")>=6,DATEDIF(TODAY(),Q37,"M")<=11),"AMARILLO"))),S37)) | S37: =IF(Q37=0," ",IF(Q37<=$N$5,"VENCIDO","NO VENCIDO"))
R38: =IF(Q38=0," ",IFERROR(IF(DATEDIF(TODAY(),Q38,"M")<=5,"ROJO",IF(DATEDIF(TODAY(),Q38,"M")>=12,"VERDE",IF(AND(DATEDIF(TODAY(),Q38,"M")>=6,DATEDIF(TODAY(),Q38,"M")<=11),"AMARILLO"))),S38)) | S38: =IF(Q38=0," ",IF(Q38<=$N$5,"VENCIDO","NO VENCIDO"))
R39: =IF(Q39=0," ",IFERROR(IF(DATEDIF(TODAY(),Q39,"M")<=5,"ROJO",IF(DATEDIF(TODAY(),Q39,"M")>=12,"VERDE",IF(AND(DATEDIF(TODAY(),Q39,"M")>=6,DATEDIF(TODAY(),Q39,"M")<=11),"AMARILLO"))),S39)) | S39: =IF(Q39=0," ",IF(Q39<=$N$5,"VENCIDO","NO VENCIDO"))
R40: =IF(Q40=0," ",IFERROR(IF(DATEDIF(TODAY(),Q40,"M")<=5,"ROJO",IF(DATEDIF(TODAY(),Q40,"M")>=12,"VERDE",IF(AND(DATEDIF(TODAY(),Q40,"M")>=6,DATEDIF(TODAY(),Q40,"M")<=11),"AMARILLO"))),S40)) | S40: =IF(Q40=0," ",IF(Q40<=$N$5,"VENCIDO","NO VENCIDO"))
...

Sheet Marzo
A1: MUNICIPIOS / IPS VACUNADORAS
A2: ÍTEM | B2: INSUMOS | D2: SALDO MES ANTERIOR | E2: BIOLÓGICO RECIBIDO DEL CENTRO DE ACOPIO DEPARTAMENTAL / DISTRITAL | F2: DOSIS APLICADAS | H2: Entradas | I2: Salidas | J2: TOTAL DOSIS APLICADAS | K2: DOSIS PERDIDAS | L2: TOTAL DOSIS ÚTILIZADAS EN EL MES | M2: SALDO QUE INICIA EL MES SIGUIENTE (SOLO MUNICIPIOS) | N2: DOSIS POR LOTES | O2: No. LOTE | P2: LABORATORIO | Q2: FECHA DE VENCIMIENTO | R2: SEMAFORIZACION VIDA ÚTIL DEL BIOLÓGICO | S2: CONDICIÓN FINAL DEL BIOLÓGICO, DILUYENTE Y CARNET | T2: DOSIS EN CUARENTENA | U2: LABORATORIO | V2: No. LOTE | W2: FECHA DE VENCIMEINTO | X2: FECHA DE INICIO CUARENTENA | Y2: PORCENTAJE DE PERDIDA DEL MES | Z2: OBSERVACIONES | AB2: CAUSAS PERDIDA DE BIOLÓGICOS (Remítase a la primera hoja donde se especifica la clasificación de las perdidas) | AO2: TOTAL DOSIS PERDIDAS
F3: DOSIS APLICADAS COLOMBIANOS | G3: DOSIS APLICADAS EXTRANJEROS | H3: DOSIS INGRESADAS POR TRASLADOS DE MUNICIPIOS O IPS | I3: DOSIS TRASLADADAS A OTROS MUNICIPIOS O IPS | AB3: 1 | AE3: 2 | AF3: 3 | AG3: 4 | AH3: 5 | AI3: 6 | AJ3: 7 | AK3: 8 | AL3: 9 | AM3: 10 | AN3: 11
AB4: POLÍTICA DE FRASCOS ABIERTO | AE4: INTERRUPCIÓN DE CADENA DE FRÍO | AF4: CONTAMINACION DEL BIOLÓGICO/DISPOSITIVO MÉDICO | AG4: VIAL ROTO | AH4: ERRORES EN LA MANIPULACIÓN | AI4: VENCIMIENTO DEL BIOLÓGICO O JERINGA | AJ4: FARMACOVIGILANCIA / TECNOVIGILANCIA | AK4: VOMITO FRANCO | AL4: APLICACIÓN FUERA DE LA EDAD | AM4: POR DECISIÓN FINAL DEL PACIENTE DE NO VACUNACIÓN | AN4: SINIESTRO O ROBO
AB5: INSTITUCIONAL | AC5: EXTRAMURAL | AD5: TOTAL
A6: 1 | B6: Vacuna de BCG (Bacilo de Calmette y Guérin) Liofilizada | D6: =+Febrero!M6 -> 200 | E6: 300 | F6: 37 | J6: =+F6+G6 -> 37 | K6: =+AO6 -> 233 | L6: =+J6+K6 -> 270 | M6: =+(D6+E6)-(L6)+H6-I6 -> 230 | N6: 230 | O6: 0374MA072 | Q6: 46357 | R6: =IF(Q6=0," ",IFERROR(IF(DATEDIF(TODAY(),Q6,"M")<=5,"ROJO",IF(DATEDIF(TODAY(),Q6,"M")>=12,"VERDE",IF(AND(DATEDIF(TODAY(),Q6,"M")>=6,DATEDIF(TODAY(),Q6,"M")<=11),"AMARILLO"))),S6)) -> ROJO | S6: =IF(Q6=0," ",IF(Q6<=$N$5,"VENCIDO","NO VENCIDO")) -> NO VENCIDO | Y6: =+AT6 -> 0 | AB6: 95 | AC6: 138 | AD6: =+AB6+AC6 -> 233 | AO6: =SUM(AD6:AN10) -> 233
R7: =IF(Q7=0," ",IFERROR(IF(DATEDIF(TODAY(),Q7,"M")<=5,"ROJO",IF(DATEDIF(TODAY(),Q7,"M")>=12,"VERDE",IF(AND(DATEDIF(TODAY(),Q7,"M")>=6,DATEDIF(TODAY(),Q7,"M")<=11),"AMARILLO"))),S7)) | S7: =IF(Q7=0," ",IF(Q7<=$N$5,"VENCIDO","NO VENCIDO"))
R8: =IF(Q8=0," ",IFERROR(IF(DATEDIF(TODAY(),Q8,"M")<=5,"ROJO",IF(DATEDIF(TODAY(),Q8,"M")>=12,"VERDE",IF(AND(DATEDIF(TODAY(),Q8,"M")>=6,DATEDIF(TODAY(),Q8,"M")<=11),"AMARILLO"))),S8)) | S8: =IF(Q8=0," ",IF(Q8<=$N$5,"VENCIDO","NO VENCIDO"))
R9: =IF(Q9=0," ",IFERROR(IF(DATEDIF(TODAY(),Q9,"M")<=5,"ROJO",IF(DATEDIF(TODAY(),Q9,"M")>=12,"VERDE",IF(AND(DATEDIF(TODAY(),Q9,"M")>=6,DATEDIF(TODAY(),Q9,"M")<=11),"AMARILLO"))),S9)) | S9: =IF(Q9=0," ",IF(Q9<=$N$5,"VENCIDO","NO VENCIDO"))
R10: =IF(Q10=0," ",IFERROR(IF(DATEDIF(TODAY(),Q10,"M")<=5,"ROJO",IF(DATEDIF(TODAY(),Q10,"M")>=12,"VERDE",IF(AND(DATEDIF(TODAY(),Q10,"M")>=6,DATEDIF(TODAY(),Q10,"M")<=11),"AMARILLO"))),S10)) | S10: =IF(Q10=0," ",IF(Q10<=$N$5,"VENCIDO","NO VENCIDO"))
M11: =M6=N11 -> TRUE | N11: =SUM(N6:N10) -> 230 | O11: “Verdadero” indica que la cantidad por lote, coincide con el saldo que inicia al mes siguiente. "Falso" no coinicide. | T11: =SUM(T6:T10) -> 0
A12: =A6+1 -> 2 | B12: Vacuna de Hepatitis B Recombinante Pediátrica - Liquida | D12: =+Febrero!M12 -> 79 | E12: 150 | F12: 32 | J12: =+F12+G12 -> 32 | K12: =+AO12 -> 0 | L12: =+J12+K12 -> 32 | M12: =+(D12+E12)-(L12)+H12-I12 -> 197 | N12: 197 | O12: 0324LO13B | Q12: 46784 | R12: =IF(Q12=0," ",IFERROR(IF(DATEDIF(TODAY(),Q12,"M")<=5,"ROJO",IF(DATEDIF(TODAY(),Q12,"M")>=12,"VERDE",IF(AND(DATEDIF(TODAY(),Q12,"M")>=6,DATEDIF(TODAY(),Q12,"M")<=11),"AMARILLO"))),S12)) -> VERDE | S12: =IF(Q12=0," ",IF(Q12<=$N$5,"VENCIDO","NO VENCIDO")) -> NO VENCIDO | Y12: =+AT12 -> 0 | AD12: =+AB12+AC12 -> 0 | AO12: =SUM(AD12:AN16) -> 0
R13: =IF(Q13=0," ",IFERROR(IF(DATEDIF(TODAY(),Q13,"M")<=5,"ROJO",IF(DATEDIF(TODAY(),Q13,"M")>=12,"VERDE",IF(AND(DATEDIF(TODAY(),Q13,"M")>=6,DATEDIF(TODAY(),Q13,"M")<=11),"AMARILLO"))),S13)) | S13: =IF(Q13=0," ",IF(Q13<=$N$5,"VENCIDO","NO VENCIDO"))
R14: =IF(Q14=0," ",IFERROR(IF(DATEDIF(TODAY(),Q14,"M")<=5,"ROJO",IF(DATEDIF(TODAY(),Q14,"M")>=12,"VERDE",IF(AND(DATEDIF(TODAY(),Q14,"M")>=6,DATEDIF(TODAY(),Q14,"M")<=11),"AMARILLO"))),S14)) | S14: =IF(Q14=0," ",IF(Q14<=$N$5,"VENCIDO","NO VENCIDO"))
R15: =IF(Q15=0," ",IFERROR(IF(DATEDIF(TODAY(),Q15,"M")<=5,"ROJO",IF(DATEDIF(TODAY(),Q15,"M")>=12,"VERDE",IF(AND(DATEDIF(TODAY(),Q15,"M")>=6,DATEDIF(TODAY(),Q15,"M")<=11),"AMARILLO"))),S15)) | S15: =IF(Q15=0," ",IF(Q15<=$N$5,"VENCIDO","NO VENCIDO"))
R16: =IF(Q16=0," ",IFERROR(IF(DATEDIF(TODAY(),Q16,"M")<=5,"ROJO",IF(DATEDIF(TODAY(),Q16,"M")>=12,"VERDE",IF(AND(DATEDIF(TODAY(),Q16,"M")>=6,DATEDIF(TODAY(),Q16,"M")<=11),"AMARILLO"))),S16)) | S16: =IF(Q16=0," ",IF(Q16<=$N$5,"VENCIDO","NO VENCIDO"))
M17: =M12=N17 -> TRUE | N17: =SUM(N12:N16) -> 197 | O17: “Verdadero” indica que la cantidad por lote, coincide con el saldo que inicia al mes siguiente. "Falso" no coinicide. | T17: =SUM(T12:T16) -> 0
A18: =A12+1 -> 3 | B18: Vacuna de Hepatitis B Recombinante Adultos - Liquida | D18: =+Febrero!M18 -> 12 | F18: 8 | J18: =+F18+G18 -> 8 | K18: =+AO18 -> 0 | L18: =+J18+K18 -> 8 | M18: =+(D18+E18)-(L18)+H18-I18 -> 4 | N18: 4 | O18: 03344X002C | Q18: 46539 | R18: =IF(Q18=0," ",IFERROR(IF(DATEDIF(TODAY(),Q18,"M")<=5,"ROJO",IF(DATEDIF(TODAY(),Q18,"M")>=12,"VERDE",IF(AND(DATEDIF(TODAY(),Q18,"M")>=6,DATEDIF(TODAY(),Q18,"M")<=11),"AMARILLO"))),S18)) -> AMARILLO | S18: =IF(Q18=0," ",IF(Q18<=$N$5,"VENCIDO","NO VENCIDO")) -> NO VENCIDO | Y18: =+AT18 -> 0 | AD18: =+AB18+AC18 -> 0 | AO18: =SUM(AD18:AN22) -> 0
R19: =IF(Q19=0," ",IFERROR(IF(DATEDIF(TODAY(),Q19,"M")<=5,"ROJO",IF(DATEDIF(TODAY(),Q19,"M")>=12,"VERDE",IF(AND(DATEDIF(TODAY(),Q19,"M")>=6,DATEDIF(TODAY(),Q19,"M")<=11),"AMARILLO"))),S19)) | S19: =IF(Q19=0," ",IF(Q19<=$N$5,"VENCIDO","NO VENCIDO"))
R20: =IF(Q20=0," ",IFERROR(IF(DATEDIF(TODAY(),Q20,"M")<=5,"ROJO",IF(DATEDIF(TODAY(),Q20,"M")>=12,"VERDE",IF(AND(DATEDIF(TODAY(),Q20,"M")>=6,DATEDIF(TODAY(),Q20,"M")<=11),"AMARILLO"))),S20)) | S20: =IF(Q20=0," ",IF(Q20<=$N$5,"VENCIDO","NO VENCIDO"))
R21: =IF(Q21=0," ",IFERROR(IF(DATEDIF(TODAY(),Q21,"M")<=5,"ROJO",IF(DATEDIF(TODAY(),Q21,"M")>=12,"VERDE",IF(AND(DATEDIF(TODAY(),Q21,"M")>=6,DATEDIF(TODAY(),Q21,"M")<=11),"AMARILLO"))),S21)) | S21: =IF(Q21=0," ",IF(Q21<=$N$5,"VENCIDO","NO VENCIDO"))
R22: =IF(Q22=0," ",IFERROR(IF(DATEDIF(TODAY(),Q22,"M")<=5,"ROJO",IF(DATEDIF(TODAY(),Q22,"M")>=12,"VERDE",IF(AND(DATEDIF(TODAY(),Q22,"M")>=6,DATEDIF(TODAY(),Q22,"M")<=11),"AMARILLO"))),S22)) | S22: =IF(Q22=0," ",IF(Q22<=$N$5,"VENCIDO","NO VENCIDO"))
M23: =M18=N23 -> TRUE | N23: =SUM(N18:N22) -> 4 | O23: “Verdadero” indica que la cantidad por lote, coincide con el saldo que inicia al mes siguiente. "Falso" no coinicide. | T23: =SUM(T18:T22) -> 0
A24: =A18+1 -> 4 | B24: Vacuna de Poliovirus Inactiva IPV - Liquida | D24: =+Febrero!M24 -> 177 | E24: 300 | F24: 243 | J24: =+F24+G24 -> 243 | K24: =+AO24 -> 0 | L24: =+J24+K24 -> 243 | M24: =+(D24+E24)-(L24)+H24-I24 -> 234 | N24: 234 | O24: 2522006A | Q24: 46784 | R24: =IF(Q24=0," ",IFERROR(IF(DATEDIF(TODAY(),Q24,"M")<=5,"ROJO",IF(DATEDIF(TODAY(),Q24,"M")>=12,"VERDE",IF(AND(DATEDIF(TODAY(),Q24,"M")>=6,DATEDIF(TODAY(),Q24,"M")<=11),"AMARILLO"))),S24)) -> VERDE | S24: =IF(Q24=0," ",IF(Q24<=$N$5,"VENCIDO","NO VENCIDO")) -> NO VENCIDO | Y24: =+AT24 -> 0 | AD24: =+AB24+AC24 -> 0 | AO24: =SUM(AD24:AN28) -> 0
R25: =IF(Q25=0," ",IFERROR(IF(DATEDIF(TODAY(),Q25,"M")<=5,"ROJO",IF(DATEDIF(TODAY(),Q25,"M")>=12,"VERDE",IF(AND(DATEDIF(TODAY(),Q25,"M")>=6,DATEDIF(TODAY(),Q25,"M")<=11),"AMARILLO"))),S25)) | S25: =IF(Q25=0," ",IF(Q25<=$N$5,"VENCIDO","NO VENCIDO"))
R26: =IF(Q26=0," ",IFERROR(IF(DATEDIF(TODAY(),Q26,"M")<=5,"ROJO",IF(DATEDIF(TODAY(),Q26,"M")>=12,"VERDE",IF(AND(DATEDIF(TODAY(),Q26,"M")>=6,DATEDIF(TODAY(),Q26,"M")<=11),"AMARILLO"))),S26)) | S26: =IF(Q26=0," ",IF(Q26<=$N$5,"VENCIDO","NO VENCIDO"))
R27: =IF(Q27=0," ",IFERROR(IF(DATEDIF(TODAY(),Q27,"M")<=5,"ROJO",IF(DATEDIF(TODAY(),Q27,"M")>=12,"VERDE",IF(AND(DATEDIF(TODAY(),Q27,"M")>=6,DATEDIF(TODAY(),Q27,"M")<=11),"AMARILLO"))),S27)) | S27: =IF(Q27=0," ",IF(Q27<=$N$5,"VENCIDO","NO VENCIDO"))
R28: =IF(Q28=0," ",IFERROR(IF(DATEDIF(TODAY(),Q28,"M")<=5,"ROJO",IF(DATEDIF(TODAY(),Q28,"M")>=12,"VERDE",IF(AND(DATEDIF(TODAY(),Q28,"M")>=6,DATEDIF(TODAY(),Q28,"M")<=11),"AMARILLO"))),S28)) | S28: =IF(Q28=0," ",IF(Q28<=$N$5,"VENCIDO","NO VENCIDO"))
M29: =M24=N29 -> TRUE | N29: =SUM(N24:N28) -> 234 | O29: “Verdadero” indica que la cantidad por lote, coincide con el saldo que inicia al mes siguiente. "Falso" no coinicide. | T29: =SUM(T24:T28) -> 0
A30: =A24+1 -> 5 | B30: Vacuna de Difteria - Tos ferina (Celula completa) - Tétanos - Hepatitis B - Haemophilus influenzae tipo B (DTwP-HepB-Hib) PENTAVALENTE PEDIÁTRICA - Liquida | D30: =+Febrero!M30 -> 224 | E30: 300 | F30: 202 | J30: =+F30+G30 -> 202 | K30: =+AO30 -> 0 | L30: =+J30+K30 -> 202 | M30: =+(D30+E30)-(L30)+H30-I30 -> 322 | N30: 322 | O30: 2855X001A | Q30: 46539 | R30: =IF(Q30=0," ",IFERROR(IF(DATEDIF(TODAY(),Q30,"M")<=5,"ROJO",IF(DATEDIF(TODAY(),Q30,"M")>=12,"VERDE",IF(AND(DATEDIF(TODAY(),Q30,"M")>=6,DATEDIF(TODAY(),Q30,"M")<=11),"AMARILLO"))),S30)) -> AMARILLO | S30: =IF(Q30=0," ",IF(Q30<=$N$5,"VENCIDO","NO VENCIDO")) -> NO VENCIDO | Y30: =+AT30 -> 0 | AD30: =+AB30+AC30 -> 0 | AO30: =SUM(AD30:AN34) -> 0
R31: =IF(Q31=0," ",IFERROR(IF(DATEDIF(TODAY(),Q31,"M")<=5,"ROJO",IF(DATEDIF(TODAY(),Q31,"M")>=12,"VERDE",IF(AND(DATEDIF(TODAY(),Q31,"M")>=6,DATEDIF(TODAY(),Q31,"M")<=11),"AMARILLO"))),S31)) | S31: =IF(Q31=0," ",IF(Q31<=$N$5,"VENCIDO","NO VENCIDO"))
R32: =IF(Q32=0," ",IFERROR(IF(DATEDIF(TODAY(),Q32,"M")<=5,"ROJO",IF(DATEDIF(TODAY(),Q32,"M")>=12,"VERDE",IF(AND(DATEDIF(TODAY(),Q32,"M")>=6,DATEDIF(TODAY(),Q32,"M")<=11),"AMARILLO"))),S32)) | S32: =IF(Q32=0," ",IF(Q32<=$N$5,"VENCIDO","NO VENCIDO"))
R33: =IF(Q33=0," ",IFERROR(IF(DATEDIF(TODAY(),Q33,"M")<=5,"ROJO",IF(DATEDIF(TODAY(),Q33,"M")>=12,"VERDE",IF(AND(DATEDIF(TODAY(),Q33,"M")>=6,DATEDIF(TODAY(),Q33,"M")<=11),"AMARILLO"))),S33)) | S33: =IF(Q33=0," ",IF(Q33<=$N$5,"VENCIDO","NO VENCIDO"))
R34: =IF(Q34=0," ",IFERROR(IF(DATEDIF(TODAY(),Q34,"M")<=5,"ROJO",IF(DATEDIF(TODAY(),Q34,"M")>=12,"VERDE",IF(AND(DATEDIF(TODAY(),Q34,"M")>=6,DATEDIF(TODAY(),Q34,"M")<=11),"AMARILLO"))),S34)) | S34: =IF(Q34=0," ",IF(Q34<=$N$5,"VENCIDO","NO VENCIDO"))
M35: =M30=N35 -> TRUE | N35: =SUM(N30:N34) -> 322 | O35: “Verdadero” indica que la cantidad por lote, coincide con el saldo que inicia al mes siguiente. "Falso" no coinicide. | T35: =SUM(T30:T34) -> 0
A36: =A30+1 -> 6 | B36: Vacuna de Difteria - Tétanos - Tos ferina acelular - Poliovirus inactivado - Hepatitis B - Haemophilus influenzae tipo B (DTaP-IPV-HepB-Hib (HEXAVALENTE ACELULAR) - Liquida | D36: =+Febrero!M36 -> 3 | J36: =+F36+G36 -> 0 | K36: =+AO36 -> 0 | L36: =+J36+K36 -> 0 | M36: =+(D36+E36)-(L36)+H36-I36 -> 3 | N36: 3 | O36: Y3CY9 | Q36: 46784 | R36: =IF(Q36=0," ",IFERROR(IF(DATEDIF(TODAY(),Q36,"M")<=5,"ROJO",IF(DATEDIF(TODAY(),Q36,"M")>=12,"VERDE",IF(AND(DATEDIF(TODAY(),Q36,"M")>=6,DATEDIF(TODAY(),Q36,"M")<=11),"AMARILLO"))),S36)) -> VERDE | S36: =IF(Q36=0," ",IF(Q36<=$N$5,"VENCIDO","NO VENCIDO")) -> NO VENCIDO | Y36: =+AT36 -> 0 | AD36: =+AB36+AC36 -> 0 | AO36: =SUM(AD36:AN40) -> 0
R37: =IF(Q37=0," ",IFERROR(IF(DATEDIF(TODAY(),Q37,"M")<=5,"ROJO",IF(DATEDIF(TODAY(),Q37,"M")>=12,"VERDE",IF(AND(DATEDIF(TODAY(),Q37,"M")>=6,DATEDIF(TODAY(),Q37,"M")<=11),"AMARILLO"))),S37)) | S37: =IF(Q37=0," ",IF(Q37<=$N$5,"VENCIDO","NO VENCIDO"))
R38: =IF(Q38=0," ",IFERROR(IF(DATEDIF(TODAY(),Q38,"M")<=5,"ROJO",IF(DATEDIF(TODAY(),Q38,"M")>=12,"VERDE",IF(AND(DATEDIF(TODAY(),Q38,"M")>=6,DATEDIF(TODAY(),Q38,"M")<=11),"AMARILLO"))),S38)) | S38: =IF(Q38=0," ",IF(Q38<=$N$5,"VENCIDO","NO VENCIDO"))
R39: =IF(Q39=0," ",IFERROR(IF(DATEDIF(TODAY(),Q39,"M")<=5,"ROJO",IF(DATEDIF(TODAY(),Q39,"M")>=12,"VERDE",IF(AND(DATEDIF(TODAY(),Q39,"M")>=6,DATEDIF(TODAY(),Q39,"M")<=11),"AMARILLO"))),S39)) | S39: =IF(Q39=0," ",IF(Q39<=$N$5,"VENCIDO","NO VENCIDO"))
R40: =IF(Q40=0," ",IFERROR(IF(DATEDIF(TODAY(),Q40,"M")<=5,"ROJO",IF(DATEDIF(TODAY(),Q40,"M")>=12,"VERDE",IF(AND(DATEDIF(TODAY(),Q40,"M")>=6,DATEDIF(TODAY(),Q40,"M")<=11),"AMARILLO"))),S40)) | S40: =IF(Q40=0," ",IF(Q40<=$N$5,"VENCIDO","NO VENCIDO"))
...

Sheet Abril
A1: MUNICIPIOS / IPS VACUNADORAS
A2: ÍTEM | B2: INSUMOS | D2: SALDO MES ANTERIOR | E2: BIOLÓGICO RECIBIDO DEL CENTRO DE ACOPIO DEPARTAMENTAL / DISTRITAL | F2: DOSIS APLICADAS | H2: Entradas | I2: Salidas | J2: TOTAL DOSIS APLICADAS | K2: DOSIS PERDIDAS | L2: TOTAL DOSIS ÚTILIZADAS EN EL MES | M2: SALDO QUE INICIA EL MES SIGUIENTE (SOLO MUNICIPIOS) | N2: DOSIS POR LOTES | O2: No. LOTE | P2: LABORATORIO | Q2: FECHA DE VENCIMIENTO | R2: SEMAFORIZACION VIDA ÚTIL DEL BIOLÓGICO | S2: CONDICIÓN FINAL DEL BIOLÓGICO, DILUYENTE Y CARNET | T2: DOSIS EN CUARENTENA | U2: LABORATORIO | V2: No. LOTE | W2: FECHA DE VENCIMEINTO | X2: FECHA DE INICIO CUARENTENA | Y2: PORCENTAJE DE PERDIDA DEL MES | Z2: OBSERVACIONES | AB2: CAUSAS PERDIDA DE BIOLÓGICOS (Remítase a la primera hoja donde se especifica la clasificación de las perdidas) | AO2: TOTAL DOSIS PERDIDAS
F3: DOSIS APLICADAS COLOMBIANOS | G3: DOSIS APLICADAS EXTRANJEROS | H3: DOSIS INGRESADAS POR TRASLADOS DE MUNICIPIOS O IPS | I3: DOSIS TRASLADADAS A OTROS MUNICIPIOS O IPS | AB3: 1 | AE3: 2 | AF3: 3 | AG3: 4 | AH3: 5 | AI3: 6 | AJ3: 7 | AK3: 8 | AL3: 9 | AM3: 10 | AN3: 11
AB4: POLÍTICA DE FRASCOS ABIERTO | AE4: INTERRUPCIÓN DE CADENA DE FRÍO | AF4: CONTAMINACION DEL BIOLÓGICO/DISPOSITIVO MÉDICO | AG4: VIAL ROTO | AH4: ERRORES EN LA MANIPULACIÓN | AI4: VENCIMIENTO DEL BIOLÓGICO O JERINGA | AJ4: FARMACOVIGILANCIA / TECNOVIGILANCIA | AK4: VOMITO FRANCO | AL4: APLICACIÓN FUERA DE LA EDAD | AM4: POR DECISIÓN FINAL DEL PACIENTE DE NO VACUNACIÓN | AN4: SINIESTRO O ROBO
AB5: INSTITUCIONAL | AC5: EXTRAMURAL | AD5: TOTAL
A6: 1 | B6: Vacuna de BCG (Bacilo de Calmette y Guérin) Liofilizada | D6: =+Marzo!M6 -> 230 | E6: 200 | F6: 50 | J6: =+F6+G6 -> 50 | K6: =+AO6 -> 170 | L6: =+J6+K6 -> 220 | M6: =+(D6+E6)-(L6)+H6-I6 -> 210 | N6: 210 | O6: 0374MA071 | Q6: 46357 | R6: =IF(Q6=0," ",IFERROR(IF(DATEDIF(TODAY(),Q6,"M")<=5,"ROJO",IF(DATEDIF(TODAY(),Q6,"M")>=12,"VERDE",IF(AND(DATEDIF(TODAY(),Q6,"M")>=6,DATEDIF(TODAY(),Q6,"M")<=11),"AMARILLO"))),S6)) -> ROJO | S6: =IF(Q6=0," ",IF(Q6<=$N$5,"VENCIDO","NO VENCIDO")) -> NO VENCIDO | Y6: =+AT6 -> 0 | AB6: 106 | AC6: 64 | AD6: =+AB6+AC6 -> 170 | AO6: =SUM(AD6:AN10) -> 170
R7: =IF(Q7=0," ",IFERROR(IF(DATEDIF(TODAY(),Q7,"M")<=5,"ROJO",IF(DATEDIF(TODAY(),Q7,"M")>=12,"VERDE",IF(AND(DATEDIF(TODAY(),Q7,"M")>=6,DATEDIF(TODAY(),Q7,"M")<=11),"AMARILLO"))),S7)) | S7: =IF(Q7=0," ",IF(Q7<=$N$5,"VENCIDO","NO VENCIDO"))
R8: =IF(Q8=0," ",IFERROR(IF(DATEDIF(TODAY(),Q8,"M")<=5,"ROJO",IF(DATEDIF(TODAY(),Q8,"M")>=12,"VERDE",IF(AND(DATEDIF(TODAY(),Q8,"M")>=6,DATEDIF(TODAY(),Q8,"M")<=11),"AMARILLO"))),S8)) | S8: =IF(Q8=0," ",IF(Q8<=$N$5,"VENCIDO","NO VENCIDO"))
R9: =IF(Q9=0," ",IFERROR(IF(DATEDIF(TODAY(),Q9,"M")<=5,"ROJO",IF(DATEDIF(TODAY(),Q9,"M")>=12,"VERDE",IF(AND(DATEDIF(TODAY(),Q9,"M")>=6,DATEDIF(TODAY(),Q9,"M")<=11),"AMARILLO"))),S9)) | S9: =IF(Q9=0," ",IF(Q9<=$N$5,"VENCIDO","NO VENCIDO"))
R10: =IF(Q10=0," ",IFERROR(IF(DATEDIF(TODAY(),Q10,"M")<=5,"ROJO",IF(DATEDIF(TODAY(),Q10,"M")>=12,"VERDE",IF(AND(DATEDIF(TODAY(),Q10,"M")>=6,DATEDIF(TODAY(),Q10,"M")<=11),"AMARILLO"))),S10)) | S10: =IF(Q10=0," ",IF(Q10<=$N$5,"VENCIDO","NO VENCIDO"))
M11: =M6=N11 -> TRUE | N11: =SUM(N6:N10) -> 210 | O11: “Verdadero” indica que la cantidad por lote, coincide con el saldo que inicia al mes siguiente. "Falso" no coinicide. | T11: =SUM(T6:T10) -> 0
A12: =A6+1 -> 2 | B12: Vacuna de Hepatitis B Recombinante Pediátrica - Liquida | D12: =+Marzo!M12 -> 197 | E12: 50 | F12: 41 | J12: =+F12+G12 -> 41 | K12: =+AO12 -> 0 | L12: =+J12+K12 -> 41 | M12: =+(D12+E12)-(L12)+H12-I12 -> 206 | N12: 206 | O12: 0324LO13B | Q12: 46692 | R12: =IF(Q12=0," ",IFERROR(IF(DATEDIF(TODAY(),Q12,"M")<=5,"ROJO",IF(DATEDIF(TODAY(),Q12,"M")>=12,"VERDE",IF(AND(DATEDIF(TODAY(),Q12,"M")>=6,DATEDIF(TODAY(),Q12,"M")<=11),"AMARILLO"))),S12)) -> VERDE | S12: =IF(Q12=0," ",IF(Q12<=$N$5,"VENCIDO","NO VENCIDO")) -> NO VENCIDO | Y12: =+AT12 -> 0 | AD12: =+AB12+AC12 -> 0 | AO12: =SUM(AD12:AN16) -> 0
R13: =IF(Q13=0," ",IFERROR(IF(DATEDIF(TODAY(),Q13,"M")<=5,"ROJO",IF(DATEDIF(TODAY(),Q13,"M")>=12,"VERDE",IF(AND(DATEDIF(TODAY(),Q13,"M")>=6,DATEDIF(TODAY(),Q13,"M")<=11),"AMARILLO"))),S13)) | S13: =IF(Q13=0," ",IF(Q13<=$N$5,"VENCIDO","NO VENCIDO"))
R14: =IF(Q14=0," ",IFERROR(IF(DATEDIF(TODAY(),Q14,"M")<=5,"ROJO",IF(DATEDIF(TODAY(),Q14,"M")>=12,"VERDE",IF(AND(DATEDIF(TODAY(),Q14,"M")>=6,DATEDIF(TODAY(),Q14,"M")<=11),"AMARILLO"))),S14)) | S14: =IF(Q14=0," ",IF(Q14<=$N$5,"VENCIDO","NO VENCIDO"))
R15: =IF(Q15=0," ",IFERROR(IF(DATEDIF(TODAY(),Q15,"M")<=5,"ROJO",IF(DATEDIF(TODAY(),Q15,"M")>=12,"VERDE",IF(AND(DATEDIF(TODAY(),Q15,"M")>=6,DATEDIF(TODAY(),Q15,"M")<=11),"AMARILLO"))),S15)) | S15: =IF(Q15=0," ",IF(Q15<=$N$5,"VENCIDO","NO VENCIDO"))
R16: =IF(Q16=0," ",IFERROR(IF(DATEDIF(TODAY(),Q16,"M")<=5,"ROJO",IF(DATEDIF(TODAY(),Q16,"M")>=12,"VERDE",IF(AND(DATEDIF(TODAY(),Q16,"M")>=6,DATEDIF(TODAY(),Q16,"M")<=11),"AMARILLO"))),S16)) | S16: =IF(Q16=0," ",IF(Q16<=$N$5,"VENCIDO","NO VENCIDO"))
M17: =M12=N17 -> TRUE | N17: =SUM(N12:N16) -> 206 | O17: “Verdadero” indica que la cantidad por lote, coincide con el saldo que inicia al mes siguiente. "Falso" no coinicide. | T17: =SUM(T12:T16) -> 0
A18: =A12+1 -> 3 | B18: Vacuna de Hepatitis B Recombinante Adultos - Liquida | D18: =+Marzo!M18 -> 4 | E18: 20 | F18: 12 | J18: =+F18+G18 -> 12 | K18: =+AO18 -> 0 | L18: =+J18+K18 -> 12 | M18: =+(D18+E18)-(L18)+H18-I18 -> 12 | N18: 12 | O18: 0344X002C | Q18: 46539 | R18: =IF(Q18=0," ",IFERROR(IF(DATEDIF(TODAY(),Q18,"M")<=5,"ROJO",IF(DATEDIF(TODAY(),Q18,"M")>=12,"VERDE",IF(AND(DATEDIF(TODAY(),Q18,"M")>=6,DATEDIF(TODAY(),Q18,"M")<=11),"AMARILLO"))),S18)) -> AMARILLO | S18: =IF(Q18=0," ",IF(Q18<=$N$5,"VENCIDO","NO VENCIDO")) -> NO VENCIDO | Y18: =+AT18 -> 0 | AD18: =+AB18+AC18 -> 0 | AO18: =SUM(AD18:AN22) -> 0
R19: =IF(Q19=0," ",IFERROR(IF(DATEDIF(TODAY(),Q19,"M")<=5,"ROJO",IF(DATEDIF(TODAY(),Q19,"M")>=12,"VERDE",IF(AND(DATEDIF(TODAY(),Q19,"M")>=6,DATEDIF(TODAY(),Q19,"M")<=11),"AMARILLO"))),S19)) | S19: =IF(Q19=0," ",IF(Q19<=$N$5,"VENCIDO","NO VENCIDO"))
R20: =IF(Q20=0," ",IFERROR(IF(DATEDIF(TODAY(),Q20,"M")<=5,"ROJO",IF(DATEDIF(TODAY(),Q20,"M")>=12,"VERDE",IF(AND(DATEDIF(TODAY(),Q20,"M")>=6,DATEDIF(TODAY(),Q20,"M")<=11),"AMARILLO"))),S20)) | S20: =IF(Q20=0," ",IF(Q20<=$N$5,"VENCIDO","NO VENCIDO"))
R21: =IF(Q21=0," ",IFERROR(IF(DATEDIF(TODAY(),Q21,"M")<=5,"ROJO",IF(DATEDIF(TODAY(),Q21,"M")>=12,"VERDE",IF(AND(DATEDIF(TODAY(),Q21,"M")>=6,DATEDIF(TODAY(),Q21,"M")<=11),"AMARILLO"))),S21)) | S21: =IF(Q21=0," ",IF(Q21<=$N$5,"VENCIDO","NO VENCIDO"))
R22: =IF(Q22=0," ",IFERROR(IF(DATEDIF(TODAY(),Q22,"M")<=5,"ROJO",IF(DATEDIF(TODAY(),Q22,"M")>=12,"VERDE",IF(AND(DATEDIF(TODAY(),Q22,"M")>=6,DATEDIF(TODAY(),Q22,"M")<=11),"AMARILLO"))),S22)) | S22: =IF(Q22=0," ",IF(Q22<=$N$5,"VENCIDO","NO VENCIDO"))
M23: =M18=N23 -> TRUE | N23: =SUM(N18:N22) -> 12 | O23: “Verdadero” indica que la cantidad por lote, coincide con el saldo que inicia al mes siguiente. "Falso" no coinicide. | T23: =SUM(T18:T22) -> 0
A24: =A18+1 -> 4 | B24: Vacuna de Poliovirus Inactiva IPV - Liquida | D24: =+Marzo!M24 -> 234 | E24: 300 | F24: 301 | J24: =+F24+G24 -> 301 | K24: =+AO24 -> 0 | L24: =+J24+K24 -> 301 | M24: =+(D24+E24)-(L24)+H24-I24 -> 233 | N24: 233 | O24: 2522006A | Q24: 46784 | R24: =IF(Q24=0," ",IFERROR(IF(DATEDIF(TODAY(),Q24,"M")<=5,"ROJO",IF(DATEDIF(TODAY(),Q24,"M")>=12,"VERDE",IF(AND(DATEDIF(TODAY(),Q24,"M")>=6,DATEDIF(TODAY(),Q24,"M")<=11),"AMARILLO"))),S24)) -> VERDE | S24: =IF(Q24=0," ",IF(Q24<=$N$5,"VENCIDO","NO VENCIDO")) -> NO VENCIDO | Y24: =+AT24 -> 0 | AD24: =+AB24+AC24 -> 0 | AO24: =SUM(AD24:AN28) -> 0
R25: =IF(Q25=0," ",IFERROR(IF(DATEDIF(TODAY(),Q25,"M")<=5,"ROJO",IF(DATEDIF(TODAY(),Q25,"M")>=12,"VERDE",IF(AND(DATEDIF(TODAY(),Q25,"M")>=6,DATEDIF(TODAY(),Q25,"M")<=11),"AMARILLO"))),S25)) | S25: =IF(Q25=0," ",IF(Q25<=$N$5,"VENCIDO","NO VENCIDO"))
R26: =IF(Q26=0," ",IFERROR(IF(DATEDIF(TODAY(),Q26,"M")<=5,"ROJO",IF(DATEDIF(TODAY(),Q26,"M")>=12,"VERDE",IF(AND(DATEDIF(TODAY(),Q26,"M")>=6,DATEDIF(TODAY(),Q26,"M")<=11),"AMARILLO"))),S26)) | S26: =IF(Q26=0," ",IF(Q26<=$N$5,"VENCIDO","NO VENCIDO"))
R27: =IF(Q27=0," ",IFERROR(IF(DATEDIF(TODAY(),Q27,"M")<=5,"ROJO",IF(DATEDIF(TODAY(),Q27,"M")>=12,"VERDE",IF(AND(DATEDIF(TODAY(),Q27,"M")>=6,DATEDIF(TODAY(),Q27,"M")<=11),"AMARILLO"))),S27)) | S27: =IF(Q27=0," ",IF(Q27<=$N$5,"VENCIDO","NO VENCIDO"))
R28: =IF(Q28=0," ",IFERROR(IF(DATEDIF(TODAY(),Q28,"M")<=5,"ROJO",IF(DATEDIF(TODAY(),Q28,"M")>=12,"VERDE",IF(AND(DATEDIF(TODAY(),Q28,"M")>=6,DATEDIF(TODAY(),Q28,"M")<=11),"AMARILLO"))),S28)) | S28: =IF(Q28=0," ",IF(Q28<=$N$5,"VENCIDO","NO VENCIDO"))
M29: =M24=N29 -> TRUE | N29: =SUM(N24:N28) -> 233 | O29: “Verdadero” indica que la cantidad por lote, coincide con el saldo que inicia al mes siguiente. "Falso" no coinicide. | T29: =SUM(T24:T28) -> 0
A30: =A24+1 -> 5 | B30: Vacuna de Difteria - Tos ferina (Celula completa) - Tétanos - Hepatitis B - Haemophilus influenzae tipo B (DTwP-HepB-Hib) PENTAVALENTE PEDIÁTRICA - Liquida | D30: =+Marzo!M30 -> 322 | E30: 300 | F30: 231 | J30: =+F30+G30 -> 231 | K30: =+AO30 -> 0 | L30: =+J30+K30 -> 231 | M30: =+(D30+E30)-(L30)+H30-I30 -> 391 | N30: 391 | O30: 2855X001A | Q30: 46539 | R30: =IF(Q30=0," ",IFERROR(IF(DATEDIF(TODAY(),Q30,"M")<=5,"ROJO",IF(DATEDIF(TODAY(),Q30,"M")>=12,"VERDE",IF(AND(DATEDIF(TODAY(),Q30,"M")>=6,DATEDIF(TODAY(),Q30,"M")<=11),"AMARILLO"))),S30)) -> AMARILLO | S30: =IF(Q30=0," ",IF(Q30<=$N$5,"VENCIDO","NO VENCIDO")) -> NO VENCIDO | Y30: =+AT30 -> 0 | AD30: =+AB30+AC30 -> 0 | AO30: =SUM(AD30:AN34) -> 0
R31: =IF(Q31=0," ",IFERROR(IF(DATEDIF(TODAY(),Q31,"M")<=5,"ROJO",IF(DATEDIF(TODAY(),Q31,"M")>=12,"VERDE",IF(AND(DATEDIF(TODAY(),Q31,"M")>=6,DATEDIF(TODAY(),Q31,"M")<=11),"AMARILLO"))),S31)) | S31: =IF(Q31=0," ",IF(Q31<=$N$5,"VENCIDO","NO VENCIDO"))
R32: =IF(Q32=0," ",IFERROR(IF(DATEDIF(TODAY(),Q32,"M")<=5,"ROJO",IF(DATEDIF(TODAY(),Q32,"M")>=12,"VERDE",IF(AND(DATEDIF(TODAY(),Q32,"M")>=6,DATEDIF(TODAY(),Q32,"M")<=11),"AMARILLO"))),S32)) | S32: =IF(Q32=0," ",IF(Q32<=$N$5,"VENCIDO","NO VENCIDO"))
R33: =IF(Q33=0," ",IFERROR(IF(DATEDIF(TODAY(),Q33,"M")<=5,"ROJO",IF(DATEDIF(TODAY(),Q33,"M")>=12,"VERDE",IF(AND(DATEDIF(TODAY(),Q33,"M")>=6,DATEDIF(TODAY(),Q33,"M")<=11),"AMARILLO"))),S33)) | S33: =IF(Q33=0," ",IF(Q33<=$N$5,"VENCIDO","NO VENCIDO"))
R34: =IF(Q34=0," ",IFERROR(IF(DATEDIF(TODAY(),Q34,"M")<=5,"ROJO",IF(DATEDIF(TODAY(),Q34,"M")>=12,"VERDE",IF(AND(DATEDIF(TODAY(),Q34,"M")>=6,DATEDIF(TODAY(),Q34,"M")<=11),"AMARILLO"))),S34)) | S34: =IF(Q34=0," ",IF(Q34<=$N$5,"VENCIDO","NO VENCIDO"))
M35: =M30=N35 -> TRUE | N35: =SUM(N30:N34) -> 391 | O35: “Verdadero” indica que la cantidad por lote, coincide con el saldo que inicia al mes siguiente. "Falso" no coinicide. | T35: =SUM(T30:T34) -> 0
A36: =A30+1 -> 6 | B36: Vacuna de Difteria - Tétanos - Tos ferina acelular - Poliovirus inactivado - Hepatitis B - Haemophilus influenzae tipo B (DTaP-IPV-HepB-Hib (HEXAVALENTE ACELULAR) - Liquida | D36: =+Marzo!M36 -> 3 | J36: =+F36+G36 -> 0 | K36: =+AO36 -> 0 | L36: =+J36+K36 -> 0 | M36: =+(D36+E36)-(L36)+H36-I36 -> 3 | N36: 3 | O36: Y3CY9 | Q36: 46784 | R36: =IF(Q36=0," ",IFERROR(IF(DATEDIF(TODAY(),Q36,"M")<=5,"ROJO",IF(DATEDIF(TODAY(),Q36,"M")>=12,"VERDE",IF(AND(DATEDIF(TODAY(),Q36,"M")>=6,DATEDIF(TODAY(),Q36,"M")<=11),"AMARILLO"))),S36)) -> VERDE | S36: =IF(Q36=0," ",IF(Q36<=$N$5,"VENCIDO","NO VENCIDO")) -> NO VENCIDO | Y36: =+AT36 -> 0 | AD36: =+AB36+AC36 -> 0 | AO36: =SUM(AD36:AN40) -> 0
R37: =IF(Q37=0," ",IFERROR(IF(DATEDIF(TODAY(),Q37,"M")<=5,"ROJO",IF(DATEDIF(TODAY(),Q37,"M")>=12,"VERDE",IF(AND(DATEDIF(TODAY(),Q37,"M")>=6,DATEDIF(TODAY(),Q37,"M")<=11),"AMARILLO"))),S37)) | S37: =IF(Q37=0," ",IF(Q37<=$N$5,"VENCIDO","NO VENCIDO"))
R38: =IF(Q38=0," ",IFERROR(IF(DATEDIF(TODAY(),Q38,"M")<=5,"ROJO",IF(DATEDIF(TODAY(),Q38,"M")>=12,"VERDE",IF(AND(DATEDIF(TODAY(),Q38,"M")>=6,DATEDIF(TODAY(),Q38,"M")<=11),"AMARILLO"))),S38)) | S38: =IF(Q38=0," ",IF(Q38<=$N$5,"VENCIDO","NO VENCIDO"))
R39: =IF(Q39=0," ",IFERROR(IF(DATEDIF(TODAY(),Q39,"M")<=5,"ROJO",IF(DATEDIF(TODAY(),Q39,"M")>=12,"VERDE",IF(AND(DATEDIF(TODAY(),Q39,"M")>=6,DATEDIF(TODAY(),Q39,"M")<=11),"AMARILLO"))),S39)) | S39: =IF(Q39=0," ",IF(Q39<=$N$5,"VENCIDO","NO VENCIDO"))
R40: =IF(Q40=0," ",IFERROR(IF(DATEDIF(TODAY(),Q40,"M")<=5,"ROJO",IF(DATEDIF(TODAY(),Q40,"M")>=12,"VERDE",IF(AND(DATEDIF(TODAY(),Q40,"M")>=6,DATEDIF(TODAY(),Q40,"M")<=11),"AMARILLO"))),S40)) | S40: =IF(Q40=0," ",IF(Q40<=$N$5,"VENCIDO","NO VENCIDO"))
...

Sheet Mayo
A1: MUNICIPIOS / IPS VACUNADORAS
A2: ÍTEM | B2: INSUMOS | D2: SALDO MES ANTERIOR | E2: BIOLÓGICO RECIBIDO DEL CENTRO DE ACOPIO DEPARTAMENTAL / DISTRITAL | F2: DOSIS APLICADAS | H2: Entradas | I2: Salidas | J2: TOTAL DOSIS APLICADAS | K2: DOSIS PERDIDAS | L2: TOTAL DOSIS ÚTILIZADAS EN EL MES | M2: SALDO QUE INICIA EL MES SIGUIENTE (SOLO MUNICIPIOS) | N2: DOSIS POR LOTES | O2: No. LOTE | P2: LABORATORIO | Q2: FECHA DE VENCIMIENTO | R2: SEMAFORIZACION VIDA ÚTIL DEL BIOLÓGICO | S2: CONDICIÓN FINAL DEL BIOLÓGICO, DILUYENTE Y CARNET | T2: DOSIS EN CUARENTENA | U2: LABORATORIO | V2: No. LOTE | W2: FECHA DE VENCIMEINTO | X2: FECHA DE INICIO CUARENTENA | Y2: PORCENTAJE DE PERDIDA DEL MES | Z2: OBSERVACIONES | AB2: CAUSAS PERDIDA DE BIOLÓGICOS (Remítase a la primera hoja donde se especifica la clasificación de las perdidas) | AO2: TOTAL DOSIS PERDIDAS
F3: DOSIS APLICADAS COLOMBIANOS | G3: DOSIS APLICADAS EXTRANJEROS | H3: DOSIS INGRESADAS POR TRASLADOS DE MUNICIPIOS O IPS | I3: DOSIS TRASLADADAS A OTROS MUNICIPIOS O IPS | AB3: 1 | AE3: 2 | AF3: 3 | AG3: 4 | AH3: 5 | AI3: 6 | AJ3: 7 | AK3: 8 | AL3: 9 | AM3: 10 | AN3: 11
AB4: POLÍTICA DE FRASCOS ABIERTO | AE4: INTERRUPCIÓN DE CADENA DE FRÍO | AF4: CONTAMINACION DEL BIOLÓGICO/DISPOSITIVO MÉDICO | AG4: VIAL ROTO | AH4: ERRORES EN LA MANIPULACIÓN | AI4: VENCIMIENTO DEL BIOLÓGICO O JERINGA | AJ4: FARMACOVIGILANCIA / TECNOVIGILANCIA | AK4: VOMITO FRANCO | AL4: APLICACIÓN FUERA DE LA EDAD | AM4: POR DECISIÓN FINAL DEL PACIENTE DE NO VACUNACIÓN | AN4: SINIESTRO O ROBO
AB5: INSTITUCIONAL | AC5: EXTRAMURAL | AD5: TOTAL
A6: 1 | B6: Vacuna de BCG (Bacilo de Calmette y Guérin) Liofilizada | D6: =+Abril!M6 -> 210 | E6: 150 | F6: 44 | J6: =+F6+G6 -> 44 | K6: =+AO6 -> 246 | L6: =+J6+K6 -> 290 | M6: =+(D6+E6)-(L6)+H6-I6 -> 70 | N6: 70 | O6: 0374MA072 | Q6: 46357 | R6: =IF(Q6=0," ",IFERROR(IF(DATEDIF(TODAY(),Q6,"M")<=5,"ROJO",IF(DATEDIF(TODAY(),Q6,"M")>=12,"VERDE",IF(AND(DATEDIF(TODAY(),Q6,"M")>=6,DATEDIF(TODAY(),Q6,"M")<=11),"AMARILLO"))),S6)) -> ROJO | S6: =IF(Q6=0," ",IF(Q6<=$N$5,"VENCIDO","NO VENCIDO")) -> NO VENCIDO | Y6: =+AT6 -> 0 | AB6: 120 | AC6: 126 | AD6: =+AB6+AC6 -> 246 | AO6: =SUM(AD6:AN10) -> 246
R7: =IF(Q7=0," ",IFERROR(IF(DATEDIF(TODAY(),Q7,"M")<=5,"ROJO",IF(DATEDIF(TODAY(),Q7,"M")>=12,"VERDE",IF(AND(DATEDIF(TODAY(),Q7,"M")>=6,DATEDIF(TODAY(),Q7,"M")<=11),"AMARILLO"))),S7)) | S7: =IF(Q7=0," ",IF(Q7<=$N$5,"VENCIDO","NO VENCIDO"))
R8: =IF(Q8=0," ",IFERROR(IF(DATEDIF(TODAY(),Q8,"M")<=5,"ROJO",IF(DATEDIF(TODAY(),Q8,"M")>=12,"VERDE",IF(AND(DATEDIF(TODAY(),Q8,"M")>=6,DATEDIF(TODAY(),Q8,"M")<=11),"AMARILLO"))),S8)) | S8: =IF(Q8=0," ",IF(Q8<=$N$5,"VENCIDO","NO VENCIDO"))
R9: =IF(Q9=0," ",IFERROR(IF(DATEDIF(TODAY(),Q9,"M")<=5,"ROJO",IF(DATEDIF(TODAY(),Q9,"M")>=12,"VERDE",IF(AND(DATEDIF(TODAY(),Q9,"M")>=6,DATEDIF(TODAY(),Q9,"M")<=11),"AMARILLO"))),S9)) | S9: =IF(Q9=0," ",IF(Q9<=$N$5,"VENCIDO","NO VENCIDO"))
R10: =IF(Q10=0," ",IFERROR(IF(DATEDIF(TODAY(),Q10,"M")<=5,"ROJO",IF(DATEDIF(TODAY(),Q10,"M")>=12,"VERDE",IF(AND(DATEDIF(TODAY(),Q10,"M")>=6,DATEDIF(TODAY(),Q10,"M")<=11),"AMARILLO"))),S10)) | S10: =IF(Q10=0," ",IF(Q10<=$N$5,"VENCIDO","NO VENCIDO"))
M11: =M6=N11 -> TRUE | N11: =SUM(N6:N10) -> 70 | O11: “Verdadero” indica que la cantidad por lote, coincide con el saldo que inicia al mes siguiente. "Falso" no coinicide. | T11: =SUM(T6:T10) -> 0
A12: =A6+1 -> 2 | B12: Vacuna de Hepatitis B Recombinante Pediátrica - Liquida | D12: =+Abril!M12 -> 206 | F12: 41 | J12: =+F12+G12 -> 41 | K12: =+AO12 -> 0 | L12: =+J12+K12 -> 41 | M12: =+(D12+E12)-(L12)+H12-I12 -> 165 | N12: 165 | O12: 0324LO13B | Q12: 46692 | R12: =IF(Q12=0," ",IFERROR(IF(DATEDIF(TODAY(),Q12,"M")<=5,"ROJO",IF(DATEDIF(TODAY(),Q12,"M")>=12,"VERDE",IF(AND(DATEDIF(TODAY(),Q12,"M")>=6,DATEDIF(TODAY(),Q12,"M")<=11),"AMARILLO"))),S12)) -> VERDE | S12: =IF(Q12=0," ",IF(Q12<=$N$5,"VENCIDO","NO VENCIDO")) -> NO VENCIDO | Y12: =+AT12 -> 0 | AD12: =+AB12+AC12 -> 0 | AO12: =SUM(AD12:AN16) -> 0
R13: =IF(Q13=0," ",IFERROR(IF(DATEDIF(TODAY(),Q13,"M")<=5,"ROJO",IF(DATEDIF(TODAY(),Q13,"M")>=12,"VERDE",IF(AND(DATEDIF(TODAY(),Q13,"M")>=6,DATEDIF(TODAY(),Q13,"M")<=11),"AMARILLO"))),S13)) | S13: =IF(Q13=0," ",IF(Q13<=$N$5,"VENCIDO","NO VENCIDO"))
R14: =IF(Q14=0," ",IFERROR(IF(DATEDIF(TODAY(),Q14,"M")<=5,"ROJO",IF(DATEDIF(TODAY(),Q14,"M")>=12,"VERDE",IF(AND(DATEDIF(TODAY(),Q14,"M")>=6,DATEDIF(TODAY(),Q14,"M")<=11),"AMARILLO"))),S14)) | S14: =IF(Q14=0," ",IF(Q14<=$N$5,"VENCIDO","NO VENCIDO"))
R15: =IF(Q15=0," ",IFERROR(IF(DATEDIF(TODAY(),Q15,"M")<=5,"ROJO",IF(DATEDIF(TODAY(),Q15,"M")>=12,"VERDE",IF(AND(DATEDIF(TODAY(),Q15,"M")>=6,DATEDIF(TODAY(),Q15,"M")<=11),"AMARILLO"))),S15)) | S15: =IF(Q15=0," ",IF(Q15<=$N$5,"VENCIDO","NO VENCIDO"))
R16: =IF(Q16=0," ",IFERROR(IF(DATEDIF(TODAY(),Q16,"M")<=5,"ROJO",IF(DATEDIF(TODAY(),Q16,"M")>=12,"VERDE",IF(AND(DATEDIF(TODAY(),Q16,"M")>=6,DATEDIF(TODAY(),Q16,"M")<=11),"AMARILLO"))),S16)) | S16: =IF(Q16=0," ",IF(Q16<=$N$5,"VENCIDO","NO VENCIDO"))
M17: =M12=N17 -> TRUE | N17: =SUM(N12:N16) -> 165 | O17: “Verdadero” indica que la cantidad por lote, coincide con el saldo que inicia al mes siguiente. "Falso" no coinicide. | T17: =SUM(T12:T16) -> 0
A18: =A12+1 -> 3 | B18: Vacuna de Hepatitis B Recombinante Adultos - Liquida | D18: =+Abril!M18 -> 12 | F18: 7 | J18: =+F18+G18 -> 7 | K18: =+AO18 -> 0 | L18: =+J18+K18 -> 7 | M18: =+(D18+E18)-(L18)+H18-I18 -> 5 | N18: 5 | O18: 0344X002C | Q18: 46539 | R18: =IF(Q18=0," ",IFERROR(IF(DATEDIF(TODAY(),Q18,"M")<=5,"ROJO",IF(DATEDIF(TODAY(),Q18,"M")>=12,"VERDE",IF(AND(DATEDIF(TODAY(),Q18,"M")>=6,DATEDIF(TODAY(),Q18,"M")<=11),"AMARILLO"))),S18)) -> AMARILLO | S18: =IF(Q18=0," ",IF(Q18<=$N$5,"VENCIDO","NO VENCIDO")) -> NO VENCIDO | Y18: =+AT18 -> 0 | AD18: =+AB18+AC18 -> 0 | AO18: =SUM(AD18:AN22) -> 0
R19: =IF(Q19=0," ",IFERROR(IF(DATEDIF(TODAY(),Q19,"M")<=5,"ROJO",IF(DATEDIF(TODAY(),Q19,"M")>=12,"VERDE",IF(AND(DATEDIF(TODAY(),Q19,"M")>=6,DATEDIF(TODAY(),Q19,"M")<=11),"AMARILLO"))),S19)) | S19: =IF(Q19=0," ",IF(Q19<=$N$5,"VENCIDO","NO VENCIDO"))
R20: =IF(Q20=0," ",IFERROR(IF(DATEDIF(TODAY(),Q20,"M")<=5,"ROJO",IF(DATEDIF(TODAY(),Q20,"M")>=12,"VERDE",IF(AND(DATEDIF(TODAY(),Q20,"M")>=6,DATEDIF(TODAY(),Q20,"M")<=11),"AMARILLO"))),S20)) | S20: =IF(Q20=0," ",IF(Q20<=$N$5,"VENCIDO","NO VENCIDO"))
