Workbook

Sheet CLASF. PERDIDAS
A2: CLASIFICACIÓN DE MOTIVOS DE PERDIDAS
A3: MOVIMIENTO DE BIOLÓGICOS (MB) VS PAIWEB
B5: MOTIVO DE PERDIDA MOVIMIENTO DE BIOLÓGICO | C5: MOTIVO DE PERDIDA PAIWEB
A6: 1 | B6: POR FRASCO ABIERTO INSTITUCIONAL | C6: PAI - Política de frascos abiertos intramural (Verificar lo contenido en la Circular 26 del 01 de agosto de 2017).
B7: POR FRASCO ABIERTO EXTRAMURAL | C7: PAI - Política de frasco abierto extramural (Verificar lo contenido en la Circular 26 del 01 de agosto de 2017).
A8: 2 | B8: INTERRUPCIÓN DE CADENA DE FRÍO | C8: PAI - Pérdida de cadena de frío.
C9: PAI - Por excursión temperatura.
C10: PEDIDOS - Interrupción de cadena de frío en el transporte o en el lugar de la recepción.
A11: 3 | B11: CONTAMINACION DEL BIOLÓGICO/DISPOSITIVO MÉDICO | C11: PAI - Contaminación del biológico o dispositivo en la cadena de distribución que no incluya la manipulación (ejemplo: accidente en el transporte que representa que la vacuna se salga de su contenedor sin ruptura, pero si exposición con agentes contaminantes).
A12: 4 | B12: VIAL ROTO | C12: PAI - Frasco vial roto (aplica para viales, jeringas prellenadas y diluyentes)
C13: PEDIDOS - Frasco de biológico roto en recepción (aplica para viales, jeringas prellenadas y diluyentes)
A14: 5 | B14: ERRORES EN LA MANIPULACIÓN | C14: PAI - Derrame de biológico o diluyente en la prepara
C15: PAI - Derrame del biológico o diluyente en la aplición
C16: PAI - Contaminación dispositivo médico x manipulación
C17: PAI - Anulación por error al diligenciamiento
C18: PAI - Error en la dosificación sobre o subdosificación
C19: PAI - Reconstitución de vacuna
C20: PAI - Error en la reconstitución - jeringa
A21: 6 | B21: VENCIMIENTO DEL BIOLÓGICO O JERINGA | C21: PAI - Vencimiento de biológico
C22: PAI - Vencimiento de diluyente
C23: PAI - Vencimiento de jeringa
C24: PAI - Excede días de almacenamiento permitidos por reconstitución del biológico según el laboratorio fabricante.
A25: 7 | B25: FARMACOVIGILANCIA/ TECNOVIGILANCIA | C25: PAI - Defectos de fabricación dispositivos médicos (ejemplo: desprendimiento de agujas, mal sellamiento del embolo, etc.)
C26: PAI - Defectos de fabricación en biológicos
C27: PAI - Por reacción alérgica a biológicos
C28: PAI - Rendimiento menor a la presentación
A29: 8 | B29: VOMITO FRANCO | C29: PAI - Vómito franco por a administración de vacunas por vía oral
A30: 9 | B30: APLICACIÓN FUERA DE LA EDAD | C30: PAI - Aplicación fuera de edad
C31: PAI - Revacunación
A32: 10 | B32: POR DECISIÓN FINAL DEL PACIENTE DE NO VACUNACIÓN | C32: PAI - Reconstitución o alistamiento de la vacuna posterior al diligenciamiento del consentimiento informado con decisión final de no vacunación por parte del paciente o adulto responsable.
C33: PAI - Jeringa o insumo utilizado en la reconstitución o alistamiento de la vacuna en el contexto de este punto.
A34: 11 | B34: SINIESTRO O ROBO | C34: PAI - Robo de biológico
C35: PAI - Robo de jeringa
C36: PAI - Siniestro
A39: MOTIVOS DE PÉRDIDAS DE VACUNAS CONTRA LA COVID-19 RESOLUCIÓN 0986 DEL 21 DE JUNIO DE 2023 DISPONIBLE EN EL SIGUIENTE LINK: chrome-extension://efaidnbmnnnibpcajpcglclefindmkaj/https://www.minsalud.gov.co/Normatividad_Nuevo/Resoluci%C3%B3n%20No.%20986%20de%202023.pdf
A40: MOVIMIENTO DE BIOLÓGICOS (MB) VS PAIWEB
A42: ÍTEM | B42: MOTIVO DE PERDIDA MOVIMIENTO DE BIOLÓGICO | C42: MOTIVO DE PERDIDA PAIWEB
A43: =+[1]Hoja1!$C$3 -> 1 | B43: POLÍTICA DE FRASCOS ABIERTO | C43: Dosis pérdidas de acuerdo con las indicaciones del laboratorio productor en la estrategia intramural o extramural.
A44: =+[1]Hoja1!$C4 -> 2 | B44: INTERRUPCIÓN DE LA CADENA DE FRÍO | C44: Vacuna COVID-19 con concepto técnico de NO USO por parte del INVIMA.
A45: =+[1]Hoja1!$C5 -> 3 | B45: CONTAMINACIÓN DEL BIOLÓGICO | C45: Corresponde a la cantidad de dosis pérdidas debido a que el vial se contaminó durante el proceso de almacenamiento, alistamiento, envasado, aplicación de la vacuna COVID-19, entre otras, inmersión del vial, agujas permanentes insertadas sobre el tapón del frasco, mala manipulación.
...

Sheet Enero
A1: ÍTEM | B1: INSUMOS | D1: SALDO MES ANTERIOR | E1: BIOLÓGICO RECIBIDO DEL CENTRO DE ACOPIO DEPARTAMENTAL / DISTRITAL | F1: DOSIS APLICADAS | H1: Entradas | I1: Salidas | J1: TOTAL DOSIS APLICADAS | K1: DOSIS PERDIDAS | L1: TOTAL DOSIS ÚTILIZADAS EN EL MES | M1: SALDO QUE INICIA EL MES SIGUIENTE (SOLO MUNICIPIOS) | N1: DOSIS POR LOTES | O1: No. LOTE | P1: LABORATORIO | Q1: FECHA DE VENCIMIENTO | R1: SEMAFORIZACION VIDA ÚTIL DEL BIOLÓGICO | S1: CONDICIÓN FINAL DEL BIOLÓGICO, DILUYENTE Y CARNET | T1: DOSIS EN CUARENTENA | U1: LABORATORIO | V1: No. LOTE | W1: FECHA DE VENCIMEINTO | X1: FECHA DE INICIO CUARENTENA | Y1: PORCENTAJE DE PERDIDA DEL MES | Z1: OBSERVACIONES | AB1: CAUSAS PERDIDA DE BIOLÓGICOS (Remítase a la primera hoja donde se especifica la clasificación de las perdidas) | AO1: TOTAL DOSIS PERDIDAS
F2: DOSIS APLICADAS COLOMBIANOS | G2: DOSIS APLICADAS EXTRANJEROS | H2: DOSIS INGRESADAS POR TRASLADOS DE MUNICIPIOS O IPS | I2: DOSIS TRASLADADAS A OTROS MUNICIPIOS O IPS | AB2: 1 | AE2: 2 | AF2: 3 | AG2: 4 | AH2: 5 | AI2: 6 | AJ2: 7 | AK2: 8 | AL2: 9 | AM2: 10 | AN2: 11
AB3: POLÍTICA DE FRASCOS ABIERTO | AE3: INTERRUPCIÓN DE CADENA DE FRÍO | AF3: CONTAMINACION DEL BIOLÓGICO/DISPOSITIVO MÉDICO | AG3: VIAL ROTO | AH3: ERRORES EN LA MANIPULACIÓN | AI3: VENCIMIENTO DEL BIOLÓGICO O JERINGA | AJ3: FARMACOVIGILANCIA / TECNOVIGILANCIA | AK3: VOMITO FRANCO | AL3: APLICACIÓN FUERA DE LA EDAD | AM3: POR DECISIÓN FINAL DEL PACIENTE DE NO VACUNACIÓN | AN3: SINIESTRO O ROBO
AB4: INSTITUCIONAL | AC4: EXTRAMURAL | AD4: TOTAL
A5: 1 | B5: Vacuna de BCG (Bacilo de Calmette y Guérin) Liofilizada | D5: 40 | F5: 1 | J5: =+F5+G5 -> 1 | K5: =+AO5 -> 9 | L5: =+J5+K5 -> 10 | M5: =+(D5+E5)-(L5)+H5-I5 -> 30 | N5: 39 | O5: 0373M117 | P5: SERUM | Q5: 46203 | R5: =IF(Q5=0," ",IFERROR(IF(DATEDIF(TODAY(),Q5,"M")<=5,"ROJO",IF(DATEDIF(TODAY(),Q5,"M")>=12,"VERDE",IF(AND(DATEDIF(TODAY(),Q5,"M")>=6,DATEDIF(TODAY(),Q5,"M")<=11),"AMARILLO"))),S5)) -> NO VENCIDO | S5: =IF(Q5=0," ",IF(Q5<=$N$4,"VENCIDO","NO VENCIDO")) -> NO VENCIDO | Y5: =+AT5 -> 0 | AB5: 9 | AD5: =+AB5+AC5 -> 9 | AO5: =SUM(AD5:AN9) -> 9
R6: =IF(Q6=0," ",IFERROR(IF(DATEDIF(TODAY(),Q6,"M")<=5,"ROJO",IF(DATEDIF(TODAY(),Q6,"M")>=12,"VERDE",IF(AND(DATEDIF(TODAY(),Q6,"M")>=6,DATEDIF(TODAY(),Q6,"M")<=11),"AMARILLO"))),S6)) | S6: =IF(Q6=0," ",IF(Q6<=$N$4,"VENCIDO","NO VENCIDO"))
R7: =IF(Q7=0," ",IFERROR(IF(DATEDIF(TODAY(),Q7,"M")<=5,"ROJO",IF(DATEDIF(TODAY(),Q7,"M")>=12,"VERDE",IF(AND(DATEDIF(TODAY(),Q7,"M")>=6,DATEDIF(TODAY(),Q7,"M")<=11),"AMARILLO"))),S7)) | S7: =IF(Q7=0," ",IF(Q7<=$N$4,"VENCIDO","NO VENCIDO"))
R8: =IF(Q8=0," ",IFERROR(IF(DATEDIF(TODAY(),Q8,"M")<=5,"ROJO",IF(DATEDIF(TODAY(),Q8,"M")>=12,"VERDE",IF(AND(DATEDIF(TODAY(),Q8,"M")>=6,DATEDIF(TODAY(),Q8,"M")<=11),"AMARILLO"))),S8)) | S8: =IF(Q8=0," ",IF(Q8<=$N$4,"VENCIDO","NO VENCIDO"))
R9: =IF(Q9=0," ",IFERROR(IF(DATEDIF(TODAY(),Q9,"M")<=5,"ROJO",IF(DATEDIF(TODAY(),Q9,"M")>=12,"VERDE",IF(AND(DATEDIF(TODAY(),Q9,"M")>=6,DATEDIF(TODAY(),Q9,"M")<=11),"AMARILLO"))),S9)) | S9: =IF(Q9=0," ",IF(Q9<=$N$4,"VENCIDO","NO VENCIDO"))
M10: =M5=N10 -> FALSE | N10: =SUM(N5:N9) -> 39 | O10: “Verdadero” indica que la cantidad por lote, coincide con el saldo que inicia al mes siguiente. "Falso" no coinicide. | T10: =SUM(T5:T9) -> 0
A11: =A5+1 -> 2 | B11: Vacuna de Hepatitis B Recombinante Pediátrica - Liquida | D11: 14 | F11: 0 | J11: =+F11+G11 -> 0 | K11: =+AO11 -> 0 | L11: =+J11+K11 -> 0 | M11: =+(D11+E11)-(L11)+H11-I11 -> 14 | N11: 14 | O11: 0323X019E | P11: SERUM | Q11: 46173 | R11: =IF(Q11=0," ",IFERROR(IF(DATEDIF(TODAY(),Q11,"M")<=5,"ROJO",IF(DATEDIF(TODAY(),Q11,"M")>=12,"VERDE",IF(AND(DATEDIF(TODAY(),Q11,"M")>=6,DATEDIF(TODAY(),Q11,"M")<=11),"AMARILLO"))),S11)) -> NO VENCIDO | S11: =IF(Q11=0," ",IF(Q11<=$N$4,"VENCIDO","NO VENCIDO")) -> NO VENCIDO | Y11: =+AT11 -> 0 | AD11: =+AB11+AC11 -> 0 | AO11: =SUM(AD11:AN15) -> 0
R12: =IF(Q12=0," ",IFERROR(IF(DATEDIF(TODAY(),Q12,"M")<=5,"ROJO",IF(DATEDIF(TODAY(),Q12,"M")>=12,"VERDE",IF(AND(DATEDIF(TODAY(),Q12,"M")>=6,DATEDIF(TODAY(),Q12,"M")<=11),"AMARILLO"))),S12)) | S12: =IF(Q12=0," ",IF(Q12<=$N$4,"VENCIDO","NO VENCIDO"))
R13: =IF(Q13=0," ",IFERROR(IF(DATEDIF(TODAY(),Q13,"M")<=5,"ROJO",IF(DATEDIF(TODAY(),Q13,"M")>=12,"VERDE",IF(AND(DATEDIF(TODAY(),Q13,"M")>=6,DATEDIF(TODAY(),Q13,"M")<=11),"AMARILLO"))),S13)) | S13: =IF(Q13=0," ",IF(Q13<=$N$4,"VENCIDO","NO VENCIDO"))
R14: =IF(Q14=0," ",IFERROR(IF(DATEDIF(TODAY(),Q14,"M")<=5,"ROJO",IF(DATEDIF(TODAY(),Q14,"M")>=12,"VERDE",IF(AND(DATEDIF(TODAY(),Q14,"M")>=6,DATEDIF(TODAY(),Q14,"M")<=11),"AMARILLO"))),S14)) | S14: =IF(Q14=0," ",IF(Q14<=$N$4,"VENCIDO","NO VENCIDO"))
R15: =IF(Q15=0," ",IFERROR(IF(DATEDIF(TODAY(),Q15,"M")<=5,"ROJO",IF(DATEDIF(TODAY(),Q15,"M")>=12,"VERDE",IF(AND(DATEDIF(TODAY(),Q15,"M")>=6,DATEDIF(TODAY(),Q15,"M")<=11),"AMARILLO"))),S15)) | S15: =IF(Q15=0," ",IF(Q15<=$N$4,"VENCIDO","NO VENCIDO"))
M16: =M11=N16 -> TRUE | N16: =SUM(N11:N15) -> 14 | O16: “Verdadero” indica que la cantidad por lote, coincide con el saldo que inicia al mes siguiente. "Falso" no coinicide. | T16: =SUM(T11:T15) -> 0
A17: =A11+1 -> 3 | B17: Vacuna de Hepatitis B Recombinante Adultos - Liquida | D17: 11 | F17: 5 | J17: =+F17+G17 -> 5 | K17: =+AO17 -> 0 | L17: =+J17+K17 -> 5 | M17: =+(D17+E17)-(L17)+H17-I17 -> 6 | N17: 6 | O17: 0343Q010C | P17: SERUM | Q17: 46233 | R17: =IF(Q17=0," ",IFERROR(IF(DATEDIF(TODAY(),Q17,"M")<=5,"ROJO",IF(DATEDIF(TODAY(),Q17,"M")>=12,"VERDE",IF(AND(DATEDIF(TODAY(),Q17,"M")>=6,DATEDIF(TODAY(),Q17,"M")<=11),"AMARILLO"))),S17)) -> NO VENCIDO | S17: =IF(Q17=0," ",IF(Q17<=$N$4,"VENCIDO","NO VENCIDO")) -> NO VENCIDO | Y17: =+AT17 -> 0 | AD17: =+AB17+AC17 -> 0 | AO17: =SUM(AD17:AN21) -> 0
R18: =IF(Q18=0," ",IFERROR(IF(DATEDIF(TODAY(),Q18,"M")<=5,"ROJO",IF(DATEDIF(TODAY(),Q18,"M")>=12,"VERDE",IF(AND(DATEDIF(TODAY(),Q18,"M")>=6,DATEDIF(TODAY(),Q18,"M")<=11),"AMARILLO"))),S18)) | S18: =IF(Q18=0," ",IF(Q18<=$N$4,"VENCIDO","NO VENCIDO"))
R19: =IF(Q19=0," ",IFERROR(IF(DATEDIF(TODAY(),Q19,"M")<=5,"ROJO",IF(DATEDIF(TODAY(),Q19,"M")>=12,"VERDE",IF(AND(DATEDIF(TODAY(),Q19,"M")>=6,DATEDIF(TODAY(),Q19,"M")<=11),"AMARILLO"))),S19)) | S19: =IF(Q19=0," ",IF(Q19<=$N$4,"VENCIDO","NO VENCIDO"))
R20: =IF(Q20=0," ",IFERROR(IF(DATEDIF(TODAY(),Q20,"M")<=5,"ROJO",IF(DATEDIF(TODAY(),Q20,"M")>=12,"VERDE",IF(AND(DATEDIF(TODAY(),Q20,"M")>=6,DATEDIF(TODAY(),Q20,"M")<=11),"AMARILLO"))),S20)) | S20: =IF(Q20=0," ",IF(Q20<=$N$4,"VENCIDO","NO VENCIDO"))
R21: =IF(Q21=0," ",IFERROR(IF(DATEDIF(TODAY(),Q21,"M")<=5,"ROJO",IF(DATEDIF(TODAY(),Q21,"M")>=12,"VERDE",IF(AND(DATEDIF(TODAY(),Q21,"M")>=6,DATEDIF(TODAY(),Q21,"M")<=11),"AMARILLO"))),S21)) | S21: =IF(Q21=0," ",IF(Q21<=$N$4,"VENCIDO","NO VENCIDO"))
M22: =M17=N22 -> TRUE | N22: =SUM(N17:N21) -> 6 | O22: “Verdadero” indica que la cantidad por lote, coincide con el saldo que inicia al mes siguiente. "Falso" no coinicide. | T22: =SUM(T17:T21) -> 0
A23: =A17+1 -> 4 | B23: Vacuna de Poliovirus Inactiva IPV - Liquida | D23: 65 | F23: 30 | J23: =+F23+G23 -> 30 | K23: =+AO23 -> 0 | L23: =+J23+K23 -> 30 | M23: =+(D23+E23)-(L23)+H23-I23 -> 35 | N23: 35 | O23: 2429006 | P23: BILTHOVEN | Q23: 46450 | R23: =IF(Q23=0," ",IFERROR(IF(DATEDIF(TODAY(),Q23,"M")<=5,"ROJO",IF(DATEDIF(TODAY(),Q23,"M")>=12,"VERDE",IF(AND(DATEDIF(TODAY(),Q23,"M")>=6,DATEDIF(TODAY(),Q23,"M")<=11),"AMARILLO"))),S23)) -> ROJO | S23: =IF(Q23=0," ",IF(Q23<=$N$4,"VENCIDO","NO VENCIDO")) -> NO VENCIDO | Y23: =+AT23 -> 0 | AD23: =+AB23+AC23 -> 0 | AO23: =SUM(AD23:AN27) -> 0
R24: =IF(Q24=0," ",IFERROR(IF(DATEDIF(TODAY(),Q24,"M")<=5,"ROJO",IF(DATEDIF(TODAY(),Q24,"M")>=12,"VERDE",IF(AND(DATEDIF(TODAY(),Q24,"M")>=6,DATEDIF(TODAY(),Q24,"M")<=11),"AMARILLO"))),S24)) | S24: =IF(Q24=0," ",IF(Q24<=$N$4,"VENCIDO","NO VENCIDO"))
R25: =IF(Q25=0," ",IFERROR(IF(DATEDIF(TODAY(),Q25,"M")<=5,"ROJO",IF(DATEDIF(TODAY(),Q25,"M")>=12,"VERDE",IF(AND(DATEDIF(TODAY(),Q25,"M")>=6,DATEDIF(TODAY(),Q25,"M")<=11),"AMARILLO"))),S25)) | S25: =IF(Q25=0," ",IF(Q25<=$N$4,"VENCIDO","NO VENCIDO"))
R26: =IF(Q26=0," ",IFERROR(IF(DATEDIF(TODAY(),Q26,"M")<=5,"ROJO",IF(DATEDIF(TODAY(),Q26,"M")>=12,"VERDE",IF(AND(DATEDIF(TODAY(),Q26,"M")>=6,DATEDIF(TODAY(),Q26,"M")<=11),"AMARILLO"))),S26)) | S26: =IF(Q26=0," ",IF(Q26<=$N$4,"VENCIDO","NO VENCIDO"))
R27: =IF(Q27=0," ",IFERROR(IF(DATEDIF(TODAY(),Q27,"M")<=5,"ROJO",IF(DATEDIF(TODAY(),Q27,"M")>=12,"VERDE",IF(AND(DATEDIF(TODAY(),Q27,"M")>=6,DATEDIF(TODAY(),Q27,"M")<=11),"AMARILLO"))),S27)) | S27: =IF(Q27=0," ",IF(Q27<=$N$4,"VENCIDO","NO VENCIDO"))
M28: =M23=N28 -> TRUE | N28: =SUM(N23:N27) -> 35 | O28: “Verdadero” indica que la cantidad por lote, coincide con el saldo que inicia al mes siguiente. "Falso" no coinicide. | T28: =SUM(T23:T27) -> 0
A29: =A23+1 -> 5 | B29: Vacuna de Difteria - Tos ferina (Celula completa) - Tétanos - Hepatitis B - Haemophilus influenzae tipo B (DTwP-HepB-Hib) PENTAVALENTE PEDIÁTRICA - Liquida | D29: 65 | F29: 17 | J29: =+F29+G29 -> 17 | K29: =+AO29 -> 0 | L29: =+J29+K29 -> 17 | M29: =+(D29+E29)-(L29)+H29-I29 -> 48 | N29: 48 | O29: 2854X013E | P29: SERUM | Q29: 46356 | R29: =IF(Q29=0," ",IFERROR(IF(DATEDIF(TODAY(),Q29,"M")<=5,"ROJO",IF(DATEDIF(TODAY(),Q29,"M")>=12,"VERDE",IF(AND(DATEDIF(TODAY(),Q29,"M")>=6,DATEDIF(TODAY(),Q29,"M")<=11),"AMARILLO"))),S29)) -> ROJO | S29: =IF(Q29=0," ",IF(Q29<=$N$4,"VENCIDO","NO VENCIDO")) -> NO VENCIDO | Y29: =+AT29 -> 0 | AD29: =+AB29+AC29 -> 0 | AO29: =SUM(AD29:AN33) -> 0
R30: =IF(Q30=0," ",IFERROR(IF(DATEDIF(TODAY(),Q30,"M")<=5,"ROJO",IF(DATEDIF(TODAY(),Q30,"M")>=12,"VERDE",IF(AND(DATEDIF(TODAY(),Q30,"M")>=6,DATEDIF(TODAY(),Q30,"M")<=11),"AMARILLO"))),S30)) | S30: =IF(Q30=0," ",IF(Q30<=$N$4,"VENCIDO","NO VENCIDO"))
R31: =IF(Q31=0," ",IFERROR(IF(DATEDIF(TODAY(),Q31,"M")<=5,"ROJO",IF(DATEDIF(TODAY(),Q31,"M")>=12,"VERDE",IF(AND(DATEDIF(TODAY(),Q31,"M")>=6,DATEDIF(TODAY(),Q31,"M")<=11),"AMARILLO"))),S31)) | S31: =IF(Q31=0," ",IF(Q31<=$N$4,"VENCIDO","NO VENCIDO"))
R32: =IF(Q32=0," ",IFERROR(IF(DATEDIF(TODAY(),Q32,"M")<=5,"ROJO",IF(DATEDIF(TODAY(),Q32,"M")>=12,"VERDE",IF(AND(DATEDIF(TODAY(),Q32,"M")>=6,DATEDIF(TODAY(),Q32,"M")<=11),"AMARILLO"))),S32)) | S32: =IF(Q32=0," ",IF(Q32<=$N$4,"VENCIDO","NO VENCIDO"))
R33: =IF(Q33=0," ",IFERROR(IF(DATEDIF(TODAY(),Q33,"M")<=5,"ROJO",IF(DATEDIF(TODAY(),Q33,"M")>=12,"VERDE",IF(AND(DATEDIF(TODAY(),Q33,"M")>=6,DATEDIF(TODAY(),Q33,"M")<=11),"AMARILLO"))),S33)) | S33: =IF(Q33=0," ",IF(Q33<=$N$4,"VENCIDO","NO VENCIDO"))
M34: =M29=N34 -> TRUE | N34: =SUM(N29:N33) -> 48 | O34: “Verdadero” indica que la cantidad por lote, coincide con el saldo que inicia al mes siguiente. "Falso" no coinicide. | T34: =SUM(T29:T33) -> 0
A35: =A29+1 -> 6 | B35: Vacuna de Difteria - Tétanos - Tos ferina acelular - Poliovirus inactivado - Hepatitis B - Haemophilus influenzae tipo B (DTaP-IPV-HepB-Hib (HEXAVALENTE ACELULAR) - Liquida | D35: 3 | F35: 0 | J35: =+F35+G35 -> 0 | K35: =+AO35 -> 0 | L35: =+J35+K35 -> 0 | M35: =+(D35+E35)-(L35)+H35-I35 -> 3 | N35: 3 | O35: 4CA03C1 | P35: SANOFI | Q35: 46325 | R35: =IF(Q35=0," ",IFERROR(IF(DATEDIF(TODAY(),Q35,"M")<=5,"ROJO",IF(DATEDIF(TODAY(),Q35,"M")>=12,"VERDE",IF(AND(DATEDIF(TODAY(),Q35,"M")>=6,DATEDIF(TODAY(),Q35,"M")<=11),"AMARILLO"))),S35)) -> ROJO | S35: =IF(Q35=0," ",IF(Q35<=$N$4,"VENCIDO","NO VENCIDO")) -> NO VENCIDO | Y35: =+AT35 -> 0 | AD35: =+AB35+AC35 -> 0 | AO35: =SUM(AD35:AN39) -> 0
R36: =IF(Q36=0," ",IFERROR(IF(DATEDIF(TODAY(),Q36,"M")<=5,"ROJO",IF(DATEDIF(TODAY(),Q36,"M")>=12,"VERDE",IF(AND(DATEDIF(TODAY(),Q36,"M")>=6,DATEDIF(TODAY(),Q36,"M")<=11),"AMARILLO"))),S36)) | S36: =IF(Q36=0," ",IF(Q36<=$N$4,"VENCIDO","NO VENCIDO"))
R37: =IF(Q37=0," ",IFERROR(IF(DATEDIF(TODAY(),Q37,"M")<=5,"ROJO",IF(DATEDIF(TODAY(),Q37,"M")>=12,"VERDE",IF(AND(DATEDIF(TODAY(),Q37,"M")>=6,DATEDIF(TODAY(),Q37,"M")<=11),"AMARILLO"))),S37)) | S37: =IF(Q37=0," ",IF(Q37<=$N$4,"VENCIDO","NO VENCIDO"))
R38: =IF(Q38=0," ",IFERROR(IF(DATEDIF(TODAY(),Q38,"M")<=5,"ROJO",IF(DATEDIF(TODAY(),Q38,"M")>=12,"VERDE",IF(AND(DATEDIF(TODAY(),Q38,"M")>=6,DATEDIF(TODAY(),Q38,"M")<=11),"AMARILLO"))),S38)) | S38: =IF(Q38=0," ",IF(Q38<=$N$4,"VENCIDO","NO VENCIDO"))
R39: =IF(Q39=0," ",IFERROR(IF(DATEDIF(TODAY(),Q39,"M")<=5,"ROJO",IF(DATEDIF(TODAY(),Q39,"M")>=12,"VERDE",IF(AND(DATEDIF(TODAY(),Q39,"M")>=6,DATEDIF(TODAY(),Q39,"M")<=11),"AMARILLO"))),S39)) | S39: =IF(Q39=0," ",IF(Q39<=$N$4,"VENCIDO","NO VENCIDO"))
M40: =M35=N40 -> TRUE | N40: =SUM(N35:N39) -> 3 | O40: “Verdadero” indica que la cantidad por lote, coincide con el saldo que inicia al mes siguiente. "Falso" no coinicide. | T40: =SUM(T35:T39) -> 0
...

Sheet Febrero
A1: ÍTEM | B1: INSUMOS | D1: SALDO MES ANTERIOR | E1: BIOLÓGICO RECIBIDO DEL CENTRO DE ACOPIO DEPARTAMENTAL / DISTRITAL | F1: DOSIS APLICADAS | H1: Entradas | I1: Salidas | J1: TOTAL DOSIS APLICADAS | K1: DOSIS PERDIDAS | L1: TOTAL DOSIS ÚTILIZADAS EN EL MES | M1: SALDO QUE INICIA EL MES SIGUIENTE (SOLO MUNICIPIOS) | N1: DOSIS POR LOTES | O1: No. LOTE | P1: LABORATORIO | Q1: FECHA DE VENCIMIENTO | R1: SEMAFORIZACION VIDA ÚTIL DEL BIOLÓGICO | S1: CONDICIÓN FINAL DEL BIOLÓGICO, DILUYENTE Y CARNET | T1: DOSIS EN CUARENTENA | U1: LABORATORIO | V1: No. LOTE | W1: FECHA DE VENCIMEINTO | X1: FECHA DE INICIO CUARENTENA | Y1: PORCENTAJE DE PERDIDA DEL MES | Z1: OBSERVACIONES | AB1: CAUSAS PERDIDA DE BIOLÓGICOS (Remítase a la primera hoja donde se especifica la clasificación de las perdidas) | AO1: TOTAL DOSIS PERDIDAS
F2: DOSIS APLICADAS COLOMBIANOS | G2: DOSIS APLICADAS EXTRANJEROS | H2: DOSIS INGRESADAS POR TRASLADOS DE MUNICIPIOS O IPS | I2: DOSIS TRASLADADAS A OTROS MUNICIPIOS O IPS | AB2: 1 | AE2: 2 | AF2: 3 | AG2: 4 | AH2: 5 | AI2: 6 | AJ2: 7 | AK2: 8 | AL2: 9 | AM2: 10 | AN2: 11
AB3: POLÍTICA DE FRASCOS ABIERTO | AE3: INTERRUPCIÓN DE CADENA DE FRÍO | AF3: CONTAMINACION DEL BIOLÓGICO/DISPOSITIVO MÉDICO | AG3: VIAL ROTO | AH3: ERRORES EN LA MANIPULACIÓN | AI3: VENCIMIENTO DEL BIOLÓGICO O JERINGA | AJ3: FARMACOVIGILANCIA / TECNOVIGILANCIA | AK3: VOMITO FRANCO | AL3: APLICACIÓN FUERA DE LA EDAD | AM3: POR DECISIÓN FINAL DEL PACIENTE DE NO VACUNACIÓN | AN3: SINIESTRO O ROBO
AB4: INSTITUCIONAL | AC4: EXTRAMURAL | AD4: TOTAL
A5: 1 | B5: Vacuna de BCG (Bacilo de Calmette y Guérin) Liofilizada | D5: =+Enero!M5 -> 30 | F5: 1 | J5: =+F5+G5 -> 1 | K5: =+AO5 -> 9 | L5: =+J5+K5 -> 10 | M5: =+(D5+E5)-(L5)+H5-I5 -> 20 | N5: 20 | O5: 0373M117 | P5: SERUM | Q5: 46203 | R5: =IF(Q5=0," ",IFERROR(IF(DATEDIF(TODAY(),Q5,"M")<=5,"ROJO",IF(DATEDIF(TODAY(),Q5,"M")>=12,"VERDE",IF(AND(DATEDIF(TODAY(),Q5,"M")>=6,DATEDIF(TODAY(),Q5,"M")<=11),"AMARILLO"))),S5)) -> NO VENCIDO | S5: =IF(Q5=0," ",IF(Q5<=$N$4,"VENCIDO","NO VENCIDO")) -> NO VENCIDO | Y5: =+AT5 -> 0 | AB5: 9 | AD5: =+AB5+AC5 -> 9 | AO5: =SUM(AD5:AN9) -> 9
R6: =IF(Q6=0," ",IFERROR(IF(DATEDIF(TODAY(),Q6,"M")<=5,"ROJO",IF(DATEDIF(TODAY(),Q6,"M")>=12,"VERDE",IF(AND(DATEDIF(TODAY(),Q6,"M")>=6,DATEDIF(TODAY(),Q6,"M")<=11),"AMARILLO"))),S6)) | S6: =IF(Q6=0," ",IF(Q6<=$N$4,"VENCIDO","NO VENCIDO"))
R7: =IF(Q7=0," ",IFERROR(IF(DATEDIF(TODAY(),Q7,"M")<=5,"ROJO",IF(DATEDIF(TODAY(),Q7,"M")>=12,"VERDE",IF(AND(DATEDIF(TODAY(),Q7,"M")>=6,DATEDIF(TODAY(),Q7,"M")<=11),"AMARILLO"))),S7)) | S7: =IF(Q7=0," ",IF(Q7<=$N$4,"VENCIDO","NO VENCIDO"))
R8: =IF(Q8=0," ",IFERROR(IF(DATEDIF(TODAY(),Q8,"M")<=5,"ROJO",IF(DATEDIF(TODAY(),Q8,"M")>=12,"VERDE",IF(AND(DATEDIF(TODAY(),Q8,"M")>=6,DATEDIF(TODAY(),Q8,"M")<=11),"AMARILLO"))),S8)) | S8: =IF(Q8=0," ",IF(Q8<=$N$4,"VENCIDO","NO VENCIDO"))
R9: =IF(Q9=0," ",IFERROR(IF(DATEDIF(TODAY(),Q9,"M")<=5,"ROJO",IF(DATEDIF(TODAY(),Q9,"M")>=12,"VERDE",IF(AND(DATEDIF(TODAY(),Q9,"M")>=6,DATEDIF(TODAY(),Q9,"M")<=11),"AMARILLO"))),S9)) | S9: =IF(Q9=0," ",IF(Q9<=$N$4,"VENCIDO","NO VENCIDO"))
M10: =M5=N10 -> TRUE | N10: =SUM(N5:N9) -> 20 | O10: “Verdadero” indica que la cantidad por lote, coincide con el saldo que inicia al mes siguiente. "Falso" no coinicide. | T10: =SUM(T5:T9) -> 0
A11: =A5+1 -> 2 | B11: Vacuna de Hepatitis B Recombinante Pediátrica - Liquida | D11: =+Enero!M11 -> 14 | E11: 10 | J11: =+F11+G11 -> 0 | K11: =+AO11 -> 0 | L11: =+J11+K11 -> 0 | M11: =+(D11+E11)-(L11)+H11-I11 -> 24 | N11: 10 | O11: 0324L013A | P11: SERUM | Q11: 46721 | R11: =IF(Q11=0," ",IFERROR(IF(DATEDIF(TODAY(),Q11,"M")<=5,"ROJO",IF(DATEDIF(TODAY(),Q11,"M")>=12,"VERDE",IF(AND(DATEDIF(TODAY(),Q11,"M")>=6,DATEDIF(TODAY(),Q11,"M")<=11),"AMARILLO"))),S11)) -> VERDE | S11: =IF(Q11=0," ",IF(Q11<=$N$4,"VENCIDO","NO VENCIDO")) -> NO VENCIDO | Y11: =+AT11 -> 0 | AD11: =+AB11+AC11 -> 0 | AO11: =SUM(AD11:AN15) -> 0
N12: 14 | O12: 0323X019E | P12: SERUM | Q12: 46173 | R12: =IF(Q12=0," ",IFERROR(IF(DATEDIF(TODAY(),Q12,"M")<=5,"ROJO",IF(DATEDIF(TODAY(),Q12,"M")>=12,"VERDE",IF(AND(DATEDIF(TODAY(),Q12,"M")>=6,DATEDIF(TODAY(),Q12,"M")<=11),"AMARILLO"))),S12)) -> NO VENCIDO | S12: =IF(Q12=0," ",IF(Q12<=$N$4,"VENCIDO","NO VENCIDO")) -> NO VENCIDO
R13: =IF(Q13=0," ",IFERROR(IF(DATEDIF(TODAY(),Q13,"M")<=5,"ROJO",IF(DATEDIF(TODAY(),Q13,"M")>=12,"VERDE",IF(AND(DATEDIF(TODAY(),Q13,"M")>=6,DATEDIF(TODAY(),Q13,"M")<=11),"AMARILLO"))),S13)) | S13: =IF(Q13=0," ",IF(Q13<=$N$4,"VENCIDO","NO VENCIDO"))
R14: =IF(Q14=0," ",IFERROR(IF(DATEDIF(TODAY(),Q14,"M")<=5,"ROJO",IF(DATEDIF(TODAY(),Q14,"M")>=12,"VERDE",IF(AND(DATEDIF(TODAY(),Q14,"M")>=6,DATEDIF(TODAY(),Q14,"M")<=11),"AMARILLO"))),S14)) | S14: =IF(Q14=0," ",IF(Q14<=$N$4,"VENCIDO","NO VENCIDO"))
R15: =IF(Q15=0," ",IFERROR(IF(DATEDIF(TODAY(),Q15,"M")<=5,"ROJO",IF(DATEDIF(TODAY(),Q15,"M")>=12,"VERDE",IF(AND(DATEDIF(TODAY(),Q15,"M")>=6,DATEDIF(TODAY(),Q15,"M")<=11),"AMARILLO"))),S15)) | S15: =IF(Q15=0," ",IF(Q15<=$N$4,"VENCIDO","NO VENCIDO"))
M16: =M11=N16 -> TRUE | N16: =SUM(N11:N15) -> 24 | O16: “Verdadero” indica que la cantidad por lote, coincide con el saldo que inicia al mes siguiente. "Falso" no coinicide. | T16: =SUM(T11:T15) -> 0
A17: =A11+1 -> 3 | B17: Vacuna de Hepatitis B Recombinante Adultos - Liquida | D17: =+Enero!M17 -> 6 | F17: 5 | J17: =+F17+G17 -> 5 | K17: =+AO17 -> 0 | L17: =+J17+K17 -> 5 | M17: =+(D17+E17)-(L17)+H17-I17 -> 1 | N17: 1 | O17: 0343Q010C | P17: SERUM | Q17: 46233 | R17: =IF(Q17=0," ",IFERROR(IF(DATEDIF(TODAY(),Q17,"M")<=5,"ROJO",IF(DATEDIF(TODAY(),Q17,"M")>=12,"VERDE",IF(AND(DATEDIF(TODAY(),Q17,"M")>=6,DATEDIF(TODAY(),Q17,"M")<=11),"AMARILLO"))),S17)) -> NO VENCIDO | S17: =IF(Q17=0," ",IF(Q17<=$N$4,"VENCIDO","NO VENCIDO")) -> NO VENCIDO | Y17: =+AT17 -> 0 | AD17: =+AB17+AC17 -> 0 | AO17: =SUM(AD17:AN21) -> 0
R18: =IF(Q18=0," ",IFERROR(IF(DATEDIF(TODAY(),Q18,"M")<=5,"ROJO",IF(DATEDIF(TODAY(),Q18,"M")>=12,"VERDE",IF(AND(DATEDIF(TODAY(),Q18,"M")>=6,DATEDIF(TODAY(),Q18,"M")<=11),"AMARILLO"))),S18)) | S18: =IF(Q18=0," ",IF(Q18<=$N$4,"VENCIDO","NO VENCIDO"))
R19: =IF(Q19=0," ",IFERROR(IF(DATEDIF(TODAY(),Q19,"M")<=5,"ROJO",IF(DATEDIF(TODAY(),Q19,"M")>=12,"VERDE",IF(AND(DATEDIF(TODAY(),Q19,"M")>=6,DATEDIF(TODAY(),Q19,"M")<=11),"AMARILLO"))),S19)) | S19: =IF(Q19=0," ",IF(Q19<=$N$4,"VENCIDO","NO VENCIDO"))
R20: =IF(Q20=0," ",IFERROR(IF(DATEDIF(TODAY(),Q20,"M")<=5,"ROJO",IF(DATEDIF(TODAY(),Q20,"M")>=12,"VERDE",IF(AND(DATEDIF(TODAY(),Q20,"M")>=6,DATEDIF(TODAY(),Q20,"M")<=11),"AMARILLO"))),S20)) | S20: =IF(Q20=0," ",IF(Q20<=$N$4,"VENCIDO","NO VENCIDO"))
R21: =IF(Q21=0," ",IFERROR(IF(DATEDIF(TODAY(),Q21,"M")<=5,"ROJO",IF(DATEDIF(TODAY(),Q21,"M")>=12,"VERDE",IF(AND(DATEDIF(TODAY(),Q21,"M")>=6,DATEDIF(TODAY(),Q21,"M")<=11),"AMARILLO"))),S21)) | S21: =IF(Q21=0," ",IF(Q21<=$N$4,"VENCIDO","NO VENCIDO"))
M22: =M17=N22 -> TRUE | N22: =SUM(N17:N21) -> 1 | O22: “Verdadero” indica que la cantidad por lote, coincide con el saldo que inicia al mes siguiente. "Falso" no coinicide. | T22: =SUM(T17:T21) -> 0
A23: =A17+1 -> 4 | B23: Vacuna de Poliovirus Inactiva IPV - Liquida | D23: =+Enero!M23 -> 35 | E23: 50 | F23: 27 | J23: =+F23+G23 -> 27 | K23: =+AO23 -> 0 | L23: =+J23+K23 -> 27 | M23: =+(D23+E23)-(L23)+H23-I23 -> 58 | N23: 8 | O23: 2429006 | P23: BILTHOVEN | Q23: 46450 | R23: =IF(Q23=0," ",IFERROR(IF(DATEDIF(TODAY(),Q23,"M")<=5,"ROJO",IF(DATEDIF(TODAY(),Q23,"M")>=12,"VERDE",IF(AND(DATEDIF(TODAY(),Q23,"M")>=6,DATEDIF(TODAY(),Q23,"M")<=11),"AMARILLO"))),S23)) -> ROJO | S23: =IF(Q23=0," ",IF(Q23<=$N$4,"VENCIDO","NO VENCIDO")) -> NO VENCIDO | Y23: =+AT23 -> 0 | AD23: =+AB23+AC23 -> 0 | AO23: =SUM(AD23:AN27) -> 0
N24: 50 | O24: 2435007 | P24: BILTHOVEN | Q24: 46521 | R24: =IF(Q24=0," ",IFERROR(IF(DATEDIF(TODAY(),Q24,"M")<=5,"ROJO",IF(DATEDIF(TODAY(),Q24,"M")>=12,"VERDE",IF(AND(DATEDIF(TODAY(),Q24,"M")>=6,DATEDIF(TODAY(),Q24,"M")<=11),"AMARILLO"))),S24)) -> AMARILLO | S24: =IF(Q24=0," ",IF(Q24<=$N$4,"VENCIDO","NO VENCIDO")) -> NO VENCIDO
R25: =IF(Q25=0," ",IFERROR(IF(DATEDIF(TODAY(),Q25,"M")<=5,"ROJO",IF(DATEDIF(TODAY(),Q25,"M")>=12,"VERDE",IF(AND(DATEDIF(TODAY(),Q25,"M")>=6,DATEDIF(TODAY(),Q25,"M")<=11),"AMARILLO"))),S25)) | S25: =IF(Q25=0," ",IF(Q25<=$N$4,"VENCIDO","NO VENCIDO"))
R26: =IF(Q26=0," ",IFERROR(IF(DATEDIF(TODAY(),Q26,"M")<=5,"ROJO",IF(DATEDIF(TODAY(),Q26,"M")>=12,"VERDE",IF(AND(DATEDIF(TODAY(),Q26,"M")>=6,DATEDIF(TODAY(),Q26,"M")<=11),"AMARILLO"))),S26)) | S26: =IF(Q26=0," ",IF(Q26<=$N$4,"VENCIDO","NO VENCIDO"))
R27: =IF(Q27=0," ",IFERROR(IF(DATEDIF(TODAY(),Q27,"M")<=5,"ROJO",IF(DATEDIF(TODAY(),Q27,"M")>=12,"VERDE",IF(AND(DATEDIF(TODAY(),Q27,"M")>=6,DATEDIF(TODAY(),Q27,"M")<=11),"AMARILLO"))),S27)) | S27: =IF(Q27=0," ",IF(Q27<=$N$4,"VENCIDO","NO VENCIDO"))
M28: =M23=N28 -> TRUE | N28: =SUM(N23:N27) -> 58 | O28: “Verdadero” indica que la cantidad por lote, coincide con el saldo que inicia al mes siguiente. "Falso" no coinicide. | T28: =SUM(T23:T27) -> 0
A29: =A23+1 -> 5 | B29: Vacuna de Difteria - Tos ferina (Celula completa) - Tétanos - Hepatitis B - Haemophilus influenzae tipo B (DTwP-HepB-Hib) PENTAVALENTE PEDIÁTRICA - Liquida | D29: =+Enero!M29 -> 48 | F29: 19 | J29: =+F29+G29 -> 19 | K29: =+AO29 -> 0 | L29: =+J29+K29 -> 19 | M29: =+(D29+E29)-(L29)+H29-I29 -> 29 | N29: 29 | O29: 2854X013E | P29: SERUM | Q29: 46356 | R29: =IF(Q29=0," ",IFERROR(IF(DATEDIF(TODAY(),Q29,"M")<=5,"ROJO",IF(DATEDIF(TODAY(),Q29,"M")>=12,"VERDE",IF(AND(DATEDIF(TODAY(),Q29,"M")>=6,DATEDIF(TODAY(),Q29,"M")<=11),"AMARILLO"))),S29)) -> ROJO | S29: =IF(Q29=0," ",IF(Q29<=$N$4,"VENCIDO","NO VENCIDO")) -> NO VENCIDO | Y29: =+AT29 -> 0 | AD29: =+AB29+AC29 -> 0 | AO29: =SUM(AD29:AN33) -> 0
R30: =IF(Q30=0," ",IFERROR(IF(DATEDIF(TODAY(),Q30,"M")<=5,"ROJO",IF(DATEDIF(TODAY(),Q30,"M")>=12,"VERDE",IF(AND(DATEDIF(TODAY(),Q30,"M")>=6,DATEDIF(TODAY(),Q30,"M")<=11),"AMARILLO"))),S30)) | S30: =IF(Q30=0," ",IF(Q30<=$N$4,"VENCIDO","NO VENCIDO"))
R31: =IF(Q31=0," ",IFERROR(IF(DATEDIF(TODAY(),Q31,"M")<=5,"ROJO",IF(DATEDIF(TODAY(),Q31,"M")>=12,"VERDE",IF(AND(DATEDIF(TODAY(),Q31,"M")>=6,DATEDIF(TODAY(),Q31,"M")<=11),"AMARILLO"))),S31)) | S31: =IF(Q31=0," ",IF(Q31<=$N$4,"VENCIDO","NO VENCIDO"))
R32: =IF(Q32=0," ",IFERROR(IF(DATEDIF(TODAY(),Q32,"M")<=5,"ROJO",IF(DATEDIF(TODAY(),Q32,"M")>=12,"VERDE",IF(AND(DATEDIF(TODAY(),Q32,"M")>=6,DATEDIF(TODAY(),Q32,"M")<=11),"AMARILLO"))),S32)) | S32: =IF(Q32=0," ",IF(Q32<=$N$4,"VENCIDO","NO VENCIDO"))
R33: =IF(Q33=0," ",IFERROR(IF(DATEDIF(TODAY(),Q33,"M")<=5,"ROJO",IF(DATEDIF(TODAY(),Q33,"M")>=12,"VERDE",IF(AND(DATEDIF(TODAY(),Q33,"M")>=6,DATEDIF(TODAY(),Q33,"M")<=11),"AMARILLO"))),S33)) | S33: =IF(Q33=0," ",IF(Q33<=$N$4,"VENCIDO","NO VENCIDO"))
M34: =M29=N34 -> TRUE | N34: =SUM(N29:N33) -> 29 | O34: “Verdadero” indica que la cantidad por lote, coincide con el saldo que inicia al mes siguiente. "Falso" no coinicide. | T34: =SUM(T29:T33) -> 0
A35: =A29+1 -> 6 | B35: Vacuna de Difteria - Tétanos - Tos ferina acelular - Poliovirus inactivado - Hepatitis B - Haemophilus influenzae tipo B (DTaP-IPV-HepB-Hib (HEXAVALENTE ACELULAR) - Liquida | D35: =+Enero!M35 -> 3 | J35: =+F35+G35 -> 0 | K35: =+AO35 -> 0 | L35: =+J35+K35 -> 0 | M35: =+(D35+E35)-(L35)+H35-I35 -> 3 | N35: 3 | O35: 4CA03C1 | P35: SANOFI | Q35: 46325 | R35: =IF(Q35=0," ",IFERROR(IF(DATEDIF(TODAY(),Q35,"M")<=5,"ROJO",IF(DATEDIF(TODAY(),Q35,"M")>=12,"VERDE",IF(AND(DATEDIF(TODAY(),Q35,"M")>=6,DATEDIF(TODAY(),Q35,"M")<=11),"AMARILLO"))),S35)) -> ROJO | S35: =IF(Q35=0," ",IF(Q35<=$N$4,"VENCIDO","NO VENCIDO")) -> NO VENCIDO | Y35: =+AT35 -> 0 | AD35: =+AB35+AC35 -> 0 | AO35: =SUM(AD35:AN39) -> 0
R36: =IF(Q36=0," ",IFERROR(IF(DATEDIF(TODAY(),Q36,"M")<=5,"ROJO",IF(DATEDIF(TODAY(),Q36,"M")>=12,"VERDE",IF(AND(DATEDIF(TODAY(),Q36,"M")>=6,DATEDIF(TODAY(),Q36,"M")<=11),"AMARILLO"))),S36)) | S36: =IF(Q36=0," ",IF(Q36<=$N$4,"VENCIDO","NO VENCIDO"))
R37: =IF(Q37=0," ",IFERROR(IF(DATEDIF(TODAY(),Q37,"M")<=5,"ROJO",IF(DATEDIF(TODAY(),Q37,"M")>=12,"VERDE",IF(AND(DATEDIF(TODAY(),Q37,"M")>=6,DATEDIF(TODAY(),Q37,"M")<=11),"AMARILLO"))),S37)) | S37: =IF(Q37=0," ",IF(Q37<=$N$4,"VENCIDO","NO VENCIDO"))
R38: =IF(Q38=0," ",IFERROR(IF(DATEDIF(TODAY(),Q38,"M")<=5,"ROJO",IF(DATEDIF(TODAY(),Q38,"M")>=12,"VERDE",IF(AND(DATEDIF(TODAY(),Q38,"M")>=6,DATEDIF(TODAY(),Q38,"M")<=11),"AMARILLO"))),S38)) | S38: =IF(Q38=0," ",IF(Q38<=$N$4,"VENCIDO","NO VENCIDO"))
R39: =IF(Q39=0," ",IFERROR(IF(DATEDIF(TODAY(),Q39,"M")<=5,"ROJO",IF(DATEDIF(TODAY(),Q39,"M")>=12,"VERDE",IF(AND(DATEDIF(TODAY(),Q39,"M")>=6,DATEDIF(TODAY(),Q39,"M")<=11),"AMARILLO"))),S39)) | S39: =IF(Q39=0," ",IF(Q39<=$N$4,"VENCIDO","NO VENCIDO"))
M40: =M35=N40 -> TRUE | N40: =SUM(N35:N39) -> 3 | O40: “Verdadero” indica que la cantidad por lote, coincide con el saldo que inicia al mes siguiente. "Falso" no coinicide. | T40: =SUM(T35:T39) -> 0
...

Sheet Marzo
A1: ÍTEM | B1: INSUMOS | D1: SALDO MES ANTERIOR | E1: BIOLÓGICO RECIBIDO DEL CENTRO DE ACOPIO DEPARTAMENTAL / DISTRITAL | F1: DOSIS APLICADAS | H1: Entradas | I1: Salidas | J1: TOTAL DOSIS APLICADAS | K1: DOSIS PERDIDAS | L1: TOTAL DOSIS ÚTILIZADAS EN EL MES | M1: SALDO QUE INICIA EL MES SIGUIENTE (SOLO MUNICIPIOS) | N1: DOSIS POR LOTES | O1: No. LOTE | P1: LABORATORIO | Q1: FECHA DE VENCIMIENTO | R1: SEMAFORIZACION VIDA ÚTIL DEL BIOLÓGICO | S1: CONDICIÓN FINAL DEL BIOLÓGICO, DILUYENTE Y CARNET | T1: DOSIS EN CUARENTENA | U1: LABORATORIO | V1: No. LOTE | W1: FECHA DE VENCIMEINTO | X1: FECHA DE INICIO CUARENTENA | Y1: PORCENTAJE DE PERDIDA DEL MES | Z1: OBSERVACIONES | AB1: CAUSAS PERDIDA DE BIOLÓGICOS (Remítase a la primera hoja donde se especifica la clasificación de las perdidas) | AO1: TOTAL DOSIS PERDIDAS
F2: DOSIS APLICADAS COLOMBIANOS | G2: DOSIS APLICADAS EXTRANJEROS | H2: DOSIS INGRESADAS POR TRASLADOS DE MUNICIPIOS O IPS | I2: DOSIS TRASLADADAS A OTROS MUNICIPIOS O IPS | AB2: 1 | AE2: 2 | AF2: 3 | AG2: 4 | AH2: 5 | AI2: 6 | AJ2: 7 | AK2: 8 | AL2: 9 | AM2: 10 | AN2: 11
AB3: POLÍTICA DE FRASCOS ABIERTO | AE3: INTERRUPCIÓN DE CADENA DE FRÍO | AF3: CONTAMINACION DEL BIOLÓGICO/DISPOSITIVO MÉDICO | AG3: VIAL ROTO | AH3: ERRORES EN LA MANIPULACIÓN | AI3: VENCIMIENTO DEL BIOLÓGICO O JERINGA | AJ3: FARMACOVIGILANCIA / TECNOVIGILANCIA | AK3: VOMITO FRANCO | AL3: APLICACIÓN FUERA DE LA EDAD | AM3: POR DECISIÓN FINAL DEL PACIENTE DE NO VACUNACIÓN | AN3: SINIESTRO O ROBO
AB4: INSTITUCIONAL | AC4: EXTRAMURAL | AD4: TOTAL
A5: 1 | B5: Vacuna de BCG (Bacilo de Calmette y Guérin) Liofilizada | D5: =+Febrero!M5 -> 20 | E5: 0 | F5: 1 | J5: =+F5+G5 -> 1 | K5: =+AO5 -> 9 | L5: =+J5+K5 -> 10 | M5: =+(D5+E5)-(L5)+H5-I5 -> 10 | N5: 10 | O5: 0373M117 | P5: SERUM | Q5: 46203 | R5: =IF(Q5=0," ",IFERROR(IF(DATEDIF(TODAY(),Q5,"M")<=5,"ROJO",IF(DATEDIF(TODAY(),Q5,"M")>=12,"VERDE",IF(AND(DATEDIF(TODAY(),Q5,"M")>=6,DATEDIF(TODAY(),Q5,"M")<=11),"AMARILLO"))),S5)) -> NO VENCIDO | S5: =IF(Q5=0," ",IF(Q5<=$N$4,"VENCIDO","NO VENCIDO")) -> NO VENCIDO | Y5: =+AT5 -> 0 | AB5: 9 | AD5: =+AB5+AC5 -> 9 | AO5: =SUM(AD5:AN9) -> 9
R6: =IF(Q6=0," ",IFERROR(IF(DATEDIF(TODAY(),Q6,"M")<=5,"ROJO",IF(DATEDIF(TODAY(),Q6,"M")>=12,"VERDE",IF(AND(DATEDIF(TODAY(),Q6,"M")>=6,DATEDIF(TODAY(),Q6,"M")<=11),"AMARILLO"))),S6)) | S6: =IF(Q6=0," ",IF(Q6<=$N$4,"VENCIDO","NO VENCIDO"))
R7: =IF(Q7=0," ",IFERROR(IF(DATEDIF(TODAY(),Q7,"M")<=5,"ROJO",IF(DATEDIF(TODAY(),Q7,"M")>=12,"VERDE",IF(AND(DATEDIF(TODAY(),Q7,"M")>=6,DATEDIF(TODAY(),Q7,"M")<=11),"AMARILLO"))),S7)) | S7: =IF(Q7=0," ",IF(Q7<=$N$4,"VENCIDO","NO VENCIDO"))
R8: =IF(Q8=0," ",IFERROR(IF(DATEDIF(TODAY(),Q8,"M")<=5,"ROJO",IF(DATEDIF(TODAY(),Q8,"M")>=12,"VERDE",IF(AND(DATEDIF(TODAY(),Q8,"M")>=6,DATEDIF(TODAY(),Q8,"M")<=11),"AMARILLO"))),S8)) | S8: =IF(Q8=0," ",IF(Q8<=$N$4,"VENCIDO","NO VENCIDO"))
R9: =IF(Q9=0," ",IFERROR(IF(DATEDIF(TODAY(),Q9,"M")<=5,"ROJO",IF(DATEDIF(TODAY(),Q9,"M")>=12,"VERDE",IF(AND(DATEDIF(TODAY(),Q9,"M")>=6,DATEDIF(TODAY(),Q9,"M")<=11),"AMARILLO"))),S9)) | S9: =IF(Q9=0," ",IF(Q9<=$N$4,"VENCIDO","NO VENCIDO"))
M10: =M5=N10 -> TRUE | N10: =SUM(N5:N9) -> 10 | O10: “Verdadero” indica que la cantidad por lote, coincide con el saldo que inicia al mes siguiente. "Falso" no coinicide. | T10: =SUM(T5:T9) -> 0
A11: =A5+1 -> 2 | B11: Vacuna de Hepatitis B Recombinante Pediátrica - Liquida | D11: =+Febrero!M11 -> 24 | E11: 0 | F11: 1 | J11: =+F11+G11 -> 1 | K11: =+AO11 -> 0 | L11: =+J11+K11 -> 1 | M11: =+(D11+E11)-(L11)+H11-I11 -> 23 | N11: 10 | O11: 0324L013A | P11: SERUM | Q11: 46721 | R11: =IF(Q11=0," ",IFERROR(IF(DATEDIF(TODAY(),Q11,"M")<=5,"ROJO",IF(DATEDIF(TODAY(),Q11,"M")>=12,"VERDE",IF(AND(DATEDIF(TODAY(),Q11,"M")>=6,DATEDIF(TODAY(),Q11,"M")<=11),"AMARILLO"))),S11)) -> VERDE | S11: =IF(Q11=0," ",IF(Q11<=$N$4,"VENCIDO","NO VENCIDO")) -> NO VENCIDO | Y11: =+AT11 -> 0 | AD11: =+AB11+AC11 -> 0 | AO11: =SUM(AD11:AN15) -> 0
N12: 13 | O12: 0323X019E | P12: SERUM | Q12: 46173 | R12: =IF(Q12=0," ",IFERROR(IF(DATEDIF(TODAY(),Q12,"M")<=5,"ROJO",IF(DATEDIF(TODAY(),Q12,"M")>=12,"VERDE",IF(AND(DATEDIF(TODAY(),Q12,"M")>=6,DATEDIF(TODAY(),Q12,"M")<=11),"AMARILLO"))),S12)) -> NO VENCIDO | S12: =IF(Q12=0," ",IF(Q12<=$N$4,"VENCIDO","NO VENCIDO")) -> NO VENCIDO
R13: =IF(Q13=0," ",IFERROR(IF(DATEDIF(TODAY(),Q13,"M")<=5,"ROJO",IF(DATEDIF(TODAY(),Q13,"M")>=12,"VERDE",IF(AND(DATEDIF(TODAY(),Q13,"M")>=6,DATEDIF(TODAY(),Q13,"M")<=11),"AMARILLO"))),S13)) | S13: =IF(Q13=0," ",IF(Q13<=$N$4,"VENCIDO","NO VENCIDO"))
R14: =IF(Q14=0," ",IFERROR(IF(DATEDIF(TODAY(),Q14,"M")<=5,"ROJO",IF(DATEDIF(TODAY(),Q14,"M")>=12,"VERDE",IF(AND(DATEDIF(TODAY(),Q14,"M")>=6,DATEDIF(TODAY(),Q14,"M")<=11),"AMARILLO"))),S14)) | S14: =IF(Q14=0," ",IF(Q14<=$N$4,"VENCIDO","NO VENCIDO"))
R15: =IF(Q15=0," ",IFERROR(IF(DATEDIF(TODAY(),Q15,"M")<=5,"ROJO",IF(DATEDIF(TODAY(),Q15,"M")>=12,"VERDE",IF(AND(DATEDIF(TODAY(),Q15,"M")>=6,DATEDIF(TODAY(),Q15,"M")<=11),"AMARILLO"))),S15)) | S15: =IF(Q15=0," ",IF(Q15<=$N$4,"VENCIDO","NO VENCIDO"))
M16: =M11=N16 -> TRUE | N16: =SUM(N11:N15) -> 23 | O16: “Verdadero” indica que la cantidad por lote, coincide con el saldo que inicia al mes siguiente. "Falso" no coinicide. | T16: =SUM(T11:T15) -> 0
A17: =A11+1 -> 3 | B17: Vacuna de Hepatitis B Recombinante Adultos - Liquida | D17: =+Febrero!M17 -> 1 | E17: 0 | F17: 1 | J17: =+F17+G17 -> 1 | K17: =+AO17 -> 0 | L17: =+J17+K17 -> 1 | M17: =+(D17+E17)-(L17)+H17-I17 -> 0 | R17: =IF(Q17=0," ",IFERROR(IF(DATEDIF(TODAY(),Q17,"M")<=5,"ROJO",IF(DATEDIF(TODAY(),Q17,"M")>=12,"VERDE",IF(AND(DATEDIF(TODAY(),Q17,"M")>=6,DATEDIF(TODAY(),Q17,"M")<=11),"AMARILLO"))),S17)) | S17: =IF(Q17=0," ",IF(Q17<=$N$4,"VENCIDO","NO VENCIDO")) | Y17: =+AT17 -> 0 | AD17: =+AB17+AC17 -> 0 | AO17: =SUM(AD17:AN21) -> 0
R18: =IF(Q18=0," ",IFERROR(IF(DATEDIF(TODAY(),Q18,"M")<=5,"ROJO",IF(DATEDIF(TODAY(),Q18,"M")>=12,"VERDE",IF(AND(DATEDIF(TODAY(),Q18,"M")>=6,DATEDIF(TODAY(),Q18,"M")<=11),"AMARILLO"))),S18)) | S18: =IF(Q18=0," ",IF(Q18<=$N$4,"VENCIDO","NO VENCIDO"))
R19: =IF(Q19=0," ",IFERROR(IF(DATEDIF(TODAY(),Q19,"M")<=5,"ROJO",IF(DATEDIF(TODAY(),Q19,"M")>=12,"VERDE",IF(AND(DATEDIF(TODAY(),Q19,"M")>=6,DATEDIF(TODAY(),Q19,"M")<=11),"AMARILLO"))),S19)) | S19: =IF(Q19=0," ",IF(Q19<=$N$4,"VENCIDO","NO VENCIDO"))
R20: =IF(Q20=0," ",IFERROR(IF(DATEDIF(TODAY(),Q20,"M")<=5,"ROJO",IF(DATEDIF(TODAY(),Q20,"M")>=12,"VERDE",IF(AND(DATEDIF(TODAY(),Q20,"M")>=6,DATEDIF(TODAY(),Q20,"M")<=11),"AMARILLO"))),S20)) | S20: =IF(Q20=0," ",IF(Q20<=$N$4,"VENCIDO","NO VENCIDO"))
R21: =IF(Q21=0," ",IFERROR(IF(DATEDIF(TODAY(),Q21,"M")<=5,"ROJO",IF(DATEDIF(TODAY(),Q21,"M")>=12,"VERDE",IF(AND(DATEDIF(TODAY(),Q21,"M")>=6,DATEDIF(TODAY(),Q21,"M")<=11),"AMARILLO"))),S21)) | S21: =IF(Q21=0," ",IF(Q21<=$N$4,"VENCIDO","NO VENCIDO"))
M22: =M17=N22 -> TRUE | N22: =SUM(N17:N21) -> 0 | O22: “Verdadero” indica que la cantidad por lote, coincide con el saldo que inicia al mes siguiente. "Falso" no coinicide. | T22: =SUM(T17:T21) -> 0
A23: =A17+1 -> 4 | B23: Vacuna de Poliovirus Inactiva IPV - Liquida | D23: =+Febrero!M23 -> 58 | E23: 0 | F23: 32 | J23: =+F23+G23 -> 32 | K23: =+AO23 -> 0 | L23: =+J23+K23 -> 32 | M23: =+(D23+E23)-(L23)+H23-I23 -> 26 | N23: 26 | O23: 2435007 | P23: BILTHOVEN | Q23: 46521 | R23: =IF(Q23=0," ",IFERROR(IF(DATEDIF(TODAY(),Q23,"M")<=5,"ROJO",IF(DATEDIF(TODAY(),Q23,"M")>=12,"VERDE",IF(AND(DATEDIF(TODAY(),Q23,"M")>=6,DATEDIF(TODAY(),Q23,"M")<=11),"AMARILLO"))),S23)) -> AMARILLO | S23: =IF(Q23=0," ",IF(Q23<=$N$4,"VENCIDO","NO VENCIDO")) -> NO VENCIDO | Y23: =+AT23 -> 0 | AD23: =+AB23+AC23 -> 0 | AO23: =SUM(AD23:AN27) -> 0
R24: =IF(Q24=0," ",IFERROR(IF(DATEDIF(TODAY(),Q24,"M")<=5,"ROJO",IF(DATEDIF(TODAY(),Q24,"M")>=12,"VERDE",IF(AND(DATEDIF(TODAY(),Q24,"M")>=6,DATEDIF(TODAY(),Q24,"M")<=11),"AMARILLO"))),S24)) | S24: =IF(Q24=0," ",IF(Q24<=$N$4,"VENCIDO","NO VENCIDO"))
R25: =IF(Q25=0," ",IFERROR(IF(DATEDIF(TODAY(),Q25,"M")<=5,"ROJO",IF(DATEDIF(TODAY(),Q25,"M")>=12,"VERDE",IF(AND(DATEDIF(TODAY(),Q25,"M")>=6,DATEDIF(TODAY(),Q25,"M")<=11),"AMARILLO"))),S25)) | S25: =IF(Q25=0," ",IF(Q25<=$N$4,"VENCIDO","NO VENCIDO"))
R26: =IF(Q26=0," ",IFERROR(IF(DATEDIF(TODAY(),Q26,"M")<=5,"ROJO",IF(DATEDIF(TODAY(),Q26,"M")>=12,"VERDE",IF(AND(DATEDIF(TODAY(),Q26,"M")>=6,DATEDIF(TODAY(),Q26,"M")<=11),"AMARILLO"))),S26)) | S26: =IF(Q26=0," ",IF(Q26<=$N$4,"VENCIDO","NO VENCIDO"))
R27: =IF(Q27=0," ",IFERROR(IF(DATEDIF(TODAY(),Q27,"M")<=5,"ROJO",IF(DATEDIF(TODAY(),Q27,"M")>=12,"VERDE",IF(AND(DATEDIF(TODAY(),Q27,"M")>=6,DATEDIF(TODAY(),Q27,"M")<=11),"AMARILLO"))),S27)) | S27: =IF(Q27=0," ",IF(Q27<=$N$4,"VENCIDO","NO VENCIDO"))
M28: =M23=N28 -> TRUE | N28: =SUM(N23:N27) -> 26 | O28: “Verdadero” indica que la cantidad por lote, coincide con el saldo que inicia al mes siguiente. "Falso" no coinicide. | T28: =SUM(T23:T27) -> 0
A29: =A23+1 -> 5 | B29: Vacuna de Difteria - Tos ferina (Celula completa) - Tétanos - Hepatitis B - Haemophilus influenzae tipo B (DTwP-HepB-Hib) PENTAVALENTE PEDIÁTRICA - Liquida | D29: =+Febrero!M29 -> 29 | E29: 10 | F29: 25 | J29: =+F29+G29 -> 25 | K29: =+AO29 -> 0 | L29: =+J29+K29 -> 25 | M29: =+(D29+E29)-(L29)+H29-I29 -> 14 | N29: 4 | O29: 2854X013E | P29: SERUM | Q29: 46356 | R29: =IF(Q29=0," ",IFERROR(IF(DATEDIF(TODAY(),Q29,"M")<=5,"ROJO",IF(DATEDIF(TODAY(),Q29,"M")>=12,"VERDE",IF(AND(DATEDIF(TODAY(),Q29,"M")>=6,DATEDIF(TODAY(),Q29,"M")<=11),"AMARILLO"))),S29)) -> ROJO | S29: =IF(Q29=0," ",IF(Q29<=$N$4,"VENCIDO","NO VENCIDO")) -> NO VENCIDO | Y29: =+AT29 -> 0 | AD29: =+AB29+AC29 -> 0 | AO29: =SUM(AD29:AN33) -> 0
N30: 10 | O30: 2855X001A | P30: SERUM | Q30: 46568 | R30: =IF(Q30=0," ",IFERROR(IF(DATEDIF(TODAY(),Q30,"M")<=5,"ROJO",IF(DATEDIF(TODAY(),Q30,"M")>=12,"VERDE",IF(AND(DATEDIF(TODAY(),Q30,"M")>=6,DATEDIF(TODAY(),Q30,"M")<=11),"AMARILLO"))),S30)) -> AMARILLO | S30: =IF(Q30=0," ",IF(Q30<=$N$4,"VENCIDO","NO VENCIDO")) -> NO VENCIDO
R31: =IF(Q31=0," ",IFERROR(IF(DATEDIF(TODAY(),Q31,"M")<=5,"ROJO",IF(DATEDIF(TODAY(),Q31,"M")>=12,"VERDE",IF(AND(DATEDIF(TODAY(),Q31,"M")>=6,DATEDIF(TODAY(),Q31,"M")<=11),"AMARILLO"))),S31)) | S31: =IF(Q31=0," ",IF(Q31<=$N$4,"VENCIDO","NO VENCIDO"))
R32: =IF(Q32=0," ",IFERROR(IF(DATEDIF(TODAY(),Q32,"M")<=5,"ROJO",IF(DATEDIF(TODAY(),Q32,"M")>=12,"VERDE",IF(AND(DATEDIF(TODAY(),Q32,"M")>=6,DATEDIF(TODAY(),Q32,"M")<=11),"AMARILLO"))),S32)) | S32: =IF(Q32=0," ",IF(Q32<=$N$4,"VENCIDO","NO VENCIDO"))
R33: =IF(Q33=0," ",IFERROR(IF(DATEDIF(TODAY(),Q33,"M")<=5,"ROJO",IF(DATEDIF(TODAY(),Q33,"M")>=12,"VERDE",IF(AND(DATEDIF(TODAY(),Q33,"M")>=6,DATEDIF(TODAY(),Q33,"M")<=11),"AMARILLO"))),S33)) | S33: =IF(Q33=0," ",IF(Q33<=$N$4,"VENCIDO","NO VENCIDO"))
M34: =M29=N34 -> TRUE | N34: =SUM(N29:N33) -> 14 | O34: “Verdadero” indica que la cantidad por lote, coincide con el saldo que inicia al mes siguiente. "Falso" no coinicide. | T34: =SUM(T29:T33) -> 0
A35: =A29+1 -> 6 | B35: Vacuna de Difteria - Tétanos - Tos ferina acelular - Poliovirus inactivado - Hepatitis B - Haemophilus influenzae tipo B (DTaP-IPV-HepB-Hib (HEXAVALENTE ACELULAR) - Liquida | D35: =+Febrero!M35 -> 3 | E35: 0 | F35: 0 | J35: =+F35+G35 -> 0 | K35: =+AO35 -> 0 | L35: =+J35+K35 -> 0 | M35: =+(D35+E35)-(L35)+H35-I35 -> 3 | N35: 3 | O35: 4CA03C1 | P35: SANOFI | Q35: 46325 | R35: =IF(Q35=0," ",IFERROR(IF(DATEDIF(TODAY(),Q35,"M")<=5,"ROJO",IF(DATEDIF(TODAY(),Q35,"M")>=12,"VERDE",IF(AND(DATEDIF(TODAY(),Q35,"M")>=6,DATEDIF(TODAY(),Q35,"M")<=11),"AMARILLO"))),S35)) -> ROJO | S35: =IF(Q35=0," ",IF(Q35<=$N$4,"VENCIDO","NO VENCIDO")) -> NO VENCIDO | Y35: =+AT35 -> 0 | AD35: =+AB35+AC35 -> 0 | AO35: =SUM(AD35:AN39) -> 0
R36: =IF(Q36=0," ",IFERROR(IF(DATEDIF(TODAY(),Q36,"M")<=5,"ROJO",IF(DATEDIF(TODAY(),Q36,"M")>=12,"VERDE",IF(AND(DATEDIF(TODAY(),Q36,"M")>=6,DATEDIF(TODAY(),Q36,"M")<=11),"AMARILLO"))),S36)) | S36: =IF(Q36=0," ",IF(Q36<=$N$4,"VENCIDO","NO VENCIDO"))
R37: =IF(Q37=0," ",IFERROR(IF(DATEDIF(TODAY(),Q37,"M")<=5,"ROJO",IF(DATEDIF(TODAY(),Q37,"M")>=12,"VERDE",IF(AND(DATEDIF(TODAY(),Q37,"M")>=6,DATEDIF(TODAY(),Q37,"M")<=11),"AMARILLO"))),S37)) | S37: =IF(Q37=0," ",IF(Q37<=$N$4,"VENCIDO","NO VENCIDO"))
R38: =IF(Q38=0," ",IFERROR(IF(DATEDIF(TODAY(),Q38,"M")<=5,"ROJO",IF(DATEDIF(TODAY(),Q38,"M")>=12,"VERDE",IF(AND(DATEDIF(TODAY(),Q38,"M")>=6,DATEDIF(TODAY(),Q38,"M")<=11),"AMARILLO"))),S38)) | S38: =IF(Q38=0," ",IF(Q38<=$N$4,"VENCIDO","NO VENCIDO"))
R39: =IF(Q39=0," ",IFERROR(IF(DATEDIF(TODAY(),Q39,"M")<=5,"ROJO",IF(DATEDIF(TODAY(),Q39,"M")>=12,"VERDE",IF(AND(DATEDIF(TODAY(),Q39,"M")>=6,DATEDIF(TODAY(),Q39,"M")<=11),"AMARILLO"))),S39)) | S39: =IF(Q39=0," ",IF(Q39<=$N$4,"VENCIDO","NO VENCIDO"))
M40: =M35=N40 -> TRUE | N40: =SUM(N35:N39) -> 3 | O40: “Verdadero” indica que la cantidad por lote, coincide con el saldo que inicia al mes siguiente. "Falso" no coinicide. | T40: =SUM(T35:T39) -> 0
...

Sheet Abril
A1: ÍTEM | B1: INSUMOS | D1: SALDO MES ANTERIOR | E1: BIOLÓGICO RECIBIDO DEL CENTRO DE ACOPIO DEPARTAMENTAL / DISTRITAL | F1: DOSIS APLICADAS | H1: Entradas | I1: Salidas | J1: TOTAL DOSIS APLICADAS | K1: DOSIS PERDIDAS | L1: TOTAL DOSIS ÚTILIZADAS EN EL MES | M1: SALDO QUE INICIA EL MES SIGUIENTE (SOLO MUNICIPIOS) | N1: DOSIS POR LOTES | O1: No. LOTE | P1: LABORATORIO | Q1: FECHA DE VENCIMIENTO | R1: SEMAFORIZACION VIDA ÚTIL DEL BIOLÓGICO | S1: CONDICIÓN FINAL DEL BIOLÓGICO, DILUYENTE Y CARNET | T1: DOSIS EN CUARENTENA | U1: LABORATORIO | V1: No. LOTE | W1: FECHA DE VENCIMEINTO | X1: FECHA DE INICIO CUARENTENA | Y1: PORCENTAJE DE PERDIDA DEL MES | Z1: OBSERVACIONES | AB1: CAUSAS PERDIDA DE BIOLÓGICOS (Remítase a la primera hoja donde se especifica la clasificación de las perdidas) | AO1: TOTAL DOSIS PERDIDAS
F2: DOSIS APLICADAS COLOMBIANOS | G2: DOSIS APLICADAS EXTRANJEROS | H2: DOSIS INGRESADAS POR TRASLADOS DE MUNICIPIOS O IPS | I2: DOSIS TRASLADADAS A OTROS MUNICIPIOS O IPS | AB2: 1 | AE2: 2 | AF2: 3 | AG2: 4 | AH2: 5 | AI2: 6 | AJ2: 7 | AK2: 8 | AL2: 9 | AM2: 10 | AN2: 11
AB3: POLÍTICA DE FRASCOS ABIERTO | AE3: INTERRUPCIÓN DE CADENA DE FRÍO | AF3: CONTAMINACION DEL BIOLÓGICO/DISPOSITIVO MÉDICO | AG3: VIAL ROTO | AH3: ERRORES EN LA MANIPULACIÓN | AI3: VENCIMIENTO DEL BIOLÓGICO O JERINGA | AJ3: FARMACOVIGILANCIA / TECNOVIGILANCIA | AK3: VOMITO FRANCO | AL3: APLICACIÓN FUERA DE LA EDAD | AM3: POR DECISIÓN FINAL DEL PACIENTE DE NO VACUNACIÓN | AN3: SINIESTRO O ROBO
AB4: INSTITUCIONAL | AC4: EXTRAMURAL | AD4: TOTAL
A5: 1 | B5: Vacuna de BCG (Bacilo de Calmette y Guérin) Liofilizada | D5: =+Marzo!M5 -> 10 | E5: 10 | F5: 0 | J5: =+F5+G5 -> 0 | K5: =+AO5 -> 0 | L5: =+J5+K5 -> 0 | M5: =+(D5+E5)-(L5)+H5-I5 -> 20 | N5: 10 | O5: 0373M117 | P5: SERUM | Q5: 46203 | R5: =IF(Q5=0," ",IFERROR(IF(DATEDIF(TODAY(),Q5,"M")<=5,"ROJO",IF(DATEDIF(TODAY(),Q5,"M")>=12,"VERDE",IF(AND(DATEDIF(TODAY(),Q5,"M")>=6,DATEDIF(TODAY(),Q5,"M")<=11),"AMARILLO"))),S5)) -> NO VENCIDO | S5: =IF(Q5=0," ",IF(Q5<=$N$4,"VENCIDO","NO VENCIDO")) -> NO VENCIDO | Y5: =+AT5 -> 0 | AD5: =+AB5+AC5 -> 0 | AO5: =SUM(AD5:AN9) -> 0
N6: 10 | O6: 0374MA071 | P6: SERUM | Q6: 46387 | R6: =IF(Q6=0," ",IFERROR(IF(DATEDIF(TODAY(),Q6,"M")<=5,"ROJO",IF(DATEDIF(TODAY(),Q6,"M")>=12,"VERDE",IF(AND(DATEDIF(TODAY(),Q6,"M")>=6,DATEDIF(TODAY(),Q6,"M")<=11),"AMARILLO"))),S6)) -> ROJO | S6: =IF(Q6=0," ",IF(Q6<=$N$4,"VENCIDO","NO VENCIDO")) -> NO VENCIDO
R7: =IF(Q7=0," ",IFERROR(IF(DATEDIF(TODAY(),Q7,"M")<=5,"ROJO",IF(DATEDIF(TODAY(),Q7,"M")>=12,"VERDE",IF(AND(DATEDIF(TODAY(),Q7,"M")>=6,DATEDIF(TODAY(),Q7,"M")<=11),"AMARILLO"))),S7)) | S7: =IF(Q7=0," ",IF(Q7<=$N$4,"VENCIDO","NO VENCIDO"))
R8: =IF(Q8=0," ",IFERROR(IF(DATEDIF(TODAY(),Q8,"M")<=5,"ROJO",IF(DATEDIF(TODAY(),Q8,"M")>=12,"VERDE",IF(AND(DATEDIF(TODAY(),Q8,"M")>=6,DATEDIF(TODAY(),Q8,"M")<=11),"AMARILLO"))),S8)) | S8: =IF(Q8=0," ",IF(Q8<=$N$4,"VENCIDO","NO VENCIDO"))
R9: =IF(Q9=0," ",IFERROR(IF(DATEDIF(TODAY(),Q9,"M")<=5,"ROJO",IF(DATEDIF(TODAY(),Q9,"M")>=12,"VERDE",IF(AND(DATEDIF(TODAY(),Q9,"M")>=6,DATEDIF(TODAY(),Q9,"M")<=11),"AMARILLO"))),S9)) | S9: =IF(Q9=0," ",IF(Q9<=$N$4,"VENCIDO","NO VENCIDO"))
M10: =M5=N10 -> TRUE | N10: =SUM(N5:N9) -> 20 | O10: “Verdadero” indica que la cantidad por lote, coincide con el saldo que inicia al mes siguiente. "Falso" no coinicide. | T10: =SUM(T5:T9) -> 0
A11: =A5+1 -> 2 | B11: Vacuna de Hepatitis B Recombinante Pediátrica - Liquida | D11: =+Marzo!M11 -> 23 | E11: 0 | F11: 0 | J11: =+F11+G11 -> 0 | K11: =+AO11 -> 0 | L11: =+J11+K11 -> 0 | M11: =+(D11+E11)-(L11)+H11-I11 -> 23 | N11: 10 | O11: 0324L013A | P11: SERUM | Q11: 46721 | R11: =IF(Q11=0," ",IFERROR(IF(DATEDIF(TODAY(),Q11,"M")<=5,"ROJO",IF(DATEDIF(TODAY(),Q11,"M")>=12,"VERDE",IF(AND(DATEDIF(TODAY(),Q11,"M")>=6,DATEDIF(TODAY(),Q11,"M")<=11),"AMARILLO"))),S11)) -> VERDE | S11: =IF(Q11=0," ",IF(Q11<=$N$4,"VENCIDO","NO VENCIDO")) -> NO VENCIDO | Y11: =+AT11 -> 0 | AD11: =+AB11+AC11 -> 0 | AO11: =SUM(AD11:AN15) -> 0
N12: 13 | O12: 0323X019E | P12: SERUM | Q12: 46173 | R12: =IF(Q12=0," ",IFERROR(IF(DATEDIF(TODAY(),Q12,"M")<=5,"ROJO",IF(DATEDIF(TODAY(),Q12,"M")>=12,"VERDE",IF(AND(DATEDIF(TODAY(),Q12,"M")>=6,DATEDIF(TODAY(),Q12,"M")<=11),"AMARILLO"))),S12)) -> NO VENCIDO | S12: =IF(Q12=0," ",IF(Q12<=$N$4,"VENCIDO","NO VENCIDO")) -> NO VENCIDO
R13: =IF(Q13=0," ",IFERROR(IF(DATEDIF(TODAY(),Q13,"M")<=5,"ROJO",IF(DATEDIF(TODAY(),Q13,"M")>=12,"VERDE",IF(AND(DATEDIF(TODAY(),Q13,"M")>=6,DATEDIF(TODAY(),Q13,"M")<=11),"AMARILLO"))),S13)) | S13: =IF(Q13=0," ",IF(Q13<=$N$4,"VENCIDO","NO VENCIDO"))
R14: =IF(Q14=0," ",IFERROR(IF(DATEDIF(TODAY(),Q14,"M")<=5,"ROJO",IF(DATEDIF(TODAY(),Q14,"M")>=12,"VERDE",IF(AND(DATEDIF(TODAY(),Q14,"M")>=6,DATEDIF(TODAY(),Q14,"M")<=11),"AMARILLO"))),S14)) | S14: =IF(Q14=0," ",IF(Q14<=$N$4,"VENCIDO","NO VENCIDO"))
R15: =IF(Q15=0," ",IFERROR(IF(DATEDIF(TODAY(),Q15,"M")<=5,"ROJO",IF(DATEDIF(TODAY(),Q15,"M")>=12,"VERDE",IF(AND(DATEDIF(TODAY(),Q15,"M")>=6,DATEDIF(TODAY(),Q15,"M")<=11),"AMARILLO"))),S15)) | S15: =IF(Q15=0," ",IF(Q15<=$N$4,"VENCIDO","NO VENCIDO"))
M16: =M11=N16 -> TRUE | N16: =SUM(N11:N15) -> 23 | O16: “Verdadero” indica que la cantidad por lote, coincide con el saldo que inicia al mes siguiente. "Falso" no coinicide. | T16: =SUM(T11:T15) -> 0
A17: =A11+1 -> 3 | B17: Vacuna de Hepatitis B Recombinante Adultos - Liquida | D17: =+Marzo!M17 -> 0 | E17: 0 | F17: 0 | J17: =+F17+G17 -> 0 | K17: =+AO17 -> 0 | L17: =+J17+K17 -> 0 | M17: =+(D17+E17)-(L17)+H17-I17 -> 0 | R17: =IF(Q17=0," ",IFERROR(IF(DATEDIF(TODAY(),Q17,"M")<=5,"ROJO",IF(DATEDIF(TODAY(),Q17,"M")>=12,"VERDE",IF(AND(DATEDIF(TODAY(),Q17,"M")>=6,DATEDIF(TODAY(),Q17,"M")<=11),"AMARILLO"))),S17)) | S17: =IF(Q17=0," ",IF(Q17<=$N$4,"VENCIDO","NO VENCIDO")) | Y17: =+AT17 -> 0 | AD17: =+AB17+AC17 -> 0 | AO17: =SUM(AD17:AN21) -> 0
R18: =IF(Q18=0," ",IFERROR(IF(DATEDIF(TODAY(),Q18,"M")<=5,"ROJO",IF(DATEDIF(TODAY(),Q18,"M")>=12,"VERDE",IF(AND(DATEDIF(TODAY(),Q18,"M")>=6,DATEDIF(TODAY(),Q18,"M")<=11),"AMARILLO"))),S18)) | S18: =IF(Q18=0," ",IF(Q18<=$N$4,"VENCIDO","NO VENCIDO"))
R19: =IF(Q19=0," ",IFERROR(IF(DATEDIF(TODAY(),Q19,"M")<=5,"ROJO",IF(DATEDIF(TODAY(),Q19,"M")>=12,"VERDE",IF(AND(DATEDIF(TODAY(),Q19,"M")>=6,DATEDIF(TODAY(),Q19,"M")<=11),"AMARILLO"))),S19)) | S19: =IF(Q19=0," ",IF(Q19<=$N$4,"VENCIDO","NO VENCIDO"))
R20: =IF(Q20=0," ",IFERROR(IF(DATEDIF(TODAY(),Q20,"M")<=5,"ROJO",IF(DATEDIF(TODAY(),Q20,"M")>=12,"VERDE",IF(AND(DATEDIF(TODAY(),Q20,"M")>=6,DATEDIF(TODAY(),Q20,"M")<=11),"AMARILLO"))),S20)) | S20: =IF(Q20=0," ",IF(Q20<=$N$4,"VENCIDO","NO VENCIDO"))
R21: =IF(Q21=0," ",IFERROR(IF(DATEDIF(TODAY(),Q21,"M")<=5,"ROJO",IF(DATEDIF(TODAY(),Q21,"M")>=12,"VERDE",IF(AND(DATEDIF(TODAY(),Q21,"M")>=6,DATEDIF(TODAY(),Q21,"M")<=11),"AMARILLO"))),S21)) | S21: =IF(Q21=0," ",IF(Q21<=$N$4,"VENCIDO","NO VENCIDO"))
M22: =M17=N22 -> TRUE | N22: =SUM(N17:N21) -> 0 | O22: “Verdadero” indica que la cantidad por lote, coincide con el saldo que inicia al mes siguiente. "Falso" no coinicide. | T22: =SUM(T17:T21) -> 0
A23: =A17+1 -> 4 | B23: Vacuna de Poliovirus Inactiva IPV - Liquida | D23: =+Marzo!M23 -> 26 | E23: 30 | F23: 36 | J23: =+F23+G23 -> 36 | K23: =+AO23 -> 0 | L23: =+J23+K23 -> 36 | M23: =+(D23+E23)-(L23)+H23-I23 -> 20 | N23: 20 | O23: 2522006A | P23: BILTHOVEN | Q23: 46808 | R23: =IF(Q23=0," ",IFERROR(IF(DATEDIF(TODAY(),Q23,"M")<=5,"ROJO",IF(DATEDIF(TODAY(),Q23,"M")>=12,"VERDE",IF(AND(DATEDIF(TODAY(),Q23,"M")>=6,DATEDIF(TODAY(),Q23,"M")<=11),"AMARILLO"))),S23)) -> VERDE | S23: =IF(Q23=0," ",IF(Q23<=$N$4,"VENCIDO","NO VENCIDO")) -> NO VENCIDO | Y23: =+AT23 -> 0 | AD23: =+AB23+AC23 -> 0 | AO23: =SUM(AD23:AN27) -> 0
R24: =IF(Q24=0," ",IFERROR(IF(DATEDIF(TODAY(),Q24,"M")<=5,"ROJO",IF(DATEDIF(TODAY(),Q24,"M")>=12,"VERDE",IF(AND(DATEDIF(TODAY(),Q24,"M")>=6,DATEDIF(TODAY(),Q24,"M")<=11),"AMARILLO"))),S24)) | S24: =IF(Q24=0," ",IF(Q24<=$N$4,"VENCIDO","NO VENCIDO"))
R25: =IF(Q25=0," ",IFERROR(IF(DATEDIF(TODAY(),Q25,"M")<=5,"ROJO",IF(DATEDIF(TODAY(),Q25,"M")>=12,"VERDE",IF(AND(DATEDIF(TODAY(),Q25,"M")>=6,DATEDIF(TODAY(),Q25,"M")<=11),"AMARILLO"))),S25)) | S25: =IF(Q25=0," ",IF(Q25<=$N$4,"VENCIDO","NO VENCIDO"))
R26: =IF(Q26=0," ",IFERROR(IF(DATEDIF(TODAY(),Q26,"M")<=5,"ROJO",IF(DATEDIF(TODAY(),Q26,"M")>=12,"VERDE",IF(AND(DATEDIF(TODAY(),Q26,"M")>=6,DATEDIF(TODAY(),Q26,"M")<=11),"AMARILLO"))),S26)) | S26: =IF(Q26=0," ",IF(Q26<=$N$4,"VENCIDO","NO VENCIDO"))
R27: =IF(Q27=0," ",IFERROR(IF(DATEDIF(TODAY(),Q27,"M")<=5,"ROJO",IF(DATEDIF(TODAY(),Q27,"M")>=12,"VERDE",IF(AND(DATEDIF(TODAY(),Q27,"M")>=6,DATEDIF(TODAY(),Q27,"M")<=11),"AMARILLO"))),S27)) | S27: =IF(Q27=0," ",IF(Q27<=$N$4,"VENCIDO","NO VENCIDO"))
M28: =M23=N28 -> TRUE | N28: =SUM(N23:N27) -> 20 | O28: “Verdadero” indica que la cantidad por lote, coincide con el saldo que inicia al mes siguiente. "Falso" no coinicide. | T28: =SUM(T23:T27) -> 0
A29: =A23+1 -> 5 | B29: Vacuna de Difteria - Tos ferina (Celula completa) - Tétanos - Hepatitis B - Haemophilus influenzae tipo B (DTwP-HepB-Hib) PENTAVALENTE PEDIÁTRICA - Liquida | D29: =+Marzo!M29 -> 14 | E29: 40 | F29: 28 | J29: =+F29+G29 -> 28 | K29: =+AO29 -> 0 | L29: =+J29+K29 -> 28 | M29: =+(D29+E29)-(L29)+H29-I29 -> 26 | N29: 26 | O29: 2855X062C | P29: SERUM | Q29: 46568 | R29: =IF(Q29=0," ",IFERROR(IF(DATEDIF(TODAY(),Q29,"M")<=5,"ROJO",IF(DATEDIF(TODAY(),Q29,"M")>=12,"VERDE",IF(AND(DATEDIF(TODAY(),Q29,"M")>=6,DATEDIF(TODAY(),Q29,"M")<=11),"AMARILLO"))),S29)) -> AMARILLO | S29: =IF(Q29=0," ",IF(Q29<=$N$4,"VENCIDO","NO VENCIDO")) -> NO VENCIDO | Y29: =+AT29 -> 0 | AD29: =+AB29+AC29 -> 0 | AO29: =SUM(AD29:AN33) -> 0
R30: =IF(Q30=0," ",IFERROR(IF(DATEDIF(TODAY(),Q30,"M")<=5,"ROJO",IF(DATEDIF(TODAY(),Q30,"M")>=12,"VERDE",IF(AND(DATEDIF(TODAY(),Q30,"M")>=6,DATEDIF(TODAY(),Q30,"M")<=11),"AMARILLO"))),S30)) | S30: =IF(Q30=0," ",IF(Q30<=$N$4,"VENCIDO","NO VENCIDO"))
R31: =IF(Q31=0," ",IFERROR(IF(DATEDIF(TODAY(),Q31,"M")<=5,"ROJO",IF(DATEDIF(TODAY(),Q31,"M")>=12,"VERDE",IF(AND(DATEDIF(TODAY(),Q31,"M")>=6,DATEDIF(TODAY(),Q31,"M")<=11),"AMARILLO"))),S31)) | S31: =IF(Q31=0," ",IF(Q31<=$N$4,"VENCIDO","NO VENCIDO"))
R32: =IF(Q32=0," ",IFERROR(IF(DATEDIF(TODAY(),Q32,"M")<=5,"ROJO",IF(DATEDIF(TODAY(),Q32,"M")>=12,"VERDE",IF(AND(DATEDIF(TODAY(),Q32,"M")>=6,DATEDIF(TODAY(),Q32,"M")<=11),"AMARILLO"))),S32)) | S32: =IF(Q32=0," ",IF(Q32<=$N$4,"VENCIDO","NO VENCIDO"))
R33: =IF(Q33=0," ",IFERROR(IF(DATEDIF(TODAY(),Q33,"M")<=5,"ROJO",IF(DATEDIF(TODAY(),Q33,"M")>=12,"VERDE",IF(AND(DATEDIF(TODAY(),Q33,"M")>=6,DATEDIF(TODAY(),Q33,"M")<=11),"AMARILLO"))),S33)) | S33: =IF(Q33=0," ",IF(Q33<=$N$4,"VENCIDO","NO VENCIDO"))
M34: =M29=N34 -> TRUE | N34: =SUM(N29:N33) -> 26 | O34: “Verdadero” indica que la cantidad por lote, coincide con el saldo que inicia al mes siguiente. "Falso" no coinicide. | T34: =SUM(T29:T33) -> 0
A35: =A29+1 -> 6 | B35: Vacuna de Difteria - Tétanos - Tos ferina acelular - Poliovirus inactivado - Hepatitis B - Haemophilus influenzae tipo B (DTaP-IPV-HepB-Hib (HEXAVALENTE ACELULAR) - Liquida | D35: =+Marzo!M35 -> 3 | E35: 0 | F35: 0 | J35: =+F35+G35 -> 0 | K35: =+AO35 -> 0 | L35: =+J35+K35 -> 0 | M35: =+(D35+E35)-(L35)+H35-I35 -> 3 | N35: 3 | O35: 4CA03C1 | P35: SANOFI | Q35: 46325 | R35: =IF(Q35=0," ",IFERROR(IF(DATEDIF(TODAY(),Q35,"M")<=5,"ROJO",IF(DATEDIF(TODAY(),Q35,"M")>=12,"VERDE",IF(AND(DATEDIF(TODAY(),Q35,"M")>=6,DATEDIF(TODAY(),Q35,"M")<=11),"AMARILLO"))),S35)) -> ROJO | S35: =IF(Q35=0," ",IF(Q35<=$N$4,"VENCIDO","NO VENCIDO")) -> NO VENCIDO | Y35: =+AT35 -> 0 | AD35: =+AB35+AC35 -> 0 | AO35: =SUM(AD35:AN39) -> 0
R36: =IF(Q36=0," ",IFERROR(IF(DATEDIF(TODAY(),Q36,"M")<=5,"ROJO",IF(DATEDIF(TODAY(),Q36,"M")>=12,"VERDE",IF(AND(DATEDIF(TODAY(),Q36,"M")>=6,DATEDIF(TODAY(),Q36,"M")<=11),"AMARILLO"))),S36)) | S36: =IF(Q36=0," ",IF(Q36<=$N$4,"VENCIDO","NO VENCIDO"))
R37: =IF(Q37=0," ",IFERROR(IF(DATEDIF(TODAY(),Q37,"M")<=5,"ROJO",IF(DATEDIF(TODAY(),Q37,"M")>=12,"VERDE",IF(AND(DATEDIF(TODAY(),Q37,"M")>=6,DATEDIF(TODAY(),Q37,"M")<=11),"AMARILLO"))),S37)) | S37: =IF(Q37=0," ",IF(Q37<=$N$4,"VENCIDO","NO VENCIDO"))
R38: =IF(Q38=0," ",IFERROR(IF(DATEDIF(TODAY(),Q38,"M")<=5,"ROJO",IF(DATEDIF(TODAY(),Q38,"M")>=12,"VERDE",IF(AND(DATEDIF(TODAY(),Q38,"M")>=6,DATEDIF(TODAY(),Q38,"M")<=11),"AMARILLO"))),S38)) | S38: =IF(Q38=0," ",IF(Q38<=$N$4,"VENCIDO","NO VENCIDO"))
R39: =IF(Q39=0," ",IFERROR(IF(DATEDIF(TODAY(),Q39,"M")<=5,"ROJO",IF(DATEDIF(TODAY(),Q39,"M")>=12,"VERDE",IF(AND(DATEDIF(TODAY(),Q39,"M")>=6,DATEDIF(TODAY(),Q39,"M")<=11),"AMARILLO"))),S39)) | S39: =IF(Q39=0," ",IF(Q39<=$N$4,"VENCIDO","NO VENCIDO"))
M40: =M35=N40 -> TRUE | N40: =SUM(N35:N39) -> 3 | O40: “Verdadero” indica que la cantidad por lote, coincide con el saldo que inicia al mes siguiente. "Falso" no coinicide. | T40: =SUM(T35:T39) -> 0
...

Sheet Mayo
A1: ÍTEM | B1: INSUMOS | D1: SALDO MES ANTERIOR | E1: BIOLÓGICO RECIBIDO DEL CENTRO DE ACOPIO DEPARTAMENTAL / DISTRITAL | F1: DOSIS APLICADAS | H1: Entradas | I1: Salidas | J1: TOTAL DOSIS APLICADAS | K1: DOSIS PERDIDAS | L1: TOTAL DOSIS ÚTILIZADAS EN EL MES | M1: SALDO QUE INICIA EL MES SIGUIENTE (SOLO MUNICIPIOS) | N1: DOSIS POR LOTES | O1: No. LOTE | P1: LABORATORIO | Q1: FECHA DE VENCIMIENTO | R1: SEMAFORIZACION VIDA ÚTIL DEL BIOLÓGICO | S1: CONDICIÓN FINAL DEL BIOLÓGICO, DILUYENTE Y CARNET | T1: DOSIS EN CUARENTENA | U1: LABORATORIO | V1: No. LOTE | W1: FECHA DE VENCIMEINTO | X1: FECHA DE INICIO CUARENTENA | Y1: PORCENTAJE DE PERDIDA DEL MES | Z1: OBSERVACIONES | AB1: CAUSAS PERDIDA DE BIOLÓGICOS (Remítase a la primera hoja donde se especifica la clasificación de las perdidas) | AO1: TOTAL DOSIS PERDIDAS
F2: DOSIS APLICADAS COLOMBIANOS | G2: DOSIS APLICADAS EXTRANJEROS | H2: DOSIS INGRESADAS POR TRASLADOS DE MUNICIPIOS O IPS | I2: DOSIS TRASLADADAS A OTROS MUNICIPIOS O IPS | AB2: 1 | AE2: 2 | AF2: 3 | AG2: 4 | AH2: 5 | AI2: 6 | AJ2: 7 | AK2: 8 | AL2: 9 | AM2: 10 | AN2: 11
AB3: POLÍTICA DE FRASCOS ABIERTO | AE3: INTERRUPCIÓN DE CADENA DE FRÍO | AF3: CONTAMINACION DEL BIOLÓGICO/DISPOSITIVO MÉDICO | AG3: VIAL ROTO | AH3: ERRORES EN LA MANIPULACIÓN | AI3: VENCIMIENTO DEL BIOLÓGICO O JERINGA | AJ3: FARMACOVIGILANCIA / TECNOVIGILANCIA | AK3: VOMITO FRANCO | AL3: APLICACIÓN FUERA DE LA EDAD | AM3: POR DECISIÓN FINAL DEL PACIENTE DE NO VACUNACIÓN | AN3: SINIESTRO O ROBO
AB4: INSTITUCIONAL | AC4: EXTRAMURAL | AD4: TOTAL
A5: 1 | B5: Vacuna de BCG (Bacilo de Calmette y Guérin) Liofilizada | D5: =+Abril!M5 -> 20 | G5: 0 | J5: =+F5+G5 -> 0 | K5: =+AO5 -> 0 | L5: =+J5+K5 -> 0 | M5: =+(D5+E5)-(L5)+H5-I5 -> 20 | N5: 10 | O5: 0373M117 | P5: SERUM | Q5: 46203 | R5: =IF(Q5=0," ",IFERROR(IF(DATEDIF(TODAY(),Q5,"M")<=5,"ROJO",IF(DATEDIF(TODAY(),Q5,"M")>=12,"VERDE",IF(AND(DATEDIF(TODAY(),Q5,"M")>=6,DATEDIF(TODAY(),Q5,"M")<=11),"AMARILLO"))),S5)) -> NO VENCIDO | S5: =IF(Q5=0," ",IF(Q5<=$N$4,"VENCIDO","NO VENCIDO")) -> NO VENCIDO | Y5: =+AT5 -> 0 | AD5: =+AB5+AC5 -> 0 | AO5: =SUM(AD5:AN9) -> 0
N6: 10 | O6: 0374MA071 | P6: SERUM | Q6: 46387 | R6: =IF(Q6=0," ",IFERROR(IF(DATEDIF(TODAY(),Q6,"M")<=5,"ROJO",IF(DATEDIF(TODAY(),Q6,"M")>=12,"VERDE",IF(AND(DATEDIF(TODAY(),Q6,"M")>=6,DATEDIF(TODAY(),Q6,"M")<=11),"AMARILLO"))),S6)) -> ROJO | S6: =IF(Q6=0," ",IF(Q6<=$N$4,"VENCIDO","NO VENCIDO")) -> NO VENCIDO
R7: =IF(Q7=0," ",IFERROR(IF(DATEDIF(TODAY(),Q7,"M")<=5,"ROJO",IF(DATEDIF(TODAY(),Q7,"M")>=12,"VERDE",IF(AND(DATEDIF(TODAY(),Q7,"M")>=6,DATEDIF(TODAY(),Q7,"M")<=11),"AMARILLO"))),S7)) | S7: =IF(Q7=0," ",IF(Q7<=$N$4,"VENCIDO","NO VENCIDO"))
R8: =IF(Q8=0," ",IFERROR(IF(DATEDIF(TODAY(),Q8,"M")<=5,"ROJO",IF(DATEDIF(TODAY(),Q8,"M")>=12,"VERDE",IF(AND(DATEDIF(TODAY(),Q8,"M")>=6,DATEDIF(TODAY(),Q8,"M")<=11),"AMARILLO"))),S8)) | S8: =IF(Q8=0," ",IF(Q8<=$N$4,"VENCIDO","NO VENCIDO"))
R9: =IF(Q9=0," ",IFERROR(IF(DATEDIF(TODAY(),Q9,"M")<=5,"ROJO",IF(DATEDIF(TODAY(),Q9,"M")>=12,"VERDE",IF(AND(DATEDIF(TODAY(),Q9,"M")>=6,DATEDIF(TODAY(),Q9,"M")<=11),"AMARILLO"))),S9)) | S9: =IF(Q9=0," ",IF(Q9<=$N$4,"VENCIDO","NO VENCIDO"))
M10: =M5=N10 -> TRUE | N10: =SUM(N5:N9) -> 20 | O10: “Verdadero” indica que la cantidad por lote, coincide con el saldo que inicia al mes siguiente. "Falso" no coinicide. | T10: =SUM(T5:T9) -> 0
A11: =A5+1 -> 2 | B11: Vacuna de Hepatitis B Recombinante Pediátrica - Liquida | D11: =+Abril!M11 -> 23 | F11: 12 | G11: 1 | J11: =+F11+G11 -> 13 | K11: =+AO11 -> 0 | L11: =+J11+K11 -> 13 | M11: =+(D11+E11)-(L11)+H11-I11 -> 10 | N11: 10 | O11: 0324L013A | P11: SERUM | Q11: 46721 | R11: =IF(Q11=0," ",IFERROR(IF(DATEDIF(TODAY(),Q11,"M")<=5,"ROJO",IF(DATEDIF(TODAY(),Q11,"M")>=12,"VERDE",IF(AND(DATEDIF(TODAY(),Q11,"M")>=6,DATEDIF(TODAY(),Q11,"M")<=11),"AMARILLO"))),S11)) -> VERDE | S11: =IF(Q11=0," ",IF(Q11<=$N$4,"VENCIDO","NO VENCIDO")) -> NO VENCIDO | Y11: =+AT11 -> 0 | AD11: =+AB11+AC11 -> 0 | AO11: =SUM(AD11:AN15) -> 0
R12: =IF(Q12=0," ",IFERROR(IF(DATEDIF(TODAY(),Q12,"M")<=5,"ROJO",IF(DATEDIF(TODAY(),Q12,"M")>=12,"VERDE",IF(AND(DATEDIF(TODAY(),Q12,"M")>=6,DATEDIF(TODAY(),Q12,"M")<=11),"AMARILLO"))),S12)) | S12: =IF(Q12=0," ",IF(Q12<=$N$4,"VENCIDO","NO VENCIDO"))
R13: =IF(Q13=0," ",IFERROR(IF(DATEDIF(TODAY(),Q13,"M")<=5,"ROJO",IF(DATEDIF(TODAY(),Q13,"M")>=12,"VERDE",IF(AND(DATEDIF(TODAY(),Q13,"M")>=6,DATEDIF(TODAY(),Q13,"M")<=11),"AMARILLO"))),S13)) | S13: =IF(Q13=0," ",IF(Q13<=$N$4,"VENCIDO","NO VENCIDO"))
R14: =IF(Q14=0," ",IFERROR(IF(DATEDIF(TODAY(),Q14,"M")<=5,"ROJO",IF(DATEDIF(TODAY(),Q14,"M")>=12,"VERDE",IF(AND(DATEDIF(TODAY(),Q14,"M")>=6,DATEDIF(TODAY(),Q14,"M")<=11),"AMARILLO"))),S14)) | S14: =IF(Q14=0," ",IF(Q14<=$N$4,"VENCIDO","NO VENCIDO"))
R15: =IF(Q15=0," ",IFERROR(IF(DATEDIF(TODAY(),Q15,"M")<=5,"ROJO",IF(DATEDIF(TODAY(),Q15,"M")>=12,"VERDE",IF(AND(DATEDIF(TODAY(),Q15,"M")>=6,DATEDIF(TODAY(),Q15,"M")<=11),"AMARILLO"))),S15)) | S15: =IF(Q15=0," ",IF(Q15<=$N$4,"VENCIDO","NO VENCIDO"))
M16: =M11=N16 -> TRUE | N16: =SUM(N11:N15) -> 10 | O16: “Verdadero” indica que la cantidad por lote, coincide con el saldo que inicia al mes siguiente. "Falso" no coinicide. | T16: =SUM(T11:T15) -> 0
